Workbook

Sheet AXIS 3167
A1: Name :- AJAY KUMAR GUPTA
A2: Joint Holder :- -
A3: FLAT NO D-07 ISHWAR PARADISE ASHOKA MARG
A4: NASHIK BEHIND INOX THEATRE
A5: NASHIK-422011
A6: MAHARASHTRA-INDIA
A7: Customer ID :- 837058342
A8: IFSC Code :- UTIB0000115
A9: MICR Code :- 422211002
A10: Nominee Registered :- Y
A11: Registered Mobile No :- XXXXXX4014
A12: Registered Email ID :- g.XXXXay@yahoo.com
A13: PAN :- ACLPG1926E
A14: Statement of Account No - 910010047943167 for the period (From : 01-04-2023 To : 31-12-2023) | D14: =SUBTOTAL(9,D16:D186) -> 2424706.7 | E14: =SUBTOTAL(9,E16:E186) -> 2267777.9 | F14: =F16+D16 -> 188100.16
A15: SRL NO | B15: Tran Date | C15: PARTICULARS | D15: DR | E15: CR | F15: BAL | G15: Account No | I15: TX Date | J15: Particulars | K15: Ref | L15: DR | M15: CR | N15: Balance | O15: Account No
A16: 1 | B16: 45018 | C16: UPI/P2A/345797693295/SACHIN BA/Kotak Mah/Diesal | D16: 3400 | E16: 0 | F16: 184700.16 | G16: AXIS 3167 | H16: =F14-D16+E16-F16 -> 0 | I16: =B16 -> 45018 | J16: =C16 -> UPI/P2A/345797693295/SACHIN BA/Kotak Mah/Diesal | L16: =D16 -> 3400 | M16: =E16 -> 0 | N16: =F16 -> 184700.16 | O16: =G16 -> AXIS 3167
A17: 2 | B17: 45018 | C17: UPI/P2M/345789552921/MANISH HE/Yes Bank /Amle | D17: 230 | E17: 0 | F17: 184470.16 | G17: AXIS 3167 | H17: =F16-D17+E17-F17 -> 0 | I17: =B17 -> 45018 | J17: =C17 -> UPI/P2M/345789552921/MANISH HE/Yes Bank /Amle | L17: =D17 -> 230 | M17: =E17 -> 0 | N17: =F17 -> 184470.16 | O17: =G17 -> AXIS 3167
A18: 3 | B18: 45018 | C18: UPI/P2M/345726651875/SAGAR SWE/Yes Bank /sweets | D18: 416 | E18: 0 | F18: 184054.16 | G18: AXIS 3167 | H18: =F17-D18+E18-F18 -> 0 | I18: =B18 -> 45018 | J18: =C18 -> UPI/P2M/345726651875/SAGAR SWE/Yes Bank /sweets | L18: =D18 -> 416 | M18: =E18 -> 0 | N18: =F18 -> 184054.16 | O18: =G18 -> AXIS 3167
A19: 4 | B19: 45018 | C19: INB/NEFT/AXIR230915974036/Ajay Kum/STATE B/Housin | D19: 100000 | E19: 0 | F19: 84054.16 | G19: AXIS 3167 | H19: =F18-D19+E19-F19 -> 0 | I19: =B19 -> 45018 | J19: =C19 -> INB/NEFT/AXIR230915974036/Ajay Kum/STATE B/Housin | L19: =D19 -> 100000 | M19: =E19 -> 0 | N19: =F19 -> 84054.16 | O19: =G19 -> AXIS 3167
A20: 5 | B20: 45020 | C20: UPI/P2M/346037289751/SHAGUN TR/Yes Bank /Ice cre | D20: 115 | E20: 0 | F20: 83939.16 | G20: AXIS 3167 | H20: =F19-D20+E20-F20 -> 0 | I20: =B20 -> 45020 | J20: =C20 -> UPI/P2M/346037289751/SHAGUN TR/Yes Bank /Ice cre | L20: =D20 -> 115 | M20: =E20 -> 0 | N20: =F20 -> 83939.16 | O20: =G20 -> AXIS 3167
A21: 6 | B21: 45023 | C21: BRN-PYMT-CARD-4111460000883615 | D21: 10917.37 | E21: 0 | F21: 73021.79 | G21: AXIS 3167 | H21: =F20-D21+E21-F21 -> 0 | I21: =B21 -> 45023 | J21: =C21 -> BRN-PYMT-CARD-4111460000883615 | L21: =D21 -> 10917.37 | M21: =E21 -> 0 | N21: =F21 -> 73021.79 | O21: =G21 -> AXIS 3167
A22: 7 | B22: 45034 | C22: UPI/P2A/347498540738/SANGITA R/State Ban/Teeth i | D22: 15000 | E22: 0 | F22: 58021.79 | G22: AXIS 3167 | H22: =F21-D22+E22-F22 -> 0 | I22: =B22 -> 45034 | J22: =C22 -> UPI/P2A/347498540738/SANGITA R/State Ban/Teeth i | L22: =D22 -> 15000 | M22: =E22 -> 0 | N22: =F22 -> 58021.79 | O22: =G22 -> AXIS 3167
A23: 8 | B23: 45034 | C23: ATM-CASH-AXIS/BPRH265601/7630/180423/NASHIK | D23: 20000 | E23: 0 | F23: 38021.79 | G23: AXIS 3167 | H23: =F22-D23+E23-F23 -> 0 | I23: =B23 -> 45034 | J23: =C23 -> ATM-CASH-AXIS/BPRH265601/7630/180423/NASHIK | L23: =D23 -> 20000 | M23: =E23 -> 0 | N23: =F23 -> 38021.79 | O23: =G23 -> AXIS 3167
A24: 9 | B24: 45034 | C24: CASH-AXIS-RVSL/180423/21:04 | D24: 0 | E24: 20000 | F24: 58021.79 | G24: AXIS 3167 | H24: =F23-D24+E24-F24 -> 0 | I24: =B24 -> 45034 | J24: =C24 -> CASH-AXIS-RVSL/180423/21:04 | L24: =D24 -> 0 | M24: =E24 -> 20000 | N24: =F24 -> 58021.79 | O24: =G24 -> AXIS 3167
A25: 10 | B25: 45034 | C25: ATM-CASH-AXIS/BPRH265601/7631/180423/NASHIK | D25: 10000 | E25: 0 | F25: 48021.79 | G25: AXIS 3167 | H25: =F24-D25+E25-F25 -> 0 | I25: =B25 -> 45034 | J25: =C25 -> ATM-CASH-AXIS/BPRH265601/7631/180423/NASHIK | L25: =D25 -> 10000 | M25: =E25 -> 0 | N25: =F25 -> 48021.79 | O25: =G25 -> AXIS 3167
A26: 11 | B26: 45034 | C26: CASH-AXIS-RVSL/180423/21:06 | D26: 0 | E26: 10000 | F26: 58021.79 | G26: AXIS 3167 | H26: =F25-D26+E26-F26 -> 0 | I26: =B26 -> 45034 | J26: =C26 -> CASH-AXIS-RVSL/180423/21:06 | L26: =D26 -> 0 | M26: =E26 -> 10000 | N26: =F26 -> 58021.79 | O26: =G26 -> AXIS 3167
A27: 12 | B27: 45036 | C27: UPI/P2A/311016102687/AMOL DHON/Kotak Mah/Diesal | D27: 3450 | E27: 0 | F27: 54571.79 | G27: AXIS 3167 | H27: =F26-D27+E27-F27 -> 0 | I27: =B27 -> 45036 | J27: =C27 -> UPI/P2A/311016102687/AMOL DHON/Kotak Mah/Diesal | L27: =D27 -> 3450 | M27: =E27 -> 0 | N27: =F27 -> 54571.79 | O27: =G27 -> AXIS 3167
A28: 13 | B28: 45038 | C28: ATM-CASH-AXIS/SPCN11530/8513/220423/SINNAR | D28: 20000 | E28: 0 | F28: 34571.79 | G28: AXIS 3167 | H28: =F27-D28+E28-F28 -> 0 | I28: =B28 -> 45038 | J28: =C28 -> ATM-CASH-AXIS/SPCN11530/8513/220423/SINNAR | L28: =D28 -> 20000 | M28: =E28 -> 0 | N28: =F28 -> 34571.79 | O28: =G28 -> AXIS 3167
... A267: 252 | B267: 45382 | C267: SB:910010047943167:Int.Pd:01-01-2024 to 31-03-2024 | D267: 0 | E267: 1054 | F267: 90615.86 | G267: AXIS 3167 | H267: =F266-D267+E267-F267 -> 0 | I267: =B267 -> 45382 | J267: =C267 -> SB:910010047943167:Int.Pd:01-01-2024 to 31-03-2024 | L267: =D267 -> 0 | M267: =E267 -> 1054 | N267: =F267 -> 90615.86 | O267: =G267 -> AXIS 3167

Sheet BOI 6699
A1: -->
A2: Bank of India
A5: INDUSTRIAL AREA KOTA Branch
A7: Account statement
A9: Name AJAY KUMAR GUPTA
A10: Account No. 662113100016699
A11: Account Type Savings Account
A12: Customer Id 007154451
A13: Statement of Account for the period 01/04/2023 to 31/03/2024
A15: All Amounts in INR
A17: No. | B17: Txn Date | C17: Description | D17: ChequeNo. | E17: Cr/Dr | F17: Amount(INR) | G17: Balance(INR)
A19: 1 | B19: 45043.353 | C19: 662113100016699:SBInt.Pd:01-02-2023 to 26-04-2023 | E19: CR | F19: 55 | G19: 8641 | H19: =G19-F19 -> 8586
A20: 2 | B20: 45043.492 | C20: DORMANT ACCOUNT TRANSFER DEBIT | E20: DR | F20: 8641 | G20: 0
A21: 3 | B21: 45287.778 | C21: 662113100016699 DORMANT ACCOUNT REFUND | E21: CR | F21: 8814 | G21: 8814
A22: 4 | B22: 45288.574 | C22: BY CASH-6621-INDUSTRIAL AREA KOTA | E22: CR | F22: 1000 | G22: 9814
A23: 5 | B23: 45296.76 | C23: NEFT/SBIN424005475251/SBIN/Mr AJAY KUMAR GUPTA | E23: CR | F23: 1000 | G23: 10814
A24: 6 | B24: 45326.624 | C24: 662113100016699:SBInt.Pd:01-11-2023 to 31-01-2024 | E24: CR | F24: 29 | G24: 10843
A25: 7 | B25: 45337.279 | C25: Min Bal Charge+Serv.TAX December23 | E25: DR | F25: 118 | G25: 10725
A26: 8 | B26: 45352.723 | C26: NEFT/SBIN324061157023/SBIN/Mr AJAY KUMAR GUPTA | E26: CR | F26: 5000 | G26: 15725
A28: Any discrepancy in this document of accounts should be notified to the bank within a period of 30 days of receipt
A29: of this statement. It will be treated that the entries/contents of this statement are checked and found correct by
A30: you, if no such complaint is made within the period stated above.
A33: Beware of fictitious offers, messages/SMS about lottery winnings, cheap fund offers, employment offers, scholarship offers, offer of emigration visas, offer of admission to reputed universities abroad and similar such offers from fraudsters either within the country or from abroad.
A35: For any support or clarification please contact Call Centre No.1800 220 229, 1800 103 1906 , 022 40919191.

Sheet HDFC 5930
D1: Account Branch :KOTA - RAJASTHAN
A2: MR. AJAY KUMAR GUPTA | D2: Address :SHOWROOM NO. 13-14
A3: 11 NEW MARKET | D3: MAIN JHALAWAR ROAD
A4: ABHINANDAN NEW MARKET | D4: .
A5: RAWATBHATA | D5: City :KOTA
A6: RAWATBHATTA BAZAR 323307 | D6: State :RAJASTHAN
D7: Phone no. :18002026161
D8: Email :
A9: JOINT HOLDERS : | D9: OD Limit :0 Currency :INR
D10: Cust ID :2600484
A11: Nomination : Registered | D11: Account No :01671000085930 VRM POTENTIAL
A12: Statement From : 01/04/2023 To : 31/12/2023 | D12: A/C Open Date :01/06/2005
D13: Account Status :Regular
D14: RTGS/NEFT IFSC :HDFC0000167 MICR :324240002
D15: =SUM(D17:D861) -> 7665777.6 | E15: =SUM(E17:E861) -> 7690470 | F15: =F17+D17 -> 32408.51
A16: Date | B16: Narration | C16: Value Dt | D16: Withdrawal Amt. | E16: Deposit Amt. | F16: Closing Balance | G16: Account No | I16: TX Date | J16: Particulars | K16: Ref | L16: DR | M16: CR | N16: Balance | O16: Account No
A17: 45019 | B17: NET PI TO HSL SEC A/C 347707-00602340029392 | C17: 45019 | D17: 881.67 | E17: 0 | F17: 31526.84 | G17: HDFC 5930 | I17: =A17 -> 45019 | J17: =B17 -> NET PI TO HSL SEC A/C 347707-00602340029392 | L17: =D17 -> 881.67 | M17: =E17 -> 0 | N17: =F17 -> 31526.84 | O17: =G17 -> HDFC 5930
A18: 45019 | B18: NET PO FROM HSL A/C 347707-00602340029392 | C18: 45019 | D18: 0 | E18: 3799.47 | F18: 35326.31 | G18: HDFC 5930 | H18: =F17-D18+E18-F18 -> 0 | I18: =A18 -> 45019 | J18: =B18 -> NET PO FROM HSL A/C 347707-00602340029392 | L18: =D18 -> 0 | M18: =E18 -> 3799.47 | N18: =F18 -> 35326.31 | O18: =G18 -> HDFC 5930
A19: 45020 | B19: ACH D- TP ACH INVESTOCAFE-1111407380 | C19: 45020 | D19: 1500 | E19: 0 | F19: 33826.31 | G19: HDFC 5930 | H19: =F18-D19+E19-F19 -> 0 | I19: =A19 -> 45020 | J19: =B19 -> ACH D- TP ACH INVESTOCAFE-1111407380 | L19: =D19 -> 1500 | M19: =E19 -> 0 | N19: =F19 -> 33826.31 | O19: =G19 -> HDFC 5930
A20: 45020 | B20: ACH D- TP ACH INVESTOCAFE-1111407381 | C20: 45020 | D20: 2000 | E20: 0 | F20: 31826.31 | G20: HDFC 5930 | H20: =F19-D20+E20-F20 -> 0 | I20: =A20 -> 45020 | J20: =B20 -> ACH D- TP ACH INVESTOCAFE-1111407381 | L20: =D20 -> 2000 | M20: =E20 -> 0 | N20: =F20 -> 31826.31 | O20: =G20 -> HDFC 5930
A21: 45020 | B21: ACH D- TP ACH INVESTOCAFE-1111407382 | C21: 45020 | D21: 2000 | E21: 0 | F21: 29826.31 | G21: HDFC 5930 | H21: =F20-D21+E21-F21 -> 0 | I21: =A21 -> 45020 | J21: =B21 -> ACH D- TP ACH INVESTOCAFE-1111407382 | L21: =D21 -> 2000 | M21: =E21 -> 0 | N21: =F21 -> 29826.31 | O21: =G21 -> HDFC 5930
A22: 45021 | B22: NET PI TO HSL SEC A/C 347707-00602340029392 | C22: 45021 | D22: 591.52 | E22: 0 | F22: 29234.79 | G22: HDFC 5930 | H22: =F21-D22+E22-F22 -> 0 | I22: =A22 -> 45021 | J22: =B22 -> NET PI TO HSL SEC A/C 347707-00602340029392 | L22: =D22 -> 591.52 | M22: =E22 -> 0 | N22: =F22 -> 29234.79 | O22: =G22 -> HDFC 5930
A23: 45021 | B23: NET PI TO HSL SEC A/C 347707-00602340029392 | C23: 45021 | D23: 15603.7 | E23: 0 | F23: 13631.09 | G23: HDFC 5930 | H23: =F22-D23+E23-F23 -> 0 | I23: =A23 -> 45021 | J23: =B23 -> NET PI TO HSL SEC A/C 347707-00602340029392 | L23: =D23 -> 15603.7 | M23: =E23 -> 0 | N23: =F23 -> 13631.09 | O23: =G23 -> HDFC 5930
A24: 45022 | B24: NET PO FROM HSL A/C 347707-00602340029392 | C24: 45022 | D24: 0 | E24: 7926.99 | F24: 21558.08 | G24: HDFC 5930 | H24: =F23-D24+E24-F24 -> 0 | I24: =A24 -> 45022 | J24: =B24 -> NET PO FROM HSL A/C 347707-00602340029392 | L24: =D24 -> 0 | M24: =E24 -> 7926.99 | N24: =F24 -> 21558.08 | O24: =G24 -> HDFC 5930
A25: 45022 | B25: NET PI TO HSL SEC A/C 347707-00602340029392 | C25: 45022 | D25: 288.07 | E25: 0 | F25: 21270.01 | G25: HDFC 5930 | H25: =F24-D25+E25-F25 -> 0 | I25: =A25 -> 45022 | J25: =B25 -> NET PI TO HSL SEC A/C 347707-00602340029392 | L25: =D25 -> 288.07 | M25: =E25 -> 0 | N25: =F25 -> 21270.01 | O25: =G25 -> HDFC 5930
A26: 45022 | B26: NET PO FROM HSL A/C 347707-00602340029392 | C26: 45022 | D26: 0 | E26: 661.41 | F26: 21931.42 | G26: HDFC 5930 | H26: =F25-D26+E26-F26 -> 0 | I26: =A26 -> 45022 | J26: =B26 -> NET PO FROM HSL A/C 347707-00602340029392 | L26: =D26 -> 0 | M26: =E26 -> 661.41 | N26: =F26 -> 21931.42 | O26: =G26 -> HDFC 5930
A27: 45024 | B27: ACH D- TP ACH INVESTOCAFE-1116440799 | C27: 45024 | D27: 2000 | E27: 0 | F27: 19931.42 | G27: HDFC 5930 | H27: =F26-D27+E27-F27 -> 0 | I27: =A27 -> 45024 | J27: =B27 -> ACH D- TP ACH INVESTOCAFE-1116440799 | L27: =D27 -> 2000 | M27: =E27 -> 0 | N27: =F27 -> 19931.42 | O27: =G27 -> HDFC 5930
A28: 45024 | B28: ACH D- TP ACH INVESTOCAFE-1116440800 | C28: 45024 | D28: 2500 | E28: 0 | F28: 17431.42 | G28: HDFC 5930 | H28: =F27-D28+E28-F28 -> 0 | I28: =A28 -> 45024 | J28: =B28 -> ACH D- TP ACH INVESTOCAFE-1116440800 | L28: =D28 -> 2500 | M28: =E28 -> 0 | N28: =F28 -> 17431.42 | O28: =G28 -> HDFC 5930
A29: 45026 | B29: O/MF-HSBC MF -O416 -000000101236 | C29: 45026 | D29: 4000 | E29: 0 | F29: 13431.42 | G29: HDFC 5930 | H29: =F28-D29+E29-F29 -> 0 | I29: =A29 -> 45026 | J29: =B29 -> O/MF-HSBC MF -O416 -000000101236 | L29: =D29 -> 4000 | M29: =E29 -> 0 | N29: =F29 -> 13431.42 | O29: =G29 -> HDFC 5930
... A1094: 45383 | B1094: CREDIT INTEREST CAPITALISED | C1094: 45382 | D1094: 0 | E1094: 538 | F1094: 37929.61 | G1094: HDFC 5930 | H1094: =F1093-D1094+E1094-F1094 -> 0 | I1094: =A1094 -> 45383 | J1094: =B1094 -> CREDIT INTEREST CAPITALISED | L1094: =D1094 -> 0 | M1094: =E1094 -> 538 | N1094: =F1094 -> 37929.61 | O1094: =G1094 -> HDFC 5930

Sheet SBI OD 5441
A1: Account Name : | B1: Mr. AJAY KUMAR GUPTA
A2: Address : | B2: FLAT NO D-07 ISHWAR PARADISE
B3: ASHOKA MARG NASIK ROAD
B4: NASIK-422101
B5: Nashik
A6: Date : | B6: 45304
A7: Account Number : | B7: _00000032718635441
A8: Account Description: | B8: SBI SURAKSHIT HL MAXGN AUG 12
A9: Branch : | B9: SHIVAJI NAGAR, NASIK
A10: Drawing Power : | B10: 1800295
A11: Interest Rate(% p.a.): | B11: 10.5
A12: CIF No. : | B12: _85190853479
A13: IFS (Indian Financial System) Code : | B13: SBIN0011669
A14: MICR (Magnetic Ink Character Recognition) Code : | B14: _422002020
A15: Nomination Registered : | B15: No
A16: Balance on 1 Apr 2023 : | B16: -307107.37
A17: Start Date : | B17: 45017
A18: End Date : | B18: 45291 | E18: =SUM(E20:E87) -> 2665450 | F18: =SUM(F20:F87) -> 2944355 | G18: =G20+E20 -> -307107.37
A19: Txn Date | B19: Value Date | C19: Description | D19: Ref No./Cheque No. | E19: Debit | F19: Credit | G19: Balance | H19: Account No | J19: TX Date | K19: Particulars | L19: Ref | M19: DR | N19: CR | O19: Balance | P19: Account No
A20: 45017 | B20: 45017 | C20: TO TRANSFER-INB Payment towards loan repayment-- | D20: IIB6318597 TRANSFER TO 20010697703 | E20: 25000 | F20: 0 | G20: -332107.37 | H20: SBI 5441 | J20: =A20 -> 45017 | K20: =C20 -> TO TRANSFER-INB Payment towards loan repayment-- | L20: =D20 -> IIB6318597 TRANSFER TO 20010697703 | M20: =E20 -> 25000 | N20: =F20 -> 0 | O20: =G20 -> -332107.37 | P20: =H20 -> SBI 5441
A21: 45018 | B21: 45018 | C21: BY TRANSFER-NEFT*UTIB0000115*AXIR230915974036*AJAY KUMAR GUPTA-- | D21: TRANSFER FROM 3199964044308 | E21: 0 | F21: 100000 | G21: -232107.37 | H21: SBI 5441 | I21: =G20-E21+F21-G21 -> 0 | J21: =A21 -> 45018 | K21: =C21 -> BY TRANSFER-NEFT*UTIB0000115*AXIR230915974036*AJAY KUMAR GUPTA-- | L21: =D21 -> TRANSFER FROM 3199964044308 | M21: =E21 -> 0 | N21: =F21 -> 100000 | O21: =G21 -> -232107.37 | P21: =H21 -> SBI 5441
A22: 45018 | B22: 45018 | C22: DEPOSIT TRANSFER--- | D22: TRANSFER FROM 20010697703 | E22: 0 | F22: 26595 | G22: -205512.37 | H22: SBI 5441 | I22: =G21-E22+F22-G22 -> 0 | J22: =A22 -> 45018 | K22: =C22 -> DEPOSIT TRANSFER--- | L22: =D22 -> TRANSFER FROM 20010697703 | M22: =E22 -> 0 | N22: =F22 -> 26595 | O22: =G22 -> -205512.37 | P22: =H22 -> SBI 5441
A23: 45029 | B23: 45029 | C23: BY TRANSFER-SBILT13042023084220295270-Loan repayment-- | D23: TRANSFER FROM 20010697703 | E23: 0 | F23: 50000 | G23: -155512.37 | H23: SBI 5441 | I23: =G22-E23+F23-G23 -> 0 | J23: =A23 -> 45029 | K23: =C23 -> BY TRANSFER-SBILT13042023084220295270-Loan repayment-- | L23: =D23 -> TRANSFER FROM 20010697703 | M23: =E23 -> 0 | N23: =F23 -> 50000 | O23: =G23 -> -155512.37 | P23: =H23 -> SBI 5441
A24: 45031 | B24: 45031 | C24: BY TRANSFER-INB Payment towards loan repayment-- | D24: IIB6794633 TRANSFER FROM 20010697703 | E24: 0 | F24: 100000 | G24: -55512.37 | H24: SBI 5441 | I24: =G23-E24+F24-G24 -> 0 | J24: =A24 -> 45031 | K24: =C24 -> BY TRANSFER-INB Payment towards loan repayment-- | L24: =D24 -> IIB6794633 TRANSFER FROM 20010697703 | M24: =E24 -> 0 | N24: =F24 -> 100000 | O24: =G24 -> -55512.37 | P24: =H24 -> SBI 5441
A25: 45039 | B25: 45039 | C25: TO TRANSFER-INB Payment towards loan repayment-- | D25: IIB6951402 TRANSFER TO 20010697703 | E25: 35000 | F25: 0 | G25: -90512.37 | H25: SBI 5441 | I25: =G24-E25+F25-G25 -> 0 | J25: =A25 -> 45039 | K25: =C25 -> TO TRANSFER-INB Payment towards loan repayment-- | L25: =D25 -> IIB6951402 TRANSFER TO 20010697703 | M25: =E25 -> 35000 | N25: =F25 -> 0 | O25: =G25 -> -90512.37 | P25: =H25 -> SBI 5441
A26: 45039 | B26: 45039 | C26: BY TRANSFER-INB Payment towards loan repayment-- | D26: IIB6951312 TRANSFER FROM 20010697703 | E26: 0 | F26: 70000 | G26: -20512.37 | H26: SBI 5441 | I26: =G25-E26+F26-G26 -> 0 | J26: =A26 -> 45039 | K26: =C26 -> BY TRANSFER-INB Payment towards loan repayment-- | L26: =D26 -> IIB6951312 TRANSFER FROM 20010697703 | M26: =E26 -> 0 | N26: =F26 -> 70000 | O26: =G26 -> -20512.37 | P26: =H26 -> SBI 5441
A27: 45042 | B27: 45042 | C27: TO TRANSFER-INB Deposit / Investment-- | D27: IIB7031794 TRANSFER TO 20010697703 | E27: 10000 | F27: 0 | G27: -30512.37 | H27: SBI 5441 | I27: =G26-E27+F27-G27 -> 0 | J27: =A27 -> 45042 | K27: =C27 -> TO TRANSFER-INB Deposit / Investment-- | L27: =D27 -> IIB7031794 TRANSFER TO 20010697703 | M27: =E27 -> 10000 | N27: =F27 -> 0 | O27: =G27 -> -30512.37 | P27: =H27 -> SBI 5441
A28: 45046 | B28: 45046 | C28: TO TRANSFER-INB Payment towards loan repayment-- | D28: IIB7146807 TRANSFER TO 20010697703 | E28: 20000 | F28: 0 | G28: -50512.37 | H28: SBI 5441 | I28: =G27-E28+F28-G28 -> 0 | J28: =A28 -> 45046 | K28: =C28 -> TO TRANSFER-INB Payment towards loan repayment-- | L28: =D28 -> IIB7146807 TRANSFER TO 20010697703 | M28: =E28 -> 20000 | N28: =F28 -> 0 | O28: =G28 -> -50512.37 | P28: =H28 -> SBI 5441
A29: 45046 | B29: 45046 | C29: DEBIT INTEREST--- | E29: 1016 | F29: 0 | G29: -51528.37 | H29: SBI 5441 | I29: =G28-E29+F29-G29 -> 0 | J29: =A29 -> 45046 | K29: =C29 -> DEBIT INTEREST--- | L29: =D29 -> 0 | M29: =E29 -> 1016 | N29: =F29 -> 0 | O29: =G29 -> -51528.37 | P29: =H29 -> SBI 5441
A30: 45048 | B30: 45048 | C30: DEPOSIT TRANSFER--- | D30: TRANSFER FROM 20010697703 | E30: 0 | F30: 26595 | G30: -24933.37 | H30: SBI 5441 | I30: =G29-E30+F30-G30 -> 0 | J30: =A30 -> 45048 | K30: =C30 -> DEPOSIT TRANSFER--- | L30: =D30 -> TRANSFER FROM 20010697703 | M30: =E30 -> 0 | N30: =F30 -> 26595 | O30: =G30 -> -24933.37 | P30: =H30 -> SBI 5441
A31: 45077 | B31: 45077 | C31: DEBIT INTEREST--- | E31: 227 | F31: 0 | G31: -25160.37 | H31: SBI 5441 | I31: =G30-E31+F31-G31 -> 0 | J31: =A31 -> 45077 | K31: =C31 -> DEBIT INTEREST--- | L31: =D31 -> 0 | M31: =E31 -> 227 | N31: =F31 -> 0 | O31: =G31 -> -25160.37 | P31: =H31 -> SBI 5441
A32: 45078 | B32: 45078 | C32: TO TRANSFER-INB Deposit / Investment-- | D32: IIB8049885 TRANSFER TO 20010697703 | E32: 30000 | F32: 0 | G32: -55160.37 | H32: SBI 5441 | I32: =G31-E32+F32-G32 -> 0 | J32: =A32 -> 45078 | K32: =C32 -> TO TRANSFER-INB Deposit / Investment-- | L32: =D32 -> IIB8049885 TRANSFER TO 20010697703 | M32: =E32 -> 30000 | N32: =F32 -> 0 | O32: =G32 -> -55160.37 | P32: =H32 -> SBI 5441
A33: 45079 | B33: 45079 | C33: DEPOSIT TRANSFER--- | D33: TRANSFER FROM 20010697703 | E33: 0 | F33: 26595 | G33: -28565.37 | H33: SBI 5441 | I33: =G32-E33+F33-G33 -> 0 | J33: =A33 -> 45079 | K33: =C33 -> DEPOSIT TRANSFER--- | L33: =D33 -> TRANSFER FROM 20010697703 | M33: =E33 -> 0 | N33: =F33 -> 26595 | O33: =G33 -> -28565.37 | P33: =H33 -> SBI 5441
A34: 45082 | B34: 45082 | C34: TO TRANSFER-INB Deposit / Investment-- | D34: IIB8169986 TRANSFER TO 20010697703 | E34: 75000 | F34: 0 | G34: -103565.37 | H34: SBI 5441 | I34: =G33-E34+F34-G34 -> 0 | J34: =A34 -> 45082 | K34: =C34 -> TO TRANSFER-INB Deposit / Investment-- | L34: =D34 -> IIB8169986 TRANSFER TO 20010697703 | M34: =E34 -> 75000 | N34: =F34 -> 0 | O34: =G34 -> -103565.37 | P34: =H34 -> SBI 5441
A35: 45089 | B35: 45089 | C35: TO TRANSFER-INB Deposit / Investment-- | D35: IIB8402515 TRANSFER TO 20010697703 | E35: 10000 | F35: 0 | G35: -113565.37 | H35: SBI 5441 | I35: =G34-E35+F35-G35 -> 0 | J35: =A35 -> 45089 | K35: =C35 -> TO TRANSFER-INB Deposit / Investment-- | L35: =D35 -> IIB8402515 TRANSFER TO 20010697703 | M35: =E35 -> 10000 | N35: =F35 -> 0 | O35: =G35 -> -113565.37 | P35: =H35 -> SBI 5441
A36: 45092 | B36: 45092 | C36: TO TRANSFER-INB Deposit / Investment-- | D36: IIB8464838 TRANSFER TO 20010697703 | E36: 75000 | F36: 0 | G36: -188565.37 | H36: SBI 5441 | I36: =G35-E36+F36-G36 -> 0 | J36: =A36 -> 45092 | K36: =C36 -> TO TRANSFER-INB Deposit / Investment-- | L36: =D36 -> IIB8464838 TRANSFER TO 20010697703 | M36: =E36 -> 75000 | N36: =F36 -> 0 | O36: =G36 -> -188565.37 | P36: =H36 -> SBI 5441
A37: 45102 | B37: 45102 | C37: BY TRANSFER-INB Payment towards loan repayment-- | D37: IIB8695782 TRANSFER FROM 20010697703 | E37: 0 | F37: 40000 | G37: -148565.37 | H37: SBI 5441 | I37: =G36-E37+F37-G37 -> 0 | J37: =A37 -> 45102 | K37: =C37 -> BY TRANSFER-INB Payment towards loan repayment-- | L37: =D37 -> IIB8695782 TRANSFER FROM 20010697703 | M37: =E37 -> 0 | N37: =F37 -> 40000 | O37: =G37 -> -148565.37 | P37: =H37 -> SBI 5441
A38: 45107 | B38: 45107 | C38: DEBIT INTEREST--- | E38: 1130 | F38: 0 | G38: -149695.37 | H38: SBI 5441 | I38: =G37-E38+F38-G38 -> 0 | J38: =A38 -> 45107 | K38: =C38 -> DEBIT INTEREST--- | L38: =D38 -> 0 | M38: =E38 -> 1130 | N38: =F38 -> 0 | O38: =G38 -> -149695.37 | P38: =H38 -> SBI 5441
A39: 45109 | B39: 45109 | C39: DEPOSIT TRANSFER--- | D39: TRANSFER FROM 20010697703 | E39: 0 | F39: 26595 | G39: -123100.37 | H39: SBI 5441 | I39: =G38-E39+F39-G39 -> 0 | J39: =A39 -> 45109 | K39: =C39 -> DEPOSIT TRANSFER--- | L39: =D39 -> TRANSFER FROM 20010697703 | M39: =E39 -> 0 | N39: =F39 -> 26595 | O39: =G39 -> -123100.37 | P39: =H39 -> SBI 5441
A40: 45117 | B40: 45117 | C40: TO TRANSFER-INB NEFT UTR NO: SBIN123191905507--AJAY KUMAR GUPTA | D40: NEFT INB: IRW5728101 / AJAY KUMAR GUPTA | E40: 100000 | F40: 0 | G40: -223100.37 | H40: SBI 5441 | I40: =G39-E40+F40-G40 -> 0 | J40: =A40 -> 45117 | K40: =C40 -> TO TRANSFER-INB NEFT UTR NO: SBIN123191905507--AJAY KUMAR GUPTA | L40: =D40 -> NEFT INB: IRW5728101 / AJAY KUMAR GUPTA | M40: =E40 -> 100000 | N40: =F40 -> 0 | O40: =G40 -> -223100.37 | P40: =H40 -> SBI 5441
...

Sheet SBI Bank 3479
A1: Account Name : | B1: Mr. AJAY KUMAR GUPTA
A2: Address : | B2: FLAT NO D-07 ISHWAR PARADISE
B3: ASHOKA MARG NASIK ROAD
B4: NASIK-422101
B5: Nashik
A6: Date : | B6: 45304
A7: Account Number : | B7: _00000020010697703
A8: Account Description: | B8: SBCHQ-SBP-GEN-PUB-IND-ALL-INR
A9: Branch : | B9: SHIVAJI NAGAR, NASIK
A10: Drawing Power : | B10: 0
A11: Interest Rate(% p.a.): | B11: 2.7
A12: MOD Balance : | B12: 0
A13: CIF No. : | B13: _85190853479
A14: IFS (Indian Financial System) Code : | B14: SBIN0011669
A15: MICR (Magnetic Ink Character Recognition) Code : | B15: _422002020
A16: Nomination Registered : | B16: Yes
A17: Balance on 1 Apr 2023 : | B17: 4724.4
A18: Start Date : | B18: 45017
A19: End Date : | B19: 45291 | E19: =SUBTOTAL(9,E21:E178) -> 2832081.1 | F19: =SUBTOTAL(9,F21:F178) -> 3143745.2 | G19: =G21-F21 -> 4724.4
A20: Txn Date | B20: Value Date | C20: Description | D20: Ref No./Cheque No. | E20: Debit | F20: Credit | G20: Balance | H20: Account No | J20: TX Date | K20: Particulars | L20: Ref | M20: DR | N20: CR | O20: Balance | P20: Account No
A21: 45017 | B21: 45017 | C21: BY TRANSFER-INB Payment towards loan repayment-- | D21: IIB6318597 TRANSFER FROM 32718635441 | E21: 0 | F21: 25000 | G21: 29724.4 | H21: SBI 3479 | I21: =G19+F21-E21-G21 -> 0 | J21: =A21 -> 45017 | K21: =C21 -> BY TRANSFER-INB Payment towards loan repayment-- | L21: =D21 -> IIB6318597 TRANSFER FROM 32718635441 | M21: =E21 -> 0 | N21: =F21 -> 25000 | O21: =G21 -> 29724.4 | P21: =H21 -> SBI 3479
A22: 45018 | B22: 45018 | C22: WITHDRAWAL TRANSFER--- | D22: TRANSFER TO 32718635441 | E22: 26595 | F22: 0 | G22: 3129.4 | H22: SBI 3479 | I22: =G21+F22-E22-G22 -> 0 | J22: =A22 -> 45018 | K22: =C22 -> WITHDRAWAL TRANSFER--- | L22: =D22 -> TRANSFER TO 32718635441 | M22: =E22 -> 26595 | N22: =F22 -> 0 | O22: =G22 -> 3129.4 | P22: =H22 -> SBI 3479
A23: 45022 | B23: 45022 | C23: BY TRANSFER-INB -For 19260165-- | D23: 6503260805CTW5438690 TRANSFER FROM 4 | E23: 0 | F23: 1664.77 | G23: 4794.17 | H23: SBI 3479 | I23: =G22+F23-E23-G23 -> 0 | J23: =A23 -> 45022 | K23: =C23 -> BY TRANSFER-INB -For 19260165-- | L23: =D23 -> 6503260805CTW5438690 TRANSFER FROM 4 | M23: =E23 -> 0 | N23: =F23 -> 1664.77 | O23: =G23 -> 4794.17 | P23: =H23 -> SBI 3479
A24: 45027 | B24: 45027 | C24: BY TRANSFER-INB -For 19260165-- | D24: 6503375120CTW5943163 TRANSFER FROM 4 | E24: 0 | F24: 290.28 | G24: 5084.45 | H24: SBI 3479 | I24: =G23+F24-E24-G24 -> 0 | J24: =A24 -> 45027 | K24: =C24 -> BY TRANSFER-INB -For 19260165-- | L24: =D24 -> 6503375120CTW5943163 TRANSFER FROM 4 | M24: =E24 -> 0 | N24: =F24 -> 290.28 | O24: =G24 -> 5084.45 | P24: =H24 -> SBI 3479
A25: 45027 | B25: 45027 | C25: BY TRANSFER-INB -For 19260165-- | D25: 6503407916CTW6110905 TRANSFER FROM 4 | E25: 0 | F25: 173592.01 | G25: 178676.46 | H25: SBI 3479 | I25: =G24+F25-E25-G25 -> 0 | J25: =A25 -> 45027 | K25: =C25 -> BY TRANSFER-INB -For 19260165-- | L25: =D25 -> 6503407916CTW6110905 TRANSFER FROM 4 | M25: =E25 -> 0 | N25: =F25 -> 173592.01 | O25: =G25 -> 178676.46 | P25: =H25 -> SBI 3479
A26: 45028 | B26: 45028 | C26: BULK POSTING-ACHCr HDFC01984000016202 DWARIKESH INTD-- | E26: 0 | F26: 1200 | G26: 179876.46 | H26: SBI 3479 | I26: =G25+F26-E26-G26 -> 0 | J26: =A26 -> 45028 | K26: =C26 -> BULK POSTING-ACHCr HDFC01984000016202 DWARIKESH INTD-- | L26: =D26 -> 0 | M26: =E26 -> 0 | N26: =F26 -> 1200 | O26: =G26 -> 179876.46 | P26: =H26 -> SBI 3479
A27: 45029 | B27: 45029 | C27: TO TRANSFER-SBILT13042023084220295270-Loan repayment-- | D27: TRANSFER TO 32718635441 | E27: 50000 | F27: 0 | G27: 129876.46 | H27: SBI 3479 | I27: =G26+F27-E27-G27 -> 0 | J27: =A27 -> 45029 | K27: =C27 -> TO TRANSFER-SBILT13042023084220295270-Loan repayment-- | L27: =D27 -> TRANSFER TO 32718635441 | M27: =E27 -> 50000 | N27: =F27 -> 0 | O27: =G27 -> 129876.46 | P27: =H27 -> SBI 3479
A28: 45031 | B28: 45031 | C28: TO TRANSFER-INB SBICARD FOR BILLDESK SBICARD Payments-- | D28: YSBI1843207721IGAPLILQC0 TRANSFER TO | E28: 4502 | F28: 0 | G28: 125374.46 | H28: SBI 3479 | I28: =G27+F28-E28-G28 -> 0 | J28: =A28 -> 45031 | K28: =C28 -> TO TRANSFER-INB SBICARD FOR BILLDESK SBICARD Payments-- | L28: =D28 -> YSBI1843207721IGAPLILQC0 TRANSFER TO | M28: =E28 -> 4502 | N28: =F28 -> 0 | O28: =G28 -> 125374.46 | P28: =H28 -> SBI 3479
A29: 45031 | B29: 45031 | C29: TO TRANSFER-INB Payment towards loan repayment-- | D29: IIB6794633 TRANSFER TO 32718635441 | E29: 100000 | F29: 0 | G29: 25374.46 | H29: SBI 3479 | I29: =G28+F29-E29-G29 -> 0 | J29: =A29 -> 45031 | K29: =C29 -> TO TRANSFER-INB Payment towards loan repayment-- | L29: =D29 -> IIB6794633 TRANSFER TO 32718635441 | M29: =E29 -> 100000 | N29: =F29 -> 0 | O29: =G29 -> 25374.46 | P29: =H29 -> SBI 3479
A30: 45035 | B30: 45035 | C30: BY TRANSFER-INB -For 19260165-- | D30: 6503644322CTW7125901 TRANSFER FROM 4 | E30: 0 | F30: 3231.91 | G30: 28606.37 | H30: SBI 3479 | I30: =G29+F30-E30-G30 -> 0 | J30: =A30 -> 45035 | K30: =C30 -> BY TRANSFER-INB -For 19260165-- | L30: =D30 -> 6503644322CTW7125901 TRANSFER FROM 4 | M30: =E30 -> 0 | N30: =F30 -> 3231.91 | O30: =G30 -> 28606.37 | P30: =H30 -> SBI 3479
A31: 45036 | B31: 45036 | C31: BY TRANSFER-INB -For 19260165-- | D31: 6503677670CTW7273599 TRANSFER FROM 4 | E31: 0 | F31: 15083.73 | G31: 43690.1 | H31: SBI 3479 | I31: =G30+F31-E31-G31 -> 0 | J31: =A31 -> 45036 | K31: =C31 -> BY TRANSFER-INB -For 19260165-- | L31: =D31 -> 6503677670CTW7273599 TRANSFER FROM 4 | M31: =E31 -> 0 | N31: =F31 -> 15083.73 | O31: =G31 -> 43690.1 | P31: =H31 -> SBI 3479
A32: 45039 | B32: 45039 | C32: BY TRANSFER-INB Payment towards loan repayment-- | D32: IIB6951402 TRANSFER FROM 32718635441 | E32: 0 | F32: 35000 | G32: 78690.1 | H32: SBI 3479 | I32: =G31+F32-E32-G32 -> 0 | J32: =A32 -> 45039 | K32: =C32 -> BY TRANSFER-INB Payment towards loan repayment-- | L32: =D32 -> IIB6951402 TRANSFER FROM 32718635441 | M32: =E32 -> 0 | N32: =F32 -> 35000 | O32: =G32 -> 78690.1 | P32: =H32 -> SBI 3479
A33: 45039 | B33: 45039 | C33: TO TRANSFER-INB Payment towards loan repayment-- | D33: IIB6951312 TRANSFER TO 32718635441 | E33: 70000 | F33: 0 | G33: 8690.1 | H33: SBI 3479 | I33: =G32+F33-E33-G33 -> 0 | J33: =A33 -> 45039 | K33: =C33 -> TO TRANSFER-INB Payment towards loan repayment-- | L33: =D33 -> IIB6951312 TRANSFER TO 32718635441 | M33: =E33 -> 70000 | N33: =F33 -> 0 | O33: =G33 -> 8690.1 | P33: =H33 -> SBI 3479
A34: 45041 | B34: 45041 | C34: BULK POSTING-ACHCr KKBK00188000018285 DHAMPUR SUGAR-- | E34: 0 | F34: 300 | G34: 8990.1 | H34: SBI 3479 | I34: =G33+F34-E34-G34 -> 0 | J34: =A34 -> 45041 | K34: =C34 -> BULK POSTING-ACHCr KKBK00188000018285 DHAMPUR SUGAR-- | L34: =D34 -> 0 | M34: =E34 -> 0 | N34: =F34 -> 300 | O34: =G34 -> 8990.1 | P34: =H34 -> SBI 3479
A35: 45042 | B35: 45042 | C35: BY TRANSFER-INB Deposit / Investment-- | D35: IIB7031794 TRANSFER FROM 32718635441 | E35: 0 | F35: 10000 | G35: 18990.1 | H35: SBI 3479 | I35: =G34+F35-E35-G35 -> 0 | J35: =A35 -> 45042 | K35: =C35 -> BY TRANSFER-INB Deposit / Investment-- | L35: =D35 -> IIB7031794 TRANSFER FROM 32718635441 | M35: =E35 -> 0 | N35: =F35 -> 10000 | O35: =G35 -> 18990.1 | P35: =H35 -> SBI 3479
A36: 45044 | B36: 45044 | C36: BY TRANSFER-INB -For 19260165-- | D36: 6503910734CTW8203019 TRANSFER FROM 4 | E36: 0 | F36: 5755.3 | G36: 24745.4 | H36: SBI 3479 | I36: =G35+F36-E36-G36 -> 0 | J36: =A36 -> 45044 | K36: =C36 -> BY TRANSFER-INB -For 19260165-- | L36: =D36 -> 6503910734CTW8203019 TRANSFER FROM 4 | M36: =E36 -> 0 | N36: =F36 -> 5755.3 | O36: =G36 -> 24745.4 | P36: =H36 -> SBI 3479
A37: 45046 | B37: 45046 | C37: BY TRANSFER-INB Payment towards loan repayment-- | D37: IIB7146807 TRANSFER FROM 32718635441 | E37: 0 | F37: 20000 | G37: 44745.4 | H37: SBI 3479 | I37: =G36+F37-E37-G37 -> 0 | J37: =A37 -> 45046 | K37: =C37 -> BY TRANSFER-INB Payment towards loan repayment-- | L37: =D37 -> IIB7146807 TRANSFER FROM 32718635441 | M37: =E37 -> 0 | N37: =F37 -> 20000 | O37: =G37 -> 44745.4 | P37: =H37 -> SBI 3479
A38: 45048 | B38: 45048 | C38: WITHDRAWAL TRANSFER--- | D38: TRANSFER TO 32718635441 | E38: 26595 | F38: 0 | G38: 18150.4 | H38: SBI 3479 | I38: =G37+F38-E38-G38 -> 0 | J38: =A38 -> 45048 | K38: =C38 -> WITHDRAWAL TRANSFER--- | L38: =D38 -> TRANSFER TO 32718635441 | M38: =E38 -> 26595 | N38: =F38 -> 0 | O38: =G38 -> 18150.4 | P38: =H38 -> SBI 3479
A39: 45049 | B39: 45049 | C39: BY TRANSFER-INB -For 19260165-- | D39: 6504023356CTW8820042 TRANSFER FROM 4 | E39: 0 | F39: 6485.61 | G39: 24636.01 | H39: SBI 3479 | I39: =G38+F39-E39-G39 -> 0 | J39: =A39 -> 45049 | K39: =C39 -> BY TRANSFER-INB -For 19260165-- | L39: =D39 -> 6504023356CTW8820042 TRANSFER FROM 4 | M39: =E39 -> 0 | N39: =F39 -> 6485.61 | O39: =G39 -> 24636.01 | P39: =H39 -> SBI 3479
A40: 45050 | B40: 45050 | C40: TO TRANSFER-TRFD TO MANKIND PHARMA LTD IPO ALLOTMENT-- | D40: TRANSFER TO 38660007037 | E40: 14040 | F40: 0 | G40: 10596.01 | H40: SBI 3479 | I40: =G39+F40-E40-G40 -> 0 | J40: =A40 -> 45050 | K40: =C40 -> TO TRANSFER-TRFD TO MANKIND PHARMA LTD IPO ALLOTMENT-- | L40: =D40 -> TRANSFER TO 38660007037 | M40: =E40 -> 14040 | N40: =F40 -> 0 | O40: =G40 -> 10596.01 | P40: =H40 -> SBI 3479
...

Sheet Conso
A1: Ajay Kumar Gupta | D1: ='HDFC 5930'!D15 -> 7665777.6 | E1: ='HDFC 5930'!E15 -> 7690470 | L1: Earnings | N1: Amount | O1: Recoveries | P1: Amount
A2: Account of Statements from 01-04-2023 to 31-03-2024 | D2: =SUBTOTAL(9,D4:D1632) -> 80000 | E2: =SUBTOTAL(9,E4:E1632) -> 0 | F2: =D2-E2 -> 80000 | L2: Salary JUL AUG | M2: 14 Days | N2: 129902 | O2: PF | P2: 10663
A3: TX Date | B3: Particulars | C3: Ref | D3: DR | E3: CR | F3: Balance | G3: Kya hai? | H3: Account No | L3: LTA | M3: 2022-23 | N3: 10726 | O3: Prof Tax | P3: 200
A4: 45017 | B4: BY TRANSFER-INB Payment towards loan repayment-- | C4: IIB6318597 TRANSFER FROM 32718635441 | D4: 0 | E4: 25000 | F4: 29724.4 | G4: Contra | H4: SBI 3479 | L4: Leave Encashment | M4: 97 Days | N4: 822114 | O4: Income Tax (Tentative) | P4: 92321
A5: 45017 | B5: TO TRANSFER-INB Payment towards loan repayment-- | C5: IIB6318597 TRANSFER TO 20010697703 | D5: 25000 | E5: 0 | F5: -332107.37 | G5: Contra | H5: SBI 5441 | M5: 59.5 Days | N5: 210119 | O5: Extra Availed Leave | P5: 14429
A6: 45018 | B6: UPI/P2A/345797693295/SACHIN BA/Kotak Mah/Diesal | D6: 3400 | E6: 0 | F6: 184700.16 | G6: Personal | H6: AXIS 3167 | L6: Bonus | M6: 2022-23 | N6: 416051 | O6: Cash Advance | P6: 283333
A7: 45018 | B7: UPI/P2M/345789552921/MANISH HE/Yes Bank /Amle | D7: 230 | E7: 0 | F7: 184470.16 | G7: Personal | H7: AXIS 3167 | L7: CAR Reimbursement | M7: 2023-24 | N7: 134178 | O7: Uniform Charges | P7: 4299
A8: 45018 | B8: UPI/P2M/345726651875/SAGAR SWE/Yes Bank /sweets | D8: 416 | E8: 0 | F8: 184054.16 | G8: Personal | H8: AXIS 3167 | L8: Gratuity | N8: 1589138
A9: 45018 | B9: INB/NEFT/AXIR230915974036/Ajay Kum/STATE B/Housin | D9: 100000 | E9: 0 | F9: 84054.16 | G9: Contra | H9: AXIS 3167 | N9: =SUM(N2:N6) -> 1588912 | P9: =SUM(P2:P8) -> 405245
A10: 45018 | B10: WITHDRAWAL TRANSFER--- | C10: TRANSFER TO 32718635441 | D10: 26595 | E10: 0 | F10: 3129.4 | G10: Contra | H10: SBI 3479
A11: 45018 | B11: BY TRANSFER-NEFT*UTIB0000115*AXIR230915974036*AJAY KUMAR GUPTA-- | C11: TRANSFER FROM 3199964044308 | D11: 0 | E11: 100000 | F11: -232107.37 | G11: Contra | H11: SBI 5441 | O11: Holded Amount | P11: 328745
A12: 45018 | B12: DEPOSIT TRANSFER--- | C12: TRANSFER FROM 20010697703 | D12: 0 | E12: 26595 | F12: -205512.37 | G12: Contra | H12: SBI 5441 | O12: As per statement | P12: =N9-P9+P11 -> 1512412
A13: 45019 | B13: NET PI TO HSL SEC A/C 347707-00602340029392 | D13: 881.67 | E13: 0 | F13: 31526.84 | G13: HSL | H13: HDFC 5930 | N13: Full and Final | O13: Actual In bank | P13: =SUMIF($G:$G,N13,$E:$E) -> 1512412
A14: 45019 | B14: NET PO FROM HSL A/C 347707-00602340029392 | D14: 0 | E14: 3799.47 | F14: 35326.31 | G14: HSL | H14: HDFC 5930 | O14: Diff | P14: =P13-P12 -> 0
A15: 45020 | B15: UPI/P2M/346037289751/SHAGUN TR/Yes Bank /Ice cre | D15: 115 | E15: 0 | F15: 83939.16 | G15: Personal | H15: AXIS 3167
A16: 45020 | B16: ACH D- TP ACH INVESTOCAFE-1111407380 | D16: 1500 | E16: 0 | F16: 33826.31 | G16: SIP | H16: HDFC 5930
A17: 45020 | B17: ACH D- TP ACH INVESTOCAFE-1111407381 | D17: 2000 | E17: 0 | F17: 31826.31 | G17: SIP | H17: HDFC 5930
A18: 45020 | B18: ACH D- TP ACH INVESTOCAFE-1111407382 | D18: 2000 | E18: 0 | F18: 29826.31 | G18: SIP | H18: HDFC 5930
A19: 45021 | B19: NET PI TO HSL SEC A/C 347707-00602340029392 | D19: 591.52 | E19: 0 | F19: 29234.79 | G19: HSL | H19: HDFC 5930
A20: 45021 | B20: NET PI TO HSL SEC A/C 347707-00602340029392 | D20: 15603.7 | E20: 0 | F20: 13631.09 | G20: HSL | H20: HDFC 5930
A21: 45022 | B21: NET PO FROM HSL A/C 347707-00602340029392 | D21: 0 | E21: 7926.99 | F21: 21558.08 | G21: HSL | H21: HDFC 5930
A22: 45022 | B22: NET PI TO HSL SEC A/C 347707-00602340029392 | D22: 288.07 | E22: 0 | F22: 21270.01 | G22: HSL | H22: HDFC 5930
A23: 45022 | B23: NET PO FROM HSL A/C 347707-00602340029392 | D23: 0 | E23: 661.41 | F23: 21931.42 | G23: HSL | H23: HDFC 5930
A24: 45022 | B24: BY TRANSFER-INB -For 19260165-- | C24: 6503260805CTW5438690 TRANSFER FROM 4 | D24: 0 | E24: 1664.77 | F24: 4794.17 | G24: Suspense | H24: SBI 3479
A25: 45023 | B25: BRN-PYMT-CARD-4111460000883615 | D25: 10917.37 | E25: 0 | F25: 73021.79 | G25: Credit card | H25: AXIS 3167
A26: 45024 | B26: ACH D- TP ACH INVESTOCAFE-1116440799 | D26: 2000 | E26: 0 | F26: 19931.42 | G26: SIP | H26: HDFC 5930
A27: 45024 | B27: ACH D- TP ACH INVESTOCAFE-1116440800 | D27: 2500 | E27: 0 | F27: 17431.42 | G27: SIP | H27: HDFC 5930
A28: 45026 | B28: O/MF-HSBC MF -O416 -000000101236 | D28: 4000 | E28: 0 | F28: 13431.42 | G28: SIP | H28: HDFC 5930
A29: 45026 | B29: NET PAYIN TO BSE MF A/C -57500000389146- FROM A/C -01671000085930- UCC -347707-57500000389146 | D29: 3000 | E29: 0 | F29: 10431.42 | G29: SIP | H29: HDFC 5930
A30: 45026 | B30: NET PAYIN TO BSE MF A/C -57500000389146- FROM A/C -01671000085930- UCC -347707-57500000389146 | D30: 3000 | E30: 0 | F30: 7431.42 | G30: SIP | H30: HDFC 5930
A31: 45026 | B31: NET PO FROM HSL A/C 347707-00602340029392 | D31: 0 | E31: 19098.12 | F31: 26529.54 | G31: HSL | H31: HDFC 5930
A32: 45026 | B32: ACH C- STEEL AUTHORITY OF I-000000000000 | D32: 0 | E32: 100 | F32: 26629.54 | G32: Dividend Income | H32: HDFC 5930
A33: 45026 | B33: NET PI TO HSL SEC A/C 347707-00602340029392 | D33: 1153.56 | E33: 0 | F33: 25475.98 | G33: HSL | H33: HDFC 5930
A34: 45026 | B34: NET PI TO HSL SEC A/C 347707-00602340029392 | D34: 2752.88 | E34: 0 | F34: 22723.1 | G34: HSL | H34: HDFC 5930
A35: 45026 | B35: NET PO FROM HSL A/C 347707-00602340029392 | D35: 0 | E35: 4701.48 | F35: 27424.58 | G35: HSL | H35: HDFC 5930
A36: 45027 | B36: NET PI TO HSL SEC A/C 347707-00602340029392 | D36: 287.81 | E36: 0 | F36: 27136.77 | G36: HSL | H36: HDFC 5930
A37: 45027 | B37: NET PO FROM HSL A/C 347707-00602340029392 | D37: 0 | E37: 1542.96 | F37: 28679.73 | G37: HSL | H37: HDFC 5930
A38: 45027 | B38: BY TRANSFER-INB -For 19260165-- | C38: 6503375120CTW5943163 TRANSFER FROM 4 | D38: 0 | E38: 290.28 | F38: 5084.45 | G38: Suspense | H38: SBI 3479
A39: 45027 | B39: BY TRANSFER-INB -For 19260165-- | C39: 6503407916CTW6110905 TRANSFER FROM 4 | D39: 0 | E39: 173592.01 | F39: 178676.46 | G39: Suspense | H39: SBI 3479
A40: 45028 | B40: NET PI TO HSL SEC A/C 347707-00602340029392 | D40: 288.57 | E40: 0 | F40: 28391.16 | G40: HSL | H40: HDFC 5930
...

Sheet Bank Summary
B1: All Banks
B2: Ajay Gupta Bank Summary
B3: 01-04-2023 to 31-03-2024
B4: Particulars | C4: ₹ | D4: Particulars | E4: ₹
D5: Opening Balances | E5: =-I45 -> 73288.3
B7: Contra | C7: =SUMIFS(Conso!$E:$E,Conso!$G:$G,B7) -> 9230781 | D7: Contra | E7: =SUMIFS(Conso!$D:$D,Conso!$G:$G,D7) -> 9230781
B8: Personal | C8: =SUMIFS(Conso!$E:$E,Conso!$G:$G,B8) -> 17250 | D8: Personal | E8: =SUMIFS(Conso!$D:$D,Conso!$G:$G,D8) -> 37987.55
B9: HSL | C9: =SUMIFS(Conso!$E:$E,Conso!$G:$G,B9) -> 2756189 | D9: HSL | E9: =SUMIFS(Conso!$D:$D,Conso!$G:$G,D9) -> 4213437.4
B10: Suspense | C10: =SUMIFS(Conso!$E:$E,Conso!$G:$G,B10) -> 3244957.2 | D10: Suspense | E10: =SUMIFS(Conso!$D:$D,Conso!$G:$G,D10) -> 2091653.4
B11: Credit card | C11: =SUMIFS(Conso!$E:$E,Conso!$G:$G,B11) -> 0 | D11: Credit card | E11: =SUMIFS(Conso!$D:$D,Conso!$G:$G,D11) -> 421522.67
B12: Dividend Income | C12: =SUMIFS(Conso!$E:$E,Conso!$G:$G,B12) -> 43886.25 | D12: Dividend Income | E12: =SUMIFS(Conso!$D:$D,Conso!$G:$G,D12) -> 0
B13: Bank Charges | C13: =SUMIFS(Conso!$E:$E,Conso!$G:$G,B13) -> 0 | D13: Bank Charges | E13: =SUMIFS(Conso!$D:$D,Conso!$G:$G,D13) -> 23439.45
B14: UPI | C14: =SUMIFS(Conso!$E:$E,Conso!$G:$G,B14) -> 123680 | D14: UPI | E14: =SUMIFS(Conso!$D:$D,Conso!$G:$G,D14) -> 228355.95
B15: Payment from Aayush | C15: =SUMIFS(Conso!$E:$E,Conso!$G:$G,B15) -> 325000 | D15: Payment from Aayush | E15: =SUMIFS(Conso!$D:$D,Conso!$G:$G,D15) -> 20000
B16: ATM Withdrawal | C16: =SUMIFS(Conso!$E:$E,Conso!$G:$G,B16) -> 0 | D16: ATM Withdrawal | E16: =SUMIFS(Conso!$D:$D,Conso!$G:$G,D16) -> 225500
B17: Electricity | C17: =SUMIFS(Conso!$E:$E,Conso!$G:$G,B17) -> 0 | D17: Electricity | E17: =SUMIFS(Conso!$D:$D,Conso!$G:$G,D17) -> 19560
B18: Transfer to Sunita Gupta | C18: =SUMIFS(Conso!$E:$E,Conso!$G:$G,B18) -> 0 | D18: Transfer to Sunita Gupta | E18: =SUMIFS(Conso!$D:$D,Conso!$G:$G,D18) -> 1095000
... B38: Maintenance | C38: =SUMIFS(Conso!$E:$E,Conso!$G:$G,B38) -> 0 | D38: Maintenance | E38: =SUMIFS(Conso!$D:$D,Conso!$G:$G,D38) -> 15000
B39: Payment to sunita | C39: =SUMIFS(Conso!$E:$E,Conso!$G:$G,B39) -> 0 | D39: Payment to sunita | E39: =SUMIFS(Conso!$D:$D,Conso!$G:$G,D39) -> 100000 | I39: Opening Balance | J39: Closing Balance
B40: Payment from sunita | C40: =SUMIFS(Conso!$E:$E,Conso!$G:$G,B40) -> 100000 | D40: Payment from sunita | E40: =SUMIFS(Conso!$D:$D,Conso!$G:$G,D40) -> 0 | H40: AXIS | I40: ='AXIS 3167'!F14 -> 188100.16 | J40: ='AXIS 3167'!F267 -> 90615.86
C41: =SUMIFS(Conso!$E:$E,Conso!$G:$G,B41) -> 0 | D41: Advance Tax Payment | E41: =SUMIFS(Conso!$D:$D,Conso!$G:$G,D41) -> 18000 | H41: BOI | I41: ='BOI 6699'!H19 -> 8586 | J41: ='BOI 6699'!G26 -> 15725
D42: Closing Balances | E42: =C44-SUM(E5:E41) -> 232605.38 | F42: =J45 -> 212778.38 | G42: =E42-F42 -> 19827 | H42: HDFC | I42: ='HDFC 5930'!F15 -> 32408.51 | J42: ='HDFC 5930'!F1094 -> 37929.61
H43: SBI OD | I43: ='SBI OD 5441'!G18 -> -307107.37 | J43: ='SBI OD 5441'!G102 -> -195.37
C44: =SUM(C7:C43) -> 20585695 | E44: =SUM(E5:E43) -> 20585695 | G44: =C44-E44 -> 0 | H44: SBI BANK | I44: ='SBI Bank 3479'!G19 -> 4724.4 | J44: ='SBI Bank 3479'!G227 -> 68703.28
I45: =SUM(I40:I44) -> -73288.3 | J45: =SUM(J40:J44) -> 212778.38
I46: =E5+I45 -> 0
C50: =SUM(C7:C41) -> 20585695 | E50: =SUM(E7:E41) -> 20279801
C51: =Conso!E2 -> 0 | E51: =Conso!D2 -> 80000
C52: =C51-C50 -> -20585695 | E52: =E51-E50 -> -20199801
I55: =I45+C50-E50 -> 232605.38
I56: =I55-J45 -> 19827

Sheet Salary
C1: Taxable | D1: Taxable | E1: Taxable | F1: Taxable | G1: Taxable | H1: Taxable | I1: Taxable | J1: Taxable | L1: Taxable | U1: =SUM(U4:U8) -> 359852
C2: =SUBTOTAL(9,C4:C8) -> 892369.99 | D2: =SUBTOTAL(9,D4:D8) -> 356948 | E2: =SUBTOTAL(9,E4:E8) -> 50102.16 | F2: =SUBTOTAL(9,F4:F8) -> 858.19 | G2: =SUBTOTAL(9,G4:G8) -> 16685 | H2: =SUBTOTAL(9,H4:H8) -> 6674 | I2: =SUBTOTAL(9,I4:I8) -> 5362.71 | J2: =SUBTOTAL(9,J4:J8) -> 10726 | ... N2: =SUBTOTAL(9,N4:N8) -> 1589138 | P2: =SUBTOTAL(9,P4:P8) -> 1755777.1 | AB2: =SUBTOTAL(9,AB4:AB8) -> 915015.26
C3: Basic | D3: HRA | E3: Special Allowance | F3: Child Education Allow | G3: BF Basic Arrear | H3: BF HRA Arrear | I3: Other Allowance | J3: LTA | K3: Leave Encashment | L3: Bonus | M3: Car Reimb | N3: Gratuity | P3: Total Earnings | Q3: Total Earnings as per 26AS | S3: Ee PF contribution | T3: Prof Tax - split period | U3: TDS | V3: Round off | W3: Cf PF Monthly | X3: Reg. repayment (Advance) | Y3: Mess Deductions | Z3: Extra Availed leave | AA3: Uniform Charges | AB3: Total Deductions | AC3: Net Pay
B4: 45017 | C4: 195200 | D4: 78080 | E4: 11678 | F4: 200 | G4: 0 | H4: 0 | I4: 1250 | J4: 0 | K4: 0 | L4: 0 | M4: 0 | N4: 0 | O4: 6340 | P4: =SUM(C4:N4) -> 286408 | Q4: 292748 | R4: =Q4-P4 -> 6340 | S4: 23424 | T4: 200 | U4: 64038 | V4: -0.36 | W4: 0 | X4: 35416.67 | Y4: 440 | Z4: 0 | AA4: 0 | AB4: =SUM(S4:AA4) -> 123518.31 | AC4: =P4-AB4 -> 162889.69
B5: 45047 | C5: 211885 | D5: 84754 | E5: 11678 | F5: 200 | G5: =C5-C4 -> 16685 | H5: =D5-D4 -> 6674 | I5: 1250 | J5: 0 | K5: 0 | L5: 0 | M5: 0 | N5: 0 | O5: 6340 | P5: =SUM(C5:N5) -> 333126 | Q5: 339466 | R5: =Q5-P5 -> 6340 | S5: 25426 | T5: 200 | U5: 71988 | V5: 0.31 | W5: 2002 | X5: 35416.67 | Y5: 400 | Z5: 0 | AA5: 0 | AB5: =SUM(S5:AA5) -> 135432.98 | AC5: =P5-AB5 -> 197693.02
B6: 45078 | C6: 211885 | D6: 84754 | E6: 11678 | F6: 200 | G6: 0 | H6: 0 | I6: 1250 | J6: 0 | K6: 0 | L6: 0 | M6: 0 | N6: 0 | O6: 6340 | P6: =SUM(C6:N6) -> 309767 | Q6: 316107 | R6: =Q6-P6 -> 6340 | S6: 25426 | T6: 200 | U6: 71988 | V6: -0.02 | W6: 0 | X6: 35416.67 | Y6: 350 | Z6: 0 | AA6: 0 | AB6: =SUM(S6:AA6) -> 133380.65 | AC6: 0
B7: 45108 | C7: 184544.99 | D7: 73818 | E7: 10171.16 | F7: 174.19 | G7: 0 | H7: 0 | I7: 1088.71 | J7: 0 | K7: 0 | L7: 0 | M7: 0 | N7: 0 | O7: 6340 | P7: =SUM(C7:N7) -> 269797.05 | Q7: 276137 | R7: =Q7-P7 -> 6339.95 | S7: 22145 | T7: 200 | U7: 59517 | V7: -0.35 | W7: 0 | X7: 35416.67 | Y7: 160 | Z7: 0 | AA7: 0 | AB7: =SUM(S7:AA7) -> 117438.32 | AC7: 0
B8: 45139 | C8: 88855 | D8: 35542 | E8: 4897 | F8: 84 | G8: 0 | H8: 0 | I8: 524 | J8: 10726 | K8: =822114+210119 -> 1032233 | L8: 416051 | M8: 134178 | N8: 1589138 | P8: =SUM(C8:N8)-M8-N8-K8 -> 556679 | R8: =Q8-P8 -> -556679 | S8: =N16 -> 10663 | T8: =N17 -> 200 | U8: 92321 | V8: 0 | W8: 0 | X8: 283333 | Y8: 0 | Z8: 14429 | AA8: 4299 | AB8: =SUM(S8:AA8) -> 405245 | AC8: =P8-AB8+P6-AB6+P7-AB7+K8 -> 1512412.1
C9: =SUM(C4:C8) -> 892369.99 | D9: =SUM(D4:D8) -> 356948 | E9: =SUM(E4:E8) -> 50102.16 | F9: =SUM(F4:F8) -> 858.19 | G9: =SUM(G4:G8) -> 16685 | H9: =SUM(H4:H8) -> 6674 | I9: =SUM(I4:I8) -> 5362.71 | J9: =SUM(J4:J8) -> 10726 | ... O9: =SUM(O4:O8) -> 25360
C10: 909055 | D10: 363622 | E10: 60465.29 | F10: 858.06 | J10: 10726 | K10: 1032233.3 | L10: 416051
C11: =C9-C10+G9 -> -0.01 | D11: =D9-D10+H9 -> 0 | E11: =E9-E10+I9 -> -5000.42 | F11: =F9-F10 -> 0.13 | G11: =G9-G10 -> 16685 | H11: =H9-H10 -> 6674 | I11: =I9-I10 -> 5362.71 | J11: =J9-J10 -> 0 | K11: =K9-K10 -> -0.29 | L11: =L9-L10 -> 0 | M11: =M9-M10 -> 134178 | ... O11: =O9-O10 -> 25360
J15: Earnings | L15: Amount | M15: Recoveries | N15: Amount
J16: Salary JUL AUG | K16: 14 Days | L16: 129902 | M16: PF | N16: 10663
J17: LTA | K17: 2022-23 | L17: 10726 | M17: Prof Tax | N17: 200
J18: Leave Encashment | K18: 97 Days | L18: 822114 | M18: Income Tax (Tentative) | N18: 92321
K19: 59.5 Days | L19: 210119 | M19: Extra Availed Leave | N19: 14429
J20: Bonus | K20: 2022-23 | L20: 416051 | M20: Cash Advance | N20: 283333
J21: CAR Reimbursement | K21: 2023-24 | L21: 134178 | M21: Uniform Charges | N21: 4299
J22: Gratuity | L22: 1589138
L23: =SUM(L16:L20) -> 1588912 | N23: =SUM(N16:N22) -> 405245
M25: Holded Amount | N25: 328745
M26: As per statement | N26: =L23-N23+N25 -> 1512412

Sheet Leave Encashment
B2: Leave Encashment
B3: Particulars | C3: Amount (Rs)
B4: Leave encashment received (A) | C4: =SUM(Salary!L18:L19) -> 1032233
B5: Less: Exemption under Section 10(10AA) – (B) Least of the following: | C5: =MIN(C6:C9) -> 0
B6: i) Amount notified by the Government** Rs 25,00,000 (C) | C6: 2500000
B7: ii) Actual leave encashment amount (D) | C7: =C4 -> 1032233 | H7: =[1]Salary!C4 -> 0
B8: iii) Average salary* of last 10 months (E) | C8: =I8 -> 0 | E8: Salary per day | F8: No. Of days | H8: =[1]Salary!C6 -> 0 | I8: =H8*4+H7*6 -> 0 | P8: =M16 -> 0 | Q8: =M17 -> 0
B9: iv) Salary per day *unutilised leave (considering maximum 30 days leave per year) for every year of completed service (F) | C9: =G9 -> 0 | E9: =[1]Salary!C6/30 -> 0 | F9: =(97+59.5)+(0*30/42) -> 156.5 | G9: =E9*F9 -> 0
B10: Leave encashment taxable – (A) – (B) | C10: =C4-C5 -> 1032233
B13: Gratuity
B14: Particulars | C14: Amount (Rs) | AT14: =AI17-SUM(AT9:AT13) -> 0
B15: Gratuity received (A) | C15: =Salary!L22 -> 1589138
B16: Less: Exemption – (B) Least of the following: | C16: =MIN(C17:C19) -> 1589137.5 | E16: Last Drawn Salary | F16: No of Years of Service | K16: 129902 | N16: =SUM(K16:K17,K20) -> 556679
B17: Last salary (basic + DA)* number of years of employment* 15/26; | C17: =H17 -> 1589137.5 | E17: =Salary!C6 -> 211885 | F17: 13 | G17: =15/26 -> 0.57692308 | H17: =E17*F17*G17 -> 1589137.5 | K17: 10726 | AI17: =SUM(AH3:AH17) -> 0
B18: Rs. 20 lakhs (which has been hiked from Rs. 10 Lakh as per the amendment); | C18: 2000000 | K18: 822114
B19: Gratuity Actually received | C19: =C15 -> 1589138 | K19: 210119 | AI19: -150000
B20: Leave encashment taxable – (A) – (B) | C20: =ROUNDDOWN(C15-C16,0) -> 0 | K20: 416051 | AI20: -50000
K21: 134178
K22: 1589138 | AI22: =SUM(AI17:AI21) -> -200000
M26: =K23-M23+M25 -> 0

Sheet Ajay SBI Flat Insurance account
A1: Account Name : | B1: Mr. AJAY KUMAR GUPTA
A2: Address : | B2: FLAT NO D-07 ISHWAR PARADISE
B3: ASHOKA MARG NASIK ROAD
B4: NASIK-422101
B5: Nashik
A6: Date : | B6: 45426
A7: Account Number : | B7: _00000032718709979
A8: Account Description: | B8: MAXGAIN SURAKSHA
A9: Branch : | B9: SHIVAJI NAGAR, NASIK
A10: Balance on 1 Apr 2023 : | B10: -363
A11: Start Date : | B11: 45017
A12: End Date : | B12: 45382
A13: Txn Date | B13: Value Date | C13: Description | D13: Ref No./Cheque No. | E13: Debit | F13: Credit | G13: Balance
A14: 45382 | B14: 45382 | C14: INTEREST--- | D14: - | E14: 4 | G14: -404
A15: 45351 | B15: 45351 | C15: INTEREST--- | D15: - | E15: 3 | G15: -400
A16: 45322 | B16: 45322 | C16: INTEREST--- | D16: - | E16: 4 | G16: -397
A17: 45291 | B17: 45291 | C17: INTEREST--- | D17: - | E17: 4 | G17: -393
A18: 45260 | B18: 45260 | C18: INTEREST--- | D18: - | E18: 4 | G18: -389
A19: 45230 | B19: 45230 | C19: INTEREST--- | D19: - | E19: 4 | G19: -385
A20: 45199 | B20: 45199 | C20: INTEREST--- | D20: - | E20: 3 | G20: -381
A21: 45169 | B21: 45169 | C21: INTEREST--- | D21: - | E21: 3 | G21: -378
A22: 45138 | B22: 45138 | C22: INTEREST--- | D22: - | E22: 3 | G22: -375
A23: 45107 | B23: 45107 | C23: INTEREST--- | D23: - | E23: 3 | G23: -372
A24: 45077 | B24: 45077 | C24: INTEREST--- | D24: - | E24: 3 | G24: -369
A25: 45046 | B25: 45046 | C25: INTEREST--- | D25: - | E25: 3 | G25: -366
A27: **This is a computer generated statement and does not require a signature
