Workbook

Sheet AXIS
B1: Axis Bank Narration Sheet
B2: Colour Legend of Categories:
B3: UPI - Fresh Produce | C3: UPI Payment | D3: NEFT Transfer | E3: Cash Withdrawal | F3: Received - Sunita Gupta
B4: Zerodha Broking | C4: Transfer - Ajay Gupta | D4: Bank Charges | E4: Bank Interest | F4: Dividend Income
B5: UPI - Pharmacy | C5: Received - Rakhi Vin | D5: Received - Deepika U | E5: Received - Bhutada S | F5: Received - Aditya Dh
B6: Received - Priti Muk | C6: Received - Deepali A | D6: UPI - IRCTC | E6: UPI - Flipkart | F6: Misc Income
B7: UPI - Meesho | C7: Received - Sharda Ar | D7: Received - Manjoosha | E7: Transfer - Sunita Gupta | F7: Transfer - Archit Gupta
B8: Received - Google In | C8: Received - Archit Gupta | D8: Shopping - Jewellery | E8: Health Insurance
A10: Date | B10: Particulars | C10: Ref | D10: Value_Date | E10: DR | F10: CR | G10: Balance | H10: Beneficiary | I10: Human_Narration | J10: Auto_Narration | K10: Account_Head | L10: Confidence | M10: Match
A11: 45388 | B11: UPI/P2M/409717050341/SHIVBHOLA VEGETABLE E/veg/Yes Bank Ltd | C11: - | D11: 45388 | E11: 30 | F11: 0 | G11: 9444.62 | I11: Household Expenses | J11: UPI - Fresh Produce | K11: Groceries | L11: 0.82 | M11: [DIFF]
A12: 45395 | B12: UPI/P2A/447025620282/DEEPIKA UMESH MUNDADA/kitty/State Bank Of India | C12: - | D12: 45395 | E12: 1000 | F12: 0 | G12: 8444.62 | H12: Deepika Umesh Mundada | I12: Kitty | J12: UPI Payment | K12: Personal | L12: 0.55 | M12: [DIFF]
A13: 45405 | B13: UPI/P2A/448073432191/BHARTI RATAN DEVNANI /tiffin/Union Bank of India | C13: - | D13: 45405 | E13: 390 | F13: 0 | G13: 8054.62 | H13: Bharti Ratan Devnani | I13: Household Expenses | J13: UPI Payment | K13: Personal | L13: 0.55 | M13: [DIFF]
A14: 45406 | B14: UPI/P2M/448166340115/KUNAL EAKNATH MAKUNE /milk/Yes Bank Ltd | C14: - | D14: 45406 | E14: 150 | F14: 0 | G14: 7904.62 | H14: Kunal Eaknath Makune | I14: Household Expenses | J14: UPI Payment | K14: Personal | L14: 0.55 | M14: [DIFF]
A15: 45408 | B15: NEFT/YESB41177892573/ZERODHA BROKING LTD-DSCNB A//YES BANK/YESB0000001 | C15: - | D15: 45408 | E15: 0 | F15: 4251.5 | G15: 12156.12 | I15: Zerodha | J15: NEFT Transfer | K15: Transfer | L15: 0.7 | M15: [DIFF]
A16: 45415 | B16: ATM-CASH-AXIS/BPRH265601/1296/030524/NASHIK | C16: - | D16: 45415 | E16: 2000 | F16: 0 | G16: 10156.12 | I16: ATM Withdrawal | J16: Cash Withdrawal | K16: Cash | L16: 0.92 | M16: [MATCH]
A17: 45420 | B17: NEFT/N129243028299413/SUNITA GUPTA/HDFC BANK/Transfer from HDFC | C17: - | D17: 45420 | E17: 0 | F17: 50000 | G17: 60156.12 | I17: Contra | J17: Received - Sunita Gupta | K17: Sunita Gupta | L17: 0.88 | M17: [DIFF]
A18: 45420 | B18: UPI/P2M/412955259759/Zerodha Broking Ltd /001847/HDFC BANK LTD | C18: - | D18: 45420 | E18: 50000 | F18: 0 | G18: 10156.12 | I18: Zerodha | J18: Zerodha Broking | K18: Zerodha Broking Limited | L18: 0.88 | M18: [DIFF]
A19: 45422 | B19: UPI/P2M/413124576623/PREMJI TRADERS /UPI/Yes Bank Ltd | C19: - | D19: 45422 | E19: 1320 | F19: 0 | G19: 8836.12 | H19: Premji Traders | I19: Household Expenses | J19: UPI Payment | K19: Personal | L19: 0.55 | M19: [DIFF]
A20: 45427 | B20: NEFT/N136243040620640/SUNITA GUPTA/HDFC BANK/frm HDFC to Axis | C20: - | D20: 45427 | E20: 0 | F20: 100000 | G20: 108836.12 | I20: Contra | J20: Received - Sunita Gupta | K20: Sunita Gupta | L20: 0.88 | M20: [DIFF]
A21: 45427 | B21: INB/IFT/Ajay Kumar Gupta/TPARTY TRANSFER | C21: - | D21: 45427 | E21: 40000 | F21: 0 | G21: 68836.12 | I21: Transfer from Ajay | J21: Transfer - Ajay Gupta | K21: Ajay Gupta | L21: 0.88 | M21: [MATCH]
A22: 45436 | B22: INB/IFT/Ajay Kumar Gupta/TPARTY TRANSFER | C22: - | D22: 45436 | E22: 30000 | F22: 0 | G22: 38836.12 | I22: Transfer from Ajay | J22: Transfer - Ajay Gupta | K22: Ajay Gupta | L22: 0.88 | M22: [MATCH]
A23: 45451 | B23: NEFT/YESEB41601792243/ZERODHA BROKING LTD- FOR ZER/YES BANK/12067726cc9f47dca08914 Zerodh | C23: - | D23: 45451 | E23: 0 | F23: 7726.63 | G23: 46562.75 | I23: Zerodha | J23: NEFT Transfer | K23: Transfer | L23: 0.7 | M23: [DIFF]
A24: 45453 | B24: GST @18% on MAB Charge | C24: - | D24: 45453 | E24: 108 | F24: 0 | G24: 46454.75 | I24: Bank Charges | J24: Bank Charges | K24: Bank Charges | L24: 0.88 | M24: [MATCH]
A25: 45453 | B25: Non-Maint Avg bal chgs Apr2024 | C25: - | D25: 45453 | E25: 600 | F25: 0 | G25: 45854.75 | I25: Bank Charges | J25: Bank Charges | K25: Bank Charges | L25: 0.88 | M25: [MATCH]
A26: 45464 | B26: UPI/P2M/417362340012/ZERODHA BROKING LIMIT/244473/ICICI Bank | C26: - | D26: 45464 | E26: 25000 | F26: 0 | G26: 20854.75 | I26: Zerodha | J26: Zerodha Broking | K26: Zerodha Broking Limited | L26: 0.88 | M26: [DIFF]
A27: 45465 | B27: UPI/P2A/454025238186/PRERANA MANOJ CHANDAK/kitty/Axis Bank Ltd. | C27: - | D27: 45465 | E27: 1000 | F27: 0 | G27: 19854.75 | H27: Prerana Manoj Chandak | I27: Kitty | J27: UPI Payment | K27: Personal | L27: 0.55 | M27: [DIFF]
A28: 45467 | B28: NEFT/N176243108305610/SUNITA GUPTA/HDFC BANK/Trf frm Sunita HDF | C28: - | D28: 45467 | E28: 0 | F28: 50000 | G28: 69854.75 | I28: Contra | J28: Received - Sunita Gupta | K28: Sunita Gupta | L28: 0.88 | M28: [DIFF]
A29: 45467 | B29: UPI/P2M/417673461227/ZERODHA BROKING LIMIT/922743/ICICI Bank | C29: - | D29: 45467 | E29: 30000 | F29: 0 | G29: 39854.75 | I29: Zerodha | J29: Zerodha Broking | K29: Zerodha Broking Limited | L29: 0.88 | M29: [DIFF]
A30: 45467 | B30: UPI/P2M/417673480863/ZERODHA BROKING LIMIT/102002/ICICI Bank | C30: - | D30: 45467 | E30: 30000 | F30: 0 | G30: 9854.75 | I30: Zerodha | J30: Zerodha Broking | K30: Zerodha Broking Limited | L30: 0.88 | M30: [DIFF]
A31: 45467 | B31: NEFT/N176243109164220/SUNITA GUPTA/HDFC BANK/tfr frm Axis 2 hfc | C31: - | D31: 45467 | E31: 0 | F31: 25000 | G31: 34854.75 | I31: Contra | J31: Received - Sunita Gupta | K31: Sunita Gupta | L31: 0.88 | M31: [DIFF]
A32: 45472 | B32: UPI/P2A/418192452596/BHARTI RATAN DEVNANI /tiffin/Union Bank of India | C32: - | D32: 45472 | E32: 770 | F32: 0 | G32: 34084.75 | H32: Bharti Ratan Devnani | I32: Household Expenses | J32: UPI Payment | K32: Personal | L32: 0.55 | M32: [DIFF]
A33: 45474 | B33: SB:919010088767042:Int.Pd:01-04-2024 to 30-06-2024 | C33: - | D33: 45474 | E33: 0 | F33: 208 | G33: 34292.75 | I33: Bank Interest | J33: Bank Interest | K33: Bank Interest | L33: 0.93 | M33: [MATCH]
A34: 45474 | B34: ACH-CR-CANBANK DIV 2023-24-NACH-6544153-6544153 | C34: - | D34: 45474 | E34: 0 | F34: 805 | G34: 35097.75 | I34: Dividend Income | J34: Dividend Income | K34: Dividend Income | L34: 0.85 | M34: [MATCH]
A35: 45474 | B35: ATM-CASH-AXIS/BPRH265601/1591/010724/NASHIK | C35: - | D35: 45474 | E35: 2000 | F35: 0 | G35: 33097.75 | I35: ATM Withdrawal | J35: Cash Withdrawal | K35: Cash | L35: 0.92 | M35: [MATCH]
A36: 45476 | B36: NEFT/YESEB41852036982/ZERODHA BROKING LTD- FOR ZER/YES BANK/4565c0180515af30213b5d Zerodh | C36: - | D36: 45476 | E36: 0 | F36: 3688.79 | G36: 36786.54 | I36: Zerodha | J36: NEFT Transfer | K36: Transfer | L36: 0.7 | M36: [DIFF]
A37: 45478 | B37: UPI/P2M/455345663321/JEET PHARMACY AND MIN/medici/Axis Bank Ltd. | C37: - | D37: 45478 | E37: 22 | F37: 0 | G37: 36764.54 | I37: UPI | J37: UPI - Pharmacy | K37: Healthcare | L37: 0.85 | M37: [MATCH]
A38: 45478 | B38: UPI/P2A/455392699359/RAKHI VIN/ICICI Ban/UPI/ | C38: - | D38: 45478 | E38: 0 | F38: 1000 | G38: 37764.54 | I38: UPI | J38: Received - Rakhi Vin | K38: Personal | L38: 0.55 | M38: [DIFF]
A39: 45479 | B39: UPI/P2A/418872101808/DEEPIKA U/State Ban/UPI/ | C39: - | D39: 45479 | E39: 0 | F39: 1000 | G39: 38764.54 | I39: UPI | J39: Received - Deepika U | K39: Personal | L39: 0.55 | M39: [DIFF]
A40: 45481 | B40: UPI/P2A/419032821898/KAMINI MIHANI 95279/cream/State Bank Of India | C40: - | D40: 45481 | E40: 650 | F40: 0 | G40: 38114.54 | H40: Kamini Mihani 95279 | I40: UPI | J40: UPI Payment | K40: Personal | L40: 0.55 | M40: [MATCH]
A41: 45484 | B41: UPI/P2A/419395681329/BHUTADA S/Bank of B/Payment/ | C41: - | D41: 45484 | E41: 0 | F41: 1000 | G41: 39114.54 | I41: UPI | J41: Received - Bhutada S | K41: Personal | L41: 0.55 | M41: [DIFF]
...

Sheet HDFC
B1: HDFC Bank Narration Sheet
B2: Colour Legend of Categories:
B3: HDFC Securities - Buy | C3: HDFC Securities - Sell | D3: Internal Transfer | E3: Depository Charges | F3: Received - Sunita Gupta
B4: MF Investment | C4: SIP | D4: Transfer - Sunita Gupta | E4: Dividend Income | F4: Bank Charges
B5: Transfer - Archit Gupta | C5: Received - Ajay Gupta | D5: Bank Interest | E5: Cash Withdrawal | F5: Income Tax Refund
B6: UPI Payment | C6: UPI - Paytm | D6: UPI - Fresh Produce | E6: Transfer - Ajay Gupta | F6: HDFC Securities - Settlement
B7: Received - Archit Gupta | C7: MF Redemption | D7: Cash Deposit | E7: Transfer - Megha Gupta | F7: Misc Income
A9: Date | B9: Particulars | C9: Ref | D9: Value_Date | E9: DR | F9: CR | G9: Balance | H9: Beneficiary | I9: Human_Narration | J9: Auto_Narration | K9: Account_Head | L9: Confidence | M9: Match
A10: 45383 | B10: NET PI TO HSL SEC A/C 523686-00602340029434 | C10: 0000000508932363 | D10: 45383 | E10: 1672 | F10: 0 | G10: 31564 | I10: HSL | J10: HDFC Securities - Buy | K10: HDFC Securities | L10: 0.97 | M10: [MATCH]
A11: 45384 | B11: NET PO FROM HSL A/C 523686-50200085415108 | C11: 0000000509188445 | D11: 45384 | E11: 0 | F11: 16753.39 | G11: 48317.39 | I11: HSL | J11: HDFC Securities - Sell | K11: HDFC Securities | L11: 0.97 | M11: [MATCH]
A12: 45384 | B12: NET PO FROM HSL A/C 523686-50200085415108 | C12: 0000000509246217 | D12: 45384 | E12: 0 | F12: 97641.5 | G12: 145958.89 | I12: HSL | J12: HDFC Securities - Sell | K12: HDFC Securities | L12: 0.97 | M12: [MATCH]
A13: 45384 | B13: NET PI TO HSL SEC A/C 523686-00602340029434 | C13: 0000000509399140 | D13: 45384 | E13: 418 | F13: 0 | G13: 145540.89 | I13: HSL | J13: HDFC Securities - Buy | K13: HDFC Securities | L13: 0.97 | M13: [MATCH]
A14: 45384 | B14: NET PI TO HSL SEC A/C 523686-00602340029434 | C14: 0000000509532005 | D14: 45384 | E14: 103098.99 | F14: 0 | G14: 42441.9 | I14: HSL | J14: HDFC Securities - Buy | K14: HDFC Securities | L14: 0.97 | M14: [MATCH]
A15: 45385 | B15: NET PO FROM HSL A/C 523686-50200085415108 | C15: 0000000509650601 | D15: 45385 | E15: 0 | F15: 1514.95 | G15: 43956.85 | I15: HSL | J15: HDFC Securities - Sell | K15: HDFC Securities | L15: 0.97 | M15: [MATCH]
A16: 45385 | B16: NET PI TO HSL SEC A/C 523686-00602340029434 | C16: 0000000509793906 | D16: 45385 | E16: 379.22 | F16: 0 | G16: 43577.63 | I16: HSL | J16: HDFC Securities - Buy | K16: HDFC Securities | L16: 0.97 | M16: [MATCH]
A17: 45386 | B17: NET PO FROM HSL A/C 523686-50200085415108 | C17: 0000000510056916 | D17: 45386 | E17: 0 | F17: 6701.42 | G17: 50279.05 | I17: HSL | J17: HDFC Securities - Sell | K17: HDFC Securities | L17: 0.97 | M17: [MATCH]
A18: 45386 | B18: 50100128155413-TPT-TO MUMMY-AAYUSH KUMAR GUPTA | C18: 0000000526007002 | D18: 45386 | E18: 0 | F18: 30000 | G18: 80279.05 | I18: Transfer from Aayush | J18: Internal Transfer | K18: Transfer | L18: 0.8 | M18: [DIFF]
A19: 45386 | B19: NET PI TO HSL SEC A/C 523686-00602340029434 | C19: 0000000510198174 | D19: 45386 | E19: 425.81 | F19: 0 | G19: 79853.24 | I19: HSL | J19: HDFC Securities - Buy | K19: HDFC Securities | L19: 0.97 | M19: [MATCH]
A20: 45386 | B20: NET PI TO HSL SEC A/C 523686-00602340029434 | C20: 0000000510339907 | D20: 45386 | E20: 72828.22 | F20: 0 | G20: 7025.02 | I20: HSL | J20: HDFC Securities - Buy | K20: HDFC Securities | L20: 0.97 | M20: [MATCH]
A21: 45387 | B21: NET PI TO HSL SEC A/C 523686-00602340029434 | C21: 0000000510610766 | D21: 45387 | E21: 402.46 | F21: 0 | G21: 6622.56 | I21: HSL | J21: HDFC Securities - Buy | K21: HDFC Securities | L21: 0.97 | M21: [MATCH]
... A336: 45523 | B336: NET PI TO HSL SEC A/C 523686-00602340029434 | C336: 0000000553401436 | D336: 45523 | E336: 891.84 | F336: 0 | G336: 82313.36 | I336: HSL | J336: HDFC Securities - Buy | K336: HDFC Securities | L336: 0.97 | M336: [MATCH]
A337: 45523 | B337: UPI-BHARAT SHIVAJI SALVE-Q693795930@YBL-YESB0YBLUPI-459804001805-VEGITABLE | C337: 0000459804001805 | D337: 45523 | E337: 290 | F337: 0 | G337: 82023.36 | H337: Bharat Shivaji Salve | I337: UPI | J337: UPI Payment | K337: Personal | L337: 0.55 | M337: [MATCH]
A338: 45523 | B338: YHDF2417946248/BILLDKTHECALCUTTAELE | C338: 0002423259470626 | D338: 45523 | E338: 17805 | F338: 0 | G338: 64218.36 | I338: Electricity Bill | J338: SIP | K338: SIP | L338: 0.9 | M338: [DIFF]
A339: 45523 | B339: NET PI TO HSL SEC A/C 523686-00602340029434 | C339: 0000000553549010 | D339: 45523 | E339: 1362.77 | F339: 0 | G339: 62855.59 | I339: HSL | J339: HDFC Securities - Buy | K339: HDFC Securities | L339: 0.97 | M339: [MATCH]
A340: 45524 | B340: NET PO FROM HSL A/C 523686-50200085415108 | C340: 0000000553719337 | D340: 45524 | E340: 0 | F340: 87679.6 | G340: 150535.19 | I340: HSL | J340: HDFC Securities - Sell | K340: HDFC Securities | L340: 0.97 | M340: [MATCH]
A341: 45524 | B341: UPI-OM SUPAR SHOPI-PAYTMQR1BM2V0ZITY@PAYTM-YESB0PTMUPI-423376646504-CHACH | C341: 0000423376646504 | D341: 45524 | E341: 18 | F341: 0 | G341: 150517.19 | I341: UPI | J341: UPI - Paytm | K341: Personal | L341: 0.65 | M341: [MATCH]
A342: 45524 | B342: UPI-BHARAT SHIVAJI SALVE-Q275219389@YBL-YESB0YBLUPI-459917741143-FRUIT | C342: 0000459917741143 | D342: 45524 | E342: 300 | F342: 0 | G342: 150217.19 | I342: UPI | J342: UPI - Fresh Produce | K342: Groceries | L342: 0.82 | M342: [MATCH]
A343: 45524 | B343: NET PI TO HSL SEC A/C 523686-00602340029434 | C343: 0000000553854506 | D343: 45524 | E343: 279.69 | F343: 0 | G343: 149937.5 | I343: HSL | J343: HDFC Securities - Buy | K343: HDFC Securities | L343: 0.97 | M343: [MATCH]
A344: 45524 | B344: UPI-KUNAL RAMESH JADHAV-Q579080630@YBL-YESB0YBLUPI-459947687018-BUKE | C344: 0000459947687018 | D344: 45524 | E344: 130 | F344: 0 | G344: 149807.5 | H344: Kunal Ramesh Jadhav | I344: UPI | J344: UPI Payment | K344: Personal | L344: 0.55 | M344: [MATCH]
A345: 45525 | B345: NET PO FROM HSL A/C 523686-50200085415108 | C345: 0000000554118937 | D345: 45525 | E345: 0 | F345: 87035.28 | G345: 236842.78 | I345: HSL | J345: HDFC Securities - Sell | K345: HDFC Securities | L345: 0.97 | M345: [MATCH]
A346: 45525 | B346: UPI-KRUSHNASAGAR MITHAI-PAYTMQR596DKQ@PAYTM-YESB0PTMUPI-423452847251-NAMKIN | C346: 0000423452847251 | D346: 45525 | E346: 55 | F346: 0 | G346: 236787.78 | I346: UPI | J346: UPI - Paytm | K346: Personal | L346: 0.65 | M346: [MATCH]
A347: 45525 | B347: 01671000085930-TPT-BORROW FROM SUNITA-AJAY KUMAR GUPTA | C347: 0000000311404451 | D347: 45525 | E347: 200000 | F347: 0 | G347: 36787.78 | I347: Transfer to Ajay | J347: Transfer - Sunita Gupta | K347: Sunita Gupta | L347: 0.88 | M347: [DIFF]
A348: 45525 | B348: ACH C- CDSL FNLDIV 2023 24-345199 | C348: 0000007667792344 | D348: 45525 | E348: 0 | F348: 1980 | G348: 38767.78 | I348: Dividend Income | J348: Dividend Income | K348: Dividend Income | L348: 0.88 | M348: [MATCH]
A349: 45525 | B349: NET PI TO HSL SEC A/C 523686-00602340029434 | C349: 0000000554261223 | D349: 45525 | E349: 280.7 | F349: 0 | G349: 38487.08 | I349: HSL | J349: HDFC Securities - Buy | K349: HDFC Securities | L349: 0.97 | M349: [MATCH]
A350: 45526 | B350: NET PO FROM HSL A/C 523686-50200085415108 | C350: 0000000554540381 | D350: 45526 | E350: 0 | F350: 13652.52 | G350: 52139.6 | I350: HSL | J350: HDFC Securities - Sell | K350: HDFC Securities | L350: 0.97 | M350: [MATCH]
A351: 45526 | B351: NET PI TO HSL SEC A/C 523686-00602340029434 | C351: 0000000554671236 | D351: 45526 | E351: 254.07 | F351: 0 | G351: 51885.53 | I351: HSL | J351: HDFC Securities - Buy | K351: HDFC Securities | L351: 0.97 | M351: [MATCH]
A352: 45526 | B352: 01671000085930-TPT-MONEY RETURNED-AJAY KUMAR GUPTA | C352: 0000000317317050 | D352: 45526 | E352: 0 | F352: 200000 | G352: 251885.53 | I352: Transfer by Ajay | J352: Received - Ajay Gupta | K352: Ajay Gupta | L352: 0.88 | M352: [DIFF]
A353: 45527 | B353: NET PO FROM HSL A/C 523686-50200085415108 | C353: 0000000554967819 | D353: 45527 | E353: 0 | F353: 1025.02 | G353: 252910.55 | I353: HSL | J353: HDFC Securities - Sell | K353: HDFC Securities | L353: 0.97 | M353: [MATCH]
A354: 45527 | B354: NET PO FROM HSL A/C 523686-50200085415108 | C354: 0000000555007760 | D354: 45527 | E354: 0 | F354: 41057.08 | G354: 293967.63 | I354: HSL | J354: HDFC Securities - Sell | K354: HDFC Securities | L354: 0.97 | M354: [MATCH]
A355: 45527 | B355: NET PI TO HSL SEC A/C 523686-00602340029434 | C355: 0000000555104327 | D355: 45527 | E355: 258.93 | F355: 0 | G355: 293708.7 | I355: HSL | J355: HDFC Securities - Buy | K355: HDFC Securities | L355: 0.97 | M355: [MATCH]
...

Sheet SBI
B1: State Bank of India Narration Sheet
B2: Colour Legend of Categories:
B3: Cash Withdrawal | C3: Bank Interest | D3: What is this? | E3: Received - Sunita Gupta | F3: Rent
A5: Date | B5: Particulars | C5: Ref | D5: Value_Date | E5: DR | F5: CR | G5: Balance | H5: Beneficiary | I5: Human_Narration | J5: Auto_Narration | K5: Account_Head | L5: Confidence | M5: Match
A6: 45415 | B6: ATM WDL-ATM CASH 3233 SBI SHIVAJI NAGAR ATM NASHIK-- | D6: 45415 | E6: 2000 | F6: 0 | G6: 24120.7 | I6: ATM Withdrawal | J6: Cash Withdrawal | K6: Cash | L6: 0.92 | M6: [MATCH]
A7: 45468 | B7: CREDIT INTEREST--- | D7: 45468 | E7: 0 | F7: 169 | G7: 24289.7 | I7: Bank Interest | J7: Bank Interest | K7: Bank Interest | L7: 0.9 | M7: [MATCH]
A8: 45474 | B8: ATM WDL-ATM CASH 2734 SBI SHIVAJI NAGAR ATM NASHIK-- | D8: 45474 | E8: 2000 | F8: 0 | G8: 22289.7 | I8: ATM Withdrawal | J8: Cash Withdrawal | K8: Cash | L8: 0.92 | M8: [MATCH]
A9: 45554 | B9: DEBIT-ATMCard AMC 652294*8079-- | D9: 45554 | E9: 236 | F9: 0 | G9: 22053.7 | I9: Bank Charges | J9: What is this? | K9: Suspense | L9: 0 | M9: [DIFF]
A10: 45560 | B10: CREDIT INTEREST--- | D10: 45560 | E10: 0 | F10: 152 | G10: 22205.7 | I10: Bank Interest | J10: Bank Interest | K10: Bank Interest | L10: 0.9 | M10: [MATCH]
A11: 45651 | B11: CREDIT INTEREST--- | D11: 45651 | E11: 0 | F11: 149 | G11: 22354.7 | I11: Bank Interest | J11: Bank Interest | K11: Bank Interest | L11: 0.9 | M11: [MATCH]
A12: 45708 | B12: BY TRANSFER-INB borrow-- | C12: IID4853269 TRANSFER FROM 32718635441 | D12: 45708 | E12: 0 | F12: 100000 | G12: 122354.7 | I12: Transfer from Ajay | J12: What is this? | K12: Suspense | L12: 0 | M12: [DIFF]
A13: 45709 | B13: TO TRANSFER-INB Security deposit return-- | C13: IT00YWYOL0 TRANSFER TO 35730790076 | D13: 45709 | E13: 100000 | F13: 0 | G13: 22354.7 | I13: Security Deposit Returned | J13: What is this? | K13: Suspense | L13: 0 | M13: [DIFF]
A14: 45724 | B14: BY TRANSFER-INB borrow from Sunita-- | C14: IID5359354 TRANSFER FROM 32718635441 | D14: 45724 | E14: 0 | F14: 32000 | G14: 54354.7 | I14: Transfer from Ajay | J14: Received - Sunita Gupta | K14: Sunita Gupta | L14: 0.88 | M14: [DIFF]
A15: 45724 | B15: TO TRANSFER-INB Pymt twrds scrap material-- | C15: IT00ZBZYC9 TRANSFER TO 35730790076 | D15: 45724 | E15: 43000 | F15: 0 | G15: 11354.7 | I15: Asset Purchase | J15: What is this? | K15: Suspense | L15: 0 | M15: [DIFF]
A16: 45726 | B16: BY TRANSFER-NEFT*HDFC0000001*HDFCH00113163511*SUNITA GUPTA*BAT-- | C16: TRANSFER FROM 3199970044309 | D16: 45726 | E16: 0 | F16: 30000 | G16: 41354.7 | I16: Rent Income | J16: Received - Sunita Gupta | K16: Sunita Gupta | L16: 0.88 | M16: [DIFF]
A17: 45726 | B17: TO TRANSFER-INB Rent-- | C17: IT00ZCPZM4 TRANSFER TO 35730790076 | D17: 45726 | E17: 21955 | F17: 0 | G17: 19399.7 | J17: Rent | K17: Rent | L17: 0.9 | M17: N/A
A18: 45741 | B18: CREDIT INTEREST--- | D18: 45741 | E18: 0 | F18: 151 | G18: 19550.7 | I18: Bank Interest | J18: Bank Interest | K18: Bank Interest | L18: 0.9 | M18: [MATCH]

Sheet For Tally
B1: Tally Export Narration Sheet
B2: Colour Legend of Categories:
B3: HDFC Securities - Buy | C3: HDFC Securities - Sell | D3: Internal Transfer | E3: Depository Charges | F3: UPI - Fresh Produce
B4: Received - Sunita Gupta | C4: UPI Payment | D4: MF Investment | E4: SIP | F4: Transfer - Sunita Gupta
B5: Dividend Income | C5: NEFT Transfer | D5: Bank Charges | E5: Cash Withdrawal | F5: Zerodha Broking
B6: Transfer - Archit Gupta | C6: Transfer - Ajay Gupta | D6: Received - Ajay Gupta | E6: Bank Interest | F6: Received - Rakhi Vin
B7: UPI - Pharmacy | C7: Received - Deepika U | D7: Received - Bhutada S | E7: Received - Aditya Dh | F7: Received - Priti Muk
B8: Received - Deepali A | C8: UPI - IRCTC | D8: Income Tax Refund | E8: UPI - Flipkart | F8: UPI - Paytm
B9: Misc Income | C9: UPI - Meesho | D9: Received - Sharda Ar | E9: Received - Manjoosha | F9: HDFC Securities - Settlement
B10: What is this? | C10: Received - Archit Gupta | D10: MF Redemption | E10: Received - Google In | F10: Shopping - Jewellery
B11: Cash Deposit | C11: Transfer - Megha Gupta | D11: Rent | E11: Health Insurance
A13: TX Date | B13: Date | C13: DR | D13: CR | E13: Beneficiary | F13: Narration | G13: Confidence | H13: Account Head | I13: Account No | J13: Kya Hai? | K13: Particulars | L13: Bank | M13: Duplicate
A14: 45383 | B14: 45383 | C14: 1672 | D14: 0 | F14: HDFC Securities - Buy | G14: 0.97 | H14: HDFC Securities | I14: HDFC 0094 | J14: HSL | K14: NET PI TO HSL SEC A/C 523686-00602340029434 | L14: HDFC Bank
A15: 45384 | B15: 45384 | C15: 0 | D15: 16753.39 | F15: HDFC Securities - Sell | G15: 0.97 | H15: HDFC Securities | I15: HDFC 0094 | J15: HSL | K15: NET PO FROM HSL A/C 523686-50200085415108 | L15: HDFC Bank
A16: 45384 | B16: 45384 | C16: 0 | D16: 97641.5 | F16: HDFC Securities - Sell | G16: 0.97 | H16: HDFC Securities | I16: HDFC 0094 | J16: HSL | K16: NET PO FROM HSL A/C 523686-50200085415108 | L16: HDFC Bank
A17: 45384 | B17: 45384 | C17: 418 | D17: 0 | F17: HDFC Securities - Buy | G17: 0.97 | H17: HDFC Securities | I17: HDFC 0094 | J17: HSL | K17: NET PI TO HSL SEC A/C 523686-00602340029434 | L17: HDFC Bank
A18: 45384 | B18: 45384 | C18: 103098.99 | D18: 0 | F18: HDFC Securities - Buy | G18: 0.97 | H18: HDFC Securities | I18: HDFC 0094 | J18: HSL | K18: NET PI TO HSL SEC A/C 523686-00602340029434 | L18: HDFC Bank
A19: 45385 | B19: 45385 | C19: 0 | D19: 1514.95 | F19: HDFC Securities - Sell | G19: 0.97 | H19: HDFC Securities | I19: HDFC 0094 | J19: HSL | K19: NET PO FROM HSL A/C 523686-50200085415108 | L19: HDFC Bank
A20: 45385 | B20: 45385 | C20: 379.22 | D20: 0 | F20: HDFC Securities - Buy | G20: 0.97 | H20: HDFC Securities | I20: HDFC 0094 | J20: HSL | K20: NET PI TO HSL SEC A/C 523686-00602340029434 | L20: HDFC Bank
A21: 45386 | B21: 45386 | C21: 0 | D21: 6701.42 | F21: HDFC Securities - Sell | G21: 0.97 | H21: HDFC Securities | I21: HDFC 0094 | J21: HSL | K21: NET PO FROM HSL A/C 523686-50200085415108 | L21: HDFC Bank
A22: 45386 | B22: 45386 | C22: 0 | D22: 30000 | F22: Internal Transfer | G22: 0.8 | H22: Transfer | I22: HDFC 0094 | J22: Transfer from Aayush | K22: 50100128155413-TPT-TO MUMMY-AAYUSH KUMAR GUPTA | L22: HDFC Bank
A23: 45386 | B23: 45386 | C23: 425.81 | D23: 0 | F23: HDFC Securities - Buy | G23: 0.97 | H23: HDFC Securities | I23: HDFC 0094 | J23: HSL | K23: NET PI TO HSL SEC A/C 523686-00602340029434 | L23: HDFC Bank
A24: 45386 | B24: 45386 | C24: 72828.22 | D24: 0 | F24: HDFC Securities - Buy | G24: 0.97 | H24: HDFC Securities | I24: HDFC 0094 | J24: HSL | K24: NET PI TO HSL SEC A/C 523686-00602340029434 | L24: HDFC Bank
A25: 45387 | B25: 45387 | C25: 402.46 | D25: 0 | F25: HDFC Securities - Buy | G25: 0.97 | H25: HDFC Securities | I25: HDFC 0094 | J25: HSL | K25: NET PI TO HSL SEC A/C 523686-00602340029434 | L25: HDFC Bank
... A41: 45394 | B41: 45394 | C41: 0 | D41: 30503.75 | F41: HDFC Securities - Sell | G41: 0.97 | H41: HDFC Securities | I41: HDFC 0094 | J41: HSL | K41: NET PO FROM HSL A/C 523686-50200085415108 | L41: HDFC Bank
A42: 45395 | B42: 45395 | C42: 1000 | D42: 0 | E42: Deepika Umesh Mundada | F42: UPI Payment | G42: 0.55 | H42: Personal | I42: AXIS 7042 | J42: Kitty | K42: UPI/P2A/447025620282/DEEPIKA UMESH MUNDADA/kitty/State Bank Of India | L42: Axis Bank
A43: 45397 | B43: 45397 | C43: 0 | D43: 29255.99 | F43: HDFC Securities - Sell | G43: 0.97 | H43: HDFC Securities | I43: HDFC 0094 | J43: HSL | K43: NET PO FROM HSL A/C 523686-50200085415108 | L43: HDFC Bank
A44: 45397 | B44: 45397 | C44: 5000 | D44: 0 | F44: MF Investment | G44: 0.92 | H44: Mutual_Fund_Investments | I44: HDFC 0094 | J44: SIP - 5000 | K44: ACH D- INDIAN CLEARING CORP-P25847643X05 | L44: HDFC Bank
A45: 45397 | B45: 45397 | C45: 1254.81 | D45: 0 | F45: HDFC Securities - Buy | G45: 0.97 | H45: HDFC Securities | I45: HDFC 0094 | J45: HSL | K45: NET PI TO HSL SEC A/C 523686-00602340029434 | L45: HDFC Bank
A46: 45398 | B46: 45398 | C46: 32991.42 | D46: 0 | F46: HDFC Securities - Buy | G46: 0.97 | H46: HDFC Securities | I46: HDFC 0094 | J46: HSL | K46: NET PI TO HSL SEC A/C 523686-00602340029434 | L46: HDFC Bank
A47: 45398 | B47: 45398 | C47: 10000 | D47: 0 | F47: SIP | G47: 0.9 | H47: SIP | I47: HDFC 0094 | J47: Electricity Bill | K47: YHDF2301816719/BILLDKINDIANCLEARING | L47: HDFC Bank
A48: 45398 | B48: 45398 | C48: 0 | D48: 29141.48 | F48: HDFC Securities - Sell | G48: 0.97 | H48: HDFC Securities | I48: HDFC 0094 | J48: HSL | K48: NET PO FROM HSL A/C 523686-50200085415108 | L48: HDFC Bank
A49: 45398 | B49: 45398 | C49: 400.81 | D49: 0 | F49: HDFC Securities - Buy | G49: 0.97 | H49: HDFC Securities | I49: HDFC 0094 | J49: HSL | K49: NET PI TO HSL SEC A/C 523686-00602340029434 | L49: HDFC Bank
A50: 45400 | B50: 45400 | C50: 0 | D50: 10255.18 | F50: HDFC Securities - Sell | G50: 0.97 | H50: HDFC Securities | I50: HDFC 0094 | J50: HSL | K50: NET PO FROM HSL A/C 523686-50200085415108 | L50: HDFC Bank
A51: 45400 | B51: 45400 | C51: 731.06 | D51: 0 | F51: HDFC Securities - Buy | G51: 0.97 | H51: HDFC Securities | I51: HDFC 0094 | J51: HSL | K51: NET PI TO HSL SEC A/C 523686-00602340029434 | L51: HDFC Bank
A52: 45400 | B52: 45400 | C52: 20472.73 | D52: 0 | F52: HDFC Securities - Buy | G52: 0.97 | H52: HDFC Securities | I52: HDFC 0094 | J52: HSL | K52: NET PI TO HSL SEC A/C 523686-00602340029434 | L52: HDFC Bank
A53: 45401 | B53: 45401 | C53: 26524.15 | D53: 0 | F53: HDFC Securities - Buy | G53: 0.97 | H53: HDFC Securities | I53: HDFC 0094 | J53: HSL | K53: NET PI TO HSL SEC A/C 523686-00602340029434 | L53: HDFC Bank
A54: 45401 | B54: 45401 | C54: 401.53 | D54: 0 | F54: HDFC Securities - Buy | G54: 0.97 | H54: HDFC Securities | I54: HDFC 0094 | J54: HSL | K54: NET PI TO HSL SEC A/C 523686-00602340029434 | L54: HDFC Bank
A55: 45404 | B55: 45404 | C55: 1243.71 | D55: 0 | F55: HDFC Securities - Buy | G55: 0.97 | H55: HDFC Securities | I55: HDFC 0094 | J55: HSL | K55: NET PI TO HSL SEC A/C 523686-00602340029434 | L55: HDFC Bank
A56: 45405 | B56: 45405 | C56: 390 | D56: 0 | E56: Bharti Ratan Devnani | F56: UPI Payment | G56: 0.55 | H56: Personal | I56: AXIS 7042 | J56: Household Expenses | K56: UPI/P2A/448073432191/BHARTI RATAN DEVNANI /tiffin/Union Bank of India | L56: Axis Bank
...

Sheet Conso
A1: Aayush Kumar Gupta
A2: Account of Statements from 01-Apr-2024 to 29-Mar-2025 | D2: =SUM(D5:D929) | E2: =SUM(E5:E929) | F2: =E2-D2
A4: TX Date | B4: Particulars | C4: Ref | D4: DR | E4: CR | F4: Balance | G4: Account Head | H4: Account No
A5: 45383 | B5: NET PI TO HSL SEC A/C 523686-00602340029434 | C5: 0000000508932363 | D5: 1672 | E5: 0 | F5: 31564 | G5: HDFC Securities | H5: HDFC 0094
A6: 45384 | B6: NET PO FROM HSL A/C 523686-50200085415108 | C6: 0000000509188445 | D6: 0 | E6: 16753.39 | F6: 48317.39 | G6: HDFC Securities | H6: HDFC 0094
A7: 45384 | B7: NET PO FROM HSL A/C 523686-50200085415108 | C7: 0000000509246217 | D7: 0 | E7: 97641.5 | F7: 145958.89 | G7: HDFC Securities | H7: HDFC 0094
A8: 45384 | B8: NET PI TO HSL SEC A/C 523686-00602340029434 | C8: 0000000509399140 | D8: 418 | E8: 0 | F8: 145540.89 | G8: HDFC Securities | H8: HDFC 0094
A9: 45384 | B9: NET PI TO HSL SEC A/C 523686-00602340029434 | C9: 0000000509532005 | D9: 103098.99 | E9: 0 | F9: 42441.9 | G9: HDFC Securities | H9: HDFC 0094
A10: 45385 | B10: NET PO FROM HSL A/C 523686-50200085415108 | C10: 0000000509650601 | D10: 0 | E10: 1514.95 | F10: 43956.85 | G10: HDFC Securities | H10: HDFC 0094
A11: 45385 | B11: NET PI TO HSL SEC A/C 523686-00602340029434 | C11: 0000000509793906 | D11: 379.22 | E11: 0 | F11: 43577.63 | G11: HDFC Securities | H11: HDFC 0094
A12: 45386 | B12: NET PO FROM HSL A/C 523686-50200085415108 | C12: 0000000510056916 | D12: 0 | E12: 6701.42 | F12: 50279.05 | G12: HDFC Securities | H12: HDFC 0094
A13: 45386 | B13: 50100128155413-TPT-TO MUMMY-AAYUSH KUMAR GUPTA | C13: 0000000526007002 | D13: 0 | E13: 30000 | F13: 80279.05 | G13: Transfer | H13: HDFC 0094
A14: 45386 | B14: NET PI TO HSL SEC A/C 523686-00602340029434 | C14: 0000000510198174 | D14: 425.81 | E14: 0 | F14: 79853.24 | G14: HDFC Securities | H14: HDFC 0094
A15: 45386 | B15: NET PI TO HSL SEC A/C 523686-00602340029434 | C15: 0000000510339907 | D15: 72828.22 | E15: 0 | F15: 7025.02 | G15: HDFC Securities | H15: HDFC 0094
A16: 45387 | B16: NET PI TO HSL SEC A/C 523686-00602340029434 | C16: 0000000510610766 | D16: 402.46 | E16: 0 | F16: 6622.56 | G16: HDFC Securities | H16: HDFC 0094
... A81: 45415 | B81: NET PI TO HSL SEC A/C 523686-00602340029434 | C81: 0000000518339597 | D81: 10104.28 | E81: 0 | F81: 129461.15 | G81: HDFC Securities | H81: HDFC 0094
A82: 45415 | B82: ATM WDL-ATM CASH 3233 SBI SHIVAJI NAGAR ATM NASHIK-- | D82: 2000 | E82: 0 | F82: 24120.7 | G82: Cash | H82: SBI 7685
A83: 45415 | B83: NET PI TO HSL SEC A/C 523686-00602340029434 | C83: 0000000518405610 | D83: 56293.41 | E83: 0 | F83: 73167.74 | G83: HDFC Securities | H83: HDFC 0094
A84: 45415 | B84: ATM-CASH-AXIS/BPRH265601/1296/030524/NASHIK | C84: - | D84: 2000 | E84: 0 | F84: 10156.12 | G84: Cash | H84: AXIS 7042
A85: 45418 | B85: NET PO FROM HSL A/C 523686-50200085415108 | C85: 0000000518591456 | D85: 0 | E85: 4235.46 | F85: 77403.2 | G85: HDFC Securities | H85: HDFC 0094
A86: 45418 | B86: NET PI TO HSL SEC A/C 523686-00602340029434 | C86: 0000000518796402 | D86: 572.91 | E86: 0 | F86: 76830.29 | G86: HDFC Securities | H86: HDFC 0094
A87: 45419 | B87: NET PI TO HSL SEC A/C 523686-00602340029434 | C87: 0000000519455052 | D87: 25590.3 | E87: 0 | F87: 79699.58 | G87: HDFC Securities | H87: HDFC 0094
A88: 45419 | B88: NET PI TO HSL SEC A/C 523686-00602340029434 | C88: 0000000519502107 | D88: 414.01 | E88: 0 | F88: 79285.57 | G88: HDFC Securities | H88: HDFC 0094
A89: 45419 | B89: NET PI TO HSL SEC A/C 523686-00602340029434 | C89: 0000000519276521 | D89: 244.98 | E89: 0 | F89: 105289.88 | G89: HDFC Securities | H89: HDFC 0094
A90: 45419 | B90: NET PO FROM HSL A/C 523686-50200085415108 | C90: 0000000519124423 | D90: 0 | E90: 28704.57 | F90: 105534.86 | G90: HDFC Securities | H90: HDFC 0094
A91: 45420 | B91: UPI/P2M/412955259759/Zerodha Broking Ltd /001847/HDFC BANK LTD | C91: - | D91: 50000 | E91: 0 | F91: 10156.12 | G91: Zerodha Broking Limited | H91: AXIS 7042
A92: 45420 | B92: NET PO FROM HSL A/C 523686-50200085415108 | C92: 0000000519626421 | D92: 0 | E92: 100255.34 | F92: 179540.91 | G92: HDFC Securities | H92: HDFC 0094
A93: 45420 | B93: NET PI TO HSL SEC A/C 523686-00602340029434 | C93: 0000000519739579 | D93: 217.06 | E93: 0 | F93: 179323.85 | G93: HDFC Securities | H93: HDFC 0094
A94: 45420 | B94: NEFT DR-UTIB0002656-SUNITA GUPTA-NETBANK, MUM-N129243028299413-TRANSFER FROM HDFC | C94: N129243028299413 | D94: 50000 | E94: 0 | F94: 129323.85 | G94: Sunita Gupta | H94: HDFC 0094
... A229: 45468 | B229: NET PI TO HSL SEC A/C 523686-00602340029434 | C229: 0000000535062991 | D229: 31517.3 | E229: 0 | F229: 81011.44 | G229: HDFC Securities | H229: HDFC 0094
A230: 45468 | B230: CREDIT INTEREST--- | D230: 0 | E230: 169 | F230: 24289.7 | G230: Bank Interest | H230: SBI 7685
A231: 45468 | B231: ACH D- INDIAN CLEARING CORP-P25847643X05 | C231: 0000005424732775 | D231: 10000 | E231: 0 | F231: 262129.36 | G231: Mutual_Fund_Investments | H231: HDFC 0094
A232: 45469 | B232: NET PI TO HSL SEC A/C 523686-00602340029434 | C232: 0000000535488603 | D232: 5260.5 | E232: 0 | F232: 133225.42 | G232: HDFC Securities | H232: HDFC 0094
A233: 45469 | B233: NET PO FROM HSL A/C 523686-50200085415108 | C233: 0000000535184207 | D233: 0 | E233: 7425.28 | F233: 88436.72 | G233: HDFC Securities | H233: HDFC 0094
A234: 45469 | B234: NET PO FROM HSL A/C 523686-50200085415108 | C234: 0000000535222691 | D234: 0 | E234: 50389.77 | F234: 138826.49 | G234: HDFC Securities | H234: HDFC 0094
A235: 45469 | B235: NET PI TO HSL SEC A/C 523686-00602340029434 | C235: 0000000535337288 | D235: 340.57 | E235: 0 | F235: 138485.92 | G235: HDFC Securities | H235: HDFC 0094
A236: 45470 | B236: NEFT CR-UTIB0000004-AXIS MUTUAL FUND DIVIDEND A/C-SUNITA GUPTA-AXISCN0662480411 | C236: AXISCN0662480411 | D236: 0 | E236: 84.57 | F236: 132993.15 | G236: Dividend Income | H236: HDFC 0094
A237: 45470 | B237: NET PI TO HSL SEC A/C 523686-00602340029434 | C237: 0000000535761235 | D237: 316.84 | E237: 0 | F237: 132908.58 | G237: HDFC Securities | H237: HDFC 0094
A238: 45470 | B238: NET PI TO HSL SEC A/C 523686-00602340029434 | C238: 0000000535933355 | D238: 2666.08 | E238: 0 | F238: 130327.07 | G238: HDFC Securities | H238: HDFC 0094
A239: 45471 | B239: ACH C- LTIMIN FINAL 2023 24-213986 | C239: 0000005527258486 | D239: 0 | E239: 1800 | F239: 132127.07 | G239: Dividend Income | H239: HDFC 0094
...

Sheet Bank Summary
A1: All Banks
A2: Aayush Gupta Bank Summary
A3: 01-Apr-2024 to 29-Mar-2025
A5: Narration | B5: Total Credit (₹) | C5: Narration | D5: Total Debit (₹)
A6: Bank Charges | B6: =SUMIFS('For Tally'!D:D, 'For Tally'!F:F, A6) | C6: Bank Charges | D6: =SUMIFS('For Tally'!C:C, 'For Tally'!F:F, C6)
A7: Bank Interest | B7: =SUMIFS('For Tally'!D:D, 'For Tally'!F:F, A7) | C7: Bank Interest | D7: =SUMIFS('For Tally'!C:C, 'For Tally'!F:F, C7)
A8: Cash Deposit | B8: =SUMIFS('For Tally'!D:D, 'For Tally'!F:F, A8) | C8: Cash Deposit | D8: =SUMIFS('For Tally'!C:C, 'For Tally'!F:F, C8)
A9: Cash Withdrawal | B9: =SUMIFS('For Tally'!D:D, 'For Tally'!F:F, A9) | C9: Cash Withdrawal | D9: =SUMIFS('For Tally'!C:C, 'For Tally'!F:F, C9)
A10: Depository Charges | B10: =SUMIFS('For Tally'!D:D, 'For Tally'!F:F, A10) | C10: Depository Charges | D10: =SUMIFS('For Tally'!C:C, 'For Tally'!F:F, C10)
A11: Dividend Income | B11: =SUMIFS('For Tally'!D:D, 'For Tally'!F:F, A11) | C11: Dividend Income | D11: =SUMIFS('For Tally'!C:C, 'For Tally'!F:F, C11)
A12: HDFC Securities - Buy | B12: =SUMIFS('For Tally'!D:D, 'For Tally'!F:F, A12) | C12: HDFC Securities - Buy | D12: =SUMIFS('For Tally'!C:C, 'For Tally'!F:F, C12)
A13: HDFC Securities - Sell | B13: =SUMIFS('For Tally'!D:D, 'For Tally'!F:F, A13) | C13: HDFC Securities - Sell | D13: =SUMIFS('For Tally'!C:C, 'For Tally'!F:F, C13)
A14: HDFC Securities - Settlement | B14: =SUMIFS('For Tally'!D:D, 'For Tally'!F:F, A14) | C14: HDFC Securities - Settlement | D14: =SUMIFS('For Tally'!C:C, 'For Tally'!F:F, C14)
A15: Health Insurance | B15: =SUMIFS('For Tally'!D:D, 'For Tally'!F:F, A15) | C15: Health Insurance | D15: =SUMIFS('For Tally'!C:C, 'For Tally'!F:F, C15)
A16: Income Tax Refund | B16: =SUMIFS('For Tally'!D:D, 'For Tally'!F:F, A16) | C16: Income Tax Refund | D16: =SUMIFS('For Tally'!C:C, 'For Tally'!F:F, C16)
A17: Internal Transfer | B17: =SUMIFS('For Tally'!D:D, 'For Tally'!F:F, A17) | C17: Internal Transfer | D17: =SUMIFS('For Tally'!C:C, 'For Tally'!F:F, C17)
... A50: Zerodha Broking | B50: =SUMIFS('For Tally'!D:D, 'For Tally'!F:F, A50) | C50: Zerodha Broking | D50: =SUMIFS('For Tally'!C:C, 'For Tally'!F:F, C50)
A51: TOTAL | B51: =SUM(B5:B50) | C51: TOTAL | D51: =SUM(D5:D50) | E51: Net | F51: =B51-D51
A53: Opening & Closing Balances
A54: Account | B54: Opening Balance (₹) | C54: Closing Balance (₹)
A55: AXIS 7042 | B55: 9474.62 | C55: =B55 + SUMIFS('For Tally'!D:D, 'For Tally'!I:I, A55) - SUMIFS('For Tally'!C:C, 'For Tally'!I:I, A55)
A56: HDFC 0094 | B56: 33236 | C56: =B56 + SUMIFS('For Tally'!D:D, 'For Tally'!I:I, A56) - SUMIFS('For Tally'!C:C, 'For Tally'!I:I, A56)
A57: SBI 7685 | B57: 26120.7 | C57: =B57 + SUMIFS('For Tally'!D:D, 'For Tally'!I:I, A57) - SUMIFS('For Tally'!C:C, 'For Tally'!I:I, A57)
A59: Confidence Distribution
A60: Band | B60: Count | C60: % of Total
A61: High (≥ 0.85) — Confident | B61: =COUNTIF('For Tally'!G:G, ">=0.85") | C61: =B61/SUM(B61:B63)
A62: Medium (0.60–0.84) — Review | B62: =COUNTIFS('For Tally'!G:G, ">=0.60", 'For Tally'!G:G, "<0.85") | C62: =B62/SUM(B61:B63)
A63: Low (< 0.60) — Needs attention | B63: =COUNTIF('For Tally'!G:G, "<0.60") | C63: =B63/SUM(B61:B63)

Sheet Monthly Pivot
A1: Monthly Spend & Income Pivot
A3: Bank Filter Toggles: | B3: Axis Bank | C3: HDFC Bank | D3: State Bank of India
B4: TRUE | C4: TRUE | D4: TRUE
B5: =IF(B4, B3, "") | C5: =IF(C4, C3, "") | D5: =IF(D4, D3, "")
A7: PAYMENTS / DEBITS (Bank) | B7: Apr-2024 | C7: May-2024 | D7: Jun-2024 | E7: Jul-2024 | F7: Aug-2024 | G7: Sep-2024 | H7: Oct-2024 | I7: Nov-2024 | J7: Dec-2024 | K7: Jan-2025 | L7: Feb-2025 | M7: Mar-2025 | N7: TOTAL
A8: Ajay Gupta | B8: =SUMPRODUCT(SUMIFS('For Tally'!C:C, 'For Tally'!H:H, $A8, 'For Tally'!A:A, ">=2024-04-01", 'For Tally'!A:A, "<=2024-04-30", 'For Tally'!L:L, $B$5:$D$5)) | C8: =SUMPRODUCT(SUMIFS('For Tally'!C:C, 'For Tally'!H:H, $A8, 'For Tally'!A:A, ">=2024-05-01", 'For Tally'!A:A, "<=2024-05-31", 'For Tally'!L:L, $B$5:$D$5)) | D8: =SUMPRODUCT(SUMIFS('For Tally'!C:C, 'For Tally'!H:H, $A8, 'For Tally'!A:A, ">=2024-06-01", 'For Tally'!A:A, "<=2024-06-30", 'For Tally'!L:L, $B$5:$D$5)) | E8: =SUMPRODUCT(SUMIFS('For Tally'!C:C, 'For Tally'!H:H, $A8, 'For Tally'!A:A, ">=2024-07-01", 'For Tally'!A:A, "<=2024-07-31", 'For Tally'!L:L, $B$5:$D$5)) | F8: =SUMPRODUCT(SUMIFS('For Tally'!C:C, 'For Tally'!H:H, $A8, 'For Tally'!A:A, ">=2024-08-01", 'For Tally'!A:A, "<=2024-08-31", 'For Tally'!L:L, $B$5:$D$5)) | G8: =SUMPRODUCT(SUMIFS('For Tally'!C:C, 'For Tally'!H:H, $A8, 'For Tally'!A:A, ">=2024-09-01", 'For Tally'!A:A, "<=2024-09-30", 'For Tally'!L:L, $B$5:$D$5)) | H8: =SUMPRODUCT(SUMIFS('For Tally'!C:C, 'For Tally'!H:H, $A8, 'For Tally'!A:A, ">=2024-10-01", 'For Tally'!A:A, "<=2024-10-31", 'For Tally'!L:L, $B$5:$D$5)) | I8: =SUMPRODUCT(SUMIFS('For Tally'!C:C, 'For Tally'!H:H, $A8, 'For Tally'!A:A, ">=2024-11-01", 'For Tally'!A:A, "<=2024-11-30", 'For Tally'!L:L, $B$5:$D$5)) | J8: =SUMPRODUCT(SUMIFS('For Tally'!C:C, 'For Tally'!H:H, $A8, 'For Tally'!A:A, ">=2024-12-01", 'For Tally'!A:A, "<=2024-12-31", 'For Tally'!L:L, $B$5:$D$5)) | K8: =SUMPRODUCT(SUMIFS('For Tally'!C:C, 'For Tally'!H:H, $A8, 'For Tally'!A:A, ">=2025-01-01", 'For Tally'!A:A, "<=2025-01-31", 'For Tally'!L:L, $B$5:$D$5)) | L8: =SUMPRODUCT(SUMIFS('For Tally'!C:C, 'For Tally'!H:H, $A8, 'For Tally'!A:A, ">=2025-02-01", 'For Tally'!A:A, "<=2025-02-28", 'For Tally'!L:L, $B$5:$D$5)) | M8: =SUMPRODUCT(SUMIFS('For Tally'!C:C, 'For Tally'!H:H, $A8, 'For Tally'!A:A, ">=2025-03-01", 'For Tally'!A:A, "<=2025-03-31", 'For Tally'!L:L, $B$5:$D$5)) | N8: =SUM(B8:M8)
A9: Archit Gupta | B9: =SUMPRODUCT(SUMIFS('For Tally'!C:C, 'For Tally'!H:H, $A9, 'For Tally'!A:A, ">=2024-04-01", 'For Tally'!A:A, "<=2024-04-30", 'For Tally'!L:L, $B$5:$D$5)) | C9: =SUMPRODUCT(SUMIFS('For Tally'!C:C, 'For Tally'!H:H, $A9, 'For Tally'!A:A, ">=2024-05-01", 'For Tally'!A:A, "<=2024-05-31", 'For Tally'!L:L, $B$5:$D$5)) | D9: =SUMPRODUCT(SUMIFS('For Tally'!C:C, 'For Tally'!H:H, $A9, 'For Tally'!A:A, ">=2024-06-01", 'For Tally'!A:A, "<=2024-06-30", 'For Tally'!L:L, $B$5:$D$5)) | E9: =SUMPRODUCT(SUMIFS('For Tally'!C:C, 'For Tally'!H:H, $A9, 'For Tally'!A:A, ">=2024-07-01", 'For Tally'!A:A, "<=2024-07-31", 'For Tally'!L:L, $B$5:$D$5)) | F9: =SUMPRODUCT(SUMIFS('For Tally'!C:C, 'For Tally'!H:H, $A9, 'For Tally'!A:A, ">=2024-08-01", 'For Tally'!A:A, "<=2024-08-31", 'For Tally'!L:L, $B$5:$D$5)) | G9: =SUMPRODUCT(SUMIFS('For Tally'!C:C, 'For Tally'!H:H, $A9, 'For Tally'!A:A, ">=2024-09-01", 'For Tally'!A:A, "<=2024-09-30", 'For Tally'!L:L, $B$5:$D$5)) | H9: =SUMPRODUCT(SUMIFS('For Tally'!C:C, 'For Tally'!H:H, $A9, 'For Tally'!A:A, ">=2024-10-01", 'For Tally'!A:A, "<=2024-10-31", 'For Tally'!L:L, $B$5:$D$5)) | I9: =SUMPRODUCT(SUMIFS('For Tally'!C:C, 'For Tally'!H:H, $A9, 'For Tally'!A:A, ">=2024-11-01", 'For Tally'!A:A, "<=2024-11-30", 'For Tally'!L:L, $B$5:$D$5)) | J9: =SUMPRODUCT(SUMIFS('For Tally'!C:C, 'For Tally'!H:H, $A9, 'For Tally'!A:A, ">=2024-12-01", 'For Tally'!A:A, "<=2024-12-31", 'For Tally'!L:L, $B$5:$D$5)) | K9: =SUMPRODUCT(SUMIFS('For Tally'!C:C, 'For Tally'!H:H, $A9, 'For Tally'!A:A, ">=2025-01-01", 'For Tally'!A:A, "<=2025-01-31", 'For Tally'!L:L, $B$5:$D$5)) | L9: =SUMPRODUCT(SUMIFS('For Tally'!C:C, 'For Tally'!H:H, $A9, 'For Tally'!A:A, ">=2025-02-01", 'For Tally'!A:A, "<=2025-02-28", 'For Tally'!L:L, $B$5:$D$5)) | M9: =SUMPRODUCT(SUMIFS('For Tally'!C:C, 'For Tally'!H:H, $A9, 'For Tally'!A:A, ">=2025-03-01", 'For Tally'!A:A, "<=2025-03-31", 'For Tally'!L:L, $B$5:$D$5)) | N9: =SUM(B9:M9)
A10: Bank Charges | B10: =SUMPRODUCT(SUMIFS('For Tally'!C:C, 'For Tally'!H:H, $A10, 'For Tally'!A:A, ">=2024-04-01", 'For Tally'!A:A, "<=2024-04-30", 'For Tally'!L:L, $B$5:$D$5)) | C10: =SUMPRODUCT(SUMIFS('For Tally'!C:C, 'For Tally'!H:H, $A10, 'For Tally'!A:A, ">=2024-05-01", 'For Tally'!A:A, "<=2024-05-31", 'For Tally'!L:L, $B$5:$D$5)) | D10: =SUMPRODUCT(SUMIFS('For Tally'!C:C, 'For Tally'!H:H, $A10, 'For Tally'!A:A, ">=2024-06-01", 'For Tally'!A:A, "<=2024-06-30", 'For Tally'!L:L, $B$5:$D$5)) | E10: =SUMPRODUCT(SUMIFS('For Tally'!C:C, 'For Tally'!H:H, $A10, 'For Tally'!A:A, ">=2024-07-01", 'For Tally'!A:A, "<=2024-07-31", 'For Tally'!L:L, $B$5:$D$5)) | F10: =SUMPRODUCT(SUMIFS('For Tally'!C:C, 'For Tally'!H:H, $A10, 'For Tally'!A:A, ">=2024-08-01", 'For Tally'!A:A, "<=2024-08-31", 'For Tally'!L:L, $B$5:$D$5)) | G10: =SUMPRODUCT(SUMIFS('For Tally'!C:C, 'For Tally'!H:H, $A10, 'For Tally'!A:A, ">=2024-09-01", 'For Tally'!A:A, "<=2024-09-30", 'For Tally'!L:L, $B$5:$D$5)) | H10: =SUMPRODUCT(SUMIFS('For Tally'!C:C, 'For Tally'!H:H, $A10, 'For Tally'!A:A, ">=2024-10-01", 'For Tally'!A:A, "<=2024-10-31", 'For Tally'!L:L, $B$5:$D$5)) | I10: =SUMPRODUCT(SUMIFS('For Tally'!C:C, 'For Tally'!H:H, $A10, 'For Tally'!A:A, ">=2024-11-01", 'For Tally'!A:A, "<=2024-11-30", 'For Tally'!L:L, $B$5:$D$5)) | J10: =SUMPRODUCT(SUMIFS('For Tally'!C:C, 'For Tally'!H:H, $A10, 'For Tally'!A:A, ">=2024-12-01", 'For Tally'!A:A, "<=2024-12-31", 'For Tally'!L:L, $B$5:$D$5)) | K10: =SUMPRODUCT(SUMIFS('For Tally'!C:C, 'For Tally'!H:H, $A10, 'For Tally'!A:A, ">=2025-01-01", 'For Tally'!A:A, "<=2025-01-31", 'For Tally'!L:L, $B$5:$D$5)) | L10: =SUMPRODUCT(SUMIFS('For Tally'!C:C, 'For Tally'!H:H, $A10, 'For Tally'!A:A, ">=2025-02-01", 'For Tally'!A:A, "<=2025-02-28", 'For Tally'!L:L, $B$5:$D$5)) | M10: =SUMPRODUCT(SUMIFS('For Tally'!C:C, 'For Tally'!H:H, $A10, 'For Tally'!A:A, ">=2025-03-01", 'For Tally'!A:A, "<=2025-03-31", 'For Tally'!L:L, $B$5:$D$5)) | N10: =SUM(B10:M10)
A11: Cash | B11: =SUMPRODUCT(SUMIFS('For Tally'!C:C, 'For Tally'!H:H, $A11, 'For Tally'!A:A, ">=2024-04-01", 'For Tally'!A:A, "<=2024-04-30", 'For Tally'!L:L, $B$5:$D$5)) | C11: =SUMPRODUCT(SUMIFS('For Tally'!C:C, 'For Tally'!H:H, $A11, 'For Tally'!A:A, ">=2024-05-01", 'For Tally'!A:A, "<=2024-05-31", 'For Tally'!L:L, $B$5:$D$5)) | D11: =SUMPRODUCT(SUMIFS('For Tally'!C:C, 'For Tally'!H:H, $A11, 'For Tally'!A:A, ">=2024-06-01", 'For Tally'!A:A, "<=2024-06-30", 'For Tally'!L:L, $B$5:$D$5)) | E11: =SUMPRODUCT(SUMIFS('For Tally'!C:C, 'For Tally'!H:H, $A11, 'For Tally'!A:A, ">=2024-07-01", 'For Tally'!A:A, "<=2024-07-31", 'For Tally'!L:L, $B$5:$D$5)) | F11: =SUMPRODUCT(SUMIFS('For Tally'!C:C, 'For Tally'!H:H, $A11, 'For Tally'!A:A, ">=2024-08-01", 'For Tally'!A:A, "<=2024-08-31", 'For Tally'!L:L, $B$5:$D$5)) | G11: =SUMPRODUCT(SUMIFS('For Tally'!C:C, 'For Tally'!H:H, $A11, 'For Tally'!A:A, ">=2024-09-01", 'For Tally'!A:A, "<=2024-09-30", 'For Tally'!L:L, $B$5:$D$5)) | H11: =SUMPRODUCT(SUMIFS('For Tally'!C:C, 'For Tally'!H:H, $A11, 'For Tally'!A:A, ">=2024-10-01", 'For Tally'!A:A, "<=2024-10-31", 'For Tally'!L:L, $B$5:$D$5)) | I11: =SUMPRODUCT(SUMIFS('For Tally'!C:C, 'For Tally'!H:H, $A11, 'For Tally'!A:A, ">=2024-11-01", 'For Tally'!A:A, "<=2024-11-30", 'For Tally'!L:L, $B$5:$D$5)) | J11: =SUMPRODUCT(SUMIFS('For Tally'!C:C, 'For Tally'!H:H, $A11, 'For Tally'!A:A, ">=2024-12-01", 'For Tally'!A:A, "<=2024-12-31", 'For Tally'!L:L, $B$5:$D$5)) | K11: =SUMPRODUCT(SUMIFS('For Tally'!C:C, 'For Tally'!H:H, $A11, 'For Tally'!A:A, ">=2025-01-01", 'For Tally'!A:A, "<=2025-01-31", 'For Tally'!L:L, $B$5:$D$5)) | L11: =SUMPRODUCT(SUMIFS('For Tally'!C:C, 'For Tally'!H:H, $A11, 'For Tally'!A:A, ">=2025-02-01", 'For Tally'!A:A, "<=2025-02-28", 'For Tally'!L:L, $B$5:$D$5)) | M11: =SUMPRODUCT(SUMIFS('For Tally'!C:C, 'For Tally'!H:H, $A11, 'For Tally'!A:A, ">=2025-03-01", 'For Tally'!A:A, "<=2025-03-31", 'For Tally'!L:L, $B$5:$D$5)) | N11: =SUM(B11:M11)
A12: Depository Charges | B12: =SUMPRODUCT(SUMIFS('For Tally'!C:C, 'For Tally'!H:H, $A12, 'For Tally'!A:A, ">=2024-04-01", 'For Tally'!A:A, "<=2024-04-30", 'For Tally'!L:L, $B$5:$D$5)) | C12: =SUMPRODUCT(SUMIFS('For Tally'!C:C, 'For Tally'!H:H, $A12, 'For Tally'!A:A, ">=2024-05-01", 'For Tally'!A:A, "<=2024-05-31", 'For Tally'!L:L, $B$5:$D$5)) | D12: =SUMPRODUCT(SUMIFS('For Tally'!C:C, 'For Tally'!H:H, $A12, 'For Tally'!A:A, ">=2024-06-01", 'For Tally'!A:A, "<=2024-06-30", 'For Tally'!L:L, $B$5:$D$5)) | E12: =SUMPRODUCT(SUMIFS('For Tally'!C:C, 'For Tally'!H:H, $A12, 'For Tally'!A:A, ">=2024-07-01", 'For Tally'!A:A, "<=2024-07-31", 'For Tally'!L:L, $B$5:$D$5)) | F12: =SUMPRODUCT(SUMIFS('For Tally'!C:C, 'For Tally'!H:H, $A12, 'For Tally'!A:A, ">=2024-08-01", 'For Tally'!A:A, "<=2024-08-31", 'For Tally'!L:L, $B$5:$D$5)) | G12: =SUMPRODUCT(SUMIFS('For Tally'!C:C, 'For Tally'!H:H, $A12, 'For Tally'!A:A, ">=2024-09-01", 'For Tally'!A:A, "<=2024-09-30", 'For Tally'!L:L, $B$5:$D$5)) | H12: =SUMPRODUCT(SUMIFS('For Tally'!C:C, 'For Tally'!H:H, $A12, 'For Tally'!A:A, ">=2024-10-01", 'For Tally'!A:A, "<=2024-10-31", 'For Tally'!L:L, $B$5:$D$5)) | I12: =SUMPRODUCT(SUMIFS('For Tally'!C:C, 'For Tally'!H:H, $A12, 'For Tally'!A:A, ">=2024-11-01", 'For Tally'!A:A, "<=2024-11-30", 'For Tally'!L:L, $B$5:$D$5)) | J12: =SUMPRODUCT(SUMIFS('For Tally'!C:C, 'For Tally'!H:H, $A12, 'For Tally'!A:A, ">=2024-12-01", 'For Tally'!A:A, "<=2024-12-31", 'For Tally'!L:L, $B$5:$D$5)) | K12: =SUMPRODUCT(SUMIFS('For Tally'!C:C, 'For Tally'!H:H, $A12, 'For Tally'!A:A, ">=2025-01-01", 'For Tally'!A:A, "<=2025-01-31", 'For Tally'!L:L, $B$5:$D$5)) | L12: =SUMPRODUCT(SUMIFS('For Tally'!C:C, 'For Tally'!H:H, $A12, 'For Tally'!A:A, ">=2025-02-01", 'For Tally'!A:A, "<=2025-02-28", 'For Tally'!L:L, $B$5:$D$5)) | M12: =SUMPRODUCT(SUMIFS('For Tally'!C:C, 'For Tally'!H:H, $A12, 'For Tally'!A:A, ">=2025-03-01", 'For Tally'!A:A, "<=2025-03-31", 'For Tally'!L:L, $B$5:$D$5)) | N12: =SUM(B12:M12)
A13: Groceries | B13: =SUMPRODUCT(SUMIFS('For Tally'!C:C, 'For Tally'!H:H, $A13, 'For Tally'!A:A, ">=2024-04-01", 'For Tally'!A:A, "<=2024-04-30", 'For Tally'!L:L, $B$5:$D$5)) | C13: =SUMPRODUCT(SUMIFS('For Tally'!C:C, 'For Tally'!H:H, $A13, 'For Tally'!A:A, ">=2024-05-01", 'For Tally'!A:A, "<=2024-05-31", 'For Tally'!L:L, $B$5:$D$5)) | D13: =SUMPRODUCT(SUMIFS('For Tally'!C:C, 'For Tally'!H:H, $A13, 'For Tally'!A:A, ">=2024-06-01", 'For Tally'!A:A, "<=2024-06-30", 'For Tally'!L:L, $B$5:$D$5)) | E13: =SUMPRODUCT(SUMIFS('For Tally'!C:C, 'For Tally'!H:H, $A13, 'For Tally'!A:A, ">=2024-07-01", 'For Tally'!A:A, "<=2024-07-31", 'For Tally'!L:L, $B$5:$D$5)) | F13: =SUMPRODUCT(SUMIFS('For Tally'!C:C, 'For Tally'!H:H, $A13, 'For Tally'!A:A, ">=2024-08-01", 'For Tally'!A:A, "<=2024-08-31", 'For Tally'!L:L, $B$5:$D$5)) | G13: =SUMPRODUCT(SUMIFS('For Tally'!C:C, 'For Tally'!H:H, $A13, 'For Tally'!A:A, ">=2024-09-01", 'For Tally'!A:A, "<=2024-09-30", 'For Tally'!L:L, $B$5:$D$5)) | H13: =SUMPRODUCT(SUMIFS('For Tally'!C:C, 'For Tally'!H:H, $A13, 'For Tally'!A:A, ">=2024-10-01", 'For Tally'!A:A, "<=2024-10-31", 'For Tally'!L:L, $B$5:$D$5)) | I13: =SUMPRODUCT(SUMIFS('For Tally'!C:C, 'For Tally'!H:H, $A13, 'For Tally'!A:A, ">=2024-11-01", 'For Tally'!A:A, "<=2024-11-30", 'For Tally'!L:L, $B$5:$D$5)) | J13: =SUMPRODUCT(SUMIFS('For Tally'!C:C, 'For Tally'!H:H, $A13, 'For Tally'!A:A, ">=2024-12-01", 'For Tally'!A:A, "<=2024-12-31", 'For Tally'!L:L, $B$5:$D$5)) | K13: =SUMPRODUCT(SUMIFS('For Tally'!C:C, 'For Tally'!H:H, $A13, 'For Tally'!A:A, ">=2025-01-01", 'For Tally'!A:A, "<=2025-01-31", 'For Tally'!L:L, $B$5:$D$5)) | L13: =SUMPRODUCT(SUMIFS('For Tally'!C:C, 'For Tally'!H:H, $A13, 'For Tally'!A:A, ">=2025-02-01", 'For Tally'!A:A, "<=2025-02-28", 'For Tally'!L:L, $B$5:$D$5)) | M13: =SUMPRODUCT(SUMIFS('For Tally'!C:C, 'For Tally'!H:H, $A13, 'For Tally'!A:A, ">=2025-03-01", 'For Tally'!A:A, "<=2025-03-31", 'For Tally'!L:L, $B$5:$D$5)) | N13: =SUM(B13:M13)
A14: HDFC Securities | B14: =SUMPRODUCT(SUMIFS('For Tally'!C:C, 'For Tally'!H:H, $A14, 'For Tally'!A:A, ">=2024-04-01", 'For Tally'!A:A, "<=2024-04-30", 'For Tally'!L:L, $B$5:$D$5)) | C14: =SUMPRODUCT(SUMIFS('For Tally'!C:C, 'For Tally'!H:H, $A14, 'For Tally'!A:A, ">=2024-05-01", 'For Tally'!A:A, "<=2024-05-31", 'For Tally'!L:L, $B$5:$D$5)) | D14: =SUMPRODUCT(SUMIFS('For Tally'!C:C, 'For Tally'!H:H, $A14, 'For Tally'!A:A, ">=2024-06-01", 'For Tally'!A:A, "<=2024-06-30", 'For Tally'!L:L, $B$5:$D$5)) | E14: =SUMPRODUCT(SUMIFS('For Tally'!C:C, 'For Tally'!H:H, $A14, 'For Tally'!A:A, ">=2024-07-01", 'For Tally'!A:A, "<=2024-07-31", 'For Tally'!L:L, $B$5:$D$5)) | F14: =SUMPRODUCT(SUMIFS('For Tally'!C:C, 'For Tally'!H:H, $A14, 'For Tally'!A:A, ">=2024-08-01", 'For Tally'!A:A, "<=2024-08-31", 'For Tally'!L:L, $B$5:$D$5)) | G14: =SUMPRODUCT(SUMIFS('For Tally'!C:C, 'For Tally'!H:H, $A14, 'For Tally'!A:A, ">=2024-09-01", 'For Tally'!A:A, "<=2024-09-30", 'For Tally'!L:L, $B$5:$D$5)) | H14: =SUMPRODUCT(SUMIFS('For Tally'!C:C, 'For Tally'!H:H, $A14, 'For Tally'!A:A, ">=2024-10-01", 'For Tally'!A:A, "<=2024-10-31", 'For Tally'!L:L, $B$5:$D$5)) | I14: =SUMPRODUCT(SUMIFS('For Tally'!C:C, 'For Tally'!H:H, $A14, 'For Tally'!A:A, ">=2024-11-01", 'For Tally'!A:A, "<=2024-11-30", 'For Tally'!L:L, $B$5:$D$5)) | J14: =SUMPRODUCT(SUMIFS('For Tally'!C:C, 'For Tally'!H:H, $A14, 'For Tally'!A:A, ">=2024-12-01", 'For Tally'!A:A, "<=2024-12-31", 'For Tally'!L:L, $B$5:$D$5)) | K14: =SUMPRODUCT(SUMIFS('For Tally'!C:C, 'For Tally'!H:H, $A14, 'For Tally'!A:A, ">=2025-01-01", 'For Tally'!A:A, "<=2025-01-31", 'For Tally'!L:L, $B$5:$D$5)) | L14: =SUMPRODUCT(SUMIFS('For Tally'!C:C, 'For Tally'!H:H, $A14, 'For Tally'!A:A, ">=2025-02-01", 'For Tally'!A:A, "<=2025-02-28", 'For Tally'!L:L, $B$5:$D$5)) | M14: =SUMPRODUCT(SUMIFS('For Tally'!C:C, 'For Tally'!H:H, $A14, 'For Tally'!A:A, ">=2025-03-01", 'For Tally'!A:A, "<=2025-03-31", 'For Tally'!L:L, $B$5:$D$5)) | N14: =SUM(B14:M14)
A15: Health Insurance | B15: =SUMPRODUCT(SUMIFS('For Tally'!C:C, 'For Tally'!H:H, $A15, 'For Tally'!A:A, ">=2024-04-01", 'For Tally'!A:A, "<=2024-04-30", 'For Tally'!L:L, $B$5:$D$5)) | C15: =SUMPRODUCT(SUMIFS('For Tally'!C:C, 'For Tally'!H:H, $A15, 'For Tally'!A:A, ">=2024-05-01", 'For Tally'!A:A, "<=2024-05-31", 'For Tally'!L:L, $B$5:$D$5)) | D15: =SUMPRODUCT(SUMIFS('For Tally'!C:C, 'For Tally'!H:H, $A15, 'For Tally'!A:A, ">=2024-06-01", 'For Tally'!A:A, "<=2024-06-30", 'For Tally'!L:L, $B$5:$D$5)) | E15: =SUMPRODUCT(SUMIFS('For Tally'!C:C, 'For Tally'!H:H, $A15, 'For Tally'!A:A, ">=2024-07-01", 'For Tally'!A:A, "<=2024-07-31", 'For Tally'!L:L, $B$5:$D$5)) | F15: =SUMPRODUCT(SUMIFS('For Tally'!C:C, 'For Tally'!H:H, $A15, 'For Tally'!A:A, ">=2024-08-01", 'For Tally'!A:A, "<=2024-08-31", 'For Tally'!L:L, $B$5:$D$5)) | G15: =SUMPRODUCT(SUMIFS('For Tally'!C:C, 'For Tally'!H:H, $A15, 'For Tally'!A:A, ">=2024-09-01", 'For Tally'!A:A, "<=2024-09-30", 'For Tally'!L:L, $B$5:$D$5)) | H15: =SUMPRODUCT(SUMIFS('For Tally'!C:C, 'For Tally'!H:H, $A15, 'For Tally'!A:A, ">=2024-10-01", 'For Tally'!A:A, "<=2024-10-31", 'For Tally'!L:L, $B$5:$D$5)) | I15: =SUMPRODUCT(SUMIFS('For Tally'!C:C, 'For Tally'!H:H, $A15, 'For Tally'!A:A, ">=2024-11-01", 'For Tally'!A:A, "<=2024-11-30", 'For Tally'!L:L, $B$5:$D$5)) | J15: =SUMPRODUCT(SUMIFS('For Tally'!C:C, 'For Tally'!H:H, $A15, 'For Tally'!A:A, ">=2024-12-01", 'For Tally'!A:A, "<=2024-12-31", 'For Tally'!L:L, $B$5:$D$5)) | K15: =SUMPRODUCT(SUMIFS('For Tally'!C:C, 'For Tally'!H:H, $A15, 'For Tally'!A:A, ">=2025-01-01", 'For Tally'!A:A, "<=2025-01-31", 'For Tally'!L:L, $B$5:$D$5)) | L15: =SUMPRODUCT(SUMIFS('For Tally'!C:C, 'For Tally'!H:H, $A15, 'For Tally'!A:A, ">=2025-02-01", 'For Tally'!A:A, "<=2025-02-28", 'For Tally'!L:L, $B$5:$D$5)) | M15: =SUMPRODUCT(SUMIFS('For Tally'!C:C, 'For Tally'!H:H, $A15, 'For Tally'!A:A, ">=2025-03-01", 'For Tally'!A:A, "<=2025-03-31", 'For Tally'!L:L, $B$5:$D$5)) | N15: =SUM(B15:M15)
A16: Healthcare | B16: =SUMPRODUCT(SUMIFS('For Tally'!C:C, 'For Tally'!H:H, $A16, 'For Tally'!A:A, ">=2024-04-01", 'For Tally'!A:A, "<=2024-04-30", 'For Tally'!L:L, $B$5:$D$5)) | C16: =SUMPRODUCT(SUMIFS('For Tally'!C:C, 'For Tally'!H:H, $A16, 'For Tally'!A:A, ">=2024-05-01", 'For Tally'!A:A, "<=2024-05-31", 'For Tally'!L:L, $B$5:$D$5)) | D16: =SUMPRODUCT(SUMIFS('For Tally'!C:C, 'For Tally'!H:H, $A16, 'For Tally'!A:A, ">=2024-06-01", 'For Tally'!A:A, "<=2024-06-30", 'For Tally'!L:L, $B$5:$D$5)) | E16: =SUMPRODUCT(SUMIFS('For Tally'!C:C, 'For Tally'!H:H, $A16, 'For Tally'!A:A, ">=2024-07-01", 'For Tally'!A:A, "<=2024-07-31", 'For Tally'!L:L, $B$5:$D$5)) | F16: =SUMPRODUCT(SUMIFS('For Tally'!C:C, 'For Tally'!H:H, $A16, 'For Tally'!A:A, ">=2024-08-01", 'For Tally'!A:A, "<=2024-08-31", 'For Tally'!L:L, $B$5:$D$5)) | G16: =SUMPRODUCT(SUMIFS('For Tally'!C:C, 'For Tally'!H:H, $A16, 'For Tally'!A:A, ">=2024-09-01", 'For Tally'!A:A, "<=2024-09-30", 'For Tally'!L:L, $B$5:$D$5)) | H16: =SUMPRODUCT(SUMIFS('For Tally'!C:C, 'For Tally'!H:H, $A16, 'For Tally'!A:A, ">=2024-10-01", 'For Tally'!A:A, "<=2024-10-31", 'For Tally'!L:L, $B$5:$D$5)) | I16: =SUMPRODUCT(SUMIFS('For Tally'!C:C, 'For Tally'!H:H, $A16, 'For Tally'!A:A, ">=2024-11-01", 'For Tally'!A:A, "<=2024-11-30", 'For Tally'!L:L, $B$5:$D$5)) | J16: =SUMPRODUCT(SUMIFS('For Tally'!C:C, 'For Tally'!H:H, $A16, 'For Tally'!A:A, ">=2024-12-01", 'For Tally'!A:A, "<=2024-12-31", 'For Tally'!L:L, $B$5:$D$5)) | K16: =SUMPRODUCT(SUMIFS('For Tally'!C:C, 'For Tally'!H:H, $A16, 'For Tally'!A:A, ">=2025-01-01", 'For Tally'!A:A, "<=2025-01-31", 'For Tally'!L:L, $B$5:$D$5)) | L16: =SUMPRODUCT(SUMIFS('For Tally'!C:C, 'For Tally'!H:H, $A16, 'For Tally'!A:A, ">=2025-02-01", 'For Tally'!A:A, "<=2025-02-28", 'For Tally'!L:L, $B$5:$D$5)) | M16: =SUMPRODUCT(SUMIFS('For Tally'!C:C, 'For Tally'!H:H, $A16, 'For Tally'!A:A, ">=2025-03-01", 'For Tally'!A:A, "<=2025-03-31", 'For Tally'!L:L, $B$5:$D$5)) | N16: =SUM(B16:M16)
A17: Megha Gupta | B17: =SUMPRODUCT(SUMIFS('For Tally'!C:C, 'For Tally'!H:H, $A17, 'For Tally'!A:A, ">=2024-04-01", 'For Tally'!A:A, "<=2024-04-30", 'For Tally'!L:L, $B$5:$D$5)) | C17: =SUMPRODUCT(SUMIFS('For Tally'!C:C, 'For Tally'!H:H, $A17, 'For Tally'!A:A, ">=2024-05-01", 'For Tally'!A:A, "<=2024-05-31", 'For Tally'!L:L, $B$5:$D$5)) | D17: =SUMPRODUCT(SUMIFS('For Tally'!C:C, 'For Tally'!H:H, $A17, 'For Tally'!A:A, ">=2024-06-01", 'For Tally'!A:A, "<=2024-06-30", 'For Tally'!L:L, $B$5:$D$5)) | E17: =SUMPRODUCT(SUMIFS('For Tally'!C:C, 'For Tally'!H:H, $A17, 'For Tally'!A:A, ">=2024-07-01", 'For Tally'!A:A, "<=2024-07-31", 'For Tally'!L:L, $B$5:$D$5)) | F17: =SUMPRODUCT(SUMIFS('For Tally'!C:C, 'For Tally'!H:H, $A17, 'For Tally'!A:A, ">=2024-08-01", 'For Tally'!A:A, "<=2024-08-31", 'For Tally'!L:L, $B$5:$D$5)) | G17: =SUMPRODUCT(SUMIFS('For Tally'!C:C, 'For Tally'!H:H, $A17, 'For Tally'!A:A, ">=2024-09-01", 'For Tally'!A:A, "<=2024-09-30", 'For Tally'!L:L, $B$5:$D$5)) | H17: =SUMPRODUCT(SUMIFS('For Tally'!C:C, 'For Tally'!H:H, $A17, 'For Tally'!A:A, ">=2024-10-01", 'For Tally'!A:A, "<=2024-10-31", 'For Tally'!L:L, $B$5:$D$5)) | I17: =SUMPRODUCT(SUMIFS('For Tally'!C:C, 'For Tally'!H:H, $A17, 'For Tally'!A:A, ">=2024-11-01", 'For Tally'!A:A, "<=2024-11-30", 'For Tally'!L:L, $B$5:$D$5)) | J17: =SUMPRODUCT(SUMIFS('For Tally'!C:C, 'For Tally'!H:H, $A17, 'For Tally'!A:A, ">=2024-12-01", 'For Tally'!A:A, "<=2024-12-31", 'For Tally'!L:L, $B$5:$D$5)) | K17: =SUMPRODUCT(SUMIFS('For Tally'!C:C, 'For Tally'!H:H, $A17, 'For Tally'!A:A, ">=2025-01-01", 'For Tally'!A:A, "<=2025-01-31", 'For Tally'!L:L, $B$5:$D$5)) | L17: =SUMPRODUCT(SUMIFS('For Tally'!C:C, 'For Tally'!H:H, $A17, 'For Tally'!A:A, ">=2025-02-01", 'For Tally'!A:A, "<=2025-02-28", 'For Tally'!L:L, $B$5:$D$5)) | M17: =SUMPRODUCT(SUMIFS('For Tally'!C:C, 'For Tally'!H:H, $A17, 'For Tally'!A:A, ">=2025-03-01", 'For Tally'!A:A, "<=2025-03-31", 'For Tally'!L:L, $B$5:$D$5)) | N17: =SUM(B17:M17)
A18: Mutual_Fund_Investments | B18: =SUMPRODUCT(SUMIFS('For Tally'!C:C, 'For Tally'!H:H, $A18, 'For Tally'!A:A, ">=2024-04-01", 'For Tally'!A:A, "<=2024-04-30", 'For Tally'!L:L, $B$5:$D$5)) | C18: =SUMPRODUCT(SUMIFS('For Tally'!C:C, 'For Tally'!H:H, $A18, 'For Tally'!A:A, ">=2024-05-01", 'For Tally'!A:A, "<=2024-05-31", 'For Tally'!L:L, $B$5:$D$5)) | D18: =SUMPRODUCT(SUMIFS('For Tally'!C:C, 'For Tally'!H:H, $A18, 'For Tally'!A:A, ">=2024-06-01", 'For Tally'!A:A, "<=2024-06-30", 'For Tally'!L:L, $B$5:$D$5)) | E18: =SUMPRODUCT(SUMIFS('For Tally'!C:C, 'For Tally'!H:H, $A18, 'For Tally'!A:A, ">=2024-07-01", 'For Tally'!A:A, "<=2024-07-31", 'For Tally'!L:L, $B$5:$D$5)) | F18: =SUMPRODUCT(SUMIFS('For Tally'!C:C, 'For Tally'!H:H, $A18, 'For Tally'!A:A, ">=2024-08-01", 'For Tally'!A:A, "<=2024-08-31", 'For Tally'!L:L, $B$5:$D$5)) | G18: =SUMPRODUCT(SUMIFS('For Tally'!C:C, 'For Tally'!H:H, $A18, 'For Tally'!A:A, ">=2024-09-01", 'For Tally'!A:A, "<=2024-09-30", 'For Tally'!L:L, $B$5:$D$5)) | H18: =SUMPRODUCT(SUMIFS('For Tally'!C:C, 'For Tally'!H:H, $A18, 'For Tally'!A:A, ">=2024-10-01", 'For Tally'!A:A, "<=2024-10-31", 'For Tally'!L:L, $B$5:$D$5)) | I18: =SUMPRODUCT(SUMIFS('For Tally'!C:C, 'For Tally'!H:H, $A18, 'For Tally'!A:A, ">=2024-11-01", 'For Tally'!A:A, "<=2024-11-30", 'For Tally'!L:L, $B$5:$D$5)) | J18: =SUMPRODUCT(SUMIFS('For Tally'!C:C, 'For Tally'!H:H, $A18, 'For Tally'!A:A, ">=2024-12-01", 'For Tally'!A:A, "<=2024-12-31", 'For Tally'!L:L, $B$5:$D$5)) | K18: =SUMPRODUCT(SUMIFS('For Tally'!C:C, 'For Tally'!H:H, $A18, 'For Tally'!A:A, ">=2025-01-01", 'For Tally'!A:A, "<=2025-01-31", 'For Tally'!L:L, $B$5:$D$5)) | L18: =SUMPRODUCT(SUMIFS('For Tally'!C:C, 'For Tally'!H:H, $A18, 'For Tally'!A:A, ">=2025-02-01", 'For Tally'!A:A, "<=2025-02-28", 'For Tally'!L:L, $B$5:$D$5)) | M18: =SUMPRODUCT(SUMIFS('For Tally'!C:C, 'For Tally'!H:H, $A18, 'For Tally'!A:A, ">=2025-03-01", 'For Tally'!A:A, "<=2025-03-31", 'For Tally'!L:L, $B$5:$D$5)) | N18: =SUM(B18:M18)
