Workbook

Sheet AXIS Aayush Axis Statement 1
B1: Axis Bank Narration Sheet
B2: Colour Legend of Categories:
B3: Contra - HDFC | C3: Bank Charges | D3: UPI - IRCTC | E3: What is this? | F3: Transfer - Ajay Gupta
B4: Received - Ajay Gupta | C4: UPI - MakeMyTrip | D4: Bank Interest | E4: UPI - BharatPe | F4: UPI - Paytm
B5: UPI Payment | C5: Transfer - Archit Gupta | D5: Received - Archit Gupta | E5: Contra - Axis
A7: Date | B7: Particulars | C7: Ref | D7: Value_Date | E7: DR | F7: CR | G7: Balance | H7: Beneficiary | I7: Human_Narration | J7: Auto_Narration | K7: Account_Head | L7: Confidence | M7: Match
A8: 45018 | B8: NEFT/N091232397833081/AAYUSH KU/HDFC BANK/Transfe | C8: - | D8: 45018 | E8: 0 | F8: 50000 | G8: 75508.68 | J8: Contra - HDFC | K8: HDFC 5413 | L8: 0.9 | M8: N/A
A9: 45061 | B9: Dr Card Charges ISSUE 4616XXXXXXXX8177 | C9: - | D9: 45061 | E9: 590 | F9: 0 | G9: 74918.68 | J9: Bank Charges | K9: Bank Charges | L9: 0.88 | M9: N/A
A10: 45061 | B10: NBSM/12858585/IRCTC(RAZORPAY)/ | C10: - | D10: 45061 | E10: 134.85 | F10: 0 | G10: 74783.83 | J10: UPI - IRCTC | K10: Travel | L10: 0.88 | M10: N/A
A11: 45071 | B11: ICONN REF/12858585/RAZORPAY/DT.25-05-2023 | C11: - | D11: 45071 | E11: 0 | F11: 45.28 | G11: 74829.11 | J11: What is this? | K11: Suspense | L11: 0 | M11: N/A
A12: 45082 | B12: INB/NEFT/AXIR231562638106/Aayush K/HDFC BA/Borrow | C12: - | D12: 45082 | E12: 20000 | F12: 0 | G12: 54829.11 | J12: Contra - HDFC | K12: HDFC 5413 | L12: 0.9 | M12: N/A
A13: 45082 | B13: INB/IFT/Ajay Kumar Gupta/TPARTY TRANSFER | C13: - | D13: 45082 | E13: 20000 | F13: 0 | G13: 34829.11 | J13: Transfer - Ajay Gupta | K13: Ajay Gupta | L13: 0.88 | M13: N/A
A14: 45086 | B14: INB/IFT/AJAY KUMAR GUPTA/TPARTY TRANSFER | C14: - | D14: 45086 | E14: 0 | F14: 20000 | G14: 54829.11 | J14: Received - Ajay Gupta | K14: Ajay Gupta | L14: 0.88 | M14: N/A
A15: 45091 | B15: ECOM PUR/MAKEMYTRIP IN/01126521471/140623/09:39 | C15: - | D15: 45091 | E15: 6434 | F15: 0 | G15: 48395.11 | J15: UPI - MakeMyTrip | K15: Travel | L15: 0.88 | M15: N/A
A16: 45108 | B16: 915010020334307:Int.Pd:01-04-2023 to 30-06-2023 | C16: - | D16: 45108 | E16: 0 | F16: 504 | G16: 48899.11 | J16: Bank Interest | K16: Bank Interest | L16: 0.93 | M16: N/A
A17: 45130 | B17: GST @18% on Charge | C17: - | D17: 45130 | E17: 0.54 | F17: 0 | G17: 48898.57 | J17: Bank Charges | K17: Bank Charges | L17: 0.88 | M17: N/A
A18: 45130 | B18: Consolidated Charges for A/c | C18: - | D18: 45130 | E18: 3 | F18: 0 | G18: 48895.57 | J18: Bank Charges | K18: Bank Charges | L18: 0.88 | M18: N/A
A19: 45144 | B19: UPI/P2M/321834491026/BharatPe /YesBank_Y/Pay to | C19: - | D19: 45144 | E19: 136 | F19: 0 | G19: 48759.57 | J19: UPI - BharatPe | K19: Personal | L19: 0.65 | M19: N/A
... A21: 45144 | B21: UPI/P2M/321834818560/Mr JITEND/Paytm Pay/UPI | C21: - | D21: 45144 | E21: 16 | F21: 0 | G21: 46458.57 | J21: UPI - Paytm | K21: Personal | L21: 0.65 | M21: N/A
A22: 45144 | B22: UPI/P2A/321836516129/ADARSH NA/HDFC BANK/UPI | C22: - | D22: 45144 | E22: 142 | F22: 0 | G22: 46316.57 | H22: Adarsh Na | J22: UPI Payment | K22: Personal | L22: 0.55 | M22: N/A
A23: 45144 | B23: UPI/P2A/321842744773/ARCHIT GU/Axis Bank/UPI | C23: - | D23: 45144 | E23: 130 | F23: 0 | G23: 46186.57 | J23: Transfer - Archit Gupta | K23: Archit Gupta | L23: 0.85 | M23: N/A
A24: 45145 | B24: UPI/P2A/321948620399/Archit G/State Ban/UPI | C24: - | D24: 45145 | E24: 0 | F24: 130 | G24: 46316.57 | J24: Received - Archit Gupta | K24: Archit Gupta | L24: 0.85 | M24: N/A
A25: 45147 | B25: UPI/P2A/322159589854/SUSHIL KU/India Pos/UPI | C25: - | D25: 45147 | E25: 50 | F25: 0 | G25: 46266.57 | H25: Sushil Ku | J25: UPI Payment | K25: Personal | L25: 0.55 | M25: N/A
A26: 45151 | B26: UPI/P2M/322597908496/H L DHATR/Yes Bank /tyre | C26: - | D26: 45151 | E26: 110 | F26: 0 | G26: 46156.57 | H26: H L Dhatr | J26: UPI Payment | K26: Personal | L26: 0.55 | M26: N/A
A27: 45200 | B27: 915010020334307:Int.Pd:01-07-2023 to 30-09-2023 | C27: - | D27: 45200 | E27: 0 | F27: 357 | G27: 46513.57 | J27: Bank Interest | K27: Bank Interest | L27: 0.93 | M27: N/A
A28: 45221 | B28: SMS Alerts Chrgs Incl GST | C28: - | D28: 45221 | E28: 1.18 | F28: 0 | G28: 46512.39 | J28: Bank Charges | K28: Bank Charges | L28: 0.88 | M28: N/A
A29: 45235 | B29: NEFT/IR/AXOIR33099676704/Aayush Kumar Gupta/HDFC BANK/Transfer fom Aayush Axis | C29: - | D29: 45235 | E29: 30000 | F29: 0 | G29: 16512.39 | J29: Contra - Axis | K29: AXIS | L29: 0.9 | M29: N/A
A30: 45292 | B30: 915010020334307:Int.Pd:01-10-2023 to 31-12-2023 | C30: - | D30: 45292 | E30: 0 | F30: 211 | G30: 16723.39 | J30: Bank Interest | K30: Bank Interest | L30: 0.93 | M30: N/A
A31: 45312 | B31: SMS Alerts Chrgs Incl GST | C31: - | D31: 45312 | E31: 1.18 | F31: 0 | G31: 16722.21 | J31: Bank Charges | K31: Bank Charges | L31: 0.88 | M31: N/A
A32: 45382 | B32: SB:915010020334307:Int.Pd:01-01-2024 to 31-03-2024 | C32: - | D32: 45382 | E32: 0 | F32: 125 | G32: 16847.21 | J32: Bank Interest | K32: Bank Interest | L32: 0.93 | M32: N/A
A33: 45078 | B33: SMS Alert Fee | C33: 45130 | D33: 45078 | E33: 3 | F33: 3 | J33: Bank Charges | K33: Bank Charges | L33: 0.88 | M33: N/A
A34: 45170 | B34: SMS Alert Fee | C34: 45221 | D34: 45170 | E34: 1 | F34: 1 | J34: Bank Charges | K34: Bank Charges | L34: 0.88 | M34: N/A
A35: 45261 | B35: SMS Alert Fee | C35: 45312 | D35: 45261 | E35: 1 | F35: 1 | J35: Bank Charges | K35: Bank Charges | L35: 0.88 | M35: N/A

Sheet HDFC
B1: HDFC Bank Narration Sheet
B2: Colour Legend of Categories:
B3: Contra - Axis | C3: HDFC Securities - Buy | D3: HDFC Securities - Sell | E3: What is this? | F3: Depository Charges
B4: Transfer - Archit Gupta | C4: MF Investment | D4: Transfer - Ajay Gupta | E4: Cash Withdrawal | F4: Received - Archit Gupta
B5: Received - Sunita Gupta | C5: Bank Charges | D5: Dividend Income | E5: Received - Ajay Gupta | F5: Bank Interest
B6: Life Insurance Premium | C6: Transfer - Sunita Gupta | D6: SIP | E6: Health Insurance | F6: Misc Income
B7: MF Redemption | C7: Advance Tax
A9: Date | B9: Particulars | C9: Ref | D9: Value_Date | E9: DR | F9: CR | G9: Balance | H9: Beneficiary | I9: Human_Narration | J9: Auto_Narration | K9: Account_Head | L9: Confidence | M9: Match
A10: 45017 | B10: NEFT DR-UTIB0002656-AAYUSH KUMAR GUPTA-NETBANK, MUM-N091232397833081-TRANSFER FROM HDFC | C10: N091232397833081 | D10: 45017 | E10: 50000 | F10: 0 | G10: 33618.17 | J10: Contra - Axis | K10: AXIS | L10: 0.9 | M10: N/A
A11: 45019 | B11: NEFT CR-UTIB0000115-JINDAL SAW LIMITED-AAYUSH KUMAR GUPTA-AXISCN0231261220 | C11: AXISCN0231261220 | D11: 45019 | E11: 0 | F11: 57999 | G11: 91617.17 | J11: Contra - Axis | K11: AXIS | L11: 0.9 | M11: N/A
A12: 45019 | B12: NET PI TO HSL SEC A/C 2554606-00602340029427 | C12: 0000000399867464 | D12: 45019 | E12: 387.51 | F12: 0 | G12: 91229.66 | J12: HDFC Securities - Buy | K12: HDFC Securities | L12: 0.97 | M12: N/A
A13: 45019 | B13: NET PO FROM HSL A/C 2554606-00602340029427 | C13: 0000000399979610 | D13: 45019 | E13: 0 | F13: 4287.59 | G13: 95517.25 | J13: HDFC Securities - Sell | K13: HDFC Securities | L13: 0.97 | M13: N/A
A14: 45021 | B14: NET PI TO HSL SEC A/C 2554606-00602340029427 | C14: 0000000400386064 | D14: 45021 | E14: 21810.69 | F14: 0 | G14: 73706.56 | J14: HDFC Securities - Buy | K14: HDFC Securities | L14: 0.97 | M14: N/A
A15: 45022 | B15: NET PI TO HSL SEC A/C 2554606-00602340029427 | C15: 0000000400620092 | D15: 45022 | E15: 115.7 | F15: 0 | G15: 73590.86 | J15: HDFC Securities - Buy | K15: HDFC Securities | L15: 0.97 | M15: N/A
A16: 45022 | B16: NET PO FROM HSL A/C 2554606-00602340029427 | C16: 0000000400730659 | D16: 45022 | E16: 0 | F16: 1699.23 | G16: 75290.09 | J16: HDFC Securities - Sell | K16: HDFC Securities | L16: 0.97 | M16: N/A
A17: 45023 | B17: 00602300000434-021333684 | C17: 0000304077582285 | D17: 45023 | E17: 0 | F17: 1880 | G17: 77170.09 | J17: What is this? | K17: Suspense | L17: 0 | M17: N/A
A18: 45026 | B18: NET PI TO HSL SEC A/C 2554606-00602340029427 | C18: 0000000401078570 | D18: 45026 | E18: 466.16 | F18: 0 | G18: 76703.93 | J18: HDFC Securities - Buy | K18: HDFC Securities | L18: 0.97 | M18: N/A
A19: 45026 | B19: NET PO FROM HSL A/C 2554606-00602340029427 | C19: 0000000401189359 | D19: 45026 | E19: 0 | F19: 662.12 | G19: 77366.05 | J19: HDFC Securities - Sell | K19: HDFC Securities | L19: 0.97 | M19: N/A
A20: 45027 | B20: NET PI TO HSL SEC A/C 2554606-00602340029427 | C20: 0000000401415591 | D20: 45027 | E20: 116.86 | F20: 0 | G20: 77249.19 | J20: HDFC Securities - Buy | K20: HDFC Securities | L20: 0.97 | M20: N/A
A21: 45027 | B21: NET PO FROM HSL A/C 2554606-00602340029427 | C21: 0000000401522488 | D21: 45027 | E21: 0 | F21: 334.27 | G21: 77583.46 | J21: HDFC Securities - Sell | K21: HDFC Securities | L21: 0.97 | M21: N/A
... A795: 45383 | B795: CREDIT INTEREST CAPITALISED | C795: 000000000000000 | D795: 45382 | E795: 0 | F795: 394 | G795: 43050.89 | J795: Bank Interest | K795: Bank Interest | L795: 0.95 | M795: N/A

Sheet Jupiter
B1: Federal Bank (Jupiter) Narration Sheet
B2: Colour Legend of Categories:
B3: UPI Payment | C3: UPI - Paytm | D3: Contra - Kotak | E3: UPI - BharatPe | F3: What is this?
B4: MF Investment | C4: UPI - IRCTC | D4: Misc Income | E4: NEFT Transfer | F4: UPI - Ola
B5: UPI - Uber | C5: UPI - Google Pay | D5: MF Redemption | E5: UPI - Rapido | F5: UPI - Zepto
B6: UPI - Swiggy | C6: UPI - Zomato | D6: UPI - Amazon | E6: Bank Interest | F6: UPI Receipt
B7: UPI - DMart | C7: UPI - Blinkit
A9: Date | B9: Particulars | C9: Ref | D9: Value_Date | E9: DR | F9: CR | G9: Balance | H9: Beneficiary | I9: Human_Narration | J9: Auto_Narration | K9: Account_Head | L9: Confidence | M9: Match
A10: 45024 | B10: UPIOUT/309826882296/Q143041833@ybl/Sent via /5311 | D10: 45024 | E10: 10 | F10: 0 | G10: 19.86 | J10: UPI Payment | K10: Personal | L10: 0.55 | M10: N/A
A11: 45038 | B11: UPIOUT/311268164406/paytm-61240897@paytm/S en/5411 | D11: 45038 | E11: 9 | F11: 0 | G11: 10.86 | J11: UPI - Paytm | K11: Personal | L11: 0.65 | M11: N/A
A12: 45099 | B12: UPI IN/317381933693/9594435259@jupiteraxis /A/0000 | D12: 45099 | E12: 0 | F12: 190 | G12: 200.86 | J12: Contra - Kotak | K12: KOTAK 0333 | L12: 0.9 | M12: N/A
A13: 45099 | B13: UPIOUT/317381938077/playstore@axisbank/Man da/5817 | D13: 45099 | E13: 199 | F13: 0 | G13: 1.86 | J13: UPI Payment | K13: Personal | L13: 0.55 | M13: N/A
A14: 45130 | B14: UPI IN/320471883328/9594435259@jupiteraxis /A/0000 | D14: 45130 | E14: 0 | F14: 199 | G14: 200.86 | J14: Contra - Kotak | K14: KOTAK 0333 | L14: 0.9 | M14: N/A
A15: 45138 | B15: UPI IN/321287516546/9594435259@jupiteraxis /A/0000 | D15: 45138 | E15: 0 | F15: 1000 | G15: 1200.86 | J15: Contra - Kotak | K15: KOTAK 0333 | L15: 0.9 | M15: N/A
A16: 45138 | B16: UPIOUT/321287534320/paytm-69746593@paytm/S en/5813 | D16: 45138 | E16: 400 | F16: 0 | G16: 800.86 | J16: UPI - Paytm | K16: Personal | L16: 0.65 | M16: N/A
A17: 45138 | B17: UPIOUT/321289065233/paytm-69746593@paytm/S en/5813 | D17: 45138 | E17: 200 | F17: 0 | G17: 600.86 | J17: UPI - Paytm | K17: Personal | L17: 0.65 | M17: N/A
A18: 45138 | B18: UPIOUT/321290570632/0008288006214@ibl/Sent v/0000 | D18: 45138 | E18: 600 | F18: 0 | G18: 0.86 | J18: UPI Payment | K18: Personal | L18: 0.55 | M18: N/A
A19: 45185 | B19: UPI IN/325983918366/9594435259@jupiteraxis /A/0000 | D19: 45185 | E19: 0 | F19: 100 | G19: 100.86 | J19: Contra - Kotak | K19: KOTAK 0333 | L19: 0.9 | M19: N/A
A20: 45185 | B20: UPIOUT/325983946204/aayush20gupta@oksbi/Se nt/0000 | D20: 45185 | E20: 50 | F20: 0 | G20: 50.86 | J20: Contra - Kotak | K20: KOTAK 0333 | L20: 0.9 | M20: N/A
A21: 45185 | B21: UPIOUT/325983968688/aayush20gupta@oksbi/Se nt/0000 | D21: 45185 | E21: 50 | F21: 0 | G21: 0.86 | J21: Contra - Kotak | K21: KOTAK 0333 | L21: 0.9 | M21: N/A
... A849: 45382 | B849: UPIOUT/409295559930/paytmqr110em392r1@payt m//5462 | D849: 45383 | E849: 60 | F849: 0 | G849: 771.09 | J849: UPI - Paytm | K849: Personal | L849: 0.65 | M849: N/A
B850: GRAND TOTAL | E850: 179753.05 | F850: 180494.28 | J850: What is this? | K850: Suspense | L850: 0 | M850: N/A

Sheet Kotak_Salary
B1: Kotak Mahindra Bank Narration Sheet
B2: Colour Legend of Categories:
B3: Auto Sweep FD | C3: Contra - Jupiter | D3: Contra - Self | E3: IMPS Receipt | F3: Salary
B4: Card Purchase | C4: Bank Interest
A6: Date | B6: Particulars | C6: Ref | D6: Value_Date | E6: DR | F6: CR | G6: Balance | H6: Beneficiary | I6: Human_Narration | J6: Auto_Narration | K6: Account_Head | L6: Confidence | M6: Match
A7: 45366 | B7: TRANS | C7: FCM-24031594KVJN | D7: 45366 | E7: 0 | F7: 9109 | G7: 9109 | J7: Auto Sweep FD | K7: Auto Sweep FD | L7: 0.75 | M7: N/A
A8: 45369 | B8: UPI/AAYUSH KUMAR GU/407811693463/MB UPI | C8: UPI-407898263279 | D8: 45369 | E8: 1 | F8: 0 | G8: 9108 | J8: Contra - Jupiter | K8: FEDERAL 0847 | L8: 0.95 | M8: N/A
A9: 45369 | B9: UPI/AAYUSH KUMAR GU/407811695179/MB UPI | C9: UPI-407898305881 | D9: 45369 | E9: 4999 | F9: 0 | G9: 4109 | J9: Contra - Self | K9: Transfer | L9: 0.8 | M9: N/A
A10: 45370 | B10: UPI/AAYUSH KUMAR GU/407908004025/MB UPI | C10: UPI-407933197636 | D10: 45370 | E10: 4109 | F10: 0 | G10: 0 | J10: Contra - Self | K10: Transfer | L10: 0.8 | M10: N/A
A11: 45374 | B11: Recd:IMPS/408307273704/CASHFREE P/KKBK/X0008/BAV | C11: IMPS-408307596920 | D11: 45374 | E11: 0 | F11: 1.01 | G11: 1.01 | J11: IMPS Receipt | K11: Personal | L11: 0.72 | M11: N/A
A12: 45380 | B12: SALARYTRANS | C12: FCM-2403299ES9MP | D12: 45380 | E12: 0 | F12: 63942 | G12: 63943.01 | J12: Salary | K12: Salary | L12: 0.95 | M12: N/A
A13: 45381 | B13: UPI/AAYUSH KUMAR GU/409021378087/MB UPI | C13: UPI-409009155467 | D13: 45381 | E13: 1 | F13: 0 | G13: 63942.01 | J13: Contra - Jupiter | K13: FEDERAL 0847 | L13: 0.95 | M13: N/A
A14: 45381 | B14: UPI/AAYUSH KUMAR GU/409021379488/MB UPI | C14: UPI-409009192485 | D14: 45381 | E14: 1998 | F14: 0 | G14: 61944.01 | J14: Contra - Jupiter | K14: FEDERAL 0847 | L14: 0.95 | M14: N/A
A15: 45381 | B15: UPI/AAYUSH KUMAR GU/409021381201/MB UPI | C15: UPI-409009233431 | D15: 45381 | E15: 1998 | F15: 0 | G15: 59946.01 | J15: Contra - Jupiter | K15: FEDERAL 0847 | L15: 0.95 | M15: N/A
A16: 45382 | B16: PCD/4395/GYFTR COM/7840089543310324/20:49 | C16: 409115178316 | D16: 45382 | E16: 245 | F16: 0 | G16: 59701.01 | J16: Card Purchase | K16: Personal | L16: 0.88 | M16: N/A
A17: 45383 | B17: Int.Pd:3649610333:01-01-2024 to 31-03-2024 | D17: 45382 | E17: 0 | F17: 21 | G17: 59722.01 | J17: Bank Interest | K17: Bank Interest | L17: 0.95 | M17: N/A

Sheet SBI_PPF
B1: State Bank of India Narration Sheet
B2: Colour Legend of Categories:
B3: What is this? | C3: Bank Interest
A5: Date | B5: Particulars | C5: Ref | D5: Value_Date | E5: DR | F5: CR | G5: Balance | H5: Beneficiary | I5: Human_Narration | J5: Auto_Narration | K5: Account_Head | L5: Confidence | M5: Match
A6: 45211 | B6: BY TRANSFER-INB Deposit / Investment-- | C6: IF38973887 TRANSFER FROM 20276981227 | D6: 45211 | E6: 0 | F6: 5000 | G6: 22941 | J6: What is this? | K6: Suspense | L6: 0 | M6: N/A
A7: 45382 | B7: CREDIT INTEREST--- | D7: 45382 | E7: 0 | F7: 1422 | G7: 24363 | J7: Bank Interest | K7: Bank Interest | L7: 0.9 | M7: N/A

Sheet SBI_Savings
B1: State Bank of India Narration Sheet
B2: Colour Legend of Categories:
B3: Received - Ayushi M | C3: UPI Payment | D3: Received - Prashant | E3: Zerodha Broking | F3: UPI - Paytm
B4: UPI - Swiggy | C4: UPI - IRCTC | D4: Transfer - Ajay Gupta | E4: UPI - Uber | F4: Dividend Income
B5: Cash Withdrawal | C5: UPI - Google Pay | D5: What is this? | E5: UPI - Zomato | F5: Received - Archit Gupta
B6: Transfer - Archit Gupta | C6: Received - Ganesh B | D6: UPI - Amazon | E6: Received - Dealskar | F6: Received - Tanuja M
B7: Received - Sangam P | C7: UPI - BharatPe | D7: UPI - MedPlus | E7: NEFT Transfer | F7: Received - Pranav
B8: Received - Shashank | C8: Received - Vendekin | D8: Received - Monish K | E8: Received - Adarsh N | F8: Contra - Jupiter
B9: Bank Interest | C9: Received - Gaurav S | D9: Received - Tirtha T | E9: Received - Shivansh | F9: Received - Nitish K
B10: Received - Vysakh R K | C10: Received - Vivek Ku | D10: Received - Aditi G
A12: Date | B12: Particulars | C12: Ref | D12: Value_Date | E12: DR | F12: CR | G12: Balance | H12: Beneficiary | I12: Human_Narration | J12: Auto_Narration | K12: Account_Head | L12: Confidence | M12: Match
A13: 45017 | B13: BY TRANSFER-UPI/CR/309169418415/AYUSHI M/PUNB/nainamitta/UPI-- | C13: TRANSFER FROM 4693130162091 | D13: 45017 | E13: 0 | F13: 95 | G13: 124490.27 | J13: Received - Ayushi M | K13: Personal | L13: 0.55 | M13: N/A
A14: 45017 | B14: TO TRANSFER-UPI/DR/309140926569/BANANA L/HDFC/bananaleaf/UPI-- | C14: TRANSFER TO 4692478162093 | D14: 45017 | E14: 70 | F14: 0 | G14: 124420.27 | H14: Banana L | J14: UPI Payment | K14: Personal | L14: 0.55 | M14: N/A
A15: 45018 | B15: TO TRANSFER-UPI/DR/309276354517/LUCKY DH/YESB/q57871899@/UPI-- | C15: TRANSFER TO 5098091162092 | D15: 45018 | E15: 90 | F15: 0 | G15: 124330.27 | H15: Lucky Dh | J15: UPI Payment | K15: Personal | L15: 0.55 | M15: N/A
A16: 45018 | B16: BY TRANSFER-UPI/CR/309286549772/PRASHANT/HDFC/pkaps1997@/UPI-- | C16: TRANSFER FROM 4695271162095 | D16: 45018 | E16: 0 | F16: 30 | G16: 124360.27 | J16: Received - Prashant | K16: Personal | L16: 0.55 | M16: N/A
A17: 45018 | B17: TO TRANSFER-UPI/DR/309274214572/PRATYAY /SBIN/7073096110/NA-- | C17: TRANSFER TO 5098127162096 | D17: 45018 | E17: 210 | F17: 0 | G17: 124150.27 | H17: Pratyay | J17: UPI Payment | K17: Personal | L17: 0.55 | M17: N/A
A18: 45018 | B18: TO TRANSFER-UPI/DR/345885628443/WWW VODA/HDFC/vodafone1./UPI-- | C18: TRANSFER TO 5098093162090 | D18: 45018 | E18: 459 | F18: 0 | G18: 123691.27 | H18: Www Voda | J18: UPI Payment | K18: Personal | L18: 0.55 | M18: N/A
A19: 45018 | B19: TO TRANSFER-UPI/DR/309277368845/KUNAL BH/HDFC/kunalbhard/UPI-- | C19: TRANSFER TO 5099812162090 | D19: 45018 | E19: 71 | F19: 0 | G19: 123620.27 | H19: Kunal Bh | J19: UPI Payment | K19: Personal | L19: 0.55 | M19: N/A
A20: 45019 | B20: TO TRANSFER-UPI/DR/345945568018/Zerodha /HDFC/zerodhabro/08956-- | C20: TRANSFER TO 4695788162098 | D20: 45019 | E20: 5000 | F20: 0 | G20: 118620.27 | J20: Zerodha Broking | K20: Zerodha Broking Limited | L20: 0.88 | M20: N/A
A21: 45020 | B21: TO TRANSFER-UPI/DR/309414339465/SEVEN SP/PYTM/paytmqr281/UPI-- | C21: TRANSFER TO 5097637162094 | D21: 45020 | E21: 250 | F21: 0 | G21: 118370.27 | J21: UPI - Paytm | K21: Personal | L21: 0.65 | M21: N/A
A22: 45020 | B22: TO TRANSFER-UPI/DR/346087812550/SEVEN SP/PYTM/paytmqr281/UPI-- | C22: TRANSFER TO 5097617162098 | D22: 45020 | E22: 30 | F22: 0 | G22: 118340.27 | J22: UPI - Paytm | K22: Personal | L22: 0.65 | M22: N/A
A23: 45021 | B23: TO TRANSFER-UPI/DR/309564429050/BANANA L/HDFC/bananaleaf/UPI-- | C23: TRANSFER TO 4692551162099 | D23: 45021 | E23: 70 | F23: 0 | G23: 118270.27 | H23: Banana L | J23: UPI Payment | K23: Personal | L23: 0.55 | M23: N/A
A24: 45022 | B24: TO TRANSFER-UPI/DR/309682616023/Mr AADA/YESB/q423863729/UPI-- | C24: TRANSFER TO 5097803162095 | D24: 45022 | E24: 104 | F24: 0 | G24: 118166.27 | H24: Mr Aada | J24: UPI Payment | K24: Personal | L24: 0.55 | M24: N/A
A25: 45022 | B25: TO TRANSFER-UPI/DR/309673159840/Swiggy/UTIB/swiggyupi@/Swiggy-- | C25: TRANSFER TO 5097808162090 | D25: 45022 | E25: 306 | F25: 0 | G25: 117860.27 | J25: UPI - Swiggy | K25: Food & Dining | L25: 0.68 | M25: N/A
A26: 45023 | B26: TO TRANSFER-UPI/DR/309789529764/IRCTC CF/HDFC/irctc.cf@h/IRCTC-- | C26: TRANSFER TO 4692595162098 | D26: 45023 | E26: 1448.95 | F26: 0 | G26: 116411.32 | J26: UPI - IRCTC | K26: Travel | L26: 0.88 | M26: N/A
A27: 45023 | B27: TO TRANSFER-UPI/DR/309789705434/IRCTC CF/HDFC/irctc.cf@h/IRCTC-- | C27: TRANSFER TO 4696934162097 | D27: 45023 | E27: 902.15 | F27: 0 | G27: 115509.17 | J27: UPI - IRCTC | K27: Travel | L27: 0.88 | M27: N/A
A28: 45023 | B28: TO TRANSFER-UPI/DR/309720030395/Mr AADA/YESB/q143041833/UPI-- | C28: TRANSFER TO 4696933162098 | D28: 45023 | E28: 20 | F28: 0 | G28: 115489.17 | H28: Mr Aada | J28: UPI Payment | K28: Personal | L28: 0.55 | M28: N/A
A29: 45023 | B29: TO TRANSFER-UPI/DR/309790935099/IRCTC CF/HDFC/irctc.cf@h/IRCTC-- | C29: TRANSFER TO 4696185162096 | D29: 45023 | E29: 602.15 | F29: 0 | G29: 114887.02 | J29: UPI - IRCTC | K29: Travel | L29: 0.88 | M29: N/A
A30: 45023 | B30: TO TRANSFER-UPI/DR/309732235881/BANANA L/HDFC/bananaleaf/UPI-- | C30: TRANSFER TO 4692597162096 | D30: 45023 | E30: 110 | F30: 0 | G30: 114777.02 | H30: Banana L | J30: UPI Payment | K30: Personal | L30: 0.55 | M30: N/A
A31: 45024 | B31: TO TRANSFER-UPI/DR/309845925383/Mr AADA/YESB/q143041833/UPI-- | C31: TRANSFER TO 4696969162097 | D31: 45024 | E31: 40 | F31: 0 | G31: 114737.02 | H31: Mr Aada | J31: UPI Payment | K31: Personal | L31: 0.55 | M31: N/A
A32: 45024 | B32: TO TRANSFER-UPI/DR/309870836173/SEVEN SP/PYTM/paytmqr281/UPI-- | C32: TRANSFER TO 5098011162097 | D32: 45024 | E32: 60 | F32: 0 | G32: 114677.02 | J32: UPI - Paytm | K32: Personal | L32: 0.65 | M32: N/A
A33: 45024 | B33: TO TRANSFER-UPI/DR/309861185569/Raj Rani/SBIN/lalsinghla/UPI-- | C33: TRANSFER TO 4694361162091 | D33: 45024 | E33: 132 | F33: 0 | G33: 114545.02 | H33: Raj Rani | J33: UPI Payment | K33: Personal | L33: 0.55 | M33: N/A
A34: 45024 | B34: TO TRANSFER-UPI/DR/309864621113/AJAY GUPTA/HDFC/slietajayg/UPI-- | C34: TRANSFER TO 4694315162096 | D34: 45024 | E34: 100 | F34: 0 | G34: 114445.02 | J34: Transfer - Ajay Gupta | K34: Ajay Gupta | L34: 0.88 | M34: N/A
A35: 45025 | B35: TO TRANSFER-UPI/DR/309973408594/JAGDISH/PYTM/7742506388/UPI-- | C35: TRANSFER TO 5098150162096 | D35: 45025 | E35: 125 | F35: 0 | G35: 114320.02 | H35: Jagdish | J35: UPI Payment | K35: Personal | L35: 0.55 | M35: N/A
A36: 45025 | B36: TO TRANSFER-UPI/DR/309994513204/UBER IND/HDFC/uberrides@/charg-- | C36: TRANSFER TO 4897696162090 | D36: 45025 | E36: 48.52 | F36: 0 | G36: 114271.5 | J36: UPI - Uber | K36: Transport | L36: 0.68 | M36: N/A
A37: 45027 | B37: BULK POSTING-C23854246658 41774260032INTERIM DIVIDEND ACCOU-- | D37: 45027 | E37: 0 | F37: 10 | G37: 114281.5 | J37: Dividend Income | K37: Dividend Income | L37: 0.85 | M37: N/A
A38: 45027 | B38: BY TRANSFER-UPI/CR/310198604104/IRCTC CF/HDFC/irctc.cf@h/UPI R-- | C38: TRANSFER FROM 4897733162090 | D38: 45027 | E38: 0 | F38: 830 | G38: 115111.5 | J38: UPI - IRCTC | K38: Travel | L38: 0.68 | M38: N/A
A39: 45028 | B39: TO TRANSFER-UPI/DR/310294768781/S SARGUNAM/YESB/q200088506/UPI-- | C39: TRANSFER TO 4897692162094 | D39: 45028 | E39: 100 | F39: 0 | G39: 115011.5 | H39: S Sargunam | J39: UPI Payment | K39: Personal | L39: 0.55 | M39: N/A
A40: 45028 | B40: TO TRANSFER-UPI/DR/310298964851/Bharti A/HDFC/airtel.pay/UPITr-- | C40: TRANSFER TO 4897692162094 | D40: 45028 | E40: 155 | F40: 0 | G40: 114856.5 | H40: Bharti A | J40: UPI Payment | K40: Personal | L40: 0.55 | M40: N/A
A41: 45028 | B41: TO TRANSFER-UPI/DR/310299085532/billdesk/ICIC/billdesk.p/UPI-- | C41: TRANSFER TO 4897692162094 | D41: 45028 | E41: 148 | F41: 0 | G41: 114708.5 | H41: Billdesk | J41: UPI Payment | K41: Personal | L41: 0.55 | M41: N/A
...

Sheet For Tally
A1: TX Date | B1: Date | C1: DR | D1: CR | E1: Beneficiary | F1: Narration | G1: Confidence | H1: Account Head | I1: Account No | J1: Kya Hai? | K1: Particulars | L1: Bank | M1: Duplicate
A2: 45017 | B2: 45017 | C2: 0 | D2: 95 | F2: Received - Ayushi M | G2: 0.55 | H2: Personal | I2: SBI 1227 | K2: BY TRANSFER-UPI/CR/309169418415/AYUSHI M/PUNB/nainamitta/UPI-- | L2: State Bank of India
A3: 45017 | B3: 45017 | C3: 70 | D3: 0 | E3: Banana L | F3: UPI Payment | G3: 0.55 | H3: Personal | I3: SBI 1227 | K3: TO TRANSFER-UPI/DR/309140926569/BANANA L/HDFC/bananaleaf/UPI-- | L3: State Bank of India
A4: 45017 | B4: 45017 | C4: 50000 | D4: 0 | F4: Contra - Axis | G4: 0.9 | H4: AXIS | I4: HDFC 5413 | K4: NEFT DR-UTIB0002656-AAYUSH KUMAR GUPTA-NETBANK, MUM-N091232397833081-TRANSFER FROM HDFC | L4: HDFC Bank
A5: 45018 | B5: 45018 | C5: 0 | D5: 50000 | F5: Contra - HDFC | G5: 0.9 | H5: HDFC 5413 | I5: AXIS | K5: NEFT/N091232397833081/AAYUSH KU/HDFC BANK/Transfe | L5: Axis Bank
A6: 45018 | B6: 45018 | C6: 90 | D6: 0 | E6: Lucky Dh | F6: UPI Payment | G6: 0.55 | H6: Personal | I6: SBI 1227 | K6: TO TRANSFER-UPI/DR/309276354517/LUCKY DH/YESB/q57871899@/UPI-- | L6: State Bank of India
A7: 45018 | B7: 45018 | C7: 0 | D7: 30 | F7: Received - Prashant | G7: 0.55 | H7: Personal | I7: SBI 1227 | K7: BY TRANSFER-UPI/CR/309286549772/PRASHANT/HDFC/pkaps1997@/UPI-- | L7: State Bank of India
A8: 45018 | B8: 45018 | C8: 210 | D8: 0 | E8: Pratyay | F8: UPI Payment | G8: 0.55 | H8: Personal | I8: SBI 1227 | K8: TO TRANSFER-UPI/DR/309274214572/PRATYAY /SBIN/7073096110/NA-- | L8: State Bank of India
A9: 45018 | B9: 45018 | C9: 459 | D9: 0 | E9: Www Voda | F9: UPI Payment | G9: 0.55 | H9: Personal | I9: SBI 1227 | K9: TO TRANSFER-UPI/DR/345885628443/WWW VODA/HDFC/vodafone1./UPI-- | L9: State Bank of India
A10: 45018 | B10: 45018 | C10: 71 | D10: 0 | E10: Kunal Bh | F10: UPI Payment | G10: 0.55 | H10: Personal | I10: SBI 1227 | K10: TO TRANSFER-UPI/DR/309277368845/KUNAL BH/HDFC/kunalbhard/UPI-- | L10: State Bank of India
A11: 45019 | B11: 45019 | C11: 0 | D11: 4287.59 | F11: HDFC Securities - Sell | G11: 0.97 | H11: HDFC Securities | I11: HDFC 5413 | K11: NET PO FROM HSL A/C 2554606-00602340029427 | L11: HDFC Bank
A12: 45019 | B12: 45019 | C12: 0 | D12: 57999 | F12: Contra - Axis | G12: 0.9 | H12: AXIS | I12: HDFC 5413 | K12: NEFT CR-UTIB0000115-JINDAL SAW LIMITED-AAYUSH KUMAR GUPTA-AXISCN0231261220 | L12: HDFC Bank
A13: 45019 | B13: 45019 | C13: 387.51 | D13: 0 | F13: HDFC Securities - Buy | G13: 0.97 | H13: HDFC Securities | I13: HDFC 5413 | K13: NET PI TO HSL SEC A/C 2554606-00602340029427 | L13: HDFC Bank
A14: 45019 | B14: 45019 | C14: 5000 | D14: 0 | F14: Zerodha Broking | G14: 0.88 | H14: Zerodha Broking Limited | I14: SBI 1227 | K14: TO TRANSFER-UPI/DR/345945568018/Zerodha /HDFC/zerodhabro/08956-- | L14: State Bank of India
A15: 45020 | B15: 45020 | C15: 30 | D15: 0 | F15: UPI - Paytm | G15: 0.65 | H15: Personal | I15: SBI 1227 | K15: TO TRANSFER-UPI/DR/346087812550/SEVEN SP/PYTM/paytmqr281/UPI-- | L15: State Bank of India
A16: 45020 | B16: 45020 | C16: 250 | D16: 0 | F16: UPI - Paytm | G16: 0.65 | H16: Personal | I16: SBI 1227 | K16: TO TRANSFER-UPI/DR/309414339465/SEVEN SP/PYTM/paytmqr281/UPI-- | L16: State Bank of India
A17: 45021 | B17: 45021 | C17: 21810.69 | D17: 0 | F17: HDFC Securities - Buy | G17: 0.97 | H17: HDFC Securities | I17: HDFC 5413 | K17: NET PI TO HSL SEC A/C 2554606-00602340029427 | L17: HDFC Bank
A18: 45021 | B18: 45021 | C18: 70 | D18: 0 | E18: Banana L | F18: UPI Payment | G18: 0.55 | H18: Personal | I18: SBI 1227 | K18: TO TRANSFER-UPI/DR/309564429050/BANANA L/HDFC/bananaleaf/UPI-- | L18: State Bank of India
A19: 45022 | B19: 45022 | C19: 104 | D19: 0 | E19: Mr Aada | F19: UPI Payment | G19: 0.55 | H19: Personal | I19: SBI 1227 | K19: TO TRANSFER-UPI/DR/309682616023/Mr AADA/YESB/q423863729/UPI-- | L19: State Bank of India
A20: 45022 | B20: 45022 | C20: 306 | D20: 0 | F20: UPI - Swiggy | G20: 0.68 | H20: Food & Dining | I20: SBI 1227 | K20: TO TRANSFER-UPI/DR/309673159840/Swiggy/UTIB/swiggyupi@/Swiggy-- | L20: State Bank of India
A21: 45022 | B21: 45022 | C21: 115.7 | D21: 0 | F21: HDFC Securities - Buy | G21: 0.97 | H21: HDFC Securities | I21: HDFC 5413 | K21: NET PI TO HSL SEC A/C 2554606-00602340029427 | L21: HDFC Bank
A22: 45022 | B22: 45022 | C22: 0 | D22: 1699.23 | F22: HDFC Securities - Sell | G22: 0.97 | H22: HDFC Securities | I22: HDFC 5413 | K22: NET PO FROM HSL A/C 2554606-00602340029427 | L22: HDFC Bank
A23: 45023 | B23: 45023 | C23: 0 | D23: 1880 | F23: What is this? | G23: 0 | H23: Suspense | I23: HDFC 5413 | K23: 00602300000434-021333684 | L23: HDFC Bank
A24: 45023 | B24: 45023 | C24: 902.15 | D24: 0 | F24: UPI - IRCTC | G24: 0.88 | H24: Travel | I24: SBI 1227 | K24: TO TRANSFER-UPI/DR/309789705434/IRCTC CF/HDFC/irctc.cf@h/IRCTC-- | L24: State Bank of India
A25: 45023 | B25: 45023 | C25: 110 | D25: 0 | E25: Banana L | F25: UPI Payment | G25: 0.55 | H25: Personal | I25: SBI 1227 | K25: TO TRANSFER-UPI/DR/309732235881/BANANA L/HDFC/bananaleaf/UPI-- | L25: State Bank of India
A26: 45023 | B26: 45023 | C26: 602.15 | D26: 0 | F26: UPI - IRCTC | G26: 0.88 | H26: Travel | I26: SBI 1227 | K26: TO TRANSFER-UPI/DR/309790935099/IRCTC CF/HDFC/irctc.cf@h/IRCTC-- | L26: State Bank of India
A27: 45023 | B27: 45023 | C27: 20 | D27: 0 | E27: Mr Aada | F27: UPI Payment | G27: 0.55 | H27: Personal | I27: SBI 1227 | K27: TO TRANSFER-UPI/DR/309720030395/Mr AADA/YESB/q143041833/UPI-- | L27: State Bank of India
A28: 45023 | B28: 45023 | C28: 1448.95 | D28: 0 | F28: UPI - IRCTC | G28: 0.88 | H28: Travel | I28: SBI 1227 | K28: TO TRANSFER-UPI/DR/309789529764/IRCTC CF/HDFC/irctc.cf@h/IRCTC-- | L28: State Bank of India
A29: 45024 | B29: 45024 | C29: 60 | D29: 0 | F29: UPI - Paytm | G29: 0.65 | H29: Personal | I29: SBI 1227 | K29: TO TRANSFER-UPI/DR/309870836173/SEVEN SP/PYTM/paytmqr281/UPI-- | L29: State Bank of India
A30: 45024 | B30: 45024 | C30: 40 | D30: 0 | E30: Mr Aada | F30: UPI Payment | G30: 0.55 | H30: Personal | I30: SBI 1227 | K30: TO TRANSFER-UPI/DR/309845925383/Mr AADA/YESB/q143041833/UPI-- | L30: State Bank of India
A31: 45024 | B31: 45024 | C31: 100 | D31: 0 | F31: Transfer - Ajay Gupta | G31: 0.88 | H31: Ajay Gupta | I31: SBI 1227 | K31: TO TRANSFER-UPI/DR/309864621113/AJAY GUPTA/HDFC/slietajayg/UPI-- | L31: State Bank of India
A32: 45024 | B32: 45024 | C32: 132 | D32: 0 | E32: Raj Rani | F32: UPI Payment | G32: 0.55 | H32: Personal | I32: SBI 1227 | K32: TO TRANSFER-UPI/DR/309861185569/Raj Rani/SBIN/lalsinghla/UPI-- | L32: State Bank of India
A33: 45024 | B33: 45024 | C33: 10 | D33: 0 | F33: UPI Payment | G33: 0.55 | H33: Personal | I33: FEDERAL 0847 | K33: UPIOUT/309826882296/Q143041833@ybl/Sent via /5311 | L33: Federal Bank (Jupiter)
A34: 45025 | B34: 45025 | C34: 125 | D34: 0 | E34: Jagdish | F34: UPI Payment | G34: 0.55 | H34: Personal | I34: SBI 1227 | K34: TO TRANSFER-UPI/DR/309973408594/JAGDISH/PYTM/7742506388/UPI-- | L34: State Bank of India
A35: 45025 | B35: 45025 | C35: 48.52 | D35: 0 | F35: UPI - Uber | G35: 0.68 | H35: Transport | I35: SBI 1227 | K35: TO TRANSFER-UPI/DR/309994513204/UBER IND/HDFC/uberrides@/charg-- | L35: State Bank of India
A36: 45026 | B36: 45026 | C36: 466.16 | D36: 0 | F36: HDFC Securities - Buy | G36: 0.97 | H36: HDFC Securities | I36: HDFC 5413 | K36: NET PI TO HSL SEC A/C 2554606-00602340029427 | L36: HDFC Bank
A37: 45026 | B37: 45026 | C37: 0 | D37: 662.12 | F37: HDFC Securities - Sell | G37: 0.97 | H37: HDFC Securities | I37: HDFC 5413 | K37: NET PO FROM HSL A/C 2554606-00602340029427 | L37: HDFC Bank
A38: 45027 | B38: 45027 | C38: 0 | D38: 830 | F38: UPI - IRCTC | G38: 0.68 | H38: Travel | I38: SBI 1227 | K38: BY TRANSFER-UPI/CR/310198604104/IRCTC CF/HDFC/irctc.cf@h/UPI R-- | L38: State Bank of India
A39: 45027 | B39: 45027 | C39: 116.86 | D39: 0 | F39: HDFC Securities - Buy | G39: 0.97 | H39: HDFC Securities | I39: HDFC 5413 | K39: NET PI TO HSL SEC A/C 2554606-00602340029427 | L39: HDFC Bank
A40: 45027 | B40: 45027 | C40: 0 | D40: 334.27 | F40: HDFC Securities - Sell | G40: 0.97 | H40: HDFC Securities | I40: HDFC 5413 | K40: NET PO FROM HSL A/C 2554606-00602340029427 | L40: HDFC Bank
...

Sheet Conso
A1: Aayush Kumar Gupta
A2: Account of Statements from 01-Apr-2023 to 01-Apr-2024 | D2: =SUM(D5:D1967) | E2: =SUM(E5:E1967) | F2: =E2-D2
A4: TX Date | B4: Particulars | C4: Ref | D4: DR | E4: CR | F4: Balance | G4: Account Head | H4: Account No
A5: 45017 | B5: BY TRANSFER-UPI/CR/309169418415/AYUSHI M/PUNB/nainamitta/UPI-- | C5: TRANSFER FROM 4693130162091 | D5: 0 | E5: 95 | F5: 124490.27 | G5: Personal | H5: SBI 1227
A6: 45017 | B6: TO TRANSFER-UPI/DR/309140926569/BANANA L/HDFC/bananaleaf/UPI-- | C6: TRANSFER TO 4692478162093 | D6: 70 | E6: 0 | F6: 124420.27 | G6: Personal | H6: SBI 1227
A7: 45017 | B7: NEFT DR-UTIB0002656-AAYUSH KUMAR GUPTA-NETBANK, MUM-N091232397833081-TRANSFER FROM HDFC | C7: N091232397833081 | D7: 50000 | E7: 0 | F7: 33618.17 | G7: AXIS | H7: HDFC 5413
A8: 45018 | B8: NEFT/N091232397833081/AAYUSH KU/HDFC BANK/Transfe | C8: - | D8: 0 | E8: 50000 | F8: 75508.68 | G8: HDFC 5413 | H8: AXIS
A9: 45018 | B9: TO TRANSFER-UPI/DR/309276354517/LUCKY DH/YESB/q57871899@/UPI-- | C9: TRANSFER TO 5098091162092 | D9: 90 | E9: 0 | F9: 124330.27 | G9: Personal | H9: SBI 1227
A10: 45018 | B10: BY TRANSFER-UPI/CR/309286549772/PRASHANT/HDFC/pkaps1997@/UPI-- | C10: TRANSFER FROM 4695271162095 | D10: 0 | E10: 30 | F10: 124360.27 | G10: Personal | H10: SBI 1227
A11: 45018 | B11: TO TRANSFER-UPI/DR/309274214572/PRATYAY /SBIN/7073096110/NA-- | C11: TRANSFER TO 5098127162096 | D11: 210 | E11: 0 | F11: 124150.27 | G11: Personal | H11: SBI 1227
A12: 45018 | B12: TO TRANSFER-UPI/DR/345885628443/WWW VODA/HDFC/vodafone1./UPI-- | C12: TRANSFER TO 5098093162090 | D12: 459 | E12: 0 | F12: 123691.27 | G12: Personal | H12: SBI 1227
A13: 45018 | B13: TO TRANSFER-UPI/DR/309277368845/KUNAL BH/HDFC/kunalbhard/UPI-- | C13: TRANSFER TO 5099812162090 | D13: 71 | E13: 0 | F13: 123620.27 | G13: Personal | H13: SBI 1227
A14: 45019 | B14: NET PO FROM HSL A/C 2554606-00602340029427 | C14: 0000000399979610 | D14: 0 | E14: 4287.59 | F14: 95517.25 | G14: HDFC Securities | H14: HDFC 5413
A15: 45019 | B15: NEFT CR-UTIB0000115-JINDAL SAW LIMITED-AAYUSH KUMAR GUPTA-AXISCN0231261220 | C15: AXISCN0231261220 | D15: 0 | E15: 57999 | F15: 91617.17 | G15: AXIS | H15: HDFC 5413
A16: 45019 | B16: NET PI TO HSL SEC A/C 2554606-00602340029427 | C16: 0000000399867464 | D16: 387.51 | E16: 0 | F16: 91229.66 | G16: HDFC Securities | H16: HDFC 5413
... A35: 45024 | B35: TO TRANSFER-UPI/DR/309861185569/Raj Rani/SBIN/lalsinghla/UPI-- | C35: TRANSFER TO 4694361162091 | D35: 132 | E35: 0 | F35: 114545.02 | G35: Personal | H35: SBI 1227
A36: 45024 | B36: UPIOUT/309826882296/Q143041833@ybl/Sent via /5311 | D36: 10 | E36: 0 | F36: 19.86 | G36: Personal | H36: FEDERAL 0847
A37: 45025 | B37: TO TRANSFER-UPI/DR/309973408594/JAGDISH/PYTM/7742506388/UPI-- | C37: TRANSFER TO 5098150162096 | D37: 125 | E37: 0 | F37: 114320.02 | G37: Personal | H37: SBI 1227
A38: 45025 | B38: TO TRANSFER-UPI/DR/309994513204/UBER IND/HDFC/uberrides@/charg-- | C38: TRANSFER TO 4897696162090 | D38: 48.52 | E38: 0 | F38: 114271.5 | G38: Transport | H38: SBI 1227
A39: 45026 | B39: NET PI TO HSL SEC A/C 2554606-00602340029427 | C39: 0000000401078570 | D39: 466.16 | E39: 0 | F39: 76703.93 | G39: HDFC Securities | H39: HDFC 5413
A40: 45026 | B40: NET PO FROM HSL A/C 2554606-00602340029427 | C40: 0000000401189359 | D40: 0 | E40: 662.12 | F40: 77366.05 | G40: HDFC Securities | H40: HDFC 5413
A41: 45027 | B41: BY TRANSFER-UPI/CR/310198604104/IRCTC CF/HDFC/irctc.cf@h/UPI R-- | C41: TRANSFER FROM 4897733162090 | D41: 0 | E41: 830 | F41: 115111.5 | G41: Travel | H41: SBI 1227
A42: 45027 | B42: NET PI TO HSL SEC A/C 2554606-00602340029427 | C42: 0000000401415591 | D42: 116.86 | E42: 0 | F42: 77249.19 | G42: HDFC Securities | H42: HDFC 5413
A43: 45027 | B43: NET PO FROM HSL A/C 2554606-00602340029427 | C43: 0000000401522488 | D43: 0 | E43: 334.27 | F43: 77583.46 | G43: HDFC Securities | H43: HDFC 5413
A44: 45027 | B44: BULK POSTING-C23854246658 41774260032INTERIM DIVIDEND ACCOU-- | D44: 0 | E44: 10 | F44: 114281.5 | G44: Dividend Income | H44: SBI 1227
A45: 45028 | B45: TO TRANSFER-UPI/DR/310299085532/billdesk/ICIC/billdesk.p/UPI-- | C45: TRANSFER TO 4897692162094 | D45: 148 | E45: 0 | F45: 114708.5 | G45: Personal | H45: SBI 1227
A46: 45028 | B46: TO TRANSFER-UPI/DR/310298964851/Bharti A/HDFC/airtel.pay/UPITr-- | C46: TRANSFER TO 4897692162094 | D46: 155 | E46: 0 | F46: 114856.5 | G46: Personal | H46: SBI 1227
A47: 45028 | B47: NET PI TO HSL SEC A/C 2554606-00602340029427 | C47: 0000000401746881 | D47: 117.03 | E47: 0 | F47: 77466.43 | G47: HDFC Securities | H47: HDFC 5413
A48: 45028 | B48: TO TRANSFER-UPI/DR/310294768781/S SARGUNAM/YESB/q200088506/UPI-- | C48: TRANSFER TO 4897692162094 | D48: 100 | E48: 0 | F48: 115011.5 | G48: Personal | H48: SBI 1227
A49: 45028 | B49: NET PO FROM HSL A/C 2554606-00602340029427 | C49: 0000000401852472 | D49: 0 | E49: 1340.99 | F49: 78807.42 | G49: HDFC Securities | H49: HDFC 5413
A50: 45029 | B50: DEPOSITORY CHARGES MAR23 - 52812428 | C50: 000000000000000 | D50: 590 | E50: 0 | F50: 78217.42 | G50: Depository Charges | H50: HDFC 5413
A51: 45029 | B51: NET PI TO HSL SEC A/C 2554606-00602340029427 | C51: 0000000402064043 | D51: 117.69 | E51: 0 | F51: 78099.73 | G51: HDFC Securities | H51: HDFC 5413
A52: 45029 | B52: TO TRANSFER-UPI/DR/346932073976/Shankar /PYTM/paytmqr281/UPI-- | C52: TRANSFER TO 4897693162093 | D52: 80 | E52: 0 | F52: 114628.5 | G52: Personal | H52: SBI 1227
A53: 45030 | B53: NET PO FROM HSL A/C 2554606-00602340029427 | C53: 0000000402179298 | D53: 0 | E53: 134.43 | F53: 78234.16 | G53: HDFC Securities | H53: HDFC 5413
A54: 45031 | B54: TO TRANSFER-UPI/DR/310500511889/Fudr/ICIC/fudr.cf@ic/3187 Bli-- | C54: TRANSFER TO 4897695162091 | D54: 220 | E54: 0 | F54: 112849.55 | G54: Personal | H54: SBI 1227
A55: 45031 | B55: TO TRANSFER-UPI/DR/347130328853/BHAWANI /YESB/q385374207/UPI-- | C55: TRANSFER TO 4897695162091 | D55: 50 | E55: 0 | F55: 113069.55 | G55: Personal | H55: SBI 1227
A56: 45031 | B56: TO TRANSFER-UPI/DR/347115434891/PATISSER/PYTM/paytmqr281/UPI-- | C56: TRANSFER TO 4897695162091 | D56: 110 | E56: 0 | F56: 113119.55 | G56: Personal | H56: SBI 1227
... A58: 45031 | B58: 50100542230922-TPT-BORROW FROM AAYUSH-ARCHIT GUPTA | C58: 0000000340652822 | D58: 25000 | E58: 0 | F58: 53234.16 | G58: Archit Gupta | H58: HDFC 5413
A59: 45032 | B59: ATM WDL-ATM CASH 7132 CP JHALAWAR JHALRAPATAN-- | D59: 2000 | E59: 0 | F59: 110849.55 | G59: Cash | H59: SBI 1227
A60: 45033 | B60: NET PAYIN TO BSE MF A/C -57500000389146- FROM A/C -50100128155413- UCC -2554606-57500000389146 | C60: 0000000402366626 | D60: 2500 | E60: 0 | F60: 50734.16 | G60: Investments | H60: HDFC 5413
...

Sheet Bank Summary
A1: All Banks
A2: Aayush Gupta Bank Summary
A3: 01-Apr-2023 to 01-Apr-2024
A5: Narration | B5: Total Credit (₹) | C5: Narration | D5: Total Debit (₹)
A6: Advance Tax | B6: =SUMIFS('For Tally'!D:D, 'For Tally'!F:F, A6) | C6: Advance Tax | D6: =SUMIFS('For Tally'!C:C, 'For Tally'!F:F, C6)
A7: Auto Sweep FD | B7: =SUMIFS('For Tally'!D:D, 'For Tally'!F:F, A7) | C7: Auto Sweep FD | D7: =SUMIFS('For Tally'!C:C, 'For Tally'!F:F, C7)
A8: Bank Charges | B8: =SUMIFS('For Tally'!D:D, 'For Tally'!F:F, A8) | C8: Bank Charges | D8: =SUMIFS('For Tally'!C:C, 'For Tally'!F:F, C8)
A9: Bank Interest | B9: =SUMIFS('For Tally'!D:D, 'For Tally'!F:F, A9) | C9: Bank Interest | D9: =SUMIFS('For Tally'!C:C, 'For Tally'!F:F, C9)
A10: Card Purchase | B10: =SUMIFS('For Tally'!D:D, 'For Tally'!F:F, A10) | C10: Card Purchase | D10: =SUMIFS('For Tally'!C:C, 'For Tally'!F:F, C10)
A11: Cash Withdrawal | B11: =SUMIFS('For Tally'!D:D, 'For Tally'!F:F, A11) | C11: Cash Withdrawal | D11: =SUMIFS('For Tally'!C:C, 'For Tally'!F:F, C11)
A12: Contra - Axis | B12: =SUMIFS('For Tally'!D:D, 'For Tally'!F:F, A12) | C12: Contra - Axis | D12: =SUMIFS('For Tally'!C:C, 'For Tally'!F:F, C12)
A13: Contra - HDFC | B13: =SUMIFS('For Tally'!D:D, 'For Tally'!F:F, A13) | C13: Contra - HDFC | D13: =SUMIFS('For Tally'!C:C, 'For Tally'!F:F, C13)
A14: Contra - Jupiter | B14: =SUMIFS('For Tally'!D:D, 'For Tally'!F:F, A14) | C14: Contra - Jupiter | D14: =SUMIFS('For Tally'!C:C, 'For Tally'!F:F, C14)
A15: Contra - Kotak | B15: =SUMIFS('For Tally'!D:D, 'For Tally'!F:F, A15) | C15: Contra - Kotak | D15: =SUMIFS('For Tally'!C:C, 'For Tally'!F:F, C15)
A16: Contra - Self | B16: =SUMIFS('For Tally'!D:D, 'For Tally'!F:F, A16) | C16: Contra - Self | D16: =SUMIFS('For Tally'!C:C, 'For Tally'!F:F, C16)
A17: Depository Charges | B17: =SUMIFS('For Tally'!D:D, 'For Tally'!F:F, A17) | C17: Depository Charges | D17: =SUMIFS('For Tally'!C:C, 'For Tally'!F:F, C17)
... A75: Zerodha Broking | B75: =SUMIFS('For Tally'!D:D, 'For Tally'!F:F, A75) | C75: Zerodha Broking | D75: =SUMIFS('For Tally'!C:C, 'For Tally'!F:F, C75)
A76: TOTAL | B76: =SUM(B5:B75) | C76: TOTAL | D76: =SUM(D5:D75) | E76: Net | F76: =B76-D76
A78: Opening & Closing Balances
A79: Account | B79: Opening Balance (₹) | C79: Closing Balance (₹)
A80: AXIS | B80: 25508.68 | C80: =B80 + SUMIFS('For Tally'!D:D, 'For Tally'!I:I, A80) - SUMIFS('For Tally'!C:C, 'For Tally'!I:I, A80)
A81: FEDERAL 0847 | B81: 29.86 | C81: =B81 + SUMIFS('For Tally'!D:D, 'For Tally'!I:I, A81) - SUMIFS('For Tally'!C:C, 'For Tally'!I:I, A81)
A82: HDFC 5413 | B82: 83618.17 | C82: =B82 + SUMIFS('For Tally'!D:D, 'For Tally'!I:I, A82) - SUMIFS('For Tally'!C:C, 'For Tally'!I:I, A82)
A83: KOTAK 0333 | B83: 0 | C83: =B83 + SUMIFS('For Tally'!D:D, 'For Tally'!I:I, A83) - SUMIFS('For Tally'!C:C, 'For Tally'!I:I, A83)
A84: SBI 1227 | B84: 124395.27 | C84: =B84 + SUMIFS('For Tally'!D:D, 'For Tally'!I:I, A84) - SUMIFS('For Tally'!C:C, 'For Tally'!I:I, A84)
A86: Confidence Distribution
A87: Band | B87: Count | C87: % of Total
A88: High (≥ 0.85) — Confident | B88: =COUNTIF('For Tally'!G:G, ">=0.85") | C88: =B88/SUM(B88:B90)
A89: Medium (0.60–0.84) — Review | B89: =COUNTIFS('For Tally'!G:G, ">=0.60", 'For Tally'!G:G, "<0.85") | C89: =B89/SUM(B88:B90)
A90: Low (< 0.60) — Needs attention | B90: =COUNTIF('For Tally'!G:G, "<0.60") | C90: =B90/SUM(B88:B90)

Sheet Monthly Pivot
A1: Monthly Spend & Income Pivot
A3: Bank Filter Toggles: | B3: Axis Bank | C3: Federal Bank (Jupiter) | D3: HDFC Bank | E3: Kotak Mahindra Bank | F3: State Bank of India
B4: TRUE | C4: TRUE | D4: TRUE | E4: TRUE | F4: TRUE
B5: =IF(B4, B3, "") | C5: =IF(C4, C3, "") | D5: =IF(D4, D3, "") | E5: =IF(E4, E3, "") | F5: =IF(F4, F3, "")
A7: PAYMENTS / DEBITS (Bank) | B7: Apr-2023 | C7: May-2023 | D7: Jun-2023 | E7: Jul-2023 | F7: Aug-2023 | G7: Sep-2023 | H7: Oct-2023 | I7: Nov-2023 | J7: Dec-2023 | K7: Jan-2024 | L7: Feb-2024 | M7: Mar-2024 | N7: Apr-2024 | O7: TOTAL
A8: AXIS | B8: =SUMPRODUCT(SUMIFS('For Tally'!C:C, 'For Tally'!H:H, $A8, 'For Tally'!A:A, ">=2023-04-01", 'For Tally'!A:A, "<=2023-04-30", 'For Tally'!L:L, $B$5:$F$5)) | C8: =SUMPRODUCT(SUMIFS('For Tally'!C:C, 'For Tally'!H:H, $A8, 'For Tally'!A:A, ">=2023-05-01", 'For Tally'!A:A, "<=2023-05-31", 'For Tally'!L:L, $B$5:$F$5)) | D8: =SUMPRODUCT(SUMIFS('For Tally'!C:C, 'For Tally'!H:H, $A8, 'For Tally'!A:A, ">=2023-06-01", 'For Tally'!A:A, "<=2023-06-30", 'For Tally'!L:L, $B$5:$F$5)) | E8: =SUMPRODUCT(SUMIFS('For Tally'!C:C, 'For Tally'!H:H, $A8, 'For Tally'!A:A, ">=2023-07-01", 'For Tally'!A:A, "<=2023-07-31", 'For Tally'!L:L, $B$5:$F$5)) | F8: =SUMPRODUCT(SUMIFS('For Tally'!C:C, 'For Tally'!H:H, $A8, 'For Tally'!A:A, ">=2023-08-01", 'For Tally'!A:A, "<=2023-08-31", 'For Tally'!L:L, $B$5:$F$5)) | G8: =SUMPRODUCT(SUMIFS('For Tally'!C:C, 'For Tally'!H:H, $A8, 'For Tally'!A:A, ">=2023-09-01", 'For Tally'!A:A, "<=2023-09-30", 'For Tally'!L:L, $B$5:$F$5)) | H8: =SUMPRODUCT(SUMIFS('For Tally'!C:C, 'For Tally'!H:H, $A8, 'For Tally'!A:A, ">=2023-10-01", 'For Tally'!A:A, "<=2023-10-31", 'For Tally'!L:L, $B$5:$F$5)) | I8: =SUMPRODUCT(SUMIFS('For Tally'!C:C, 'For Tally'!H:H, $A8, 'For Tally'!A:A, ">=2023-11-01", 'For Tally'!A:A, "<=2023-11-30", 'For Tally'!L:L, $B$5:$F$5)) | J8: =SUMPRODUCT(SUMIFS('For Tally'!C:C, 'For Tally'!H:H, $A8, 'For Tally'!A:A, ">=2023-12-01", 'For Tally'!A:A, "<=2023-12-31", 'For Tally'!L:L, $B$5:$F$5)) | K8: =SUMPRODUCT(SUMIFS('For Tally'!C:C, 'For Tally'!H:H, $A8, 'For Tally'!A:A, ">=2024-01-01", 'For Tally'!A:A, "<=2024-01-31", 'For Tally'!L:L, $B$5:$F$5)) | L8: =SUMPRODUCT(SUMIFS('For Tally'!C:C, 'For Tally'!H:H, $A8, 'For Tally'!A:A, ">=2024-02-01", 'For Tally'!A:A, "<=2024-02-29", 'For Tally'!L:L, $B$5:$F$5)) | M8: =SUMPRODUCT(SUMIFS('For Tally'!C:C, 'For Tally'!H:H, $A8, 'For Tally'!A:A, ">=2024-03-01", 'For Tally'!A:A, "<=2024-03-31", 'For Tally'!L:L, $B$5:$F$5)) | N8: =SUMPRODUCT(SUMIFS('For Tally'!C:C, 'For Tally'!H:H, $A8, 'For Tally'!A:A, ">=2024-04-01", 'For Tally'!A:A, "<=2024-04-30", 'For Tally'!L:L, $B$5:$F$5)) | O8: =SUM(B8:N8)
A9: Advance Tax | B9: =SUMPRODUCT(SUMIFS('For Tally'!C:C, 'For Tally'!H:H, $A9, 'For Tally'!A:A, ">=2023-04-01", 'For Tally'!A:A, "<=2023-04-30", 'For Tally'!L:L, $B$5:$F$5)) | C9: =SUMPRODUCT(SUMIFS('For Tally'!C:C, 'For Tally'!H:H, $A9, 'For Tally'!A:A, ">=2023-05-01", 'For Tally'!A:A, "<=2023-05-31", 'For Tally'!L:L, $B$5:$F$5)) | D9: =SUMPRODUCT(SUMIFS('For Tally'!C:C, 'For Tally'!H:H, $A9, 'For Tally'!A:A, ">=2023-06-01", 'For Tally'!A:A, "<=2023-06-30", 'For Tally'!L:L, $B$5:$F$5)) | E9: =SUMPRODUCT(SUMIFS('For Tally'!C:C, 'For Tally'!H:H, $A9, 'For Tally'!A:A, ">=2023-07-01", 'For Tally'!A:A, "<=2023-07-31", 'For Tally'!L:L, $B$5:$F$5)) | F9: =SUMPRODUCT(SUMIFS('For Tally'!C:C, 'For Tally'!H:H, $A9, 'For Tally'!A:A, ">=2023-08-01", 'For Tally'!A:A, "<=2023-08-31", 'For Tally'!L:L, $B$5:$F$5)) | G9: =SUMPRODUCT(SUMIFS('For Tally'!C:C, 'For Tally'!H:H, $A9, 'For Tally'!A:A, ">=2023-09-01", 'For Tally'!A:A, "<=2023-09-30", 'For Tally'!L:L, $B$5:$F$5)) | H9: =SUMPRODUCT(SUMIFS('For Tally'!C:C, 'For Tally'!H:H, $A9, 'For Tally'!A:A, ">=2023-10-01", 'For Tally'!A:A, "<=2023-10-31", 'For Tally'!L:L, $B$5:$F$5)) | I9: =SUMPRODUCT(SUMIFS('For Tally'!C:C, 'For Tally'!H:H, $A9, 'For Tally'!A:A, ">=2023-11-01", 'For Tally'!A:A, "<=2023-11-30", 'For Tally'!L:L, $B$5:$F$5)) | J9: =SUMPRODUCT(SUMIFS('For Tally'!C:C, 'For Tally'!H:H, $A9, 'For Tally'!A:A, ">=2023-12-01", 'For Tally'!A:A, "<=2023-12-31", 'For Tally'!L:L, $B$5:$F$5)) | K9: =SUMPRODUCT(SUMIFS('For Tally'!C:C, 'For Tally'!H:H, $A9, 'For Tally'!A:A, ">=2024-01-01", 'For Tally'!A:A, "<=2024-01-31", 'For Tally'!L:L, $B$5:$F$5)) | L9: =SUMPRODUCT(SUMIFS('For Tally'!C:C, 'For Tally'!H:H, $A9, 'For Tally'!A:A, ">=2024-02-01", 'For Tally'!A:A, "<=2024-02-29", 'For Tally'!L:L, $B$5:$F$5)) | M9: =SUMPRODUCT(SUMIFS('For Tally'!C:C, 'For Tally'!H:H, $A9, 'For Tally'!A:A, ">=2024-03-01", 'For Tally'!A:A, "<=2024-03-31", 'For Tally'!L:L, $B$5:$F$5)) | N9: =SUMPRODUCT(SUMIFS('For Tally'!C:C, 'For Tally'!H:H, $A9, 'For Tally'!A:A, ">=2024-04-01", 'For Tally'!A:A, "<=2024-04-30", 'For Tally'!L:L, $B$5:$F$5)) | O9: =SUM(B9:N9)
A10: Ajay Gupta | B10: =SUMPRODUCT(SUMIFS('For Tally'!C:C, 'For Tally'!H:H, $A10, 'For Tally'!A:A, ">=2023-04-01", 'For Tally'!A:A, "<=2023-04-30", 'For Tally'!L:L, $B$5:$F$5)) | C10: =SUMPRODUCT(SUMIFS('For Tally'!C:C, 'For Tally'!H:H, $A10, 'For Tally'!A:A, ">=2023-05-01", 'For Tally'!A:A, "<=2023-05-31", 'For Tally'!L:L, $B$5:$F$5)) | D10: =SUMPRODUCT(SUMIFS('For Tally'!C:C, 'For Tally'!H:H, $A10, 'For Tally'!A:A, ">=2023-06-01", 'For Tally'!A:A, "<=2023-06-30", 'For Tally'!L:L, $B$5:$F$5)) | E10: =SUMPRODUCT(SUMIFS('For Tally'!C:C, 'For Tally'!H:H, $A10, 'For Tally'!A:A, ">=2023-07-01", 'For Tally'!A:A, "<=2023-07-31", 'For Tally'!L:L, $B$5:$F$5)) | F10: =SUMPRODUCT(SUMIFS('For Tally'!C:C, 'For Tally'!H:H, $A10, 'For Tally'!A:A, ">=2023-08-01", 'For Tally'!A:A, "<=2023-08-31", 'For Tally'!L:L, $B$5:$F$5)) | G10: =SUMPRODUCT(SUMIFS('For Tally'!C:C, 'For Tally'!H:H, $A10, 'For Tally'!A:A, ">=2023-09-01", 'For Tally'!A:A, "<=2023-09-30", 'For Tally'!L:L, $B$5:$F$5)) | H10: =SUMPRODUCT(SUMIFS('For Tally'!C:C, 'For Tally'!H:H, $A10, 'For Tally'!A:A, ">=2023-10-01", 'For Tally'!A:A, "<=2023-10-31", 'For Tally'!L:L, $B$5:$F$5)) | I10: =SUMPRODUCT(SUMIFS('For Tally'!C:C, 'For Tally'!H:H, $A10, 'For Tally'!A:A, ">=2023-11-01", 'For Tally'!A:A, "<=2023-11-30", 'For Tally'!L:L, $B$5:$F$5)) | J10: =SUMPRODUCT(SUMIFS('For Tally'!C:C, 'For Tally'!H:H, $A10, 'For Tally'!A:A, ">=2023-12-01", 'For Tally'!A:A, "<=2023-12-31", 'For Tally'!L:L, $B$5:$F$5)) | K10: =SUMPRODUCT(SUMIFS('For Tally'!C:C, 'For Tally'!H:H, $A10, 'For Tally'!A:A, ">=2024-01-01", 'For Tally'!A:A, "<=2024-01-31", 'For Tally'!L:L, $B$5:$F$5)) | L10: =SUMPRODUCT(SUMIFS('For Tally'!C:C, 'For Tally'!H:H, $A10, 'For Tally'!A:A, ">=2024-02-01", 'For Tally'!A:A, "<=2024-02-29", 'For Tally'!L:L, $B$5:$F$5)) | M10: =SUMPRODUCT(SUMIFS('For Tally'!C:C, 'For Tally'!H:H, $A10, 'For Tally'!A:A, ">=2024-03-01", 'For Tally'!A:A, "<=2024-03-31", 'For Tally'!L:L, $B$5:$F$5)) | N10: =SUMPRODUCT(SUMIFS('For Tally'!C:C, 'For Tally'!H:H, $A10, 'For Tally'!A:A, ">=2024-04-01", 'For Tally'!A:A, "<=2024-04-30", 'For Tally'!L:L, $B$5:$F$5)) | O10: =SUM(B10:N10)
A11: Archit Gupta | B11: =SUMPRODUCT(SUMIFS('For Tally'!C:C, 'For Tally'!H:H, $A11, 'For Tally'!A:A, ">=2023-04-01", 'For Tally'!A:A, "<=2023-04-30", 'For Tally'!L:L, $B$5:$F$5)) | C11: =SUMPRODUCT(SUMIFS('For Tally'!C:C, 'For Tally'!H:H, $A11, 'For Tally'!A:A, ">=2023-05-01", 'For Tally'!A:A, "<=2023-05-31", 'For Tally'!L:L, $B$5:$F$5)) | D11: =SUMPRODUCT(SUMIFS('For Tally'!C:C, 'For Tally'!H:H, $A11, 'For Tally'!A:A, ">=2023-06-01", 'For Tally'!A:A, "<=2023-06-30", 'For Tally'!L:L, $B$5:$F$5)) | E11: =SUMPRODUCT(SUMIFS('For Tally'!C:C, 'For Tally'!H:H, $A11, 'For Tally'!A:A, ">=2023-07-01", 'For Tally'!A:A, "<=2023-07-31", 'For Tally'!L:L, $B$5:$F$5)) | F11: =SUMPRODUCT(SUMIFS('For Tally'!C:C, 'For Tally'!H:H, $A11, 'For Tally'!A:A, ">=2023-08-01", 'For Tally'!A:A, "<=2023-08-31", 'For Tally'!L:L, $B$5:$F$5)) | G11: =SUMPRODUCT(SUMIFS('For Tally'!C:C, 'For Tally'!H:H, $A11, 'For Tally'!A:A, ">=2023-09-01", 'For Tally'!A:A, "<=2023-09-30", 'For Tally'!L:L, $B$5:$F$5)) | H11: =SUMPRODUCT(SUMIFS('For Tally'!C:C, 'For Tally'!H:H, $A11, 'For Tally'!A:A, ">=2023-10-01", 'For Tally'!A:A, "<=2023-10-31", 'For Tally'!L:L, $B$5:$F$5)) | I11: =SUMPRODUCT(SUMIFS('For Tally'!C:C, 'For Tally'!H:H, $A11, 'For Tally'!A:A, ">=2023-11-01", 'For Tally'!A:A, "<=2023-11-30", 'For Tally'!L:L, $B$5:$F$5)) | J11: =SUMPRODUCT(SUMIFS('For Tally'!C:C, 'For Tally'!H:H, $A11, 'For Tally'!A:A, ">=2023-12-01", 'For Tally'!A:A, "<=2023-12-31", 'For Tally'!L:L, $B$5:$F$5)) | K11: =SUMPRODUCT(SUMIFS('For Tally'!C:C, 'For Tally'!H:H, $A11, 'For Tally'!A:A, ">=2024-01-01", 'For Tally'!A:A, "<=2024-01-31", 'For Tally'!L:L, $B$5:$F$5)) | L11: =SUMPRODUCT(SUMIFS('For Tally'!C:C, 'For Tally'!H:H, $A11, 'For Tally'!A:A, ">=2024-02-01", 'For Tally'!A:A, "<=2024-02-29", 'For Tally'!L:L, $B$5:$F$5)) | M11: =SUMPRODUCT(SUMIFS('For Tally'!C:C, 'For Tally'!H:H, $A11, 'For Tally'!A:A, ">=2024-03-01", 'For Tally'!A:A, "<=2024-03-31", 'For Tally'!L:L, $B$5:$F$5)) | N11: =SUMPRODUCT(SUMIFS('For Tally'!C:C, 'For Tally'!H:H, $A11, 'For Tally'!A:A, ">=2024-04-01", 'For Tally'!A:A, "<=2024-04-30", 'For Tally'!L:L, $B$5:$F$5)) | O11: =SUM(B11:N11)
A12: Bank Charges | B12: =SUMPRODUCT(SUMIFS('For Tally'!C:C, 'For Tally'!H:H, $A12, 'For Tally'!A:A, ">=2023-04-01", 'For Tally'!A:A, "<=2023-04-30", 'For Tally'!L:L, $B$5:$F$5)) | C12: =SUMPRODUCT(SUMIFS('For Tally'!C:C, 'For Tally'!H:H, $A12, 'For Tally'!A:A, ">=2023-05-01", 'For Tally'!A:A, "<=2023-05-31", 'For Tally'!L:L, $B$5:$F$5)) | D12: =SUMPRODUCT(SUMIFS('For Tally'!C:C, 'For Tally'!H:H, $A12, 'For Tally'!A:A, ">=2023-06-01", 'For Tally'!A:A, "<=2023-06-30", 'For Tally'!L:L, $B$5:$F$5)) | E12: =SUMPRODUCT(SUMIFS('For Tally'!C:C, 'For Tally'!H:H, $A12, 'For Tally'!A:A, ">=2023-07-01", 'For Tally'!A:A, "<=2023-07-31", 'For Tally'!L:L, $B$5:$F$5)) | F12: =SUMPRODUCT(SUMIFS('For Tally'!C:C, 'For Tally'!H:H, $A12, 'For Tally'!A:A, ">=2023-08-01", 'For Tally'!A:A, "<=2023-08-31", 'For Tally'!L:L, $B$5:$F$5)) | G12: =SUMPRODUCT(SUMIFS('For Tally'!C:C, 'For Tally'!H:H, $A12, 'For Tally'!A:A, ">=2023-09-01", 'For Tally'!A:A, "<=2023-09-30", 'For Tally'!L:L, $B$5:$F$5)) | H12: =SUMPRODUCT(SUMIFS('For Tally'!C:C, 'For Tally'!H:H, $A12, 'For Tally'!A:A, ">=2023-10-01", 'For Tally'!A:A, "<=2023-10-31", 'For Tally'!L:L, $B$5:$F$5)) | I12: =SUMPRODUCT(SUMIFS('For Tally'!C:C, 'For Tally'!H:H, $A12, 'For Tally'!A:A, ">=2023-11-01", 'For Tally'!A:A, "<=2023-11-30", 'For Tally'!L:L, $B$5:$F$5)) | J12: =SUMPRODUCT(SUMIFS('For Tally'!C:C, 'For Tally'!H:H, $A12, 'For Tally'!A:A, ">=2023-12-01", 'For Tally'!A:A, "<=2023-12-31", 'For Tally'!L:L, $B$5:$F$5)) | K12: =SUMPRODUCT(SUMIFS('For Tally'!C:C, 'For Tally'!H:H, $A12, 'For Tally'!A:A, ">=2024-01-01", 'For Tally'!A:A, "<=2024-01-31", 'For Tally'!L:L, $B$5:$F$5)) | L12: =SUMPRODUCT(SUMIFS('For Tally'!C:C, 'For Tally'!H:H, $A12, 'For Tally'!A:A, ">=2024-02-01", 'For Tally'!A:A, "<=2024-02-29", 'For Tally'!L:L, $B$5:$F$5)) | M12: =SUMPRODUCT(SUMIFS('For Tally'!C:C, 'For Tally'!H:H, $A12, 'For Tally'!A:A, ">=2024-03-01", 'For Tally'!A:A, "<=2024-03-31", 'For Tally'!L:L, $B$5:$F$5)) | N12: =SUMPRODUCT(SUMIFS('For Tally'!C:C, 'For Tally'!H:H, $A12, 'For Tally'!A:A, ">=2024-04-01", 'For Tally'!A:A, "<=2024-04-30", 'For Tally'!L:L, $B$5:$F$5)) | O12: =SUM(B12:N12)
A13: Cash | B13: =SUMPRODUCT(SUMIFS('For Tally'!C:C, 'For Tally'!H:H, $A13, 'For Tally'!A:A, ">=2023-04-01", 'For Tally'!A:A, "<=2023-04-30", 'For Tally'!L:L, $B$5:$F$5)) | C13: =SUMPRODUCT(SUMIFS('For Tally'!C:C, 'For Tally'!H:H, $A13, 'For Tally'!A:A, ">=2023-05-01", 'For Tally'!A:A, "<=2023-05-31", 'For Tally'!L:L, $B$5:$F$5)) | D13: =SUMPRODUCT(SUMIFS('For Tally'!C:C, 'For Tally'!H:H, $A13, 'For Tally'!A:A, ">=2023-06-01", 'For Tally'!A:A, "<=2023-06-30", 'For Tally'!L:L, $B$5:$F$5)) | E13: =SUMPRODUCT(SUMIFS('For Tally'!C:C, 'For Tally'!H:H, $A13, 'For Tally'!A:A, ">=2023-07-01", 'For Tally'!A:A, "<=2023-07-31", 'For Tally'!L:L, $B$5:$F$5)) | F13: =SUMPRODUCT(SUMIFS('For Tally'!C:C, 'For Tally'!H:H, $A13, 'For Tally'!A:A, ">=2023-08-01", 'For Tally'!A:A, "<=2023-08-31", 'For Tally'!L:L, $B$5:$F$5)) | G13: =SUMPRODUCT(SUMIFS('For Tally'!C:C, 'For Tally'!H:H, $A13, 'For Tally'!A:A, ">=2023-09-01", 'For Tally'!A:A, "<=2023-09-30", 'For Tally'!L:L, $B$5:$F$5)) | H13: =SUMPRODUCT(SUMIFS('For Tally'!C:C, 'For Tally'!H:H, $A13, 'For Tally'!A:A, ">=2023-10-01", 'For Tally'!A:A, "<=2023-10-31", 'For Tally'!L:L, $B$5:$F$5)) | I13: =SUMPRODUCT(SUMIFS('For Tally'!C:C, 'For Tally'!H:H, $A13, 'For Tally'!A:A, ">=2023-11-01", 'For Tally'!A:A, "<=2023-11-30", 'For Tally'!L:L, $B$5:$F$5)) | J13: =SUMPRODUCT(SUMIFS('For Tally'!C:C, 'For Tally'!H:H, $A13, 'For Tally'!A:A, ">=2023-12-01", 'For Tally'!A:A, "<=2023-12-31", 'For Tally'!L:L, $B$5:$F$5)) | K13: =SUMPRODUCT(SUMIFS('For Tally'!C:C, 'For Tally'!H:H, $A13, 'For Tally'!A:A, ">=2024-01-01", 'For Tally'!A:A, "<=2024-01-31", 'For Tally'!L:L, $B$5:$F$5)) | L13: =SUMPRODUCT(SUMIFS('For Tally'!C:C, 'For Tally'!H:H, $A13, 'For Tally'!A:A, ">=2024-02-01", 'For Tally'!A:A, "<=2024-02-29", 'For Tally'!L:L, $B$5:$F$5)) | M13: =SUMPRODUCT(SUMIFS('For Tally'!C:C, 'For Tally'!H:H, $A13, 'For Tally'!A:A, ">=2024-03-01", 'For Tally'!A:A, "<=2024-03-31", 'For Tally'!L:L, $B$5:$F$5)) | N13: =SUMPRODUCT(SUMIFS('For Tally'!C:C, 'For Tally'!H:H, $A13, 'For Tally'!A:A, ">=2024-04-01", 'For Tally'!A:A, "<=2024-04-30", 'For Tally'!L:L, $B$5:$F$5)) | O13: =SUM(B13:N13)
A14: Depository Charges | B14: =SUMPRODUCT(SUMIFS('For Tally'!C:C, 'For Tally'!H:H, $A14, 'For Tally'!A:A, ">=2023-04-01", 'For Tally'!A:A, "<=2023-04-30", 'For Tally'!L:L, $B$5:$F$5)) | C14: =SUMPRODUCT(SUMIFS('For Tally'!C:C, 'For Tally'!H:H, $A14, 'For Tally'!A:A, ">=2023-05-01", 'For Tally'!A:A, "<=2023-05-31", 'For Tally'!L:L, $B$5:$F$5)) | D14: =SUMPRODUCT(SUMIFS('For Tally'!C:C, 'For Tally'!H:H, $A14, 'For Tally'!A:A, ">=2023-06-01", 'For Tally'!A:A, "<=2023-06-30", 'For Tally'!L:L, $B$5:$F$5)) | E14: =SUMPRODUCT(SUMIFS('For Tally'!C:C, 'For Tally'!H:H, $A14, 'For Tally'!A:A, ">=2023-07-01", 'For Tally'!A:A, "<=2023-07-31", 'For Tally'!L:L, $B$5:$F$5)) | F14: =SUMPRODUCT(SUMIFS('For Tally'!C:C, 'For Tally'!H:H, $A14, 'For Tally'!A:A, ">=2023-08-01", 'For Tally'!A:A, "<=2023-08-31", 'For Tally'!L:L, $B$5:$F$5)) | G14: =SUMPRODUCT(SUMIFS('For Tally'!C:C, 'For Tally'!H:H, $A14, 'For Tally'!A:A, ">=2023-09-01", 'For Tally'!A:A, "<=2023-09-30", 'For Tally'!L:L, $B$5:$F$5)) | H14: =SUMPRODUCT(SUMIFS('For Tally'!C:C, 'For Tally'!H:H, $A14, 'For Tally'!A:A, ">=2023-10-01", 'For Tally'!A:A, "<=2023-10-31", 'For Tally'!L:L, $B$5:$F$5)) | I14: =SUMPRODUCT(SUMIFS('For Tally'!C:C, 'For Tally'!H:H, $A14, 'For Tally'!A:A, ">=2023-11-01", 'For Tally'!A:A, "<=2023-11-30", 'For Tally'!L:L, $B$5:$F$5)) | J14: =SUMPRODUCT(SUMIFS('For Tally'!C:C, 'For Tally'!H:H, $A14, 'For Tally'!A:A, ">=2023-12-01", 'For Tally'!A:A, "<=2023-12-31", 'For Tally'!L:L, $B$5:$F$5)) | K14: =SUMPRODUCT(SUMIFS('For Tally'!C:C, 'For Tally'!H:H, $A14, 'For Tally'!A:A, ">=2024-01-01", 'For Tally'!A:A, "<=2024-01-31", 'For Tally'!L:L, $B$5:$F$5)) | L14: =SUMPRODUCT(SUMIFS('For Tally'!C:C, 'For Tally'!H:H, $A14, 'For Tally'!A:A, ">=2024-02-01", 'For Tally'!A:A, "<=2024-02-29", 'For Tally'!L:L, $B$5:$F$5)) | M14: =SUMPRODUCT(SUMIFS('For Tally'!C:C, 'For Tally'!H:H, $A14, 'For Tally'!A:A, ">=2024-03-01", 'For Tally'!A:A, "<=2024-03-31", 'For Tally'!L:L, $B$5:$F$5)) | N14: =SUMPRODUCT(SUMIFS('For Tally'!C:C, 'For Tally'!H:H, $A14, 'For Tally'!A:A, ">=2024-04-01", 'For Tally'!A:A, "<=2024-04-30", 'For Tally'!L:L, $B$5:$F$5)) | O14: =SUM(B14:N14)
A15: FEDERAL 0847 | B15: =SUMPRODUCT(SUMIFS('For Tally'!C:C, 'For Tally'!H:H, $A15, 'For Tally'!A:A, ">=2023-04-01", 'For Tally'!A:A, "<=2023-04-30", 'For Tally'!L:L, $B$5:$F$5)) | C15: =SUMPRODUCT(SUMIFS('For Tally'!C:C, 'For Tally'!H:H, $A15, 'For Tally'!A:A, ">=2023-05-01", 'For Tally'!A:A, "<=2023-05-31", 'For Tally'!L:L, $B$5:$F$5)) | D15: =SUMPRODUCT(SUMIFS('For Tally'!C:C, 'For Tally'!H:H, $A15, 'For Tally'!A:A, ">=2023-06-01", 'For Tally'!A:A, "<=2023-06-30", 'For Tally'!L:L, $B$5:$F$5)) | E15: =SUMPRODUCT(SUMIFS('For Tally'!C:C, 'For Tally'!H:H, $A15, 'For Tally'!A:A, ">=2023-07-01", 'For Tally'!A:A, "<=2023-07-31", 'For Tally'!L:L, $B$5:$F$5)) | F15: =SUMPRODUCT(SUMIFS('For Tally'!C:C, 'For Tally'!H:H, $A15, 'For Tally'!A:A, ">=2023-08-01", 'For Tally'!A:A, "<=2023-08-31", 'For Tally'!L:L, $B$5:$F$5)) | G15: =SUMPRODUCT(SUMIFS('For Tally'!C:C, 'For Tally'!H:H, $A15, 'For Tally'!A:A, ">=2023-09-01", 'For Tally'!A:A, "<=2023-09-30", 'For Tally'!L:L, $B$5:$F$5)) | H15: =SUMPRODUCT(SUMIFS('For Tally'!C:C, 'For Tally'!H:H, $A15, 'For Tally'!A:A, ">=2023-10-01", 'For Tally'!A:A, "<=2023-10-31", 'For Tally'!L:L, $B$5:$F$5)) | I15: =SUMPRODUCT(SUMIFS('For Tally'!C:C, 'For Tally'!H:H, $A15, 'For Tally'!A:A, ">=2023-11-01", 'For Tally'!A:A, "<=2023-11-30", 'For Tally'!L:L, $B$5:$F$5)) | J15: =SUMPRODUCT(SUMIFS('For Tally'!C:C, 'For Tally'!H:H, $A15, 'For Tally'!A:A, ">=2023-12-01", 'For Tally'!A:A, "<=2023-12-31", 'For Tally'!L:L, $B$5:$F$5)) | K15: =SUMPRODUCT(SUMIFS('For Tally'!C:C, 'For Tally'!H:H, $A15, 'For Tally'!A:A, ">=2024-01-01", 'For Tally'!A:A, "<=2024-01-31", 'For Tally'!L:L, $B$5:$F$5)) | L15: =SUMPRODUCT(SUMIFS('For Tally'!C:C, 'For Tally'!H:H, $A15, 'For Tally'!A:A, ">=2024-02-01", 'For Tally'!A:A, "<=2024-02-29", 'For Tally'!L:L, $B$5:$F$5)) | M15: =SUMPRODUCT(SUMIFS('For Tally'!C:C, 'For Tally'!H:H, $A15, 'For Tally'!A:A, ">=2024-03-01", 'For Tally'!A:A, "<=2024-03-31", 'For Tally'!L:L, $B$5:$F$5)) | N15: =SUMPRODUCT(SUMIFS('For Tally'!C:C, 'For Tally'!H:H, $A15, 'For Tally'!A:A, ">=2024-04-01", 'For Tally'!A:A, "<=2024-04-30", 'For Tally'!L:L, $B$5:$F$5)) | O15: =SUM(B15:N15)
