Workbook

Sheet HDFC
A1: HDFC BANK Ltd. Page No .: 1 Statement of accounts
E5: Account Branch :NASHIK ROAD
A6: MR. AAYUSH KUMAR GUPTA | E6: Address :SHOP NO 3,
A7: FLAT NO-D-07 ISHWAR PARADISE | E7: MITHILA APARTMENTS,
A8: ASHOKA MARG BEHIND FAME | E8: BYTCO POINT,NASHIK ROAD
A9: THEATRE ASHOKA MARG,NASHIK | E9: City :NASHIK
A10: NASHIK 422011 | E10: State :MAHARASHTRA
E11: Phone no. :18002026161
E12: Email :
A13: JOINT HOLDERS : | E13: OD Limit :0 Currency :INR
E14: Cust ID :65298402
A15: Nomination : Registered | E15: Account No :50100128155413 VRM POTENTIAL
A16: Statement From : 01/04/2024 To : 30/06/2024 | E16: A/C Open Date :08/10/2015
E17: Account Status :Regular
E18: RTGS/NEFT IFSC :HDFC0000456 MICR :422240003
E19: =SUBTOTAL(9,E21:E638) -> 1959345.1 | F19: =SUBTOTAL(9,F21:F638) -> 1945074.6
A20: Date | B20: Narration | C20: Chq./Ref.No. | D20: Value Dt | E20: Withdrawal Amt. | F20: Deposit Amt. | G20: Closing Balance | H20: Narration
A21: 45383 | B21: NET PI TO HSL SEC A/C 2554606-00602340029427 | C21: 0000000508915817 | D21: 45383 | E21: 686.24 | F21: 0 | G21: 42364.65 | H21: HSL
A22: 45383 | B22: ACH D- TP ACH INDIANESIGN-1400211801 | C22: 0000002398408108 | D22: 45383 | E22: 5000 | F22: 0 | G22: 37364.65 | H22: SIP - 5000
A23: 45384 | B23: NET PO FROM HSL A/C 2554606-50200085415108 | C23: 0000000509173908 | D23: 45384 | E23: 0 | F23: 4127.9 | G23: 41492.55 | H23: HSL
A24: 45384 | B24: NET PI TO HSL SEC A/C 2554606-00602340029427 | C24: 0000000509391641 | D24: 45384 | E24: 171.56 | F24: 0 | G24: 41320.99 | H24: HSL
A25: 45384 | B25: NET PI TO HSL SEC A/C 2554606-00602340029427 | C25: 0000000509532271 | D25: 45384 | E25: 10704.09 | F25: 0 | G25: 30616.9 | H25: HSL
A26: 45385 | B26: NET PI TO HSL SEC A/C 2554606-00602340029427 | C26: 0000000509775384 | D26: 45385 | E26: 158.35 | F26: 0 | G26: 30458.55 | H26: HSL
A27: 45386 | B27: NET PO FROM HSL A/C 2554606-50200085415108 | C27: 0000000510047305 | D27: 45386 | E27: 0 | F27: 11625.48 | G27: 42084.03 | H27: HSL
A28: 45386 | B28: 01671000060094-TPT-TO MUMMY-SUNITA GUPTA | C28: 0000000526007002 | D28: 45386 | E28: 30000 | F28: 0 | G28: 12084.03 | H28: Transfer to Sunita
A29: 45386 | B29: NET PI TO HSL SEC A/C 2554606-00602340029427 | C29: 0000000510173633 | D29: 45386 | E29: 158.35 | F29: 0 | G29: 11925.68 | H29: HSL
A30: 45387 | B30: NET PO FROM HSL A/C 2554606-50200085415108 | C30: 0000000510453600 | D30: 45387 | E30: 0 | F30: 2099.75 | G30: 14025.43 | H30: HSL
A31: 45387 | B31: NET PI TO HSL SEC A/C 2554606-00602340029427 | C31: 0000000510596622 | D31: 45387 | E31: 154.71 | F31: 0 | G31: 13870.72 | H31: HSL
A32: 45387 | B32: DEPOSITORY CHARGES MAR24 - 52812428 | C32: 000000000000000 | D32: 45387 | E32: 585.49 | F32: 0 | G32: 13285.23 | H32: Depository Charges
... A638: 45745 | B638: ISAQMC-JUL-SEP24-417944 070325-MIR2508871584497 | C638: MIR2508871584497 | D638: 45745 | E638: 295 | F638: 0 | G638: 28780.48 | H638: Bank Charges

Sheet AXIS
A1: Name :- AAYUSH KUMAR GUPTA
A2: Joint Holder :- -
A3: AJAY KUMAR GUPTA
A4: FLAT NO - D-07 ISHWAR PARADISE
A5: NASHIK-422011
A6: MAHARASHTRA-INDIA
A7: Customer ID :- 857324165
A8: IFSC Code :- UTIB0002656
A9: MICR Code :- 422211010
A10: Nominee Registered :- Y
A11: Registered Mobile No :- XXXXXX5259
A12: Registered Email ID :-
... A15: Statement of Account No - 915010020334307 for the period (From : 01-04-2024 To : 30-06-2024)
A17: SRL NO | B17: Tran Date | C17: CHQNO | D17: PARTICULARS | E17: DR | F17: CR | G17: BAL | H17: Narration
A18: 1 | B18: 45403 | C18: - | D18: SMS Alerts Chrgs Incl GST | E18: 1.18 | F18: 0 | G18: 16846.03 | H18: Bank Charges
A19: 2 | B19: 45474 | C19: - | D19: SB:915010020334307:Int.Pd:01-04-2024 to 30-06-2024 | E19: 0 | F19: 126 | G19: 16972.03 | H19: Bank Interest
A20: 3 | B20: 45566 | C20: - | D20: SB:915010020334307:Int.Pd:01-07-2024 to 30-09-2024 | E20: 0 | F20: 128 | G20: 17100.03 | H20: Bank Interest
A21: 4 | B21: 45658 | C21: - | D21: SB:915010020334307:Int.Pd:01-10-2024 to 31-12-2024 | E21: 0 | F21: 129 | G21: 17229.03 | H21: Bank Interest
A22: 5 | B22: 45747 | C22: - | D22: SB:915010020334307:Int.Pd:01-01-2025 to 31-03-2025 | E22: 0 | F22: 127 | G22: 17356.03 | H22: Bank Interest

Sheet SBI
A1: Account Name : | B1: Mr. AAYUSH KUMAR GUPTA
A2: Address : | B2: FLAT NO D 07 ISHWAR PARADISE ASHOKA
B3: MARG BEHIND FAME THEATRE ASHOKA MARG
B4: NASHIK-422011
B5: Nashik
A6: Date : | B6: 45478
A7: Account Number : | B7: _00000020276981227
A8: Account Description: | B8: REGULAR SB CHQ-INDIVIDUALS
A9: Branch : | B9: SHIVAJI NAGAR, NASIK
A10: Drawing Power : | B10: 0
A11: Interest Rate(% p.a.): | B11: 2.7
A12: MOD Balance : | B12: 0
A13: CIF No. : | B13: _88071759834
A14: IFS (Indian Financial System) Code : | B14: SBIN0011669
A15: MICR (Magnetic Ink Character Recognition) Code : | B15: _422002020
A16: Nomination Registered : | B16: Yes
A17: Balance on 1 Apr 2024 : | B17: 52605.78
A18: Start Date : | B18: 45383
A19: End Date : | B19: 45473 | E19: =SUBTOTAL(9,E21:E1048576) -> 219755.55 | F19: =SUBTOTAL(9,F21:F1048576) -> 178135.8
A20: Txn Date | B20: Value Date | C20: Description | D20: Ref No./Cheque No. | E20: Debit | F20: Credit | G20: Balance | H20: Narration
A21: 45383 | B21: 45383 | C21: TO TRANSFER-UPI/DR/409241614305/NELABALL/UTIB/alphalivin/UPI-- | D21: TRANSFER TO 4897690162095 | E21: 15000 | F21: 0 | G21: 37605.78 | H21: Rent
A22: 45384 | B22: 45384 | C22: BY TRANSFER-UPI/CR/409308961216/AAYUSH K/KKBK/9594435259/MB UP-- | D22: TRANSFER FROM 4897733162090 | E22: 0 | F22: 32394.22 | G22: 70000 | H22: Contra - KOTAK
A23: 45384 | B23: 45384 | C23: BY TRANSFER-UPI/CR/409364666330/ADARSH N/HDFC/adusma02-1/UPI-- | D23: TRANSFER FROM 4897733162090 | E23: 0 | F23: 590 | G23: 70590 | H23: Personal
A24: 45384 | B24: 45384 | C24: BY TRANSFER-UPI/CR/409364703330/K PRAMOD/HDFC/kpramodkri/UPI-- | D24: TRANSFER FROM 4897733162090 | E24: 0 | F24: 590 | G24: 71180 | H24: Personal
A25: 45384 | B25: 45384 | C25: BY TRANSFER-UPI/CR/445977564613/ADARSH K M/UTIB/coorgadars/Pay-- | D25: TRANSFER FROM 4897733162090 | E25: 0 | F25: 590 | G25: 71770 | H25: Personal
A26: 45384 | B26: 45384 | C26: BY TRANSFER-UPI/CR/445927539114/MONISH K/ICIC/8296488092/Payme-- | D26: TRANSFER FROM 4897733162090 | E26: 0 | F26: 590 | G26: 72360 | H26: Personal
A27: 45384 | B27: 45384 | C27: BY TRANSFER-UPI/CR/409341661367/SHASHANK/HDFC/9880498899/Sent-- | D27: TRANSFER FROM 4897733162090 | E27: 0 | F27: 590 | G27: 72950 | H27: Personal
A28: 45388 | B28: 45388 | C28: BY TRANSFER-NEFT*YESB0000001*YESB40973500546*ZERODHA BROKING L-- | D28: TRANSFER FROM 4697175044306 | E28: 0 | F28: 11.5 | G28: 72961.5 | H28: Zerodha
A29: 45389 | B29: 45389 | C29: TO TRANSFER-UPI/DR/409845869033/Ajithkumar/KKBK/6383724961/Sen-- | D29: TRANSFER TO 4897696162090 | E29: 58 | F29: 0 | G29: 72903.5 | H29: Personal
A30: 45392 | B30: 45392 | C30: BY TRANSFER-UPI/CR/446766838451/MOHANA P/KKBK/7904299233/Payme-- | D30: TRANSFER FROM 4897734162099 | E30: 0 | F30: 100 | G30: 73003.5 | H30: Personal
A31: 45397 | B31: 45397 | C31: TO TRANSFER-UPI/DR/410617540948/ARCHIT G/UTIB/archit4801/UPI-- | D31: TRANSFER TO 4897690162095 | E31: 21000 | F31: 0 | G31: 52003.5 | H31: Transfer to Archit
A32: 45405 | B32: 45405 | C32: BY TRANSFER-UPI/CR/411456275014/AAYUSH K/FDRL/9594435259/Sent-- | D32: TRANSFER FROM 4897733162090 | E32: 0 | F32: 1950.19 | G32: 53953.69 | H32: Contra - Jupiter
... A141: 45741 | B141: 45741 | C141: CREDIT INTEREST--- | D141: - | E141: 0 | F141: 230 | G141: 10986.03 | H141: Bank Interest

Sheet FEDERAL
A1: Name | B1: AAYUSH KUMAR GUPTA | D1: Branch Name | E1: Neo Banking- Jupiter
A2: Communication Address | B2: D-07 Ishwar Paradise Ashoka Marg | D2: Branch Sol ID | E2: 7777
B3: Nashik, Behind Fame Theatre,, | D3: Account Number | E3: 77770101840847
B4: Nasik, Maharashtra, India-422006 | D4: Customer ID | E4: 135342130
A5: Address Last Updated On | B5: 28/10/2021 | D5: Account Open Date | E5: 28/10/2021
A6: Regd. Mobile Number | B6: 919594435259 | D6: Account Status | E6: Closed
A7: Email ID | B7: aayushp4396@gmail.com | D7: Mode of Operation | E7: Single
A8: Type of Account | B8: Savings | D8: Joint Holders | E8: NIL
A9: Scheme | B9: SALARY-7777
A10: IFSC | B10: FDRL0007777
A11: MICR Code | B11: 682049069 | D11: Nomination | E11: Registered
A12: SWIFT Code | B12: FDRLINBBIBD | D12: Currency | E12: INR
A13: Opening Balance | B13: 771.09 | D13: Date of Issue | E13: 09/07/2024
A14: Available Balance | B14: 0
A17: Statement of Account for the period 01/04/2024 to 30/06/2024
G18: =SUBTOTAL(9,G20:G67) -> 14370.09 | H18: =SUBTOTAL(9,H20:H67) -> 13599
A19: Date | B19: Value Date | C19: Particulars | D19: Tran Type | E19: Tran ID | F19: Cheque Details | G19: Withdrawals | H19: Deposits | I19: Balance | J19: Dr/ Cr | K19: Narration
A20: 45384 | B20: 45384 | C20: UPIOUT/409397404482/ paytmqr1dvntqhgaz@ paytm//5462 | D20: TFR | E20: S42025165 | G20: 13 | H20: 0 | I20: 758.09 | J20: CR | K20: UPI
A21: 45384 | B21: 45384 | C21: UPIOUT/409339830970/ gokhana.payu@indus/ UPIIn/7311 | D21: TFR | E21: S48246883 | G21: 99 | H21: 0 | I21: 659.09 | J21: CR | K21: UPI
A22: 45384 | B22: 45384 | C22: UPIOUT/409311132507/ payzomato@hdfcbank/Sent /5814 | D22: TFR | E22: S53198210 | G22: 175 | H22: 0 | I22: 484.09 | J22: CR | K22: UPI - ZOMATO
A23: 45384 | B23: 45384 | C23: UPI IN/409319949339/9594435259 @kotak/MB UPI/0000 | D23: TFR | E23: S56152098 | G23: 0 | H23: 5000 | I23: 5484.09 | J23: CR | K23: Contra - Kotak
A24: 45384 | B24: 45384 | C24: UPIOUT/409312264752/ ashokanknk1985@okicici/S/0000 | D24: TFR | E24: S57936746 | G24: 126 | H24: 0 | I24: 5358.09 | J24: CR | K24: UPI
A25: 45384 | B25: 45384 | C25: UPIOUT/409313107361/ zomatoltd9.rzp@mairtel/P/5811 | D25: TFR | E25: S60780275 | G25: 3366.53 | H25: 0 | I25: 1991.56 | J25: CR | K25: UPI - ZOMATO
A26: 45384 | B26: 45384 | C26: UPIOUT/409313529213/rapido. rzp@icici/Payment/4121 | D26: TFR | E26: S62094747 | G26: 62 | H26: 0 | I26: 1929.56 | J26: CR | K26: UPI
A27: 45385 | B27: 45385 | C27: UPIOUT/409418186188/ Q651974618@ybl/Sent via /5814 | D27: TFR | E27: S74184665 | G27: 20 | H27: 0 | I27: 1909.56 | J27: CR | K27: UPI
A28: 45385 | B28: 45385 | C28: UPI REFUND RRC 409145904712 | D28: TFR | E28: S80138282 | G28: 0 | H28: 399 | I28: 2308.56 | J28: CR | K28: UPI
A29: 45385 | B29: 45385 | C29: UPIOUT/409420241196/ paytmqr3zacjjhvyp@paytm//5462 | D29: TFR | E29: S82129552 | G29: 25 | H29: 0 | I29: 2283.56 | J29: CR | K29: UPI
A30: 45386 | B30: 45386 | C30: UPIOUT/409524533570/ zomatoltd9.rzp@mairtel/P/5811 | D30: TFR | E30: S91955315 | G30: 50 | H30: 0 | I30: 2233.56 | J30: CR | K30: UPI - ZOMATO
A31: 45386 | B31: 45386 | C31: UPI IN/409518581802/9594435259 @kotak/MB UPI/0000 | D31: TFR | E31: S784361 | G31: 0 | H31: 2000 | I31: 4233.56 | J31: CR | K31: Contra - Kotak
... A54: 45395 | B54: 45395 | C54: UPI IN/410480092425/9594435259 @jupiteraxis/A/0000 | D54: TFR | E54: S91664392 | G54: 0 | H54: 15 | I54: 2000.19 | J54: CR | K54: Contra - KOTAK
A55: 45397 | B55: 45397 | C55: NFT/ NEOSIEXEDDD2024041502302 824034 Mirae Asset Mut | D55: FT | E55: S35382625 | F55: FBBT24106459 4566 | G55: 2000 | H55: 0 | I55: 0.19 | J55: CR | K55: Mutual Fund
A56: 45398 | B56: 45398 | C56: UPI IN/410798005765/9594435259 @jupiteraxis/A/0000 | D56: TFR | E56: S57451820 | G56: 0 | H56: 2000 | I56: 2000.19 | J56: CR | K56: Contra - Kotak
A57: 45400 | B57: 45400 | C57: UPIOUT/410920147275/ paytmqr1gs01dt6zx@ paytm//5812 | D57: TFR | E57: S3274235 | G57: 50 | H57: 0 | I57: 1950.19 | J57: CR | K57: UPI
A58: 45405 | B58: 45405 | C58: UPIOUT/411456275014/ aayush20gupta@oksbi/ Sent/0000 | D58: TFR | E58: S13736210 | G58: 1950.19 | H58: 0 | I58: 0 | J58: CR | K58: Contra - SBI
A59: 45429 | B59: 45429 | C59: IFN/ INBINBFT20240517063209434 Jupiter Rewards | D59: TFR | E59: S46271576 | G59: 0 | H59: 180 | I59: 180 | J59: CR | K59: UPI
A60: 45429 | B60: 45429 | C60: UPIOUT/413856144623/959443 5259@jupiteraxis/S/0000 | D60: TFR | E60: S46287656 | G60: 180 | H60: 0 | I60: 0 | J60: CR | K60: Contra - Kotak
A61: 45429 | B61: 45429 | C61: IFN/arMpXLmvgPlEKLWZ Withdraw from Interest Pot | D61: TFR | E61: S46768518 | G61: 0 | H61: 1 | I61: 1 | J61: CR | K61: Misc
A62: 45429 | B62: 45429 | C62: UPIOUT/413856342655/959443 5259@jupiteraxis/S/0000 | D62: TFR | E62: S46910638 | G62: 1 | H62: 0 | I62: 0 | J62: CR | K62: Contra - Kotak
A63: 45429 | B63: 45429 | C63: NFT/NAVI REDEMPTION/ N138243045353376/HDFC | D63: FT | E63: S56349530 | F63: N138243045353 376 | G63: 0 | H63: 1000 | I63: 1000 | J63: CR | K63: Redemption
A64: 45429 | B64: 45429 | C64: UPIOUT/413859249444/959443 5259@jupiteraxis/S/0000 | D64: TFR | E64: S57205993 | G64: 1000 | H64: 0 | I64: 0 | J64: CR | K64: Contra - Kotak
...

Sheet KOTAK
C1: Account Statement
A2: AAYUSH KUMAR GUPTA
A3: 2 nd floor survey no 20 7 | E3: Cust. Reln. No. | F3: 836844778
A4: Swamy legato | E4: Account No. | F4: 3649610333
A5: Kadubisanahalli | E5: Period | F5: From 01/04/2024 To 30/06/2024
A6: Bengaluru | E6: Currency | F6: INR
A7: Karnataka | E7: Branch | F7: Bangalore - Bellandur
A8: India | E8: Nomination Regd | F8: N
A9: 560103 | E9: Nominee Name
E10: Joint Holder(S)
E11: IFSC | F11: KKBK0008122
E12: MICR | F12: 560485104
J13: =SUBTOTAL(9,J15:J1048576) -> 1030939.5 | K13: =SUBTOTAL(9,K15:K1048576) -> 972950.66
A14: Sl. No. | B14: Transaction Date | C14: Value Date | D14: Description | E14: Chq / Ref No. | F14: Amount | G14: Dr / Cr | H14: Balance | I14: Dr / Cr | J14: DR | K14: CR | L14: 59722.01 | M14: Narration
A15: 1 | B15: 45384 | C15: 45384 | D15: UPI/AAYUSH KUMAR GU/409308961216/MB UPI | E15: UPI-409309998911 | F15: 32394.22 | G15: DR | H15: 27327.79 | I15: CR | J15: 32394.22 | K15: 0 | L15: =L14-J15+K15 -> 27327.79 | M15: Contra - SBI
A16: 2 | B16: 45384 | C16: 45384 | D16: UPI/AAYUSH KUMAR GU/409319949339/MB UPI | E16: UPI-409337383180 | F16: 5000 | G16: DR | H16: 22327.79 | I16: CR | J16: 5000 | K16: 0 | L16: =L15-J16+K16 -> 22327.79 | M16: Contra - Jupiter
A17: 3 | B17: 45386 | C17: 45386 | D17: UPI/AAYUSH KUMAR GU/409518581802/MB UPI | E17: UPI-409528776615 | F17: 2000 | G17: DR | H17: 20327.79 | I17: CR | J17: 2000 | K17: 0 | L17: =L16-J17+K17 -> 20327.79 | M17: Contra - Jupiter
A18: 4 | B18: 45389 | C18: 45389 | D18: UPI/AAYUSH KUMAR GU/409860235500/UPI | E18: UPI-409862899692 | F18: 1000 | G18: DR | H18: 19327.79 | I18: CR | J18: 1000 | K18: 0 | L18: =L17-J18+K18 -> 19327.79 | M18: Contra - Jupiter
A19: 5 | B19: 45390 | C19: 45390 | D19: UPI/Setu BrokenTusk/409900283744/Account Verific | E19: UPI-409982397887 | F19: 1 | G19: DR | H19: 19326.79 | I19: CR | J19: 1 | K19: 0 | L19: =L18-J19+K19 -> 19326.79 | M19: UPI
A20: 6 | B20: 45391 | C20: 45391 | D20: UPI/AAYUSH KUMAR GU/410013514219/UPI | E20: UPI-410032312885 | F20: 2000 | G20: DR | H20: 17326.79 | I20: CR | J20: 2000 | K20: 0 | L20: =L19-J20+K20 -> 17326.79 | M20: Contra - Jupiter
A21: 7 | B21: 45392 | C21: 45392 | D21: UPI_CRADJ_U2_TDT_080424_409900283744_10APR2024_7C | E21: FOS2410116195698 | F21: 1 | G21: CR | H21: 17327.79 | I21: CR | J21: 0 | K21: 1 | L21: =L20-J21+K21 -> 17327.79 | M21: UPI
A22: 8 | B22: 45394 | C22: 45394 | D22: UPI/Zerodha Broking/410380501907/448310154506035 | E22: UPI-410368028369 | F22: 10000 | G22: DR | H22: 7327.79 | I22: CR | J22: 10000 | K22: 0 | L22: =L21-J22+K22 -> 7327.79 | M22: Zerodha
A23: 9 | B23: 45394 | C23: 45394 | D23: REV-UPI/Zerodha Broki/410380501907/ | E23: UPI-410368028369 | F23: 10000 | G23: CR | H23: 17327.79 | I23: CR | J23: 0 | K23: 10000 | L23: =L22-J23+K23 -> 17327.79 | M23: Zerodha
A24: 10 | B24: 45394 | C24: 45394 | D24: Recd:IMPS/410309449048/ZERODHA BR/KKBK/X3413/IMPS | E24: IMPS-410309546274 | F24: 1 | G24: CR | H24: 17328.79 | I24: CR | J24: 0 | K24: 1 | L24: =L23-J24+K24 -> 17328.79 | M24: Zerodha
A25: 11 | B25: 45394 | C25: 45394 | D25: UPI/Zerodha/410384058067/141141334036312 | E25: UPI-410370728449 | F25: 1000 | G25: DR | H25: 16328.79 | I25: CR | J25: 1000 | K25: 0 | L25: =L24-J25+K25 -> 16328.79 | M25: Zerodha
A26: 12 | B26: 45394 | C26: 45394 | D26: UPI/CHINNA SWAMY R/410353464865/UPI | E26: UPI-410383081066 | F26: 106 | G26: DR | H26: 16222.79 | I26: CR | J26: 106 | K26: 0 | L26: =L25-J26+K26 -> 16222.79 | M26: UPI
... A92: 78 | B92: 45442 | C92: 45442 | D92: UPI/DIGVIJAY/415148486279/Pay to BharatPe | E92: UPI-415104493020 | F92: 30 | G92: DR | H92: 53710.64 | I92: CR | J92: 30 | K92: 0 | L92: =L91-J92+K92 -> 53710.64 | M92: UPI
A93: 79 | B93: 45442 | C93: 45442 | D93: ATL/4395/504433/+OUTER RING ROADBENGAL300524/22:26 | E93: 415122000000 | F93: 3000 | G93: DR | H93: 50710.64 | I93: CR | J93: 3000 | K93: 0 | L93: =L92-J93+K93 -> 50710.64 | M93: What is this?
A94: 80 | B94: 45442 | C94: 45442 | D94: UPI/M BHOOPAL/415186393331/UPI | E94: UPI-415109283089 | F94: 280 | G94: DR | H94: 50430.64 | I94: CR | J94: 280 | K94: 0 | L94: =L93-J94+K94 -> 50430.64 | M94: UPI
A95: 81 | B95: 45443 | C95: 45443 | D95: UPI/ANANDA PAVABA D/415227527561/UPI | E95: UPI-415219357268 | F95: 15 | G95: DR | H95: 50415.64 | I95: CR | J95: 15 | K95: 0 | L95: =L94-J95+K95 -> 50415.64 | M95: UPI
A96: 82 | B96: 45444 | C96: 45444 | D96: UPI/MANGAL BABAN CH/415308665779/UPI | E96: UPI-415371787163 | F96: 60 | G96: DR | H96: 50355.64 | I96: CR | J96: 60 | K96: 0 | L96: =L95-J96+K96 -> 50355.64 | M96: UPI
A97: 83 | B97: 45445 | C97: 45445 | D97: UPI/HOTEL KRISHNA R/415435780407/hotel booking | E97: UPI-415420220440 | F97: 500 | G97: DR | H97: 49855.64 | I97: CR | J97: 500 | K97: 0 | L97: =L96-J97+K97 -> 49855.64 | M97: UPI
A98: 84 | B98: 45445 | C98: 45445 | D98: UPI/HOTEL KRISHNA R/415453362758/hotel booking | E98: UPI-415436002435 | F98: 1300 | G98: DR | H98: 48555.64 | I98: CR | J98: 1300 | K98: 0 | L98: =L97-J98+K98 -> 48555.64 | M98: UPI
A99: 85 | B99: 45446 | C99: 45446 | D99: UPI/ANIL KUMAR BHAW/415599585093/UPI | E99: UPI-415574615483 | F99: 40 | G99: DR | H99: 48515.64 | I99: CR | J99: 40 | K99: 0 | L99: =L98-J99+K99 -> 48515.64 | M99: UPI
A100: 86 | B100: 45446 | C100: 45446 | D100: REV-UPI/ANIL KUMAR BH/415599585093/ | E100: UPI-415574615483 | F100: 40 | G100: CR | H100: 48555.64 | I100: CR | J100: 0 | K100: 40 | L100: =L99-J100+K100 -> 48555.64 | M100: UPI
A101: 87 | B101: 45447 | C101: 45447 | D101: UPI/Axis/415600362923/payment on CRED | E101: UPI-415686691395 | F101: 6931.19 | G101: DR | H101: 41624.45 | I101: CR | J101: 6931.19 | K101: 0 | L101: =L100-J101+K101 -> 41624.45 | M101: UPI
A102: 88 | B102: 45447 | C102: 45447 | D102: NEFT FDRLH24156013040 CURRENT ACCOUNT GENERAL FDR | E102: NEFTINW-0872796286 | F102: 4 | G102: CR | H102: 41628.45 | I102: CR | J102: 0 | K102: 4 | L102: =L101-J102+K102 -> 41628.45 | M102: Contra - Jupiter
A103: 89 | B103: 45452 | C103: 45452 | D103: UPI/IRCTC CF/416156140207/IRCTC TICKET BO | E103: UPI-416111378415 | F103: 142.25 | G103: DR | H103: 41486.2 | I103: CR | J103: 142.25 | K103: 0 | L103: =L102-J103+K103 -> 41486.2 | M103: UPI
A104: 90 | B104: 45453 | C104: 45453 | D104: NACH-MUT-DR-INDIAN CLEARING CORP-P33751105X081016 | E104: NACHDR10062400228046 | F104: 5000 | G104: DR | H104: 36486.2 | I104: CR | J104: 5000 | K104: 0 | L104: =L103-J104+K104 -> 36486.2 | M104: SIP?
A105: 91 | B105: 45455 | C105: 45455 | D105: UPI/AAYUSH KUMAR GU/416418674665/UPI | E105: UPI-416439248587 | F105: 1 | G105: CR | H105: 36487.2 | I105: CR | J105: 0 | K105: 1 | L105: =L104-J105+K105 -> 36487.2 | M105: Contra - SBI
...

Sheet SBM Bank
A1: AAYUSH KUMAR GUPTA | D1: Customer ID : R003428697
A2: Statement from 01-04-2024 To 31-03-2025 | D2: MICR Code : 110332002
A3: Savings Account No.: 20052205306441
A4: IFSC Code : STCB0000065
A6: Date | B6: Particulars | C6: Cheque Details | D6: Withdrawals | E6: Deposits | F6: Balance | G6: Narration
A7: 45383 | B7: B/F | D7: 0 | F7: 225
A8: =EOMONTH(A7,0)+1 -> 45413 | B8: 20052205306441:Int.Pd:31-03-2024- to 30-04-2024 | E8: 1 | F8: =F7+E8-D8 -> 226 | G8: Bank Interest | I8: 45382 | J8: to | K8: 20052205306441:Int.Pd: | L8: 45412 | M8: =P8&"-"&Q8&"-"&R8&"-"&" "&J8&" "&S8&"-"&T8&"-"&U8 -> 31-03-2024- to 30-04-2024 | N8: =K8&M8 -> 20052205306441:Int.Pd:31-03-2024- to 30-04-2024 | P8: =TEXT(I8,"DD") -> 31 | Q8: =TEXT(I8,"MM") -> 03 | R8: =TEXT(I8,"YYYY") -> 2024 | S8: =TEXT(L8,"DD") -> 30 | T8: =TEXT(L8,"MM") -> 04 | U8: =TEXT(L8,"YYYY") -> 2024
A9: =EOMONTH(A8,0)+1 -> 45444 | B9: 20052205306441:Int.Pd:01-05-2024- to 31-05-2024 | E9: 1 | F9: =F8+E9-D9 -> 227 | G9: Bank Interest | I9: =L8+1 -> 45413 | J9: to | K9: 20052205306441:Int.Pd: | L9: =EOMONTH(L8,1) -> 45443 | M9: =P9&"-"&Q9&"-"&R9&"-"&" "&J9&" "&S9&"-"&T9&"-"&U9 -> 01-05-2024- to 31-05-2024 | N9: =K9&M9 -> 20052205306441:Int.Pd:01-05-2024- to 31-05-2024 | P9: =TEXT(I9,"DD") -> 01 | Q9: =TEXT(I9,"MM") -> 05 | R9: =TEXT(I9,"YYYY") -> 2024 | S9: =TEXT(L9,"DD") -> 31 | T9: =TEXT(L9,"MM") -> 05 | U9: =TEXT(L9,"YYYY") -> 2024
A10: =EOMONTH(A9,0)+1 -> 45474 | B10: 20052205306441:Int.Pd:01-06-2024- to 30-06-2024 | E10: 1 | F10: =F9+E10-D10 -> 228 | G10: Bank Interest | I10: =L9+1 -> 45444 | J10: to | K10: 20052205306441:Int.Pd: | L10: =EOMONTH(L9,1) -> 45473 | M10: =P10&"-"&Q10&"-"&R10&"-"&" "&J10&" "&S10&"-"&T10&"-"&U10 -> 01-06-2024- to 30-06-2024 | N10: =K10&M10 -> 20052205306441:Int.Pd:01-06-2024- to 30-06-2024 | P10: =TEXT(I10,"DD") -> 01 | Q10: =TEXT(I10,"MM") -> 06 | R10: =TEXT(I10,"YYYY") -> 2024 | S10: =TEXT(L10,"DD") -> 30 | T10: =TEXT(L10,"MM") -> 06 | U10: =TEXT(L10,"YYYY") -> 2024
A11: =EOMONTH(A10,0)+1 -> 45505 | B11: 20052205306441:Int.Pd:01-07-2024- to 31-07-2024 | E11: 1 | F11: =F10+E11-D11 -> 229 | G11: Bank Interest | I11: =L10+1 -> 45474 | J11: to | K11: 20052205306441:Int.Pd: | L11: =EOMONTH(L10,1) -> 45504 | M11: =P11&"-"&Q11&"-"&R11&"-"&" "&J11&" "&S11&"-"&T11&"-"&U11 -> 01-07-2024- to 31-07-2024 | N11: =K11&M11 -> 20052205306441:Int.Pd:01-07-2024- to 31-07-2024 | P11: =TEXT(I11,"DD") -> 01 | Q11: =TEXT(I11,"MM") -> 07 | R11: =TEXT(I11,"YYYY") -> 2024 | S11: =TEXT(L11,"DD") -> 31 | T11: =TEXT(L11,"MM") -> 07 | U11: =TEXT(L11,"YYYY") -> 2024
A12: =EOMONTH(A11,0)+1 -> 45536 | B12: 20052205306441:Int.Pd:01-08-2024- to 31-08-2024 | E12: 1 | F12: =F11+E12-D12 -> 230 | G12: Bank Interest | I12: =L11+1 -> 45505 | J12: to | K12: 20052205306441:Int.Pd: | L12: =EOMONTH(L11,1) -> 45535 | M12: =P12&"-"&Q12&"-"&R12&"-"&" "&J12&" "&S12&"-"&T12&"-"&U12 -> 01-08-2024- to 31-08-2024 | N12: =K12&M12 -> 20052205306441:Int.Pd:01-08-2024- to 31-08-2024 | P12: =TEXT(I12,"DD") -> 01 | Q12: =TEXT(I12,"MM") -> 08 | R12: =TEXT(I12,"YYYY") -> 2024 | S12: =TEXT(L12,"DD") -> 31 | T12: =TEXT(L12,"MM") -> 08 | U12: =TEXT(L12,"YYYY") -> 2024
A13: =EOMONTH(A12,0)+1 -> 45566 | B13: 20052205306441:Int.Pd:01-09-2024- to 30-09-2024 | E13: 1 | F13: =F12+E13-D13 -> 231 | G13: Bank Interest | I13: =L12+1 -> 45536 | J13: to | K13: 20052205306441:Int.Pd: | L13: =EOMONTH(L12,1) -> 45565 | M13: =P13&"-"&Q13&"-"&R13&"-"&" "&J13&" "&S13&"-"&T13&"-"&U13 -> 01-09-2024- to 30-09-2024 | N13: =K13&M13 -> 20052205306441:Int.Pd:01-09-2024- to 30-09-2024 | P13: =TEXT(I13,"DD") -> 01 | Q13: =TEXT(I13,"MM") -> 09 | R13: =TEXT(I13,"YYYY") -> 2024 | S13: =TEXT(L13,"DD") -> 30 | T13: =TEXT(L13,"MM") -> 09 | U13: =TEXT(L13,"YYYY") -> 2024
A14: =EOMONTH(A13,0)+1 -> 45597 | B14: 20052205306441:Int.Pd:01-10-2024- to 31-10-2024 | E14: 1 | F14: =F13+E14-D14 -> 232 | G14: Bank Interest | I14: =L13+1 -> 45566 | J14: to | K14: 20052205306441:Int.Pd: | L14: =EOMONTH(L13,1) -> 45596 | M14: =P14&"-"&Q14&"-"&R14&"-"&" "&J14&" "&S14&"-"&T14&"-"&U14 -> 01-10-2024- to 31-10-2024 | N14: =K14&M14 -> 20052205306441:Int.Pd:01-10-2024- to 31-10-2024 | P14: =TEXT(I14,"DD") -> 01 | Q14: =TEXT(I14,"MM") -> 10 | R14: =TEXT(I14,"YYYY") -> 2024 | S14: =TEXT(L14,"DD") -> 31 | T14: =TEXT(L14,"MM") -> 10 | U14: =TEXT(L14,"YYYY") -> 2024
A15: =EOMONTH(A14,0)+1 -> 45627 | B15: 20052205306441:Int.Pd:01-11-2024- to 30-11-2024 | E15: 1 | F15: =F14+E15-D15 -> 233 | G15: Bank Interest | I15: =L14+1 -> 45597 | J15: to | K15: 20052205306441:Int.Pd: | L15: =EOMONTH(L14,1) -> 45626 | M15: =P15&"-"&Q15&"-"&R15&"-"&" "&J15&" "&S15&"-"&T15&"-"&U15 -> 01-11-2024- to 30-11-2024 | N15: =K15&M15 -> 20052205306441:Int.Pd:01-11-2024- to 30-11-2024 | P15: =TEXT(I15,"DD") -> 01 | Q15: =TEXT(I15,"MM") -> 11 | R15: =TEXT(I15,"YYYY") -> 2024 | S15: =TEXT(L15,"DD") -> 30 | T15: =TEXT(L15,"MM") -> 11 | U15: =TEXT(L15,"YYYY") -> 2024
A16: =EOMONTH(A15,0)+1 -> 45658 | B16: 20052205306441:Int.Pd:01-12-2024- to 31-12-2024 | E16: 1 | F16: =F15+E16-D16 -> 234 | G16: Bank Interest | I16: =L15+1 -> 45627 | J16: to | K16: 20052205306441:Int.Pd: | L16: =EOMONTH(L15,1) -> 45657 | M16: =P16&"-"&Q16&"-"&R16&"-"&" "&J16&" "&S16&"-"&T16&"-"&U16 -> 01-12-2024- to 31-12-2024 | N16: =K16&M16 -> 20052205306441:Int.Pd:01-12-2024- to 31-12-2024 | P16: =TEXT(I16,"DD") -> 01 | Q16: =TEXT(I16,"MM") -> 12 | R16: =TEXT(I16,"YYYY") -> 2024 | S16: =TEXT(L16,"DD") -> 31 | T16: =TEXT(L16,"MM") -> 12 | U16: =TEXT(L16,"YYYY") -> 2024
A17: =EOMONTH(A16,0)+1 -> 45689 | B17: 20052205306441:Int.Pd:01-01-2025- to 31-01-2025 | E17: 1 | F17: =F16+E17-D17 -> 235 | G17: Bank Interest | I17: =L16+1 -> 45658 | J17: to | K17: 20052205306441:Int.Pd: | L17: =EOMONTH(L16,1) -> 45688 | M17: =P17&"-"&Q17&"-"&R17&"-"&" "&J17&" "&S17&"-"&T17&"-"&U17 -> 01-01-2025- to 31-01-2025 | N17: =K17&M17 -> 20052205306441:Int.Pd:01-01-2025- to 31-01-2025 | P17: =TEXT(I17,"DD") -> 01 | Q17: =TEXT(I17,"MM") -> 01 | R17: =TEXT(I17,"YYYY") -> 2025 | S17: =TEXT(L17,"DD") -> 31 | T17: =TEXT(L17,"MM") -> 01 | U17: =TEXT(L17,"YYYY") -> 2025
A18: =EOMONTH(A17,0)+1 -> 45717 | B18: 20052205306441:Int.Pd:01-02-2025- to 28-02-2025 | E18: 1 | F18: =F17+E18-D18 -> 236 | G18: Bank Interest | I18: =L17+1 -> 45689 | J18: to | K18: 20052205306441:Int.Pd: | L18: =EOMONTH(L17,1) -> 45716 | M18: =P18&"-"&Q18&"-"&R18&"-"&" "&J18&" "&S18&"-"&T18&"-"&U18 -> 01-02-2025- to 28-02-2025 | N18: =K18&M18 -> 20052205306441:Int.Pd:01-02-2025- to 28-02-2025 | P18: =TEXT(I18,"DD") -> 01 | Q18: =TEXT(I18,"MM") -> 02 | R18: =TEXT(I18,"YYYY") -> 2025 | S18: =TEXT(L18,"DD") -> 28 | T18: =TEXT(L18,"MM") -> 02 | U18: =TEXT(L18,"YYYY") -> 2025
A19: =EOMONTH(A18,0) -> 45747 | B19: 20052205306441:Int.Pd:01-03-2025- to 31-03-2025 | E19: 1 | F19: =F18+E19-D19 -> 237 | G19: Bank Interest | I19: =L18+1 -> 45717 | J19: to | K19: 20052205306441:Int.Pd: | L19: =EOMONTH(L18,1) -> 45747 | M19: =P19&"-"&Q19&"-"&R19&"-"&" "&J19&" "&S19&"-"&T19&"-"&U19 -> 01-03-2025- to 31-03-2025 | N19: =K19&M19 -> 20052205306441:Int.Pd:01-03-2025- to 31-03-2025 | P19: =TEXT(I19,"DD") -> 01 | Q19: =TEXT(I19,"MM") -> 03 | R19: =TEXT(I19,"YYYY") -> 2025 | S19: =TEXT(L19,"DD") -> 31 | T19: =TEXT(L19,"MM") -> 03 | U19: =TEXT(L19,"YYYY") -> 2025

Sheet For Tally
E1: =SUBTOTAL(9,E2:E1438) -> 3110823.1
B2: TX Date | C2: Date | D2: Debit | E2: Credit | F2: Narration | G2: Cost Centre | H2: Account Head | I2: Account No | K2: Kya Hai? | L2: Particulars
B3: 45383 | C3: =EOMONTH(B3,-1)+1 -> 45383 | D3: 686.24 | E3: 0 | F3: 01-04-2024 NET PI TO HSL SEC A/C 2554606-00602340029427 | H3: HDFC Securities | I3: HDFC 5413 | K3: HSL | L3: NET PI TO HSL SEC A/C 2554606-00602340029427 | M3: =TEXT(B3,"DD") -> 01 | N3: =TEXT(B3,"MM") -> 04 | O3: =TEXT(B3,"YYYY") -> 2024 | P3: =M3&"-"&N3&"-"&O3 -> 01-04-2024
B4: 45383 | C4: =EOMONTH(B4,-1)+1 -> 45383 | D4: 5000 | E4: 0 | F4: 01-04-2024 ACH D- TP ACH INDIANESIGN-1400211801 | H4: SIP | I4: HDFC 5413 | K4: SIP - 5000 | L4: ACH D- TP ACH INDIANESIGN-1400211801 | M4: =TEXT(B4,"DD") -> 01 | N4: =TEXT(B4,"MM") -> 04 | O4: =TEXT(B4,"YYYY") -> 2024 | P4: =M4&"-"&N4&"-"&O4 -> 01-04-2024
B5: 45383 | C5: =EOMONTH(B5,-1)+1 -> 45383 | D5: 15000 | E5: 0 | F5: 01-04-2024 TO TRANSFER-UPI/DR/409241614305/NELABALL/UTIB/alphalivin/UPI-- | H5: Rent | I5: SBI 1227 | K5: Rent | L5: TO TRANSFER-UPI/DR/409241614305/NELABALL/UTIB/alphalivin/UPI-- | M5: =TEXT(B5,"DD") -> 01 | N5: =TEXT(B5,"MM") -> 04 | O5: =TEXT(B5,"YYYY") -> 2024 | P5: =M5&"-"&N5&"-"&O5 -> 01-04-2024
B6: 45384 | C6: =EOMONTH(B6,-1)+1 -> 45383 | D6: 0 | E6: 4127.9 | F6: 02-04-2024 NET PO FROM HSL A/C 2554606-50200085415108 | H6: HDFC Securities | I6: HDFC 5413 | K6: HSL | L6: NET PO FROM HSL A/C 2554606-50200085415108 | M6: =TEXT(B6,"DD") -> 02 | N6: =TEXT(B6,"MM") -> 04 | O6: =TEXT(B6,"YYYY") -> 2024 | P6: =M6&"-"&N6&"-"&O6 -> 02-04-2024
B7: 45384 | C7: =EOMONTH(B7,-1)+1 -> 45383 | D7: 171.56 | E7: 0 | F7: 02-04-2024 NET PI TO HSL SEC A/C 2554606-00602340029427 | H7: HDFC Securities | I7: HDFC 5413 | K7: HSL | L7: NET PI TO HSL SEC A/C 2554606-00602340029427 | M7: =TEXT(B7,"DD") -> 02 | N7: =TEXT(B7,"MM") -> 04 | O7: =TEXT(B7,"YYYY") -> 2024 | P7: =M7&"-"&N7&"-"&O7 -> 02-04-2024
B8: 45384 | C8: =EOMONTH(B8,-1)+1 -> 45383 | D8: 10704.09 | E8: 0 | F8: 02-04-2024 NET PI TO HSL SEC A/C 2554606-00602340029427 | H8: HDFC Securities | I8: HDFC 5413 | K8: HSL | L8: NET PI TO HSL SEC A/C 2554606-00602340029427 | M8: =TEXT(B8,"DD") -> 02 | N8: =TEXT(B8,"MM") -> 04 | O8: =TEXT(B8,"YYYY") -> 2024 | P8: =M8&"-"&N8&"-"&O8 -> 02-04-2024
B9: 45384 | C9: =EOMONTH(B9,-1)+1 -> 45383 | D9: 0 | E9: 32394.22 | F9: 02-04-2024 BY TRANSFER-UPI/CR/409308961216/AAYUSH K/KKBK/9594435259/MB UP-- | H9: KOTAK 0333 | I9: SBI 1227 | K9: Contra - KOTAK | L9: BY TRANSFER-UPI/CR/409308961216/AAYUSH K/KKBK/9594435259/MB UP-- | M9: =TEXT(B9,"DD") -> 02 | N9: =TEXT(B9,"MM") -> 04 | O9: =TEXT(B9,"YYYY") -> 2024 | P9: =M9&"-"&N9&"-"&O9 -> 02-04-2024
B10: 45384 | C10: =EOMONTH(B10,-1)+1 -> 45383 | D10: 0 | E10: 590 | F10: 02-04-2024 BY TRANSFER-UPI/CR/409364666330/ADARSH N/HDFC/adusma02-1/UPI-- | H10: Personal | I10: SBI 1227 | K10: Personal | L10: BY TRANSFER-UPI/CR/409364666330/ADARSH N/HDFC/adusma02-1/UPI-- | M10: =TEXT(B10,"DD") -> 02 | N10: =TEXT(B10,"MM") -> 04 | O10: =TEXT(B10,"YYYY") -> 2024 | P10: =M10&"-"&N10&"-"&O10 -> 02-04-2024
B11: 45384 | C11: =EOMONTH(B11,-1)+1 -> 45383 | D11: 0 | E11: 590 | F11: 02-04-2024 BY TRANSFER-UPI/CR/409364703330/K PRAMOD/HDFC/kpramodkri/UPI-- | H11: Personal | I11: SBI 1227 | K11: Personal | L11: BY TRANSFER-UPI/CR/409364703330/K PRAMOD/HDFC/kpramodkri/UPI-- | M11: =TEXT(B11,"DD") -> 02 | N11: =TEXT(B11,"MM") -> 04 | O11: =TEXT(B11,"YYYY") -> 2024 | P11: =M11&"-"&N11&"-"&O11 -> 02-04-2024
B12: 45384 | C12: =EOMONTH(B12,-1)+1 -> 45383 | D12: 0 | E12: 590 | F12: 02-04-2024 BY TRANSFER-UPI/CR/445977564613/ADARSH K M/UTIB/coorgadars/Pay-- | H12: Personal | I12: SBI 1227 | K12: Personal | L12: BY TRANSFER-UPI/CR/445977564613/ADARSH K M/UTIB/coorgadars/Pay-- | M12: =TEXT(B12,"DD") -> 02 | N12: =TEXT(B12,"MM") -> 04 | O12: =TEXT(B12,"YYYY") -> 2024 | P12: =M12&"-"&N12&"-"&O12 -> 02-04-2024
B13: 45384 | C13: =EOMONTH(B13,-1)+1 -> 45383 | D13: 0 | E13: 590 | F13: 02-04-2024 BY TRANSFER-UPI/CR/445927539114/MONISH K/ICIC/8296488092/Payme-- | H13: Personal | I13: SBI 1227 | K13: Personal | L13: BY TRANSFER-UPI/CR/445927539114/MONISH K/ICIC/8296488092/Payme-- | M13: =TEXT(B13,"DD") -> 02 | N13: =TEXT(B13,"MM") -> 04 | O13: =TEXT(B13,"YYYY") -> 2024 | P13: =M13&"-"&N13&"-"&O13 -> 02-04-2024
B14: 45384 | C14: =EOMONTH(B14,-1)+1 -> 45383 | D14: 0 | E14: 590 | F14: 02-04-2024 BY TRANSFER-UPI/CR/409341661367/SHASHANK/HDFC/9880498899/Sent-- | H14: Personal | I14: SBI 1227 | K14: Personal | L14: BY TRANSFER-UPI/CR/409341661367/SHASHANK/HDFC/9880498899/Sent-- | M14: =TEXT(B14,"DD") -> 02 | N14: =TEXT(B14,"MM") -> 04 | O14: =TEXT(B14,"YYYY") -> 2024 | P14: =M14&"-"&N14&"-"&O14 -> 02-04-2024
... B59: 45390 | C59: =EOMONTH(B59,-1)+1 -> 45383 | D59: 466.44 | E59: 0 | F59: 08-04-2024 NET PI TO HSL SEC A/C 2554606-00602340029427 | H59: HDFC Securities | I59: HDFC 5413 | K59: HSL | L59: NET PI TO HSL SEC A/C 2554606-00602340029427 | M59: =TEXT(B59,"DD") -> 08 | N59: =TEXT(B59,"MM") -> 04 | O59: =TEXT(B59,"YYYY") -> 2024 | P59: =M59&"-"&N59&"-"&O59 -> 08-04-2024
B60: 45390 | C60: =EOMONTH(B60,-1)+1 -> 45383 | D60: 0 | E60: 1880 | F60: 08-04-2024 HDFCLIFE CENTR-027086150 | G60: Annuity | H60: Insurance | I60: HDFC 5413 | K60: Annuity | L60: HDFCLIFE CENTR-027086150 | M60: =TEXT(B60,"DD") -> 08 | N60: =TEXT(B60,"MM") -> 04 | O60: =TEXT(B60,"YYYY") -> 2024 | P60: =M60&"-"&N60&"-"&O60 -> 08-04-2024
B61: 45390 | C61: =EOMONTH(B61,-1)+1 -> 45383 | D61: 277.68 | E61: 0 | F61: 08-04-2024 NET PI TO HSL SEC A/C 2554606-00602340029427 | H61: HDFC Securities | I61: HDFC 5413 | K61: HSL | L61: NET PI TO HSL SEC A/C 2554606-00602340029427 | M61: =TEXT(B61,"DD") -> 08 | N61: =TEXT(B61,"MM") -> 04 | O61: =TEXT(B61,"YYYY") -> 2024 | P61: =M61&"-"&N61&"-"&O61 -> 08-04-2024
B62: 45390 | C62: =EOMONTH(B62,-1)+1 -> 45383 | D62: 1 | E62: 0 | F62: 08-04-2024 UPI/Setu BrokenTusk/409900283744/Account Verific | H62: Personal | I62: KOTAK 0333 | K62: UPI | L62: UPI/Setu BrokenTusk/409900283744/Account Verific | M62: =TEXT(B62,"DD") -> 08 | N62: =TEXT(B62,"MM") -> 04 | O62: =TEXT(B62,"YYYY") -> 2024 | P62: =M62&"-"&N62&"-"&O62 -> 08-04-2024
B63: 45390 | C63: =EOMONTH(B63,-1)+1 -> 45383 | D63: 50 | E63: 0 | F63: 08-04-2024 UPIOUT/409950113342/ Q429259031@ybl/Sent via /5814 | H63: Personal | I63: FEDERAL 0847 | K63: UPI | L63: UPIOUT/409950113342/ Q429259031@ybl/Sent via /5814 | M63: =TEXT(B63,"DD") -> 08 | N63: =TEXT(B63,"MM") -> 04 | O63: =TEXT(B63,"YYYY") -> 2024 | P63: =M63&"-"&N63&"-"&O63 -> 08-04-2024
B64: 45390 | C64: =EOMONTH(B64,-1)+1 -> 45383 | D64: 100 | E64: 0 | F64: 08-04-2024 UPIOUT/409909465458/ bharatpe.90068347282@ fbp/7230 | H64: Personal | I64: FEDERAL 0847 | K64: UPI | L64: UPIOUT/409909465458/ bharatpe.90068347282@ fbp/7230 | M64: =TEXT(B64,"DD") -> 08 | N64: =TEXT(B64,"MM") -> 04 | O64: =TEXT(B64,"YYYY") -> 2024 | P64: =M64&"-"&N64&"-"&O64 -> 08-04-2024
B65: 45391 | C65: =EOMONTH(B65,-1)+1 -> 45383 | D65: 28.05 | E65: 0 | F65: 09-04-2024 NET PI TO HSL SEC A/C 2554606-00602340029427 | H65: HDFC Securities | I65: HDFC 5413 | K65: HSL | L65: NET PI TO HSL SEC A/C 2554606-00602340029427 | M65: =TEXT(B65,"DD") -> 09 | N65: =TEXT(B65,"MM") -> 04 | O65: =TEXT(B65,"YYYY") -> 2024 | P65: =M65&"-"&N65&"-"&O65 -> 09-04-2024
B66: 45391 | C66: =EOMONTH(B66,-1)+1 -> 45383 | D66: 2000 | E66: 0 | F66: 09-04-2024 UPI/AAYUSH KUMAR GU/410013514219/UPI | H66: FEDERAL 0847 | I66: KOTAK 0333 | K66: Contra - Jupiter | L66: UPI/AAYUSH KUMAR GU/410013514219/UPI | M66: =TEXT(B66,"DD") -> 09 | N66: =TEXT(B66,"MM") -> 04 | O66: =TEXT(B66,"YYYY") -> 2024 | P66: =M66&"-"&N66&"-"&O66 -> 09-04-2024
B67: 45391 | C67: =EOMONTH(B67,-1)+1 -> 45383 | D67: 0 | E67: 2000 | F67: 09-04-2024 UPI IN/410013514219/ aayush20gupta-3@okicici//0000 | H67: KOTAK 0333 | I67: FEDERAL 0847 | K67: Contra - Kotak | L67: UPI IN/410013514219/ aayush20gupta-3@okicici//0000 | M67: =TEXT(B67,"DD") -> 09 | N67: =TEXT(B67,"MM") -> 04 | O67: =TEXT(B67,"YYYY") -> 2024 | P67: =M67&"-"&N67&"-"&O67 -> 09-04-2024
B68: 45391 | C68: =EOMONTH(B68,-1)+1 -> 45383 | D68: 30 | E68: 0 | F68: 09-04-2024 UPIOUT/410058801403/ Q403465439@ybl/Sent via /5812 | H68: Personal | I68: FEDERAL 0847 | K68: UPI | L68: UPIOUT/410058801403/ Q403465439@ybl/Sent via /5812 | M68: =TEXT(B68,"DD") -> 09 | N68: =TEXT(B68,"MM") -> 04 | O68: =TEXT(B68,"YYYY") -> 2024 | P68: =M68&"-"&N68&"-"&O68 -> 09-04-2024
B69: 45392 | C69: =EOMONTH(B69,-1)+1 -> 45383 | D69: 0 | E69: 46373.79 | F69: 10-04-2024 NET PO FROM HSL A/C 2554606-50200085415108 | H69: HDFC Securities | I69: HDFC 5413 | K69: HSL | L69: NET PO FROM HSL A/C 2554606-50200085415108 | M69: =TEXT(B69,"DD") -> 10 | N69: =TEXT(B69,"MM") -> 04 | O69: =TEXT(B69,"YYYY") -> 2024 | P69: =M69&"-"&N69&"-"&O69 -> 10-04-2024
B70: 45392 | C70: =EOMONTH(B70,-1)+1 -> 45383 | D70: 155.42 | E70: 0 | F70: 10-04-2024 NET PI TO HSL SEC A/C 2554606-00602340029427 | H70: HDFC Securities | I70: HDFC 5413 | K70: HSL | L70: NET PI TO HSL SEC A/C 2554606-00602340029427 | M70: =TEXT(B70,"DD") -> 10 | N70: =TEXT(B70,"MM") -> 04 | O70: =TEXT(B70,"YYYY") -> 2024 | P70: =M70&"-"&N70&"-"&O70 -> 10-04-2024
B71: 45392 | C71: =EOMONTH(B71,-1)+1 -> 45383 | D71: 0 | E71: 100 | F71: 10-04-2024 BY TRANSFER-UPI/CR/446766838451/MOHANA P/KKBK/7904299233/Payme-- | H71: Personal | I71: SBI 1227 | K71: Personal | L71: BY TRANSFER-UPI/CR/446766838451/MOHANA P/KKBK/7904299233/Payme-- | M71: =TEXT(B71,"DD") -> 10 | N71: =TEXT(B71,"MM") -> 04 | O71: =TEXT(B71,"YYYY") -> 2024 | P71: =M71&"-"&N71&"-"&O71 -> 10-04-2024
B72: 45392 | C72: =EOMONTH(B72,-1)+1 -> 45383 | D72: 0 | E72: 1 | F72: 10-04-2024 UPI_CRADJ_U2_TDT_080424_409900283744_10APR2024_7C | H72: Personal | I72: KOTAK 0333 | K72: UPI | L72: UPI_CRADJ_U2_TDT_080424_409900283744_10APR2024_7C | M72: =TEXT(B72,"DD") -> 10 | N72: =TEXT(B72,"MM") -> 04 | O72: =TEXT(B72,"YYYY") -> 2024 | P72: =M72&"-"&N72&"-"&O72 -> 10-04-2024
... B148: 45412 | C148: =EOMONTH(B148,-1)+1 -> 45383 | D148: 40 | E148: 0 | F148: 30-04-2024 UPI/DIGVIJAY/412125769450/Pay to BharatPe | H148: Personal | I148: KOTAK 0333 | K148: UPI | L148: UPI/DIGVIJAY/412125769450/Pay to BharatPe | M148: =TEXT(B148,"DD") -> 30 | N148: =TEXT(B148,"MM") -> 04 | O148: =TEXT(B148,"YYYY") -> 2024 | P148: =M148&"-"&N148&"-"&O148 -> 30-04-2024
B149: 45413 | C149: =EOMONTH(B149,-1)+1 -> 45413 | D149: 0 | E149: 1 | F149: 01-05-2024 20052205306441:Int.Pd:31-03-2024- to 30-04-2024 | G149: SBM | H149: Bank Interest | I149: SBM 6441 | K149: Bank Interest | L149: 20052205306441:Int.Pd:31-03-2024- to 30-04-2024 | M149: =TEXT(B149,"DD") -> 01 | N149: =TEXT(B149,"MM") -> 05 | O149: =TEXT(B149,"YYYY") -> 2024 | P149: =M149&"-"&N149&"-"&O149 -> 01-05-2024
B150: 45414 | C150: =EOMONTH(B150,-1)+1 -> 45413 | D150: 212.74 | E150: 0 | F150: 02-05-2024 NET PI TO HSL SEC A/C 2554606-00602340029427 | H150: HDFC Securities | I150: HDFC 5413 | K150: HSL | L150: NET PI TO HSL SEC A/C 2554606-00602340029427 | M150: =TEXT(B150,"DD") -> 02 | N150: =TEXT(B150,"MM") -> 05 | O150: =TEXT(B150,"YYYY") -> 2024 | P150: =M150&"-"&N150&"-"&O150 -> 02-05-2024
B151: 45414 | C151: =EOMONTH(B151,-1)+1 -> 45413 | D151: 93.48 | E151: 0 | F151: 02-05-2024 NET PI TO HSL SEC A/C 2554606-00602340029427 | H151: HDFC Securities | I151: HDFC 5413 | K151: HSL | L151: NET PI TO HSL SEC A/C 2554606-00602340029427 | M151: =TEXT(B151,"DD") -> 02 | N151: =TEXT(B151,"MM") -> 05 | O151: =TEXT(B151,"YYYY") -> 2024 | P151: =M151&"-"&N151&"-"&O151 -> 02-05-2024
B152: 45415 | C152: =EOMONTH(B152,-1)+1 -> 45413 | D152: 295 | E152: 0 | F152: 03-05-2024 ISAQMC-JAN-MAR24-417944 260424-MIR2512491109879 | H152: Bank Charges | I152: HDFC 5413 | K152: Bank Charges | L152: ISAQMC-JAN-MAR24-417944 260424-MIR2512491109879 | M152: =TEXT(B152,"DD") -> 03 | N152: =TEXT(B152,"MM") -> 05 | O152: =TEXT(B152,"YYYY") -> 2024 | P152: =M152&"-"&N152&"-"&O152 -> 03-05-2024
B153: 45415 | C153: =EOMONTH(B153,-1)+1 -> 45413 | D153: 106.34 | E153: 0 | F153: 03-05-2024 NET PI TO HSL SEC A/C 2554606-00602340029427 | H153: HDFC Securities | I153: HDFC 5413 | K153: HSL | L153: NET PI TO HSL SEC A/C 2554606-00602340029427 | M153: =TEXT(B153,"DD") -> 03 | N153: =TEXT(B153,"MM") -> 05 | O153: =TEXT(B153,"YYYY") -> 2024 | P153: =M153&"-"&N153&"-"&O153 -> 03-05-2024
B154: 45415 | C154: =EOMONTH(B154,-1)+1 -> 45413 | D154: 2000 | E154: 0 | F154: 03-05-2024 ATW-652166XXXXXX7402-S1ANMN04-NASHIK | H154: Cash | I154: HDFC 5413 | K154: ATM Withdrawal | L154: ATW-652166XXXXXX7402-S1ANMN04-NASHIK | M154: =TEXT(B154,"DD") -> 03 | N154: =TEXT(B154,"MM") -> 05 | O154: =TEXT(B154,"YYYY") -> 2024 | P154: =M154&"-"&N154&"-"&O154 -> 03-05-2024
B155: 45415 | C155: =EOMONTH(B155,-1)+1 -> 45413 | D155: 517.47 | E155: 0 | F155: 03-05-2024 NET PI TO HSL SEC A/C 2554606-00602340029427 | H155: HDFC Securities | I155: HDFC 5413 | K155: HSL | L155: NET PI TO HSL SEC A/C 2554606-00602340029427 | M155: =TEXT(B155,"DD") -> 03 | N155: =TEXT(B155,"MM") -> 05 | O155: =TEXT(B155,"YYYY") -> 2024 | P155: =M155&"-"&N155&"-"&O155 -> 03-05-2024
B156: 45417 | C156: =EOMONTH(B156,-1)+1 -> 45413 | D156: 15000 | E156: 0 | F156: 05-05-2024 UPI/NELABALLI PRADE/412652501217/PG fees | H156: Rent | I156: KOTAK 0333 | K156: Rent | L156: UPI/NELABALLI PRADE/412652501217/PG fees | M156: =TEXT(B156,"DD") -> 05 | N156: =TEXT(B156,"MM") -> 05 | O156: =TEXT(B156,"YYYY") -> 2024 | P156: =M156&"-"&N156&"-"&O156 -> 05-05-2024
B157: 45417 | C157: =EOMONTH(B157,-1)+1 -> 45413 | D157: 14728 | E157: 0 | F157: 05-05-2024 UPI/Axis/449260771925/payment on CRED | H157: Suspense | I157: KOTAK 0333 | K157: What is this? | L157: UPI/Axis/449260771925/payment on CRED | M157: =TEXT(B157,"DD") -> 05 | N157: =TEXT(B157,"MM") -> 05 | O157: =TEXT(B157,"YYYY") -> 2024 | P157: =M157&"-"&N157&"-"&O157 -> 05-05-2024
B158: 45418 | C158: =EOMONTH(B158,-1)+1 -> 45413 | D158: 318.48 | E158: 0 | F158: 06-05-2024 NET PI TO HSL SEC A/C 2554606-00602340029427 | H158: HDFC Securities | I158: HDFC 5413 | K158: HSL | L158: NET PI TO HSL SEC A/C 2554606-00602340029427 | M158: =TEXT(B158,"DD") -> 06 | N158: =TEXT(B158,"MM") -> 05 | O158: =TEXT(B158,"YYYY") -> 2024 | P158: =M158&"-"&N158&"-"&O158 -> 06-05-2024
B159: 45418 | C159: =EOMONTH(B159,-1)+1 -> 45413 | D159: 190 | E159: 0 | F159: 06-05-2024 UPI/SUBRAT TRIPATH/412789253690/UPI | H159: Personal | I159: KOTAK 0333 | K159: UPI | L159: UPI/SUBRAT TRIPATH/412789253690/UPI | M159: =TEXT(B159,"DD") -> 06 | N159: =TEXT(B159,"MM") -> 05 | O159: =TEXT(B159,"YYYY") -> 2024 | P159: =M159&"-"&N159&"-"&O159 -> 06-05-2024
...

Sheet Conso
A1: Aayush Kumar Gupta
A2: Account of Statements from 01-04-2024 to 31-03-2025 | D2: =SUBTOTAL(9,D4:D1048576) -> 3224411.3 | E2: =SUBTOTAL(9,E4:E1048576) -> 3110823.1 | F2: =D2-E2 -> 113588.25
A3: TX Date | B3: Particulars | C3: Ref | D3: DR | E3: CR | F3: Balance | G3: Cost Centre | H3: Account Head | J3: Account No
A4: 45383 | B4: NET PI TO HSL SEC A/C 2554606-00602340029427 | C4: 0000000508915817 | D4: 686.24 | E4: 0 | F4: 42364.65 | H4: HSL | J4: HDFC
A5: 45383 | B5: ACH D- TP ACH INDIANESIGN-1400211801 | C5: 0000002398408108 | D5: 5000 | E5: 0 | F5: 37364.65 | H5: SIP - 5000 | J5: HDFC
A6: 45383 | B6: TO TRANSFER-UPI/DR/409241614305/NELABALL/UTIB/alphalivin/UPI-- | C6: TRANSFER TO 4897690162095 | D6: 15000 | E6: 0 | F6: 37605.78 | H6: Rent | J6: SBI
A7: 45384 | B7: NET PO FROM HSL A/C 2554606-50200085415108 | C7: 0000000509173908 | D7: 0 | E7: 4127.9 | F7: 41492.55 | H7: HSL | J7: HDFC
A8: 45384 | B8: NET PI TO HSL SEC A/C 2554606-00602340029427 | C8: 0000000509391641 | D8: 171.56 | E8: 0 | F8: 41320.99 | H8: HSL | J8: HDFC
A9: 45384 | B9: NET PI TO HSL SEC A/C 2554606-00602340029427 | C9: 0000000509532271 | D9: 10704.09 | E9: 0 | F9: 30616.9 | H9: HSL | J9: HDFC
A10: 45384 | B10: BY TRANSFER-UPI/CR/409308961216/AAYUSH K/KKBK/9594435259/MB UP-- | C10: TRANSFER FROM 4897733162090 | D10: 0 | E10: 32394.22 | F10: 70000 | H10: Contra - KOTAK | J10: SBI
A11: 45384 | B11: BY TRANSFER-UPI/CR/409364666330/ADARSH N/HDFC/adusma02-1/UPI-- | C11: TRANSFER FROM 4897733162090 | D11: 0 | E11: 590 | F11: 70590 | H11: Personal | J11: SBI
A12: 45384 | B12: BY TRANSFER-UPI/CR/409364703330/K PRAMOD/HDFC/kpramodkri/UPI-- | C12: TRANSFER FROM 4897733162090 | D12: 0 | E12: 590 | F12: 71180 | H12: Personal | J12: SBI
A13: 45384 | B13: BY TRANSFER-UPI/CR/445977564613/ADARSH K M/UTIB/coorgadars/Pay-- | C13: TRANSFER FROM 4897733162090 | D13: 0 | E13: 590 | F13: 71770 | H13: Personal | J13: SBI
A14: 45384 | B14: BY TRANSFER-UPI/CR/445927539114/MONISH K/ICIC/8296488092/Payme-- | C14: TRANSFER FROM 4897733162090 | D14: 0 | E14: 590 | F14: 72360 | H14: Personal | J14: SBI
A15: 45384 | B15: BY TRANSFER-UPI/CR/409341661367/SHASHANK/HDFC/9880498899/Sent-- | C15: TRANSFER FROM 4897733162090 | D15: 0 | E15: 590 | F15: 72950 | H15: Personal | J15: SBI
... A149: 45412 | B149: UPI/DIGVIJAY/412125769450/Pay to BharatPe | C149: UPI-412123252947 | D149: 40 | E149: 0 | F149: 37959.89 | H149: UPI | J149: KOTAK
A150: 45413 | B150: 20052205306441:Int.Pd:31-03-2024- to 30-04-2024 | D150: 0 | E150: 1 | F150: 226 | H150: Bank Interest | J150: SBM
A151: 45414 | B151: NET PI TO HSL SEC A/C 2554606-00602340029427 | C151: 0000000517770270 | D151: 212.74 | E151: 0 | F151: 40224.41 | H151: HSL | J151: HDFC
A152: 45414 | B152: NET PI TO HSL SEC A/C 2554606-00602340029427 | C152: 0000000517947488 | D152: 93.48 | E152: 0 | F152: 40130.93 | H152: HSL | J152: HDFC
A153: 45415 | B153: ISAQMC-JAN-MAR24-417944 260424-MIR2512491109879 | C153: MIR2512491109879 | D153: 295 | E153: 0 | F153: 39835.93 | H153: Bank Charges | J153: HDFC
A154: 45415 | B154: NET PI TO HSL SEC A/C 2554606-00602340029427 | C154: 0000000518228782 | D154: 106.34 | E154: 0 | F154: 39729.59 | H154: HSL | J154: HDFC
A155: 45415 | B155: ATW-652166XXXXXX7402-S1ANMN04-NASHIK | C155: 0000000000008401 | D155: 2000 | E155: 0 | F155: 37729.59 | H155: ATM Withdrawal | J155: HDFC
A156: 45415 | B156: NET PI TO HSL SEC A/C 2554606-00602340029427 | C156: 0000000518421745 | D156: 517.47 | E156: 0 | F156: 37212.12 | H156: HSL | J156: HDFC
A157: 45417 | B157: UPI/NELABALLI PRADE/412652501217/PG fees | C157: UPI-412645792069 | D157: 15000 | E157: 0 | F157: 22959.89 | H157: Rent | J157: KOTAK
A158: 45417 | B158: UPI/Axis/449260771925/payment on CRED | C158: UPI-412648626420 | D158: 14728 | E158: 0 | F158: 8231.89 | H158: What is this? | J158: KOTAK
A159: 45418 | B159: NET PI TO HSL SEC A/C 2554606-00602340029427 | C159: 0000000518796078 | D159: 318.48 | E159: 0 | F159: 36893.64 | H159: HSL | J159: HDFC
A160: 45418 | B160: UPI/SUBRAT TRIPATH/412789253690/UPI | C160: UPI-412781466883 | D160: 190 | E160: 0 | F160: 8041.89 | H160: UPI | J160: KOTAK
A161: 45419 | B161: NET PO FROM HSL A/C 2554606-50200085415108 | C161: 0000000519119873 | D161: 0 | E161: 22182.26 | F161: 59075.9 | H161: HSL | J161: HDFC
A162: 45419 | B162: NET PI TO HSL SEC A/C 2554606-00602340029427 | C162: 0000000519265541 | D162: 106.16 | E162: 0 | F162: 58969.74 | H162: HSL | J162: HDFC
... A255: 45442 | B255: UPI/DIGVIJAY/415148486279/Pay to BharatPe | C255: UPI-415104493020 | D255: 30 | E255: 0 | F255: 53710.64 | H255: UPI | J255: KOTAK
A256: 45442 | B256: ATL/4395/504433/+OUTER RING ROADBENGAL300524/22:26 | C256: 415122000000 | D256: 3000 | E256: 0 | F256: 50710.64 | H256: What is this? | J256: KOTAK
A257: 45442 | B257: UPI/M BHOOPAL/415186393331/UPI | C257: UPI-415109283089 | D257: 280 | E257: 0 | F257: 50430.64 | H257: UPI | J257: KOTAK
A258: 45443 | B258: NET PI TO HSL SEC A/C 2554606-00602340029427 | C258: 0000000526851088 | D258: 102.79 | E258: 0 | F258: 62652.48 | H258: HSL | J258: HDFC
A259: 45443 | B259: NET PI TO HSL SEC A/C 2554606-00602340029427 | C259: 0000000527032198 | D259: 726.98 | E259: 0 | F259: 61925.5 | H259: HSL | J259: HDFC
A260: 45443 | B260: UPI/ANANDA PAVABA D/415227527561/UPI | C260: UPI-415219357268 | D260: 15 | E260: 0 | F260: 50415.64 | H260: UPI | J260: KOTAK
A261: 45444 | B261: UPI/MANGAL BABAN CH/415308665779/UPI | C261: UPI-415371787163 | D261: 60 | E261: 0 | F261: 50355.64 | H261: UPI | J261: KOTAK
A262: 45444 | B262: 20052205306441:Int.Pd:01-05-2024- to 31-05-2024 | D262: 0 | E262: 1 | F262: 227 | H262: Bank Interest | J262: SBM
A263: 45445 | B263: UPI/HOTEL KRISHNA R/415435780407/hotel booking | C263: UPI-415420220440 | D263: 500 | E263: 0 | F263: 49855.64 | H263: UPI | J263: KOTAK
A264: 45445 | B264: UPI/HOTEL KRISHNA R/415453362758/hotel booking | C264: UPI-415436002435 | D264: 1300 | E264: 0 | F264: 48555.64 | H264: UPI | J264: KOTAK
A265: 45446 | B265: NET PI TO HSL SEC A/C 2554606-00602340029427 | C265: 0000000527400278 | D265: 307.59 | E265: 0 | F265: 61617.91 | H265: HSL | J265: HDFC
...

Sheet Bank Summary
B2: All Banks
B3: Aayush Gupta Bank Summary
B4: 01-04-2024 to 31-03-2025
B5: Particulars | C5: ₹ | D5: Particulars | E5: ₹
B6: Opening Balances | C6: =J51 -> 172996.98
P7: 0
B8: ?? | C8: =SUMIFS(Conso!$E:$E,Conso!$H:$H,B8) -> 1100 | D8: ?? | E8: =SUMIFS(Conso!$D:$D,Conso!$H:$H,D8) -> 15050 | P8: ??
B9: Advance Tax | C9: =SUMIFS(Conso!$E:$E,Conso!$H:$H,B9) -> 0 | D9: Advance Tax | E9: =SUMIFS(Conso!$D:$D,Conso!$H:$H,D9) -> 4000 | P9: Advance Tax
B10: Annuity | C10: =SUMIFS(Conso!$E:$E,Conso!$H:$H,B10) -> 22560 | D10: Annuity | E10: =SUMIFS(Conso!$D:$D,Conso!$H:$H,D10) -> 0 | P10: Annuity
B11: ATM Withdrawal | C11: =SUMIFS(Conso!$E:$E,Conso!$H:$H,B11) -> 0 | D11: ATM Withdrawal | E11: =SUMIFS(Conso!$D:$D,Conso!$H:$H,D11) -> 5000 | P11: ATM Withdrawal
B12: Bank Charges | C12: =SUMIFS(Conso!$E:$E,Conso!$H:$H,B12) -> 0 | D12: Bank Charges | E12: =SUMIFS(Conso!$D:$D,Conso!$H:$H,D12) -> 1158.06 | P12: Bank Charges
B13: Bank Interest | C13: =SUMIFS(Conso!$E:$E,Conso!$H:$H,B13) -> 5768 | D13: Bank Interest | E13: =SUMIFS(Conso!$D:$D,Conso!$H:$H,D13) -> 0 | P13: Bank Interest
B14: CARE HEALTH INSURANCE - RELIGARE | C14: =SUMIFS(Conso!$E:$E,Conso!$H:$H,B14) -> 0 | D14: CARE HEALTH INSURANCE - RELIGARE | E14: =SUMIFS(Conso!$D:$D,Conso!$H:$H,D14) -> 11240 | P14: CARE HEALTH INSURANCE - RELIGARE
B15: Cash Deposit | C15: =SUMIFS(Conso!$E:$E,Conso!$H:$H,B15) -> 127000 | D15: Cash Deposit | E15: =SUMIFS(Conso!$D:$D,Conso!$H:$H,D15) -> 0 | P15: Cash Deposit
B16: CDSL? | C16: =SUMIFS(Conso!$E:$E,Conso!$H:$H,B16) -> 244.44 | D16: CDSL? | E16: =SUMIFS(Conso!$D:$D,Conso!$H:$H,D16) -> 0 | P16: CDSL?
B17: Contra - Jupiter | C17: =SUMIFS(Conso!$E:$E,Conso!$H:$H,B17) -> 3135.19 | D17: Contra - Jupiter | E17: =SUMIFS(Conso!$D:$D,Conso!$H:$H,D17) -> 12015 | P17: Contra - Jupiter
B18: Contra - KOTAK | C18: =SUMIFS(Conso!$E:$E,Conso!$H:$H,B18) -> 79409.22 | D18: Contra - KOTAK | E18: =SUMIFS(Conso!$D:$D,Conso!$H:$H,D18) -> 31186 | P18: Contra - KOTAK
B19: Contra - SBI | C19: =SUMIFS(Conso!$E:$E,Conso!$H:$H,B19) -> 30001 | D19: Contra - SBI | E19: =SUMIFS(Conso!$D:$D,Conso!$H:$H,D19) -> 69344.41 | P19: Contra - SBI
... B44: Upwork Income | C44: =SUMIFS(Conso!$E:$E,Conso!$H:$H,B44) -> 2084.26 | D44: Upwork Income | E44: =SUMIFS(Conso!$D:$D,Conso!$H:$H,D44) -> 0 | P44: Upwork Income
B45: What is this? | C45: =SUMIFS(Conso!$E:$E,Conso!$H:$H,B45) -> 1605 | D45: What is this? | E45: =SUMIFS(Conso!$D:$D,Conso!$H:$H,D45) -> 175864.9 | J45: Opening | K45: Closing | P45: What is this?
B46: Ye kya hai? | C46: =SUMIFS(Conso!$E:$E,Conso!$H:$H,B46) -> 467832.97 | D46: Ye kya hai? | E46: =SUMIFS(Conso!$D:$D,Conso!$H:$H,D46) -> 0 | I46: HDFC | J46: =HDFC!G21+HDFC!E21 -> 43050.89 | K46: =HDFC!G638 -> 28780.48 | P46: Ye kya hai?
B47: Zerodha | C47: =SUMIFS(Conso!$E:$E,Conso!$H:$H,B47) -> 75749.59 | D47: Zerodha | E47: =SUMIFS(Conso!$D:$D,Conso!$H:$H,D47) -> 21000 | I47: AXIS | J47: =AXIS!G18+AXIS!E18 -> 16847.21 | K47: =AXIS!G22 -> 17356.03 | P47: Zerodha
I48: SBI | J48: =SBI!G21+SBI!E21 -> 52605.78 | K48: =SBI!G141 -> 10986.03
I49: FEDERAL | J49: =FEDERAL!I20+FEDERAL!G20 -> 771.09 | K49: =FEDERAL!I66 -> 0
E50: =C52-SUM(E6:E47) -> 209408.73 | G50: =E50-K51 -> 150553 | I50: KOTAK | J50: =KOTAK!L15+KOTAK!J15 -> 59722.01 | K50: =KOTAK!L645 -> 1733.19
H51: =J51+E50-K51 -> 323549.98 | J51: =SUM(J46:J50) -> 172996.98 | K51: =SUM(K46:K50) -> 58855.73
C52: =SUM(C6:C51) -> 3226820.1 | E52: =SUM(E6:E51) -> 3226820.1
