Workbook

Sheet AXIS
B1: Axis Bank Narration Sheet
B2: Colour Legend of Categories:
B3: Salary | C3: Contra - SBI | D3: UPI - IRCTC | E3: Contra - Kotak | F3: UPI Payment
B4: Credit Card Bill Payment (CRED) | C4: Received - Megha Gupta | D4: Transfer - Megha Gupta | E4: Rent Payment (via CRED) | F4: Bank Interest
B5: NEFT Transfer | C5: UPI - Fuel (HPCL) | D5: UPI - Star Bazaar | E5: UPI - Nandini Dairy | F5: UPI - Fresh Produce
B6: UPI - Pharmacy | C6: Transfer - Ajay Gupta | D6: Transfer - Archit Gupta | E6: Received - Ajay Gupta | F6: UPI - CRED
B7: Vehicle Service | C7: Food & Dining / Hotel | D7: Entertainment | E7: UPI - Fuel | F7: Rent
B8: Health Insurance | C8: UPI - CRED Wallet | D8: Toll / FASTag | E8: UPI - Amazon | F8: Shopping - Jewellery
B9: Income Tax Payment | C9: Security Deposit | D9: UPI - Zepto | E9: Security Deposit Return | F9: UPI - BharatPe
B10: UPI - DMart | C10: Received - Ret | D10: Received - Archit Gupta | E10: UPI - Flipkart | F10: UPI - Navi
A12: Date | B12: Particulars | C12: Ref | D12: Value_Date | E12: DR | F12: CR | G12: Balance | H12: Beneficiary | I12: Human_Narration | J12: Auto_Narration | K12: Account_Head | L12: Confidence | M12: Match
A13: 45749 | B13: Salary For the Month of Mar 2025 | C13: - | D13: 45749 | E13: 0 | F13: 66897 | G13: 84253.03 | I13: Salary | J13: Salary | K13: Salary | L13: 0.95 | M13: [MATCH]
A14: 45749 | B14: NEFT/MB/AXOMB09202414101/AAYUSH KUMAR GUPTA/STATE BANK OF INDIA/ | C14: - | D14: 45749 | E14: 1 | F14: 0 | G14: 84252.03 | I14: UPI | J14: Contra - SBI | K14: SBI 1227 | L14: 0.9 | M14: [MATCH]
A15: 45749 | B15: UPI/P2A/765226990925/AAYUSH KUMAR GUPTA /UPI/State Bank Of India | C15: - | D15: 45749 | E15: 1 | F15: 0 | G15: 84251.03 | I15: UPI | J15: Contra - SBI | K15: SBI 1227 | L15: 0.9 | M15: [MATCH]
A16: 45749 | B16: UPI/P2A/765382250925/AAYUSH KUMAR GUPTA /UPI/State Bank Of India | C16: - | D16: 45749 | E16: 40000 | F16: 0 | G16: 44251.03 | I16: Transfer to SBI self | J16: Contra - SBI | K16: SBI 1227 | L16: 0.9 | M16: [DIFF]
A17: 45757 | B17: UPI/P2M/100335047021/Autope Payment Soluti/Paymen/HDFC BANK LTD | C17: - | D17: 45757 | E17: 5704.5 | F17: 0 | G17: 38546.53 | I17: UPI | J17: UPI - IRCTC | K17: Travel | L17: 0.88 | M17: [MATCH]
A18: 45763 | B18: NEFT/MB/AXOMB10626155334/AAYUSH KUMAR GUPTA/STATE BANK OF INDIA/FAMILY | C18: - | D18: 45763 | E18: 25000 | F18: 0 | G18: 13546.53 | I18: Transfer to SBI self | J18: Contra - SBI | K18: SBI 1227 | L18: 0.9 | M18: [DIFF]
A19: 45779 | B19: NEFT/HDFCH00213942923/MPHASIS LIMITED/HDFC BANK/0001SALARYAPR2025 | C19: - | D19: 45779 | E19: 0 | F19: 98850 | G19: 112396.53 | I19: Salary | J19: Salary | K19: Salary | L19: 0.97 | M19: [MATCH]
A20: 45779 | B20: UPI/P2A/294187471225/AAYUSH KUMAR GUPTA /UPI/State Bank Of India | C20: - | D20: 45779 | E20: 1 | F20: 0 | G20: 112395.53 | I20: UPI | J20: Contra - SBI | K20: SBI 1227 | L20: 0.9 | M20: [MATCH]
A21: 45779 | B21: UPI/P2A/294427061225/AAYUSH KUMAR GUPTA /UPI/Kotak Mahindra Bank | C21: - | D21: 45779 | E21: 1 | F21: 0 | G21: 112394.53 | I21: UPI | J21: Contra - Kotak | K21: KOTAK 0333 | L21: 0.9 | M21: [MATCH]
A22: 45779 | B22: UPI/P2A/294526291225/AAYUSH KUMAR GUPTA /UPI/Kotak Mahindra Bank | C22: - | D22: 45779 | E22: 65000 | F22: 0 | G22: 47394.53 | I22: Transfer to Kotak self | J22: Contra - Kotak | K22: KOTAK 0333 | L22: 0.9 | M22: [DIFF]
A23: 45780 | B23: UPI/P2A/415981531235/AAYUSH KUMAR GUPTA /UPI/Kotak Mahindra Bank | C23: - | D23: 45780 | E23: 7000 | F23: 0 | G23: 40394.53 | I23: Transfer to Kotak self | J23: Contra - Kotak | K23: KOTAK 0333 | L23: 0.9 | M23: [DIFF]
A24: 45789 | B24: UPI/P2M/477823321325/Krishna Sagar /UPI/YES BANK LIMITED YBS | C24: - | D24: 45789 | E24: 60 | F24: 0 | G24: 40334.53 | H24: Krishna Sagar | I24: UPI | J24: UPI Payment | K24: Personal | L24: 0.55 | M24: [MATCH]
A25: 45789 | B25: UPI/P2A/478925241325/KETAN YADAV SO KRISHN/UPI/UNION BANK OF INDIA | C25: - | D25: 45789 | E25: 125 | F25: 0 | G25: 40209.53 | H25: Ketan Yadav So Krishn | I25: UPI | J25: UPI Payment | K25: Personal | L25: 0.55 | M25: [MATCH]
A26: 45798 | B26: UPI/P2M/439678151415/CRED Club /paymen/AXIS BANK | C26: - | D26: 45798 | E26: 1000 | F26: 0 | G26: 39209.53 | I26: UPI | J26: Credit Card Bill Payment (CRED) | K26: Credit Card | L26: 0.85 | M26: [DIFF]
A27: 45799 | B27: UPI/P2M/544150001425/CRED Club /paymen/AXIS BANK | C27: - | D27: 45799 | E27: 1240.66 | F27: 0 | G27: 37968.87 | I27: UPI | J27: Credit Card Bill Payment (CRED) | K27: Credit Card | L27: 0.85 | M27: [DIFF]
A28: 45806 | B28: UPI/P2A/514924201264/MEGHA GUP/HDFC BANK/Paid via/ | C28: - | D28: 45806 | E28: 0 | F28: 1001 | G28: 38969.87 | I28: UPI | J28: Received - Megha Gupta | K28: Megha Gupta | L28: 0.85 | M28: [DIFF]
A29: 45806 | B29: UPI/P2A/445834401495/MEGHA GUPTA /UPI/HDFC BANK LTD | C29: - | D29: 45806 | E29: 1001 | F29: 0 | G29: 37968.87 | I29: UPI | J29: Transfer - Megha Gupta | K29: Megha Gupta | L29: 0.85 | M29: [DIFF]
A30: 45810 | B30: NEFT/HDFCH00273980424/MPHASIS LIMITED/HDFC BANK/0001SALARYMAY2025 | C30: - | D30: 45810 | E30: 0 | F30: 102548 | G30: 140516.87 | I30: Salary | J30: Salary | K30: Salary | L30: 0.97 | M30: [MATCH]
A31: 45810 | B31: UPI/P2M/858334901535/CRED RENT /paymen/AXIS BANK | C31: - | D31: 45810 | E31: 23000 | F31: 0 | G31: 117516.87 | J31: Rent Payment (via CRED) | K31: Rent | L31: 0.88 | M31: N/A
A32: 45810 | B32: UPI/P2A/868844991535/AAYUSH KUMAR GUPTA /UPI/Kotak Mahindra Bank | C32: - | D32: 45810 | E32: 5000 | F32: 0 | G32: 112516.87 | J32: Contra - Kotak | K32: KOTAK 0333 | L32: 0.9 | M32: N/A
A33: 45810 | B33: UPI/P2A/869103531535/AAYUSH KUMAR GUPTA /UPI/Kotak Mahindra Bank | C33: - | D33: 45810 | E33: 40000 | F33: 0 | G33: 72516.87 | J33: Contra - Kotak | K33: KOTAK 0333 | L33: 0.9 | M33: N/A
A34: 45821 | B34: UPI/P2A/264644071645/AAYUSH KUMAR GUPTA /UPI/Kotak Mahindra Bank | C34: - | D34: 45821 | E34: 15000 | F34: 0 | G34: 57516.87 | J34: Contra - Kotak | K34: KOTAK 0333 | L34: 0.9 | M34: N/A
A35: 45835 | B35: UPI/P2A/118805941785/Miss. MEGHA GUPTA /15k hb/CENTRAL BANK OF INDI | C35: - | D35: 45835 | E35: 15000 | F35: 0 | G35: 42516.87 | J35: Transfer - Megha Gupta | K35: Megha Gupta | L35: 0.85 | M35: N/A
A36: 45839 | B36: SB:915010020334307:Int.Pd:01-04-2025 to 30-06-2025 | C36: - | D36: 45839 | E36: 0 | F36: 291 | G36: 42807.87 | J36: Bank Interest | K36: Bank Interest | L36: 0.93 | M36: N/A
A37: 45839 | B37: NEFT/HDFCH00331835485/MPHASIS LIMITED/HDFC BANK/0001SALARYJUN2025 | C37: - | D37: 45839 | E37: 0 | F37: 98850 | G37: 141657.87 | J37: Salary | K37: Salary | L37: 0.97 | M37: N/A
A38: 45840 | B38: UPI/P2A/107436117872/Miss MEGH/CENTRAL B/UPI/ | C38: - | D38: 45840 | E38: 0 | F38: 30000 | G38: 171657.87 | J38: Received - Megha Gupta | K38: Megha Gupta | L38: 0.85 | M38: N/A
A39: 45840 | B39: UPI/P2A/774946241835/Miss. MEGHA GUPTA /UPI/CENTRAL BANK OF INDI | C39: - | D39: 45840 | E39: 40000 | F39: 0 | G39: 131657.87 | J39: Transfer - Megha Gupta | K39: Megha Gupta | L39: 0.85 | M39: N/A
A40: 45840 | B40: UPI/P2A/107437679484/Miss MEGH/CENTRAL B/UPI/ | C40: - | D40: 45840 | E40: 0 | F40: 40000 | G40: 171657.87 | J40: Received - Megha Gupta | K40: Megha Gupta | L40: 0.85 | M40: N/A
A41: 45841 | B41: UPI/P2M/820086391845/CRED RENT /paymen/AXIS BANK | C41: - | D41: 45841 | E41: 23000 | F41: 0 | G41: 148657.87 | J41: Rent Payment (via CRED) | K41: Rent | L41: 0.88 | M41: N/A
...

Sheet HDFC
B1: HDFC Bank Narration Sheet
B2: Colour Legend of Categories:
B3: SIP | C3: HDFC Securities - Settlement | D3: HDFC Securities - Buy | E3: HDFC Securities - Sell | F3: Annuity Income
B4: Bank Charges | C4: Cash Withdrawal | D4: Depository Charges | E4: Received - Dnyaneshwar Kuyate | F4: UPI - Amazon
B5: Received - Ashok Divedi | C5: UPI - Fresh Produce | D5: UPI - MedPlus | E5: Transfer - Sunita Gupta | F5: Received - Ajay Gupta
B6: Dividend Income | C6: Transfer - Archit Gupta | D6: Received - Sunita Gupta | E6: Received - Archit Gupta | F6: Lounge Access Charge
B7: Bank Interest | C7: Securities Settlement | D7: Transfer - Ajay Gupta | E7: Insurance Premium | F7: Equity Buy (JSW Cement)
B8: Received - Sunil Kumar Pathak | C8: Received - Alok Kumar Gupta | D8: MF Redemption | E8: Contra - SBI
A10: Date | B10: Particulars | C10: Ref | D10: Value_Date | E10: DR | F10: CR | G10: Balance | H10: Beneficiary | I10: Human_Narration | J10: Auto_Narration | K10: Account_Head | L10: Confidence | M10: Match
A11: 45748 | B11: ACH D- TP ACH INDIANESIGN-1758642535 | C11: 0000006650023609 | D11: 45748 | E11: 5000 | F11: 0 | G11: 24321.48 | J11: SIP | K11: SIP | L11: 0.95 | M11: N/A
A12: 45749 | B12: FT- 623432246-50200085415108 - HDFC SECURITIES LTD-CLIENT DSCNB A/C - | C12: 0000001009359686 | D12: 45749 | E12: 0 | F12: 5239.85 | G12: 29561.33 | J12: HDFC Securities - Settlement | K12: HDFC Securities | L12: 0.93 | M12: N/A
A13: 45749 | B13: NET PI TO HSL SEC A/C 2554606-00602340029427 | C13: 0000000623593417 | D13: 45749 | E13: 150.26 | F13: 0 | G13: 29411.07 | J13: HDFC Securities - Buy | K13: HDFC Securities | L13: 0.97 | M13: N/A
A14: 45749 | B14: NET PI TO HSL SEC A/C 2554606-00602340029427 | C14: 0000000623760831 | D14: 45749 | E14: 9081.73 | F14: 0 | G14: 20329.34 | J14: HDFC Securities - Buy | K14: HDFC Securities | L14: 0.97 | M14: N/A
A15: 45750 | B15: FT- 623852638-50200085415108 - HDFC SECURITIES LTD-CLIENT DSCNB A/C - | C15: 0000001010969056 | D15: 45750 | E15: 0 | F15: 656.71 | G15: 20986.05 | J15: HDFC Securities - Settlement | K15: HDFC Securities | L15: 0.93 | M15: N/A
A16: 45750 | B16: NET PI TO HSL SEC A/C 2554606-00602340029427 | C16: 0000000624008014 | D16: 45750 | E16: 134.41 | F16: 0 | G16: 20851.64 | J16: HDFC Securities - Buy | K16: HDFC Securities | L16: 0.97 | M16: N/A
A17: 45751 | B17: FT- 624254248-50200085415108 - HDFC SECURITIES LTD-CLIENT DSCNB A/C - | C17: 0000001012795998 | D17: 45751 | E17: 0 | F17: 10041.41 | G17: 30893.05 | J17: HDFC Securities - Settlement | K17: HDFC Securities | L17: 0.93 | M17: N/A
A18: 45751 | B18: NET PI TO HSL SEC A/C 2554606-00602340029427 | C18: 0000000624385290 | D18: 45751 | E18: 115.2 | F18: 0 | G18: 30777.85 | J18: HDFC Securities - Buy | K18: HDFC Securities | L18: 0.97 | M18: N/A
A19: 45751 | B19: NET PO FROM HSL A/C 2554606-50200085415108 | C19: 0000000624619061 | D19: 45751 | E19: 0 | F19: 6146.26 | G19: 36924.11 | J19: HDFC Securities - Sell | K19: HDFC Securities | L19: 0.97 | M19: N/A
A20: 45754 | B20: HDFCLIFE CENTR-038144668 | C20: 0000504070711353 | D20: 45754 | E20: 0 | F20: 1880 | G20: 38804.11 | J20: Annuity Income | K20: Annuity | L20: 0.95 | M20: N/A
A21: 45754 | B21: NET PI TO HSL SEC A/C 2554606-00602340029427 | C21: 0000000624943357 | D21: 45754 | E21: 323.04 | F21: 0 | G21: 38481.07 | J21: HDFC Securities - Buy | K21: HDFC Securities | L21: 0.97 | M21: N/A
A22: 45754 | B22: NET PI TO HSL SEC A/C 2554606-00602340029427 | C22: 0000000625232784 | D22: 45754 | E22: 6242.17 | F22: 0 | G22: 32238.9 | J22: HDFC Securities - Buy | K22: HDFC Securities | L22: 0.97 | M22: N/A
... A669: 46113 | B669: INTEREST PAID TILL 31-MAR-2026 | C669: 000000000000000 | D669: 46112 | E669: 0 | F669: 162 | G669: 162 | J669: Bank Interest | K669: Bank Interest | L669: 0.95 | M669: N/A

Sheet KOTAK
B1: Kotak Mahindra Bank Narration Sheet
B2: Colour Legend of Categories:
B3: UPI Payment | C3: SuperMoney (Rewards) | D3: Zerodha Broking | E3: MF Redemption | F3: UPI - CRED
B4: UPI Reversal | C4: Credit Card Bill Payment (CRED) | D4: Govt / Utility Payment | E4: Salary | F4: Transfer - Megha Gupta
B5: UPI - IRCTC | C5: Received - Megha Gupta | D5: Contra - SBI | E5: SIP | F5: Rent Payment (via CRED)
B6: Contra - Axis | C6: UPI - Amazon | D6: IMPS Receipt | E6: UPI - BharatPe | F6: Refund - Wakefit
B7: UPI - Nandini Dairy | C7: Dividend Income | D7: Received - Archit Gupta | E7: Transfer - Archit Gupta | F7: UPI - Fuel
B8: Cashback - Kiwi | C8: INDmoney Investment | D8: Depository Credit | E8: Card Purchase | F8: Bank Interest
B9: UPI - Google Play | C9: Contra - SBM | D9: UPI - Navi | E9: UPI - District (Dining) | F9: Received - Tejas P
B10: Received - Utkarsh Bhandar | C10: Received - Kriti Gupta | D10: Received - Google Pay | E10: Misc Income | F10: UPI - Hotstar
B11: UPI - OpenAI | C11: IPO Application (UPI) | D11: Received - Google India Di | E11: UPI - Zomato | F11: MF Investment
B12: Bank Charges
A14: Date | B14: Particulars | C14: Ref | D14: Value_Date | E14: DR | F14: CR | G14: Balance | H14: Beneficiary | I14: Human_Narration | J14: Auto_Narration | K14: Account_Head | L14: Confidence | M14: Match
A15: 45748.457 | B15: UPI/BARATHI ANBAZHA/509137039846/Paid via SuperM | C15: UPI-509197194351 | D15: 45748 | E15: 121 | F15: 0 | G15: 1612.19 | H15: Barathi Anbazha | J15: UPI Payment | K15: Personal | L15: 0.55 | M15: N/A
A16: 45748.709 | B16: UPI/SAMOSA PARTY Ba/509141156489/Paid via SuperM | C16: UPI-509118876248 | D16: 45748 | E16: 30 | F16: 0 | G16: 1582.19 | H16: Samosa Party Ba | J16: UPI Payment | K16: Personal | L16: 0.55 | M16: N/A
A17: 45750.765 | B17: UPI/Mrs. G Pavithr/509367683617/Paid via SuperM | C17: UPI-509356331060 | D17: 45750 | E17: 50 | F17: 0 | G17: 1532.19 | H17: Mrs. G Pavithr | J17: UPI Payment | K17: Personal | L17: 0.55 | M17: N/A
A18: 45750.949 | B18: UPI/supermoney/509381273041/Supermoney Rewa | C18: UPI-509376992939 | D18: 45750 | E18: 0 | F18: 66.74 | G18: 1598.93 | J18: SuperMoney (Rewards) | K18: Misc Income | L18: 0.88 | M18: N/A
A19: 45751.957 | B19: UPI/WALKO FOOD COMP/509484810231/Paid via SuperM | C19: UPI-509442182659 | D19: 45751 | E19: 285 | F19: 0 | G19: 1313.93 | H19: Walko Food Comp | J19: UPI Payment | K19: Personal | L19: 0.55 | M19: N/A
A20: 45752.341 | B20: NEFT YESF350953824281 ZERODHA BROKING LTD DSCNB A | C20: NEFTINW-1174470955 | D20: 45752 | E20: 0 | F20: 4213.71 | G20: 5527.64 | J20: Zerodha Broking | K20: Zerodha Broking Limited | L20: 0.92 | M20: N/A
A21: 45752.781 | B21: UPI/Counter 4/509593584977/Paid via SuperM | C21: UPI-509588244702 | D21: 45752 | E21: 210 | F21: 0 | G21: 5317.64 | H21: Counter 4 | J21: UPI Payment | K21: Personal | L21: 0.55 | M21: N/A
A22: 45753.756 | B22: UPI/DINESH KUMAR GU/546205310184/Paid via SuperM | C22: UPI-509648113097 | D22: 45753 | E22: 30 | F22: 0 | G22: 5287.64 | H22: Dinesh Kumar Gu | J22: UPI Payment | K22: Personal | L22: 0.55 | M22: N/A
A23: 45758.422 | B23: NEFT AXISCN0958713705 NIPPON INDIA SMALL CAP FUND | C23: NEFTINW-1180794199 | D23: 45758 | E23: 0 | F23: 501 | G23: 5788.64 | J23: MF Redemption | K23: Mutual Funds | L23: 0.85 | M23: N/A
A24: 45758.846 | B24: UPI/Ferdus Alom/546773545667/Paid via CRED a | C24: UPI-510184999331 | D24: 45758 | E24: 279 | F24: 0 | G24: 5509.64 | J24: UPI - CRED | K24: Personal | L24: 0.68 | M24: N/A
A25: 45758.846 | B25: REV-UPI/Ferdus Alom/546773545667/ | C25: UPI-510184999331 | D25: 45758 | E25: 0 | F25: 279 | G25: 5788.64 | J25: UPI Reversal | K25: Personal | L25: 0.88 | M25: N/A
A26: 45758.846 | B26: UPI/Ferdus Alom/546773546667/Paid via CRED a | C26: UPI-510185051060 | D26: 45758 | E26: 279 | F26: 0 | G26: 5509.64 | J26: UPI - CRED | K26: Personal | L26: 0.68 | M26: N/A
A27: 45758.846 | B27: REV-UPI/Ferdus Alom/546773546667/ | C27: UPI-510185051060 | D27: 45758 | E27: 0 | F27: 279 | G27: 5788.64 | J27: UPI Reversal | K27: Personal | L27: 0.88 | M27: N/A
A28: 45758.949 | B28: UPI/CRED/546773735558/payment on CRED | C28: UPI-510195642472 | D28: 45758 | E28: 1500 | F28: 0 | G28: 4288.64 | J28: Credit Card Bill Payment (CRED) | K28: Credit Card | L28: 0.85 | M28: N/A
A29: 45762.399 | B29: UPI/SBIMOPS/547177174910/MOPSUPITxn | C29: UPI-510591765767 | D29: 45762 | E29: 1500 | F29: 0 | G29: 2788.64 | J29: Govt / Utility Payment | K29: Utilities | L29: 0.82 | M29: N/A
A30: 45763.345 | B30: UPI/CRED/547278151800/payment on CRED | C30: UPI-510652750321 | D30: 45763 | E30: 1000 | F30: 0 | G30: 1788.64 | J30: Credit Card Bill Payment (CRED) | K30: Credit Card | L30: 0.85 | M30: N/A
A31: 45763.46 | B31: TRANS | C31: FCM-250416G7VEUG | D31: 45763 | E31: 0 | F31: 91056 | G31: 92844.64 | J31: Salary | K31: Salary | L31: 0.85 | M31: N/A
A32: 45763.472 | B32: UPI/Miss. MEGHA GU/547278323187/Happy 3 month A | C32: UPI-510661882848 | D32: 45763 | E32: 10000 | F32: 0 | G32: 82844.64 | J32: Transfer - Megha Gupta | K32: Megha Gupta | L32: 0.85 | M32: N/A
A33: 45764.28 | B33: UPI/IRCTC CF/100375704017/IRCTC TICKET BO | C33: UPI-510713871404 | D33: 45764 | E33: 427.25 | F33: 0 | G33: 82417.39 | J33: UPI - IRCTC | K33: Travel | L33: 0.68 | M33: N/A
A34: 45764.567 | B34: UPI/CredClub/547379551441/payment on CRED | C34: UPI-510733285335 | D34: 45764 | E34: 1000 | F34: 0 | G34: 81417.39 | J34: Credit Card Bill Payment (CRED) | K34: Credit Card | L34: 0.85 | M34: N/A
... A37: 45766.693 | B37: UPI/CRED/547581914199/payment on CRED | C37: UPI-510965727111 | D37: 45766 | E37: 1000 | F37: 0 | G37: 78417.39 | J37: Credit Card Bill Payment (CRED) | K37: Credit Card | L37: 0.85 | M37: N/A
A38: 45766.887 | B38: UPI/ASHIK KHAN/510976601574/Paid via SuperM | C38: UPI-510987188278 | D38: 45766 | E38: 85 | F38: 0 | G38: 78332.39 | H38: Ashik Khan | J38: UPI Payment | K38: Personal | L38: 0.55 | M38: N/A
A39: 45766.909 | B39: UPI/MAHENDRA SINGH/510977058907/Paid via SuperM | C39: UPI-510989447720 | D39: 45766 | E39: 25 | F39: 0 | G39: 78307.39 | H39: Mahendra Singh | J39: UPI Payment | K39: Personal | L39: 0.55 | M39: N/A
A40: 45767.809 | B40: UPI/MEGHA GUPTA/547683296341/Paid via CRED | C40: UPI-511039130892 | D40: 45767 | E40: 0 | F40: 10 | G40: 78317.39 | J40: Received - Megha Gupta | K40: Megha Gupta | L40: 0.85 | M40: N/A
A41: 45767.832 | B41: UPI/CRED/547683353682/payment on CRED | C41: UPI-511041990132 | D41: 45767 | E41: 1000 | F41: 0 | G41: 77317.39 | J41: Credit Card Bill Payment (CRED) | K41: Credit Card | L41: 0.85 | M41: N/A
A42: 45768.346 | B42: UPI/CRED/547783701613/payment on CRED | C42: UPI-511161263012 | D42: 45768 | E42: 1012.11 | F42: 0 | G42: 76305.28 | J42: Credit Card Bill Payment (CRED) | K42: Credit Card | L42: 0.85 | M42: N/A
A43: 45770.337 | B43: NEFT HDFCH00196714813 MIRAE ASSET MF REDEMPTION A | C43: NEFTINW-1191507783 | D43: 45770 | E43: 0 | F43: 6904.51 | G43: 83209.79 | J43: MF Redemption | K43: Mutual Funds | L43: 0.85 | M43: N/A
...

Sheet SBI
B1: State Bank of India Narration Sheet
B2: Colour Legend of Categories:
B3: Contra - Axis | C3: Rent | D3: Credit Card Bill Payment (CRED) | E3: Transfer - Megha Gupta | F3: UPI - Paytm
B4: UPI - Nandini Dairy | C4: UPI Payment | D4: Misc Income | E4: MF Investment | F4: Contra - Kotak
B5: Received - Megha Gupta | C5: UPI - IRCTC | D5: NEFT Transfer | E5: Received - Razorpay | F5: Bank Interest
B6: UPI - Google Pay | C6: UPI - Swiggy | D6: Received - Laxmidha | E6: Received - Jaikisha | F6: Transfer - Ajay Gupta
B7: Transfer - Sunita Gupta | C7: Received - Ajay Gupta | D7: Received - Premier | E7: Income Tax Refund | F7: Zerodha Broking
B8: Received - Archit Gupta | C8: Transfer - Archit Gupta | D8: Received - Tn99 | E8: Freelance Income | F8: Received - Chirag P
B9: Contra - HDFC | C9: Contra - Self | D9: Received - Shetaans | E9: Received - Yash Gupta | F9: Cashback - BHIM
B10: UPI Receipt | C10: UPI - Hotstar | D10: SuperMoney (Rewards)
A12: Date | B12: Particulars | C12: Ref | D12: Value_Date | E12: DR | F12: CR | G12: Balance | H12: Beneficiary | I12: Human_Narration | J12: Auto_Narration | K12: Account_Head | L12: Confidence | M12: Match
A13: 45749 | B13: DEP TFR UPI/CR/765226990925/AAYUSH K/UTIB/9594435 259/UPI 0097735162098 AT 11669 SHIVAJI NAGAR NASIK | D13: 45749 | E13: 0 | F13: 1 | G13: 10987.03 | J13: Contra - Axis | K13: AXIS | L13: 0.9 | M13: N/A
A14: 45749 | B14: DEP TFR UPI/CR/765382250925/AAYUSH K/UTIB/9594435 259/UPI 0097735162098 AT 11669 SHIVAJI NAGAR NASIK | D14: 45749 | E14: 0 | F14: 40000 | G14: 50987.03 | J14: Contra - Axis | K14: AXIS | L14: 0.9 | M14: N/A
A15: 45749 | B15: WDL TFR UPI/DR/545893374949/CRED RENT/UTIB/cred.re nt@/pay 0097693162093 AT 11669 SHIVAJI NAGAR NASIK | D15: 45749 | E15: 23000 | F15: 0 | G15: 27987.03 | J15: Rent | K15: Rent | L15: 0.9 | M15: N/A
A16: 45749 | B16: DEP TFR NEFT*UTIB0002656*AXOMB09202414101*AAYUSH K UMAR GU 0099509044300 AT 11669 SHIVAJI NAGAR NASIK | D16: 45749 | E16: 0 | F16: 1 | G16: 27988.03 | J16: Contra - Axis | K16: AXIS | L16: 0.9 | M16: N/A
A17: 45749 | B17: WDL TFR UPI/DR/509208961213/CRED Club/UTIB/cred.cl ub@/pay 0097693162093 AT 11669 SHIVAJI NAGAR NASIK | D17: 45749 | E17: 3000 | F17: 0 | G17: 24988.03 | J17: Credit Card Bill Payment (CRED) | K17: Credit Card | L17: 0.85 | M17: N/A
A18: 45749 | B18: WDL TFR UPI/DR/545868712527/Miss. ME/CBIN/meghagha ti/Paid 0097693162093 AT 11669 SHIVAJI NAGAR NASIK | D18: 45749 | E18: 2000 | F18: 0 | G18: 22988.03 | J18: Transfer - Megha Gupta | K18: Megha Gupta | L18: 0.85 | M18: N/A
A19: 45749 | B19: WDL TFR UPI/DR/545878868808/CRED Club/UTIB/cred.cl ub@/pay 0097693162093 AT 11669 SHIVAJI NAGAR NASIK | D19: 45749 | E19: 2000 | F19: 0 | G19: 20988.03 | J19: Credit Card Bill Payment (CRED) | K19: Credit Card | L19: 0.85 | M19: N/A
A20: 45749 | B20: WDL TFR UPI/DR/545887987358/CRED Club/UTIB/cred.cl ub@/pay 0097693162093 AT 11669 SHIVAJI NAGAR NASIK | D20: 45749 | E20: 2000 | F20: 0 | G20: 18988.03 | J20: Credit Card Bill Payment (CRED) | K20: Credit Card | L20: 0.85 | M20: N/A
A21: 45750 | B21: WDL TFR UPI/DR/545972230401/CRED Club/UTIB/cred.cl ub@/pay 0097694162092 AT 11669 SHIVAJI NAGAR NASIK | D21: 45750 | E21: 2000 | F21: 0 | G21: 16988.03 | J21: Credit Card Bill Payment (CRED) | K21: Credit Card | L21: 0.85 | M21: N/A
A22: 45750 | B22: WDL TFR UPI/DR/509378949775/CRED Club/UTIB/cred.cl ub@/pay 0097694162092 AT 11669 SHIVAJI NAGAR NASIK | D22: 45750 | E22: 2000 | F22: 0 | G22: 14988.03 | J22: Credit Card Bill Payment (CRED) | K22: Credit Card | L22: 0.85 | M22: N/A
A23: 45750 | B23: WDL TFR UPI/DR/509336037048/CRED Club/UTIB/cred.cl ub@/pay 0097694162092 AT 11669 SHIVAJI NAGAR NASIK | D23: 45750 | E23: 2360.82 | F23: 0 | G23: 12627.21 | J23: Credit Card Bill Payment (CRED) | K23: Credit Card | L23: 0.85 | M23: N/A
A24: 45751 | B24: WDL TFR UPI/DR/509438120147/MATS FUE/YESB/paytm-31 10/Paid 0097695162091 AT 11669 SHIVAJI NAGAR NASIK | D24: 45751 | E24: 210 | F24: 0 | G24: 12417.21 | J24: UPI - Paytm | K24: Personal | L24: 0.65 | M24: N/A
A25: 45752 | B25: WDL TFR UPI/DR/546194213465/Nandini/YESB/paytm.s1 c3/Paid 0097696162090 AT 11669 SHIVAJI NAGAR NASIK | D25: 45752 | E25: 60 | F25: 0 | G25: 12357.21 | J25: UPI - Nandini Dairy | K25: Groceries | L25: 0.82 | M25: N/A
A26: 45758 | B26: WDL TFR UPI/DR/510189443769/Ferdus /FINO/fardusal om/Paid 0097695162091 AT 11669 SHIVAJI NAGAR NASIK | D26: 45758 | E26: 279 | F26: 0 | G26: 12078.21 | H26: Ferdus | J26: UPI Payment | K26: Personal | L26: 0.55 | M26: N/A
A27: 45758 | B27: DEP TFR UPI/REV/510189443769 0097 695162091 AT 11669 SHIVAJI NAGAR NASIK | D27: 45758 | E27: 0 | F27: 279 | G27: 12357.21 | J27: Misc Income | K27: Misc Income | L27: 0.7 | M27: N/A
A28: 45758 | B28: WDL TFR UPI/DR/510127516128/Miss. ME/CBIN/meghagha ti/Paid 0097695162091 AT 11669 SHIVAJI NAGAR NASIK | D28: 45758 | E28: 10 | F28: 0 | G28: 12347.21 | J28: Transfer - Megha Gupta | K28: Megha Gupta | L28: 0.85 | M28: N/A
A29: 45762 | B29: WDL TFR UPI/DR/510522647751/BHARAT S/IOBA/84248520 34/Paid 0097692162094 AT 11669 SHIVAJI NAGAR NASIK | D29: 45762 | E29: 40 | F29: 0 | G29: 12307.21 | H29: Bharat S | J29: UPI Payment | K29: Personal | L29: 0.55 | M29: N/A
A30: 45763 | B30: DEP TFR NEFT*UTIB0002656*AXOMB10626155334*AAYUSH K UMAR GU 0099509044300 AT 11669 SHIVAJI NAGAR NASIK | D30: 45763 | E30: 0 | F30: 25000 | G30: 37307.21 | J30: Contra - Axis | K30: AXIS | L30: 0.9 | M30: N/A
A31: 45763 | B31: WDL TFR UPI/DR/510629877598/Indian C/HDFC/icclzero dh/Merc 0097693162093 AT 11669 SHIVAJI NAGAR NASIK | D31: 45763 | E31: 25000 | F31: 0 | G31: 12307.21 | J31: MF Investment | K31: Investments | L31: 0.9 | M31: N/A
A32: 45773 | B32: DEP TFR UPI/CR/548257957091/AAYUSH K/KKBK/95944352 59/Paid 0097738162095 AT 11669 SHIVAJI NAGAR NASIK | D32: 45773 | E32: 0 | F32: 5000 | G32: 17307.21 | J32: Contra - Kotak | K32: KOTAK 0333 | L32: 0.9 | M32: N/A
A33: 45773 | B33: WDL TFR SBIYA25116092502872203439-Deposit or Inv 0039706 255133 OF Mr. AAYUSH KUMAR GUPTA AT 11669 SHIVAJI NAGAR NASIK | D33: 45773 | E33: 5100 | F33: 0 | G33: 12207.21 | J33: SBI PPF | K33: PPF Deposit | L33: 0.9 | M33: N/A
A34: 45779 | B34: DEP TFR UPI/CR/294187471225/AAYUSH K/UTIB/9594435 259/UPI 0097737162096 AT 11669 SHIVAJI NAGAR NASIK | D34: 45779 | E34: 0 | F34: 1 | G34: 12208.21 | J34: Contra - Axis | K34: AXIS | L34: 0.9 | M34: N/A
A35: 45781 | B35: WDL TFR UPI/DR/512468818878/SURUSHE /YESB/Q770971 173/UPI 0097690162095 AT 11669 SHIVAJI NAGAR NASIK | D35: 45781 | E35: 60 | F35: 0 | G35: 12148.21 | H35: Surushe | J35: UPI Payment | K35: Personal | L35: 0.55 | M35: N/A
A36: 45781 | B36: WDL TFR UPI/DR/512468929763/BHIMA RAM/YESB/Q280789 230/UPI 0097690162095 AT 11669 SHIVAJI NAGAR NASIK | D36: 45781 | E36: 114 | F36: 0 | G36: 12034.21 | H36: Bhima Ram | J36: UPI Payment | K36: Personal | L36: 0.55 | M36: N/A
A37: 45785 | B37: DEP TFR UPI/CR/512804757639/MEGHA GU/HDFC/80056043 28/Paid 0097736162097 AT 11669 SHIVAJI NAGAR NASIK | D37: 45785 | E37: 0 | F37: 10 | G37: 12044.21 | J37: Received - Megha Gupta | K37: Megha Gupta | L37: 0.85 | M37: N/A
A38: 45806 | B38: DEP TFR UPI/CR/514924194600/MEGHA GU/HDFC/80056043 28/Paid 0097736162097 AT 11669 SHIVAJI NAGAR NASIK | D38: 45806 | E38: 0 | F38: 1001 | G38: 13045.21 | J38: Received - Megha Gupta | K38: Megha Gupta | L38: 0.85 | M38: N/A
A39: 45806 | B39: WDL TFR UPI/DR/551503965355/MEGHA GU/HDFC/80056043 28/Paid 0097694162092 AT 11669 SHIVAJI NAGAR NASIK | D39: 45806 | E39: 1001 | F39: 0 | G39: 12044.21 | J39: Transfer - Megha Gupta | K39: Megha Gupta | L39: 0.85 | M39: N/A
A40: 45807 | B40: WDL TFR UPI/DR/551616084739/IRCTC CF/HDFC/irctc.cf @h/IRCT 0097695162091 AT 11669 SHIVAJI NAGAR NASIK | D40: 45807 | E40: 437.25 | F40: 0 | G40: 11606.96 | J40: UPI - IRCTC | K40: Travel | L40: 0.68 | M40: N/A
A41: 45810 | B41: DEP TFR IMPS/515322719699/IDF-XX432-PERFIOS /hdf cLifeD 0098302162091 AT 11669 SHIVAJI NAGAR NASIK | D41: 45810 | E41: 0 | F41: 1 | G41: 11607.96 | J41: NEFT Transfer | K41: Transfer | L41: 0.7 | M41: N/A
...

Sheet SBM Bank
B1: SBM Bank Narration Sheet
B2: Colour Legend of Categories:
B3: Bank Interest | C3: Contra - Kotak
A5: Date | B5: Particulars | C5: Ref | D5: Value_Date | E5: DR | F5: CR | G5: Balance | H5: Beneficiary | I5: Human_Narration | J5: Auto_Narration | K5: Account_Head | L5: Confidence | M5: Match
A6: 45778 | B6: 20052205306441:Int.Pd:31-03-2025 to 30-04-2025 | D6: 45778 | E6: 0 | F6: 1 | G6: 238 | I6: Bank Interest | J6: Bank Interest | K6: Bank Interest | L6: 0.97 | M6: [MATCH]
A7: 45809 | B7: 20052205306441:Int.Pd:01-05-2025 to 31-05-2025 | D7: 45809 | E7: 0 | F7: 1 | G7: 239 | I7: Bank Interest | J7: Bank Interest | K7: Bank Interest | L7: 0.97 | M7: [MATCH]
A8: 45839 | B8: 20052205306441:Int.Pd:01-06-2025 to 30-06-2025 | D8: 45839 | E8: 0 | F8: 1 | G8: 240 | I8: Bank Interest | J8: Bank Interest | K8: Bank Interest | L8: 0.97 | M8: [MATCH]
A9: 45870 | B9: 20052205306441:Int.Pd:01-07-2025 to 31-07-2025 | D9: 45870 | E9: 0 | F9: 1 | G9: 241 | I9: Bank Interest | J9: Bank Interest | K9: Bank Interest | L9: 0.97 | M9: [MATCH]
A10: 45870 | B10: NEFT/STCB010825236957/Aayush Kumar Gupta | C10: STCB010825236957 | D10: 45870 | E10: 241 | F10: 0 | G10: 0 | I10: Contra - Kotak | J10: Contra - Kotak | K10: KOTAK 0333 | L10: 0.9 | M10: [MATCH]

Sheet For Tally
B1: Tally Export Narration Sheet
B2: Colour Legend of Categories:
B3: SIP | C3: UPI Payment | D3: Contra - SBI | E3: Contra - Axis | F3: Rent
B4: Credit Card Bill Payment (CRED) | C4: Transfer - Megha Gupta | D4: Salary | E4: HDFC Securities - Settlement | F4: HDFC Securities - Buy
B5: SuperMoney (Rewards) | C5: HDFC Securities - Sell | D5: UPI - Paytm | E5: UPI - Nandini Dairy | F5: Zerodha Broking
B6: Annuity Income | C6: Bank Charges | D6: UPI - IRCTC | E6: Misc Income | F6: MF Redemption
B7: UPI - CRED | C7: UPI Reversal | D7: Cash Withdrawal | E7: Govt / Utility Payment | F7: MF Investment
B8: Depository Charges | C8: Received - Dnyaneshwar Kuyate | D8: Received - Megha Gupta | E8: Contra - Kotak | F8: UPI - Amazon
B9: Received - Ashok Divedi | C9: Bank Interest | D9: UPI - Fresh Produce | E9: Rent Payment (via CRED) | F9: UPI - MedPlus
B10: IMPS Receipt | C10: Transfer - Sunita Gupta | D10: Received - Ajay Gupta | E10: UPI - BharatPe | F10: Dividend Income
B11: Transfer - Archit Gupta | C11: Received - Sunita Gupta | D11: Refund - Wakefit | E11: Received - Archit Gupta | F11: NEFT Transfer
B12: UPI - Fuel | C12: Received - Razorpay | D12: Cashback - Kiwi | E12: INDmoney Investment | F12: Depository Credit
B13: Card Purchase | C13: Lounge Access Charge | D13: Securities Settlement | E13: Transfer - Ajay Gupta | F13: UPI - Fuel (HPCL)
B14: UPI - Google Pay | C14: UPI - Google Play | D14: UPI - Star Bazaar | E14: Insurance Premium | F14: Contra - SBM
... B22: Received - Ret | C22: Contra - Self | D22: Contra - HDFC | E22: Received - Shetaans | F22: Received - Yash Gupta
B23: Cashback - BHIM | C23: UPI Receipt | D23: UPI - Flipkart
A25: TX Date | B25: Date | C25: DR | D25: CR | E25: Beneficiary | F25: Narration | G25: Confidence | H25: Account Head | I25: Account No | J25: Kya Hai? | K25: Particulars | L25: Bank | M25: Duplicate
A26: 45748 | B26: 45748 | C26: 5000 | D26: 0 | F26: SIP | G26: 0.95 | H26: SIP | I26: HDFC 5413 | K26: ACH D- TP ACH INDIANESIGN-1758642535 | L26: HDFC Bank
A27: 45748.457 | B27: 45748 | C27: 121 | D27: 0 | E27: Barathi Anbazha | F27: UPI Payment | G27: 0.55 | H27: Personal | I27: KOTAK 0333 | K27: UPI/BARATHI ANBAZHA/509137039846/Paid via SuperM | L27: Kotak Mahindra Bank
A28: 45748.709 | B28: 45748 | C28: 30 | D28: 0 | E28: Samosa Party Ba | F28: UPI Payment | G28: 0.55 | H28: Personal | I28: KOTAK 0333 | K28: UPI/SAMOSA PARTY Ba/509141156489/Paid via SuperM | L28: Kotak Mahindra Bank
A29: 45749 | B29: 45749 | C29: 1 | D29: 0 | F29: Contra - SBI | G29: 0.9 | H29: SBI 1227 | I29: AXIS | J29: UPI | K29: UPI/P2A/765226990925/AAYUSH KUMAR GUPTA /UPI/State Bank Of India | L29: Axis Bank | M29: ⚠ Possible Duplicate
A30: 45749 | B30: 45749 | C30: 40000 | D30: 0 | F30: Contra - SBI | G30: 0.9 | H30: SBI 1227 | I30: AXIS | J30: Transfer to SBI self | K30: UPI/P2A/765382250925/AAYUSH KUMAR GUPTA /UPI/State Bank Of India | L30: Axis Bank
A31: 45749 | B31: 45749 | C31: 0 | D31: 1 | F31: Contra - Axis | G31: 0.9 | H31: AXIS | I31: SBI 1227 | K31: DEP TFR UPI/CR/765226990925/AAYUSH K/UTIB/9594435 259/UPI 0097735162098 AT 11669 SHIVAJI NAGAR NASIK | L31: State Bank of India | M31: ⚠ Possible Duplicate
A32: 45749 | B32: 45749 | C32: 0 | D32: 40000 | F32: Contra - Axis | G32: 0.9 | H32: AXIS | I32: SBI 1227 | K32: DEP TFR UPI/CR/765382250925/AAYUSH K/UTIB/9594435 259/UPI 0097735162098 AT 11669 SHIVAJI NAGAR NASIK | L32: State Bank of India
A33: 45749 | B33: 45749 | C33: 23000 | D33: 0 | F33: Rent | G33: 0.9 | H33: Rent | I33: SBI 1227 | K33: WDL TFR UPI/DR/545893374949/CRED RENT/UTIB/cred.re nt@/pay 0097693162093 AT 11669 SHIVAJI NAGAR NASIK | L33: State Bank of India
A34: 45749 | B34: 45749 | C34: 0 | D34: 1 | F34: Contra - Axis | G34: 0.9 | H34: AXIS | I34: SBI 1227 | K34: DEP TFR NEFT*UTIB0002656*AXOMB09202414101*AAYUSH K UMAR GU 0099509044300 AT 11669 SHIVAJI NAGAR NASIK | L34: State Bank of India | M34: ⚠ Possible Duplicate
A35: 45749 | B35: 45749 | C35: 3000 | D35: 0 | F35: Credit Card Bill Payment (CRED) | G35: 0.85 | H35: Credit Card | I35: SBI 1227 | K35: WDL TFR UPI/DR/509208961213/CRED Club/UTIB/cred.cl ub@/pay 0097693162093 AT 11669 SHIVAJI NAGAR NASIK | L35: State Bank of India
A36: 45749 | B36: 45749 | C36: 2000 | D36: 0 | F36: Transfer - Megha Gupta | G36: 0.85 | H36: Megha Gupta | I36: SBI 1227 | K36: WDL TFR UPI/DR/545868712527/Miss. ME/CBIN/meghagha ti/Paid 0097693162093 AT 11669 SHIVAJI NAGAR NASIK | L36: State Bank of India
A37: 45749 | B37: 45749 | C37: 2000 | D37: 0 | F37: Credit Card Bill Payment (CRED) | G37: 0.85 | H37: Credit Card | I37: SBI 1227 | K37: WDL TFR UPI/DR/545878868808/CRED Club/UTIB/cred.cl ub@/pay 0097693162093 AT 11669 SHIVAJI NAGAR NASIK | L37: State Bank of India | M37: ⚠ Possible Duplicate
A38: 45749 | B38: 45749 | C38: 2000 | D38: 0 | F38: Credit Card Bill Payment (CRED) | G38: 0.85 | H38: Credit Card | I38: SBI 1227 | K38: WDL TFR UPI/DR/545887987358/CRED Club/UTIB/cred.cl ub@/pay 0097693162093 AT 11669 SHIVAJI NAGAR NASIK | L38: State Bank of India | M38: ⚠ Possible Duplicate
A39: 45749 | B39: 45749 | C39: 1 | D39: 0 | F39: Contra - SBI | G39: 0.9 | H39: SBI 1227 | I39: AXIS | J39: UPI | K39: NEFT/MB/AXOMB09202414101/AAYUSH KUMAR GUPTA/STATE BANK OF INDIA/ | L39: Axis Bank | M39: ⚠ Possible Duplicate
A40: 45749 | B40: 45749 | C40: 0 | D40: 66897 | F40: Salary | G40: 0.95 | H40: Salary | I40: AXIS | J40: Salary | K40: Salary For the Month of Mar 2025 | L40: Axis Bank
A41: 45749 | B41: 45749 | C41: 0 | D41: 5239.85 | F41: HDFC Securities - Settlement | G41: 0.93 | H41: HDFC Securities | I41: HDFC 5413 | K41: FT- 623432246-50200085415108 - HDFC SECURITIES LTD-CLIENT DSCNB A/C - | L41: HDFC Bank
A42: 45749 | B42: 45749 | C42: 9081.73 | D42: 0 | F42: HDFC Securities - Buy | G42: 0.97 | H42: HDFC Securities | I42: HDFC 5413 | K42: NET PI TO HSL SEC A/C 2554606-00602340029427 | L42: HDFC Bank
A43: 45749 | B43: 45749 | C43: 150.26 | D43: 0 | F43: HDFC Securities - Buy | G43: 0.97 | H43: HDFC Securities | I43: HDFC 5413 | K43: NET PI TO HSL SEC A/C 2554606-00602340029427 | L43: HDFC Bank
A44: 45750 | B44: 45750 | C44: 0 | D44: 656.71 | F44: HDFC Securities - Settlement | G44: 0.93 | H44: HDFC Securities | I44: HDFC 5413 | K44: FT- 623852638-50200085415108 - HDFC SECURITIES LTD-CLIENT DSCNB A/C - | L44: HDFC Bank
A45: 45750 | B45: 45750 | C45: 134.41 | D45: 0 | F45: HDFC Securities - Buy | G45: 0.97 | H45: HDFC Securities | I45: HDFC 5413 | K45: NET PI TO HSL SEC A/C 2554606-00602340029427 | L45: HDFC Bank
A46: 45750 | B46: 45750 | C46: 2000 | D46: 0 | F46: Credit Card Bill Payment (CRED) | G46: 0.85 | H46: Credit Card | I46: SBI 1227 | K46: WDL TFR UPI/DR/545972230401/CRED Club/UTIB/cred.cl ub@/pay 0097694162092 AT 11669 SHIVAJI NAGAR NASIK | L46: State Bank of India | M46: ⚠ Possible Duplicate
A47: 45750 | B47: 45750 | C47: 2360.82 | D47: 0 | F47: Credit Card Bill Payment (CRED) | G47: 0.85 | H47: Credit Card | I47: SBI 1227 | K47: WDL TFR UPI/DR/509336037048/CRED Club/UTIB/cred.cl ub@/pay 0097694162092 AT 11669 SHIVAJI NAGAR NASIK | L47: State Bank of India
A48: 45750 | B48: 45750 | C48: 2000 | D48: 0 | F48: Credit Card Bill Payment (CRED) | G48: 0.85 | H48: Credit Card | I48: SBI 1227 | K48: WDL TFR UPI/DR/509378949775/CRED Club/UTIB/cred.cl ub@/pay 0097694162092 AT 11669 SHIVAJI NAGAR NASIK | L48: State Bank of India | M48: ⚠ Possible Duplicate
...

Sheet Conso
A1: Aayush Kumar Gupta
A2: Account of Statements from 01-Apr-2025 to 01-Apr-2026 | D2: =SUM(D5:D1565) -> 4127912.7 | E2: =SUM(E5:E1565) -> 4094424.7 | F2: =E2-D2 -> -33487.95
A4: TX Date | B4: Particulars | C4: Ref | D4: DR | E4: CR | F4: Balance | G4: Account Head | H4: Account No
A5: 45748 | B5: ACH D- TP ACH INDIANESIGN-1758642535 | C5: 0000006650023609 | D5: 5000 | E5: 0 | F5: 24321.48 | G5: SIP | H5: HDFC 5413
A6: 45748.457 | B6: UPI/BARATHI ANBAZHA/509137039846/Paid via SuperM | C6: UPI-509197194351 | D6: 121 | E6: 0 | F6: 1612.19 | G6: Personal | H6: KOTAK 0333
A7: 45748.709 | B7: UPI/SAMOSA PARTY Ba/509141156489/Paid via SuperM | C7: UPI-509118876248 | D7: 30 | E7: 0 | F7: 1582.19 | G7: Personal | H7: KOTAK 0333
A8: 45749 | B8: UPI/P2A/765226990925/AAYUSH KUMAR GUPTA /UPI/State Bank Of India | C8: - | D8: 1 | E8: 0 | F8: 84251.03 | G8: SBI 1227 | H8: AXIS
A9: 45749 | B9: UPI/P2A/765382250925/AAYUSH KUMAR GUPTA /UPI/State Bank Of India | C9: - | D9: 40000 | E9: 0 | F9: 44251.03 | G9: SBI 1227 | H9: AXIS
A10: 45749 | B10: DEP TFR UPI/CR/765226990925/AAYUSH K/UTIB/9594435 259/UPI 0097735162098 AT 11669 SHIVAJI NAGAR NASIK | D10: 0 | E10: 1 | F10: 10987.03 | G10: AXIS | H10: SBI 1227
A11: 45749 | B11: DEP TFR UPI/CR/765382250925/AAYUSH K/UTIB/9594435 259/UPI 0097735162098 AT 11669 SHIVAJI NAGAR NASIK | D11: 0 | E11: 40000 | F11: 50987.03 | G11: AXIS | H11: SBI 1227
A12: 45749 | B12: WDL TFR UPI/DR/545893374949/CRED RENT/UTIB/cred.re nt@/pay 0097693162093 AT 11669 SHIVAJI NAGAR NASIK | D12: 23000 | E12: 0 | F12: 27987.03 | G12: Rent | H12: SBI 1227
A13: 45749 | B13: DEP TFR NEFT*UTIB0002656*AXOMB09202414101*AAYUSH K UMAR GU 0099509044300 AT 11669 SHIVAJI NAGAR NASIK | D13: 0 | E13: 1 | F13: 27988.03 | G13: AXIS | H13: SBI 1227
A14: 45749 | B14: WDL TFR UPI/DR/509208961213/CRED Club/UTIB/cred.cl ub@/pay 0097693162093 AT 11669 SHIVAJI NAGAR NASIK | D14: 3000 | E14: 0 | F14: 24988.03 | G14: Credit Card | H14: SBI 1227
A15: 45749 | B15: WDL TFR UPI/DR/545868712527/Miss. ME/CBIN/meghagha ti/Paid 0097693162093 AT 11669 SHIVAJI NAGAR NASIK | D15: 2000 | E15: 0 | F15: 22988.03 | G15: Megha Gupta | H15: SBI 1227
A16: 45749 | B16: WDL TFR UPI/DR/545878868808/CRED Club/UTIB/cred.cl ub@/pay 0097693162093 AT 11669 SHIVAJI NAGAR NASIK | D16: 2000 | E16: 0 | F16: 20988.03 | G16: Credit Card | H16: SBI 1227
A17: 45749 | B17: WDL TFR UPI/DR/545887987358/CRED Club/UTIB/cred.cl ub@/pay 0097693162093 AT 11669 SHIVAJI NAGAR NASIK | D17: 2000 | E17: 0 | F17: 18988.03 | G17: Credit Card | H17: SBI 1227
A18: 45749 | B18: NEFT/MB/AXOMB09202414101/AAYUSH KUMAR GUPTA/STATE BANK OF INDIA/ | C18: - | D18: 1 | E18: 0 | F18: 84252.03 | G18: SBI 1227 | H18: AXIS
A19: 45749 | B19: Salary For the Month of Mar 2025 | C19: - | D19: 0 | E19: 66897 | F19: 84253.03 | G19: Salary | H19: AXIS
A20: 45749 | B20: FT- 623432246-50200085415108 - HDFC SECURITIES LTD-CLIENT DSCNB A/C - | C20: 0000001009359686 | D20: 0 | E20: 5239.85 | F20: 29561.33 | G20: HDFC Securities | H20: HDFC 5413
A21: 45749 | B21: NET PI TO HSL SEC A/C 2554606-00602340029427 | C21: 0000000623760831 | D21: 9081.73 | E21: 0 | F21: 20329.34 | G21: HDFC Securities | H21: HDFC 5413
A22: 45749 | B22: NET PI TO HSL SEC A/C 2554606-00602340029427 | C22: 0000000623593417 | D22: 150.26 | E22: 0 | F22: 29411.07 | G22: HDFC Securities | H22: HDFC 5413
A23: 45750 | B23: FT- 623852638-50200085415108 - HDFC SECURITIES LTD-CLIENT DSCNB A/C - | C23: 0000001010969056 | D23: 0 | E23: 656.71 | F23: 20986.05 | G23: HDFC Securities | H23: HDFC 5413
A24: 45750 | B24: NET PI TO HSL SEC A/C 2554606-00602340029427 | C24: 0000000624008014 | D24: 134.41 | E24: 0 | F24: 20851.64 | G24: HDFC Securities | H24: HDFC 5413
A25: 45750 | B25: WDL TFR UPI/DR/545972230401/CRED Club/UTIB/cred.cl ub@/pay 0097694162092 AT 11669 SHIVAJI NAGAR NASIK | D25: 2000 | E25: 0 | F25: 16988.03 | G25: Credit Card | H25: SBI 1227
A26: 45750 | B26: WDL TFR UPI/DR/509336037048/CRED Club/UTIB/cred.cl ub@/pay 0097694162092 AT 11669 SHIVAJI NAGAR NASIK | D26: 2360.82 | E26: 0 | F26: 12627.21 | G26: Credit Card | H26: SBI 1227
A27: 45750 | B27: WDL TFR UPI/DR/509378949775/CRED Club/UTIB/cred.cl ub@/pay 0097694162092 AT 11669 SHIVAJI NAGAR NASIK | D27: 2000 | E27: 0 | F27: 14988.03 | G27: Credit Card | H27: SBI 1227
A28: 45750.765 | B28: UPI/Mrs. G Pavithr/509367683617/Paid via SuperM | C28: UPI-509356331060 | D28: 50 | E28: 0 | F28: 1532.19 | G28: Personal | H28: KOTAK 0333
A29: 45750.949 | B29: UPI/supermoney/509381273041/Supermoney Rewa | C29: UPI-509376992939 | D29: 0 | E29: 66.74 | F29: 1598.93 | G29: Misc Income | H29: KOTAK 0333
A30: 45751 | B30: FT- 624254248-50200085415108 - HDFC SECURITIES LTD-CLIENT DSCNB A/C - | C30: 0000001012795998 | D30: 0 | E30: 10041.41 | F30: 30893.05 | G30: HDFC Securities | H30: HDFC 5413
A31: 45751 | B31: NET PI TO HSL SEC A/C 2554606-00602340029427 | C31: 0000000624385290 | D31: 115.2 | E31: 0 | F31: 30777.85 | G31: HDFC Securities | H31: HDFC 5413
A32: 45751 | B32: NET PO FROM HSL A/C 2554606-50200085415108 | C32: 0000000624619061 | D32: 0 | E32: 6146.26 | F32: 36924.11 | G32: HDFC Securities | H32: HDFC 5413
A33: 45751 | B33: WDL TFR UPI/DR/509438120147/MATS FUE/YESB/paytm-31 10/Paid 0097695162091 AT 11669 SHIVAJI NAGAR NASIK | D33: 210 | E33: 0 | F33: 12417.21 | G33: Personal | H33: SBI 1227
A34: 45751.957 | B34: UPI/WALKO FOOD COMP/509484810231/Paid via SuperM | C34: UPI-509442182659 | D34: 285 | E34: 0 | F34: 1313.93 | G34: Personal | H34: KOTAK 0333
A35: 45752 | B35: WDL TFR UPI/DR/546194213465/Nandini/YESB/paytm.s1 c3/Paid 0097696162090 AT 11669 SHIVAJI NAGAR NASIK | D35: 60 | E35: 0 | F35: 12357.21 | G35: Groceries | H35: SBI 1227
A36: 45752.341 | B36: NEFT YESF350953824281 ZERODHA BROKING LTD DSCNB A | C36: NEFTINW-1174470955 | D36: 0 | E36: 4213.71 | F36: 5527.64 | G36: Zerodha Broking Limited | H36: KOTAK 0333
A37: 45752.781 | B37: UPI/Counter 4/509593584977/Paid via SuperM | C37: UPI-509588244702 | D37: 210 | E37: 0 | F37: 5317.64 | G37: Personal | H37: KOTAK 0333
A38: 45753.756 | B38: UPI/DINESH KUMAR GU/546205310184/Paid via SuperM | C38: UPI-509648113097 | D38: 30 | E38: 0 | F38: 5287.64 | G38: Personal | H38: KOTAK 0333
A39: 45754 | B39: NET PI TO HSL SEC A/C 2554606-00602340029427 | C39: 0000000624943357 | D39: 323.04 | E39: 0 | F39: 38481.07 | G39: HDFC Securities | H39: HDFC 5413
A40: 45754 | B40: HDFCLIFE CENTR-038144668 | C40: 0000504070711353 | D40: 0 | E40: 1880 | F40: 38804.11 | G40: Annuity | H40: HDFC 5413
A41: 45754 | B41: NET PI TO HSL SEC A/C 2554606-00602340029427 | C41: 0000000625232784 | D41: 6242.17 | E41: 0 | F41: 32238.9 | G41: HDFC Securities | H41: HDFC 5413
...

Sheet Bank Summary
A1: All Banks
A2: Aayush Gupta Bank Summary
A3: 01-Apr-2025 to 01-Apr-2026
A5: Narration | B5: Total Credit (₹) | C5: Narration | D5: Total Debit (₹)
A6: Annuity Income | B6: =SUMIFS('For Tally'!D:D, 'For Tally'!F:F, A6) -> 22560 | C6: Annuity Income | D6: =SUMIFS('For Tally'!C:C, 'For Tally'!F:F, C6) -> 0
A7: Bank Charges | B7: =SUMIFS('For Tally'!D:D, 'For Tally'!F:F, A7) -> 0 | C7: Bank Charges | D7: =SUMIFS('For Tally'!C:C, 'For Tally'!F:F, C7) -> 2368.96
A8: Bank Interest | B8: =SUMIFS('For Tally'!D:D, 'For Tally'!F:F, A8) -> 3390 | C8: Bank Interest | D8: =SUMIFS('For Tally'!C:C, 'For Tally'!F:F, C8) -> 0
A9: Card Purchase | B9: =SUMIFS('For Tally'!D:D, 'For Tally'!F:F, A9) -> 0 | C9: Card Purchase | D9: =SUMIFS('For Tally'!C:C, 'For Tally'!F:F, C9) -> 4
A10: Cash Withdrawal | B10: =SUMIFS('For Tally'!D:D, 'For Tally'!F:F, A10) -> 0 | C10: Cash Withdrawal | D10: =SUMIFS('For Tally'!C:C, 'For Tally'!F:F, C10) -> 500
A11: Cashback - BHIM | B11: =SUMIFS('For Tally'!D:D, 'For Tally'!F:F, A11) -> 93 | C11: Cashback - BHIM | D11: =SUMIFS('For Tally'!C:C, 'For Tally'!F:F, C11) -> 0
A12: Cashback - Kiwi | B12: =SUMIFS('For Tally'!D:D, 'For Tally'!F:F, A12) -> 8 | C12: Cashback - Kiwi | D12: =SUMIFS('For Tally'!C:C, 'For Tally'!F:F, C12) -> 0
A13: Contra - Axis | B13: =SUMIFS('For Tally'!D:D, 'For Tally'!F:F, A13) -> 448836.97 | C13: Contra - Axis | D13: =SUMIFS('For Tally'!C:C, 'For Tally'!F:F, C13) -> 0
A14: Contra - HDFC | B14: =SUMIFS('For Tally'!D:D, 'For Tally'!F:F, A14) -> 50000 | C14: Contra - HDFC | D14: =SUMIFS('For Tally'!C:C, 'For Tally'!F:F, C14) -> 0
A15: Contra - Kotak | B15: =SUMIFS('For Tally'!D:D, 'For Tally'!F:F, A15) -> 17217.71 | C15: Contra - Kotak | D15: =SUMIFS('For Tally'!C:C, 'For Tally'!F:F, C15) -> 368605.37
A16: Contra - SBI | B16: =SUMIFS('For Tally'!D:D, 'For Tally'!F:F, A16) -> 56000 | C16: Contra - SBI | D16: =SUMIFS('For Tally'!C:C, 'For Tally'!F:F, C16) -> 203690.31
A17: Contra - SBM | B17: =SUMIFS('For Tally'!D:D, 'For Tally'!F:F, A17) -> 241 | C17: Contra - SBM | D17: =SUMIFS('For Tally'!C:C, 'For Tally'!F:F, C17) -> 0
... A109: Zerodha Broking | B109: =SUMIFS('For Tally'!D:D, 'For Tally'!F:F, A109) -> 35971 | C109: Zerodha Broking | D109: =SUMIFS('For Tally'!C:C, 'For Tally'!F:F, C109) -> 208000
A110: TOTAL | B110: =SUM(B5:B109) -> 4094424.8 | C110: TOTAL | D110: =SUM(D5:D109) -> 4127912.7 | E110: Net | F110: =B110-D110 -> -33487.95
A112: Opening & Closing Balances
A113: Account | B113: Opening Balance (₹) | C113: Closing Balance (₹)
A114: AXIS | B114: 17356.03 | C114: =B114 + SUMIFS('For Tally'!D:D, 'For Tally'!I:I, A114) - SUMIFS('For Tally'!C:C, 'For Tally'!I:I, A114) -> 5572.57
A115: HDFC 5413 | B115: 29321.48 | C115: =B115 + SUMIFS('For Tally'!D:D, 'For Tally'!I:I, A115) - SUMIFS('For Tally'!C:C, 'For Tally'!I:I, A115) -> 162
A116: KOTAK 0333 | B116: 1733.19 | C116: =B116 + SUMIFS('For Tally'!D:D, 'For Tally'!I:I, A116) - SUMIFS('For Tally'!C:C, 'For Tally'!I:I, A116) -> 8538.08
A117: SBI 1227 | B117: 10986.03 | C117: =B117 + SUMIFS('For Tally'!D:D, 'For Tally'!I:I, A117) - SUMIFS('For Tally'!C:C, 'For Tally'!I:I, A117) -> 11873.13
A118: SBM | B118: 237 | C118: =B118 + SUMIFS('For Tally'!D:D, 'For Tally'!I:I, A118) - SUMIFS('For Tally'!C:C, 'For Tally'!I:I, A118) -> 0
A120: Confidence Distribution
A121: Band | B121: Count | C121: % of Total
A122: High (≥ 0.85) — Confident | B122: =COUNTIF('For Tally'!G:G, ">=0.85") -> 1124 | C122: =B122/SUM(B122:B124) -> 0.72005125
A123: Medium (0.60–0.84) — Review | B123: =COUNTIFS('For Tally'!G:G, ">=0.60", 'For Tally'!G:G, "<0.85") -> 171 | C123: =B123/SUM(B122:B124) -> 0.10954516
A124: Low (< 0.60) — Needs attention | B124: =COUNTIF('For Tally'!G:G, "<0.60") -> 266 | C124: =B124/SUM(B122:B124) -> 0.17040359

Sheet Monthly Pivot
A1: Monthly Spend & Income Pivot
A3: Bank Filter Toggles: | B3: Axis Bank | C3: HDFC Bank | D3: Kotak Mahindra Bank | E3: SBM Bank | F3: State Bank of India
B4: TRUE | C4: TRUE | D4: TRUE | E4: TRUE | F4: TRUE
B5: =IF(B4, B3, "") -> Axis Bank | C5: =IF(C4, C3, "") -> HDFC Bank | D5: =IF(D4, D3, "") -> Kotak Mahindra Bank | E5: =IF(E4, E3, "") -> SBM Bank | F5: =IF(F4, F3, "") -> State Bank of India
A7: PAYMENTS / DEBITS (Bank) | B7: Apr-2025 | C7: May-2025 | D7: Jun-2025 | E7: Jul-2025 | F7: Aug-2025 | G7: Sep-2025 | H7: Oct-2025 | I7: Nov-2025 | J7: Dec-2025 | K7: Jan-2026 | L7: Feb-2026 | M7: Mar-2026 | N7: Apr-2026 | O7: TOTAL
A8: Ajay Gupta | B8: =SUMPRODUCT(SUMIFS('For Tally'!C:C, 'For Tally'!H:H, $A8, 'For Tally'!A:A, ">=2025-04-01", 'For Tally'!A:A, "<=2025-04-30", 'For Tally'!L:L, $B$5:$F$5)) -> 0 | C8: =SUMPRODUCT(SUMIFS('For Tally'!C:C, 'For Tally'!H:H, $A8, 'For Tally'!A:A, ">=2025-05-01", 'For Tally'!A:A, "<=2025-05-31", 'For Tally'!L:L, $B$5:$F$5)) -> 0 | D8: =SUMPRODUCT(SUMIFS('For Tally'!C:C, 'For Tally'!H:H, $A8, 'For Tally'!A:A, ">=2025-06-01", 'For Tally'!A:A, "<=2025-06-30", 'For Tally'!L:L, $B$5:$F$5)) -> 0 | E8: =SUMPRODUCT(SUMIFS('For Tally'!C:C, 'For Tally'!H:H, $A8, 'For Tally'!A:A, ">=2025-07-01", 'For Tally'!A:A, "<=2025-07-31", 'For Tally'!L:L, $B$5:$F$5)) -> 10000 | F8: =SUMPRODUCT(SUMIFS('For Tally'!C:C, 'For Tally'!H:H, $A8, 'For Tally'!A:A, ">=2025-08-01", 'For Tally'!A:A, "<=2025-08-31", 'For Tally'!L:L, $B$5:$F$5)) -> 65001 | G8: =SUMPRODUCT(SUMIFS('For Tally'!C:C, 'For Tally'!H:H, $A8, 'For Tally'!A:A, ">=2025-09-01", 'For Tally'!A:A, "<=2025-09-30", 'For Tally'!L:L, $B$5:$F$5)) -> 50000 | H8: =SUMPRODUCT(SUMIFS('For Tally'!C:C, 'For Tally'!H:H, $A8, 'For Tally'!A:A, ">=2025-10-01", 'For Tally'!A:A, "<=2025-10-31", 'For Tally'!L:L, $B$5:$F$5)) -> 340000 | I8: =SUMPRODUCT(SUMIFS('For Tally'!C:C, 'For Tally'!H:H, $A8, 'For Tally'!A:A, ">=2025-11-01", 'For Tally'!A:A, "<=2025-11-30", 'For Tally'!L:L, $B$5:$F$5)) -> 30000 | J8: =SUMPRODUCT(SUMIFS('For Tally'!C:C, 'For Tally'!H:H, $A8, 'For Tally'!A:A, ">=2025-12-01", 'For Tally'!A:A, "<=2025-12-31", 'For Tally'!L:L, $B$5:$F$5)) -> 0 | K8: =SUMPRODUCT(SUMIFS('For Tally'!C:C, 'For Tally'!H:H, $A8, 'For Tally'!A:A, ">=2026-01-01", 'For Tally'!A:A, "<=2026-01-31", 'For Tally'!L:L, $B$5:$F$5)) -> 0 | L8: =SUMPRODUCT(SUMIFS('For Tally'!C:C, 'For Tally'!H:H, $A8, 'For Tally'!A:A, ">=2026-02-01", 'For Tally'!A:A, "<=2026-02-28", 'For Tally'!L:L, $B$5:$F$5)) -> 0 | M8: =SUMPRODUCT(SUMIFS('For Tally'!C:C, 'For Tally'!H:H, $A8, 'For Tally'!A:A, ">=2026-03-01", 'For Tally'!A:A, "<=2026-03-31", 'For Tally'!L:L, $B$5:$F$5)) -> 0 | N8: =SUMPRODUCT(SUMIFS('For Tally'!C:C, 'For Tally'!H:H, $A8, 'For Tally'!A:A, ">=2026-04-01", 'For Tally'!A:A, "<=2026-04-30", 'For Tally'!L:L, $B$5:$F$5)) -> 0 | O8: =SUM(B8:N8) -> 495001
A9: Archit Gupta | B9: =SUMPRODUCT(SUMIFS('For Tally'!C:C, 'For Tally'!H:H, $A9, 'For Tally'!A:A, ">=2025-04-01", 'For Tally'!A:A, "<=2025-04-30", 'For Tally'!L:L, $B$5:$F$5)) -> 0 | C9: =SUMPRODUCT(SUMIFS('For Tally'!C:C, 'For Tally'!H:H, $A9, 'For Tally'!A:A, ">=2025-05-01", 'For Tally'!A:A, "<=2025-05-31", 'For Tally'!L:L, $B$5:$F$5)) -> 100000 | D9: =SUMPRODUCT(SUMIFS('For Tally'!C:C, 'For Tally'!H:H, $A9, 'For Tally'!A:A, ">=2025-06-01", 'For Tally'!A:A, "<=2025-06-30", 'For Tally'!L:L, $B$5:$F$5)) -> 0 | E9: =SUMPRODUCT(SUMIFS('For Tally'!C:C, 'For Tally'!H:H, $A9, 'For Tally'!A:A, ">=2025-07-01", 'For Tally'!A:A, "<=2025-07-31", 'For Tally'!L:L, $B$5:$F$5)) -> 0 | F9: =SUMPRODUCT(SUMIFS('For Tally'!C:C, 'For Tally'!H:H, $A9, 'For Tally'!A:A, ">=2025-08-01", 'For Tally'!A:A, "<=2025-08-31", 'For Tally'!L:L, $B$5:$F$5)) -> 0 | G9: =SUMPRODUCT(SUMIFS('For Tally'!C:C, 'For Tally'!H:H, $A9, 'For Tally'!A:A, ">=2025-09-01", 'For Tally'!A:A, "<=2025-09-30", 'For Tally'!L:L, $B$5:$F$5)) -> 43200 | H9: =SUMPRODUCT(SUMIFS('For Tally'!C:C, 'For Tally'!H:H, $A9, 'For Tally'!A:A, ">=2025-10-01", 'For Tally'!A:A, "<=2025-10-31", 'For Tally'!L:L, $B$5:$F$5)) -> 0 | I9: =SUMPRODUCT(SUMIFS('For Tally'!C:C, 'For Tally'!H:H, $A9, 'For Tally'!A:A, ">=2025-11-01", 'For Tally'!A:A, "<=2025-11-30", 'For Tally'!L:L, $B$5:$F$5)) -> 0 | J9: =SUMPRODUCT(SUMIFS('For Tally'!C:C, 'For Tally'!H:H, $A9, 'For Tally'!A:A, ">=2025-12-01", 'For Tally'!A:A, "<=2025-12-31", 'For Tally'!L:L, $B$5:$F$5)) -> 10000 | K9: =SUMPRODUCT(SUMIFS('For Tally'!C:C, 'For Tally'!H:H, $A9, 'For Tally'!A:A, ">=2026-01-01", 'For Tally'!A:A, "<=2026-01-31", 'For Tally'!L:L, $B$5:$F$5)) -> 0 | L9: =SUMPRODUCT(SUMIFS('For Tally'!C:C, 'For Tally'!H:H, $A9, 'For Tally'!A:A, ">=2026-02-01", 'For Tally'!A:A, "<=2026-02-28", 'For Tally'!L:L, $B$5:$F$5)) -> 0 | M9: =SUMPRODUCT(SUMIFS('For Tally'!C:C, 'For Tally'!H:H, $A9, 'For Tally'!A:A, ">=2026-03-01", 'For Tally'!A:A, "<=2026-03-31", 'For Tally'!L:L, $B$5:$F$5)) -> 0 | N9: =SUMPRODUCT(SUMIFS('For Tally'!C:C, 'For Tally'!H:H, $A9, 'For Tally'!A:A, ">=2026-04-01", 'For Tally'!A:A, "<=2026-04-30", 'For Tally'!L:L, $B$5:$F$5)) -> 0 | O9: =SUM(B9:N9) -> 153200
A10: Bank Charges | B10: =SUMPRODUCT(SUMIFS('For Tally'!C:C, 'For Tally'!H:H, $A10, 'For Tally'!A:A, ">=2025-04-01", 'For Tally'!A:A, "<=2025-04-30", 'For Tally'!L:L, $B$5:$F$5)) -> 295 | C10: =SUMPRODUCT(SUMIFS('For Tally'!C:C, 'For Tally'!H:H, $A10, 'For Tally'!A:A, ">=2025-05-01", 'For Tally'!A:A, "<=2025-05-31", 'For Tally'!L:L, $B$5:$F$5)) -> 0 | D10: =SUMPRODUCT(SUMIFS('For Tally'!C:C, 'For Tally'!H:H, $A10, 'For Tally'!A:A, ">=2025-06-01", 'For Tally'!A:A, "<=2025-06-30", 'For Tally'!L:L, $B$5:$F$5)) -> 305.96 | E10: =SUMPRODUCT(SUMIFS('For Tally'!C:C, 'For Tally'!H:H, $A10, 'For Tally'!A:A, ">=2025-07-01", 'For Tally'!A:A, "<=2025-07-31", 'For Tally'!L:L, $B$5:$F$5)) -> 0 | F10: =SUMPRODUCT(SUMIFS('For Tally'!C:C, 'For Tally'!H:H, $A10, 'For Tally'!A:A, ">=2025-08-01", 'For Tally'!A:A, "<=2025-08-31", 'For Tally'!L:L, $B$5:$F$5)) -> 0 | G10: =SUMPRODUCT(SUMIFS('For Tally'!C:C, 'For Tally'!H:H, $A10, 'For Tally'!A:A, ">=2025-09-01", 'For Tally'!A:A, "<=2025-09-30", 'For Tally'!L:L, $B$5:$F$5)) -> 295 | H10: =SUMPRODUCT(SUMIFS('For Tally'!C:C, 'For Tally'!H:H, $A10, 'For Tally'!A:A, ">=2025-10-01", 'For Tally'!A:A, "<=2025-10-31", 'For Tally'!L:L, $B$5:$F$5)) -> 0 | I10: =SUMPRODUCT(SUMIFS('For Tally'!C:C, 'For Tally'!H:H, $A10, 'For Tally'!A:A, ">=2025-11-01", 'For Tally'!A:A, "<=2025-11-30", 'For Tally'!L:L, $B$5:$F$5)) -> 0 | J10: =SUMPRODUCT(SUMIFS('For Tally'!C:C, 'For Tally'!H:H, $A10, 'For Tally'!A:A, ">=2025-12-01", 'For Tally'!A:A, "<=2025-12-31", 'For Tally'!L:L, $B$5:$F$5)) -> 0 | K10: =SUMPRODUCT(SUMIFS('For Tally'!C:C, 'For Tally'!H:H, $A10, 'For Tally'!A:A, ">=2026-01-01", 'For Tally'!A:A, "<=2026-01-31", 'For Tally'!L:L, $B$5:$F$5)) -> 295 | L10: =SUMPRODUCT(SUMIFS('For Tally'!C:C, 'For Tally'!H:H, $A10, 'For Tally'!A:A, ">=2026-02-01", 'For Tally'!A:A, "<=2026-02-28", 'For Tally'!L:L, $B$5:$F$5)) -> 295 | M10: =SUMPRODUCT(SUMIFS('For Tally'!C:C, 'For Tally'!H:H, $A10, 'For Tally'!A:A, ">=2026-03-01", 'For Tally'!A:A, "<=2026-03-31", 'For Tally'!L:L, $B$5:$F$5)) -> 885 | N10: =SUMPRODUCT(SUMIFS('For Tally'!C:C, 'For Tally'!H:H, $A10, 'For Tally'!A:A, ">=2026-04-01", 'For Tally'!A:A, "<=2026-04-30", 'For Tally'!L:L, $B$5:$F$5)) -> 0 | O10: =SUM(B10:N10) -> 2370.96
A11: Cash | B11: =SUMPRODUCT(SUMIFS('For Tally'!C:C, 'For Tally'!H:H, $A11, 'For Tally'!A:A, ">=2025-04-01", 'For Tally'!A:A, "<=2025-04-30", 'For Tally'!L:L, $B$5:$F$5)) -> 500 | C11: =SUMPRODUCT(SUMIFS('For Tally'!C:C, 'For Tally'!H:H, $A11, 'For Tally'!A:A, ">=2025-05-01", 'For Tally'!A:A, "<=2025-05-31", 'For Tally'!L:L, $B$5:$F$5)) -> 0 | D11: =SUMPRODUCT(SUMIFS('For Tally'!C:C, 'For Tally'!H:H, $A11, 'For Tally'!A:A, ">=2025-06-01", 'For Tally'!A:A, "<=2025-06-30", 'For Tally'!L:L, $B$5:$F$5)) -> 0 | E11: =SUMPRODUCT(SUMIFS('For Tally'!C:C, 'For Tally'!H:H, $A11, 'For Tally'!A:A, ">=2025-07-01", 'For Tally'!A:A, "<=2025-07-31", 'For Tally'!L:L, $B$5:$F$5)) -> 0 | F11: =SUMPRODUCT(SUMIFS('For Tally'!C:C, 'For Tally'!H:H, $A11, 'For Tally'!A:A, ">=2025-08-01", 'For Tally'!A:A, "<=2025-08-31", 'For Tally'!L:L, $B$5:$F$5)) -> 0 | G11: =SUMPRODUCT(SUMIFS('For Tally'!C:C, 'For Tally'!H:H, $A11, 'For Tally'!A:A, ">=2025-09-01", 'For Tally'!A:A, "<=2025-09-30", 'For Tally'!L:L, $B$5:$F$5)) -> 0 | H11: =SUMPRODUCT(SUMIFS('For Tally'!C:C, 'For Tally'!H:H, $A11, 'For Tally'!A:A, ">=2025-10-01", 'For Tally'!A:A, "<=2025-10-31", 'For Tally'!L:L, $B$5:$F$5)) -> 0 | I11: =SUMPRODUCT(SUMIFS('For Tally'!C:C, 'For Tally'!H:H, $A11, 'For Tally'!A:A, ">=2025-11-01", 'For Tally'!A:A, "<=2025-11-30", 'For Tally'!L:L, $B$5:$F$5)) -> 0 | J11: =SUMPRODUCT(SUMIFS('For Tally'!C:C, 'For Tally'!H:H, $A11, 'For Tally'!A:A, ">=2025-12-01", 'For Tally'!A:A, "<=2025-12-31", 'For Tally'!L:L, $B$5:$F$5)) -> 0 | K11: =SUMPRODUCT(SUMIFS('For Tally'!C:C, 'For Tally'!H:H, $A11, 'For Tally'!A:A, ">=2026-01-01", 'For Tally'!A:A, "<=2026-01-31", 'For Tally'!L:L, $B$5:$F$5)) -> 0 | L11: =SUMPRODUCT(SUMIFS('For Tally'!C:C, 'For Tally'!H:H, $A11, 'For Tally'!A:A, ">=2026-02-01", 'For Tally'!A:A, "<=2026-02-28", 'For Tally'!L:L, $B$5:$F$5)) -> 0 | M11: =SUMPRODUCT(SUMIFS('For Tally'!C:C, 'For Tally'!H:H, $A11, 'For Tally'!A:A, ">=2026-03-01", 'For Tally'!A:A, "<=2026-03-31", 'For Tally'!L:L, $B$5:$F$5)) -> 0 | N11: =SUMPRODUCT(SUMIFS('For Tally'!C:C, 'For Tally'!H:H, $A11, 'For Tally'!A:A, ">=2026-04-01", 'For Tally'!A:A, "<=2026-04-30", 'For Tally'!L:L, $B$5:$F$5)) -> 0 | O11: =SUM(B11:N11) -> 500
A12: Credit Card | B12: =SUMPRODUCT(SUMIFS('For Tally'!C:C, 'For Tally'!H:H, $A12, 'For Tally'!A:A, ">=2025-04-01", 'For Tally'!A:A, "<=2025-04-30", 'For Tally'!L:L, $B$5:$F$5)) -> 21872.93 | C12: =SUMPRODUCT(SUMIFS('For Tally'!C:C, 'For Tally'!H:H, $A12, 'For Tally'!A:A, ">=2025-05-01", 'For Tally'!A:A, "<=2025-05-31", 'For Tally'!L:L, $B$5:$F$5)) -> 3240.66 | D12: =SUMPRODUCT(SUMIFS('For Tally'!C:C, 'For Tally'!H:H, $A12, 'For Tally'!A:A, ">=2025-06-01", 'For Tally'!A:A, "<=2025-06-30", 'For Tally'!L:L, $B$5:$F$5)) -> 25902.75 | E12: =SUMPRODUCT(SUMIFS('For Tally'!C:C, 'For Tally'!H:H, $A12, 'For Tally'!A:A, ">=2025-07-01", 'For Tally'!A:A, "<=2025-07-31", 'For Tally'!L:L, $B$5:$F$5)) -> 15134.43 | F12: =SUMPRODUCT(SUMIFS('For Tally'!C:C, 'For Tally'!H:H, $A12, 'For Tally'!A:A, ">=2025-08-01", 'For Tally'!A:A, "<=2025-08-31", 'For Tally'!L:L, $B$5:$F$5)) -> 9876.87 | G12: =SUMPRODUCT(SUMIFS('For Tally'!C:C, 'For Tally'!H:H, $A12, 'For Tally'!A:A, ">=2025-09-01", 'For Tally'!A:A, "<=2025-09-30", 'For Tally'!L:L, $B$5:$F$5)) -> 29186.82 | H12: =SUMPRODUCT(SUMIFS('For Tally'!C:C, 'For Tally'!H:H, $A12, 'For Tally'!A:A, ">=2025-10-01", 'For Tally'!A:A, "<=2025-10-31", 'For Tally'!L:L, $B$5:$F$5)) -> 46603.95 | I12: =SUMPRODUCT(SUMIFS('For Tally'!C:C, 'For Tally'!H:H, $A12, 'For Tally'!A:A, ">=2025-11-01", 'For Tally'!A:A, "<=2025-11-30", 'For Tally'!L:L, $B$5:$F$5)) -> 26440.5 | J12: =SUMPRODUCT(SUMIFS('For Tally'!C:C, 'For Tally'!H:H, $A12, 'For Tally'!A:A, ">=2025-12-01", 'For Tally'!A:A, "<=2025-12-31", 'For Tally'!L:L, $B$5:$F$5)) -> 20167.93 | K12: =SUMPRODUCT(SUMIFS('For Tally'!C:C, 'For Tally'!H:H, $A12, 'For Tally'!A:A, ">=2026-01-01", 'For Tally'!A:A, "<=2026-01-31", 'For Tally'!L:L, $B$5:$F$5)) -> 48809.24 | L12: =SUMPRODUCT(SUMIFS('For Tally'!C:C, 'For Tally'!H:H, $A12, 'For Tally'!A:A, ">=2026-02-01", 'For Tally'!A:A, "<=2026-02-28", 'For Tally'!L:L, $B$5:$F$5)) -> 22106.85 | M12: =SUMPRODUCT(SUMIFS('For Tally'!C:C, 'For Tally'!H:H, $A12, 'For Tally'!A:A, ">=2026-03-01", 'For Tally'!A:A, "<=2026-03-31", 'For Tally'!L:L, $B$5:$F$5)) -> 12183.37 | N12: =SUMPRODUCT(SUMIFS('For Tally'!C:C, 'For Tally'!H:H, $A12, 'For Tally'!A:A, ">=2026-04-01", 'For Tally'!A:A, "<=2026-04-30", 'For Tally'!L:L, $B$5:$F$5)) -> 0 | O12: =SUM(B12:N12) -> 281526.3
A13: Depository Charges | B13: =SUMPRODUCT(SUMIFS('For Tally'!C:C, 'For Tally'!H:H, $A13, 'For Tally'!A:A, ">=2025-04-01", 'For Tally'!A:A, "<=2025-04-30", 'For Tally'!L:L, $B$5:$F$5)) -> 531 | C13: =SUMPRODUCT(SUMIFS('For Tally'!C:C, 'For Tally'!H:H, $A13, 'For Tally'!A:A, ">=2025-05-01", 'For Tally'!A:A, "<=2025-05-31", 'For Tally'!L:L, $B$5:$F$5)) -> 1062 | D13: =SUMPRODUCT(SUMIFS('For Tally'!C:C, 'For Tally'!H:H, $A13, 'For Tally'!A:A, ">=2025-06-01", 'For Tally'!A:A, "<=2025-06-30", 'For Tally'!L:L, $B$5:$F$5)) -> 719.8 | E13: =SUMPRODUCT(SUMIFS('For Tally'!C:C, 'For Tally'!H:H, $A13, 'For Tally'!A:A, ">=2025-07-01", 'For Tally'!A:A, "<=2025-07-31", 'For Tally'!L:L, $B$5:$F$5)) -> 330.4 | F13: =SUMPRODUCT(SUMIFS('For Tally'!C:C, 'For Tally'!H:H, $A13, 'For Tally'!A:A, ">=2025-08-01", 'For Tally'!A:A, "<=2025-08-31", 'For Tally'!L:L, $B$5:$F$5)) -> 460.2 | G13: =SUMPRODUCT(SUMIFS('For Tally'!C:C, 'For Tally'!H:H, $A13, 'For Tally'!A:A, ">=2025-09-01", 'For Tally'!A:A, "<=2025-09-30", 'For Tally'!L:L, $B$5:$F$5)) -> 330.4 | H13: =SUMPRODUCT(SUMIFS('For Tally'!C:C, 'For Tally'!H:H, $A13, 'For Tally'!A:A, ">=2025-10-01", 'For Tally'!A:A, "<=2025-10-31", 'For Tally'!L:L, $B$5:$F$5)) -> 637.2 | I13: =SUMPRODUCT(SUMIFS('For Tally'!C:C, 'For Tally'!H:H, $A13, 'For Tally'!A:A, ">=2025-11-01", 'For Tally'!A:A, "<=2025-11-30", 'For Tally'!L:L, $B$5:$F$5)) -> 1109.2 | J13: =SUMPRODUCT(SUMIFS('For Tally'!C:C, 'For Tally'!H:H, $A13, 'For Tally'!A:A, ">=2025-12-01", 'For Tally'!A:A, "<=2025-12-31", 'For Tally'!L:L, $B$5:$F$5)) -> 365.8 | K13: =SUMPRODUCT(SUMIFS('For Tally'!C:C, 'For Tally'!H:H, $A13, 'For Tally'!A:A, ">=2026-01-01", 'For Tally'!A:A, "<=2026-01-31", 'For Tally'!L:L, $B$5:$F$5)) -> 82.6 | L13: =SUMPRODUCT(SUMIFS('For Tally'!C:C, 'For Tally'!H:H, $A13, 'For Tally'!A:A, ">=2026-02-01", 'For Tally'!A:A, "<=2026-02-28", 'For Tally'!L:L, $B$5:$F$5)) -> 94.4 | M13: =SUMPRODUCT(SUMIFS('For Tally'!C:C, 'For Tally'!H:H, $A13, 'For Tally'!A:A, ">=2026-03-01", 'For Tally'!A:A, "<=2026-03-31", 'For Tally'!L:L, $B$5:$F$5)) -> 82.6 | N13: =SUMPRODUCT(SUMIFS('For Tally'!C:C, 'For Tally'!H:H, $A13, 'For Tally'!A:A, ">=2026-04-01", 'For Tally'!A:A, "<=2026-04-30", 'For Tally'!L:L, $B$5:$F$5)) -> 0 | O13: =SUM(B13:N13) -> 5805.6
